Workbook

Sheet Portada y criterio
A1: VERIFICACIÓN SECCIONAL DE VIGAS — ENVOLVENTES DE FLEXIÓN Y CORTANTE
A3: Alcance | B3: 592 vigas de los 12 grupos SAP; diseño individual y resumen por grupo. No incluye viguetas.
A4: Fuente | B4: resultados sap.xlsx, SAP2000 v26, unidades kN, m, C; ENVFLEX y ENVCORT con máximos y mínimos.
A5: Flexión y cortante | B5: Mu se toma de ENVFLEX. Vu diseño = máx(Vu ENVCORT; Ve DMO), sin volver a dividir las fuerzas por R.
A6: Verificación DMO | B6: Ve = Vu_ENVFLEX + (Mpr−+Mpr+)/Ln, con Ln conservadora = máx(L estación−0.60 m; 0.50L).
A7: Torsión | B7: Tu = máx(|T| ENVFLEX; |T| ENVCORT), sin reducción automática a φTcr. Los 100 casos que exceden esa referencia requieren demostrar compatibilidad y reanalizar la redistribución antes de cualquier reducción.
A8: Acero de torsión | B8: Al se provee con barras Nº5 dedicadas, adicionales al acero requerido por flexión y distribuidas alrededor del perímetro; no se acredita doblemente As superior/inferior.
A9: Agrupación | B9: Cada grupo conserva color propio. El resumen usa el frame de mayor utilización real y evita combinar máximos incompatibles de vigas diferentes.
A10: Secciones SAP | B10: VC1–VC7 y VRAUX: 0.45×0.55 m. VR1, VR N1, VR2 y VR3: 0.50×0.55 m.
A11: Resultado | B11: 536 de 592 vigas cumplen con torsión bruta; 56 quedan NO CUMPLE y requieren rediseño/reanálisis SAP. El expediente completo es NO EMITIR PARA CONSTRUCCIÓN.
A12: RESULTADOS DE CONTROL
A13: Frames exportados/diseñados | B13: 592
A14: Vigas diseñadas | B14: 592
A15: Frames que exceden referencia φTcr | B15: 100
A16: Grupos | B16: 12
A17: Grupos que cumplen | B17: 6
A18: Vigas que cumplen | B18: 536
A19: Grupos con observación | B19: 6
A20: Vigas con observación | B20: 56

Sheet Parametros
A1: PARÁMETROS GENERALES
A2: f'c | B2: 28 | C2: MPa | D2: Concreto del proyecto
A3: fy | B3: 420 | C3: MPa | D3: Acero longitudinal
A4: fyt | B4: 420 | C4: MPa | D4: Acero transversal
A5: φ flexión | B5: 0.9 | C5: — | D5: Secciones controladas por tracción
A6: φ cortante/torsión | B6: 0.75 | C6: — | D6: NSR-10 Título C
A7: Recubrimiento | B7: 40 | C7: mm | D7: Vigas interiores
A8: Área barra longitudinal | B8: 199 | C8: mm² | D8: Nº5
A9: db estribo para d | B9: 12.7 | C9: mm | D9: Nº4, conservador; el estribo adoptado se calcula por fila
A10: Separación libre vertical | B10: 25 | C10: mm | D10: Entre capas
A11: Área rama de referencia | B11: 129 | C11: mm² | D11: Nº4; cada fila muestra el área realmente adoptada
A12: db longitudinal | B12: 15.9 | C12: mm | D12: Barra Nº5
A13: R₀ del sistema DMO | B13: 5 | C13: — | D13: Valor básico adoptado
... A17: R = R₀·φa·φp·φr | B17: 5 | C17: — | D17: Coeficiente usado para reducir Ex y Ey en ENVFLEX

Sheet Justificacion DMO
A1: JUSTIFICACIÓN DEL CORTANTE ADOPTADO — SISTEMA DMO, R = 5
A3: Decisión de diseño | B3: Se adopta directamente ENVCORT y, adicionalmente, se verifica el cortante por capacidad DMO. No se reduce ni se descarta ningún valor de la envolvente de cortante.
A4: Reducción sísmica | B4: R = R₀·φa·φp·φr = 5·1·1·1 = 5, incorporado por el equipo en las combinaciones suministradas.
A5: Flexión y torsión | B5: Mu− y Mu+ se obtienen de ENVFLEX. Tu de diseño es el mayor |T| de ENVFLEX y ENVCORT, sin recorte a φTcr porque no se aportó clasificación ni reanálisis de redistribución.
A6: Cortante directo | B6: Vu,ENVCORT = máximo |V2| de ENV CORTANTE y se considera íntegramente como demanda.
A7: Cortante por capacidad | B7: Ve,DMO = Vg + (Mpr− + Mpr+)/Ln. Se adopta provisionalmente Ln = máx(L estación−0.60 m; 0.50L), hipótesis conservadora hasta confirmar las caras de apoyo en SAP. |V2| de ENVFLEX aproxima Vg.
A8: Demanda adoptada | B8: Vu,diseño = máx(Vu,ENVCORT; Ve,DMO). Por tanto, el diseño nunca queda por debajo del cortante directo suministrado.
A9: Cortante y torsión | B9: El estribo se diseña con máx(Av/s por resistencia; Av/s mínimo) + 2At/s; se verifican interacción V-T y límites de separación. Al se provee con barras dedicadas adicionales a flexión, distribuidas en el perímetro.
A10: Secciones SAP | B10: VC1–VC7 y VRAUX usan 450×550 mm; VR1, VR N1, VR2 y VR3 usan 500×550 mm. Son las secciones efectivamente reanalizadas en resultados sap.xlsx.
A11: Resultado | B11: 536/592 vigas cumplen con torsión bruta y 56 quedan NO CUMPLE. Todo el expediente se marca NO EMITIR PARA CONSTRUCCIÓN hasta rediseño y reanálisis SAP.
A14: Grupo | B14: N | C14: Vu ENVFLEX | D14: Ve DMO conserv. | E14: Vu ENVCORT | F14: Vu adoptado | G14: φVn provisto | H14: φVn máx. sección | I14: ENVCORT directo | J14: Chequeo DMO | K14: Sección adoptada | L14: Conclusión
A15: VC1 | B15: 20 | C15: 26.942 | D15: 151.60627 | E15: 74.045 | F15: 151.60627 | G15: 284.38004 | H15: 725.35478 | I15: CUMPLE DIRECTO | J15: CUMPLE | K15: 450×550 mm | L15: CUMPLE
A16: VC2 | B16: 40 | C16: 84.474 | D16: 209.13827 | E16: 359.244 | F16: 359.244 | G16: 367.4529 | H16: 725.35478 | I16: CUMPLE DIRECTO | J16: CUMPLE | K16: 450×550 mm | L16: CUMPLE
A17: VC3 | B17: 40 | C17: 90.89 | D17: 233.76348 | E17: 396.275 | F17: 396.275 | G17: 422.17446 | H17: 725.35478 | I17: CUMPLE DIRECTO | J17: CUMPLE | K17: 450×550 mm | L17: CUMPLE
A18: VC4 | B18: 20 | C18: 118.968 | D18: 282.44166 | E18: 506.77 | F18: 506.77 | G18: 547.77298 | H18: 725.35478 | I18: CUMPLE DIRECTO | J18: NO CUMPLE | K18: 450×550 mm | L18: 4 FRAMES NO CUMPLEN
A19: VC5 | B19: 40 | C19: 140.953 | D19: 287.84715 | E19: 491.129 | F19: 491.129 | G19: 506.11242 | H19: 725.35478 | I19: CUMPLE DIRECTO | J19: NO CUMPLE | K19: 450×550 mm | L19: 16 FRAMES NO CUMPLEN
A20: VC6 | B20: 40 | C20: 98.239 | D20: 245.44198 | E20: 424.48 | F20: 424.48 | G20: 437.76146 | H20: 725.35478 | I20: CUMPLE DIRECTO | J20: NO CUMPLE | K20: 450×550 mm | L20: 8 FRAMES NO CUMPLEN
A21: VC7 | B21: 40 | C21: 163.07 | D21: 444.44021 | E21: 754.708 | F21: 754.708 | G21: 761.40281 | H21: 725.35478 | I21: EXCEDE DIRECTO | J21: NO CUMPLE | K21: 450×550 mm | L21: 4 FRAMES NO CUMPLEN
A22: VR1 | B22: 80 | C22: 136.996 | D22: 294.17181 | E22: 405.204 | F22: 405.204 | G22: 408.281 | H22: 805.94976 | I22: CUMPLE DIRECTO | J22: CUMPLE | K22: 500×550 mm | L22: CUMPLE
A23: VR N1 | B23: 22 | C23: 164.744 | D23: 408.90284 | E23: 634.574 | F23: 634.574 | G23: 662.19248 | H23: 805.94976 | I23: CUMPLE DIRECTO | J23: CUMPLE | K23: 500×550 mm | L23: CUMPLE
A24: VR2 | B24: 140 | C24: 52.863 | D24: 595.43821 | E24: 101.022 | F24: 595.43821 | G24: 614.05891 | H24: 805.94976 | I24: CUMPLE DIRECTO | J24: NO CUMPLE | K24: 500×550 mm | L24: 16 FRAMES NO CUMPLEN
A25: VR3 | B25: 70 | C25: 72.314 | D25: 614.88921 | E25: 72.314 | F25: 614.88921 | G25: 616.03874 | H25: 805.94976 | I25: CUMPLE DIRECTO | J25: NO CUMPLE | K25: 500×550 mm | L25: 8 FRAMES NO CUMPLEN
A26: VRAUX | B26: 40 | C26: 43.256 | D26: 249.93623 | E26: 169.702 | F26: 249.93623 | G26: 271.17984 | H26: 725.35478 | I26: CUMPLE DIRECTO | J26: CUMPLE | K26: 450×550 mm | L26: CUMPLE

Sheet Vigas de Carga (7)
A1: DISEÑO DE VIGAS — VIGAS DE CARGA (7)
A2: Flexión: ENVFLEX. Cortante: ENVCORT directo. Torsión: máximo de ambas envolventes. Verificación DMO: Ve. Vu adoptado = máx(ENVCORT; Ve).
A3: Grupo | B3: Frame | C3: N vigas | D3: Ln adopt. mín (m) | E3: Ln adopt. máx (m) | F3: b modelo (mm) | G3: h modelo (mm) | H3: b adopt. (mm) | I3: h adopt. (mm) | J3: Mu− ENVFLEX (kN·m) | K3: Frame Mu− | L3: Mu+ ENVFLEX (kN·m) | M3: Frame Mu+ | N3: Vu ENVFLEX (kN) | O3: Vu ENVCORT (kN) | P3: Frame Vu | Q3: Tu diseño compat. (kN·m) | R3: As req. sup (mm²) | S3: Nº5 sup | T3: Capas sup | U3: d sup (mm) | V3: As prov. sup (mm²) | W3: φMn− (kN·m) | X3: Flexión − | Y3: As req. inf (mm²) | Z3: Nº5 inf | AA3: Capas inf | AB3: d inf (mm) | AC3: As prov. inf (mm²) | AD3: φMn+ (kN·m) | AE3: Flexión + | AF3: Mpr− (kN·m) | AG3: Mpr+ (kN·m) | AH3: Vcap (kN) | AI3: Vu diseño (kN) | AJ3: Vc (kN) | AK3: Vs req. (kN) | AL3: Vs máx. (kN) | AM3: Sección cortante | AN3: Estribo | AO3: Ramas | AP3: s extremo DMO (mm; zona 2h) | AQ3: s centro (mm) | AR3: φVn (kN) | AS3: Cortante | AT3: φTth (kN·m) | AU3: Torsión | AV3: At/s (mm²/mm) | AW3: Al adicional req. (mm²) | AX3: Nº5 torsión dedicadas | AY3: Chequeo torsión | AZ3: ESTADO | BA3: db estribo (mm) | BB3: Área rama (mm²) | BC3: Av/s req. cortante incl. mín. | BD3: 2At/s req. torsión | BE3: Av/s prov. extremo | BF3: Interacción V-T | BG3: Límite V-T | BH3: Chequeo V-T | BI3: Al provisto (mm²) | BJ3: Chequeo Al
A4: VC1 | B4: 154 | C4: 20 | D4: 3.15 | E4: 3.15 | F4: 450 | G4: 550 | H4: 450 | I4: 550 | J4: 33.4292 | K4: 154 | L4: 21.6211 | M4: 153 | N4: 26.942 | O4: 74.045 | P4: 154 | Q4: 13.2234 | R4: =MAX(MAX(1.4/'Parametros'!$B$3,0.25*SQRT('Parametros'!$B$2)/'Parametros'!$B$3)*H4*U4,(0.85*'Parametros'!$B$2/'Parametros'!$B$3)*(1-SQRT(1-2*(J4*1000000/('Parametros'!$B$5*H4*U4^2))/(0.85*'Parametros'!$B$2)))*H4*U4) -> 734.025 | S4: 4 | T4: 1 | U4: =IF(T4=1,I4-('Parametros'!$B$7+'Parametros'!$B$9+'Parametros'!$B$12/2),I4-(ROUNDUP(S4/2,0)*('Parametros'!$B$7+'Parametros'!$B$9+'Parametros'!$B$12/2)+ROUNDDOWN(S4/2,0)*('Parametros'!$B$7+'Parametros'!$B$9+'Parametros'!$B$12/2+'Parametros'!$B$12+'Parametros'!$B$10))/S4) -> 489.35 | V4: =S4*'Parametros'!$B$8 -> 796 | W4: ='Parametros'!$B$5*V4*'Parametros'!$B$3*(U4-(V4*'Parametros'!$B$3/(0.85*'Parametros'!$B$2*H4))/2)/1000000 -> 142.54333 | X4: =IF(W4>=J4,"CUMPLE","NO CUMPLE") -> CUMPLE | Y4: =MAX(MAX(1.4/'Parametros'!$B$3,0.25*SQRT('Parametros'!$B$2)/'Parametros'!$B$3)*H4*AB4,(0.85*'Parametros'!$B$2/'Parametros'!$B$3)*(1-SQRT(1-2*(L4*1000000/('Parametros'!$B$5*H4*AB4^2))/(0.85*'Parametros'!$B$2)))*H4*AB4) -> 734.025 | Z4: 4 | AA4: 1 | AB4: =IF(AA4=1,I4-('Parametros'!$B$7+'Parametros'!$B$9+'Parametros'!$B$12/2),I4-(ROUNDUP(Z4/2,0)*('Parametros'!$B$7+'Parametros'!$B$9+'Parametros'!$B$12/2)+ROUNDDOWN(Z4/2,0)*('Parametros'!$B$7+'Parametros'!$B$9+'Parametros'!$B$12/2+'Parametros'!$B$12+'Parametros'!$B$10))/Z4) -> 489.35 | AC4: =Z4*'Parametros'!$B$8 -> 796 | AD4: ='Parametros'!$B$5*AC4*'Parametros'!$B$3*(AB4-(AC4*'Parametros'!$B$3/(0.85*'Parametros'!$B$2*H4))/2)/1000000 -> 142.54333 | AE4: =IF(AD4>=L4,"CUMPLE","NO CUMPLE") -> CUMPLE | AF4: =V4*1.25*'Parametros'!$B$3*(U4-(V4*1.25*'Parametros'!$B$3/(0.85*'Parametros'!$B$2*H4))/2)/1000000 -> 196.34622 | AG4: =AC4*1.25*'Parametros'!$B$3*(AB4-(AC4*1.25*'Parametros'!$B$3/(0.85*'Parametros'!$B$2*H4))/2)/1000000 -> 196.34622 | AH4: =N4+(AF4+AG4)/D4 -> 151.60627 | AI4: =MAX(O4,AH4) -> 151.60627 | AJ4: =0.17*SQRT('Parametros'!$B$2)*H4*MIN(U4,AB4)/1000 -> 198.08886 | AK4: =MAX(AI4/'Parametros'!$B$6-AJ4,0) -> 4.0528313 | AL4: =0.66*SQRT('Parametros'!$B$2)*H4*MIN(U4,AB4)/1000 -> 769.05085 | AM4: =IF(AK4<=AL4,"CUMPLE","NO CUMPLE") -> CUMPLE | AN4: Nº3 cerrado | AO4: 2 | AP4: =ROUNDDOWN(MIN(IF(BC4+BD4=0,1000000000,AO4*BB4/(BC4+BD4)),MIN(U4,AB4)/4,8*'Parametros'!$B$12,24*BA4,300,IF(AV4=0,1000000000,2*((H4-2*('Parametros'!$B$7+'Parametros'!$B$9/2))+(I4-2*('Parametros'!$B$7+'Parametros'!$B$9/2)))/8))/10,0)*10 -> 120 | AQ4: =ROUNDDOWN(MIN(IF(BC4+BD4=0,1000000000,AO4*BB4/(BC4+BD4)),IF(AK4>0.33*SQRT('Parametros'!$B$2)*H4*MIN(U4,AB4)/1000,MIN(U4,AB4)/4,MIN(U4,AB4)/2),600,IF(AV4=0,1000000000,2*((H4-2*('Parametros'!$B$7+'Parametros'!$B$9/2))+(I4-2*('Parametros'!$B$7+'Parametros'!$B$9/2)))/8))/10,0)*10 -> 200 | AR4: ='Parametros'!$B$6*(AJ4+MAX(BE4-BD4,0)*'Parametros'!$B$4*MIN(U4,AB4)/1000) -> 284.38004 | AS4: =IF(AND(ISERROR(SEARCH("referencia",AN4)),AM4="CUMPLE",AR4>=AI4),"CUMPLE","NO CUMPLE") -> CUMPLE | AT4: ='Parametros'!$B$6*0.083*SQRT('Parametros'!$B$2)*(H4*I4)^2/(2*(H4+I4))/1000000 -> 10.088783 | AU4: =IF(Q4<=AT4,"DESPRECIABLE","DISEÑAR") -> DISEÑAR | AV4: =IF(Q4<=AT4,0,Q4*1000000/('Parametros'!$B$6*2*0.85*(H4-2*('Parametros'!$B$7+'Parametros'!$B$9/2))*(I4-2*('Parametros'!$B$7+'Parametros'!$B$9/2))*'Parametros'!$B$4)) -> 0.15112957 | AW4: =AV4*2*((H4-2*('Parametros'!$B$7+'Parametros'!$B$9/2))+(I4-2*('Parametros'!$B$7+'Parametros'!$B$9/2)))*'Parametros'!$B$4/'Parametros'!$B$3 -> 246.22029 | AX4: 8 | AY4: =IF(AV4=0,"DESPRECIABLE",IF(AND(ISERROR(SEARCH("referencia",AN4)),BB4/AP4>=AV4,BI4>=AW4,BH4="CUMPLE"),"CUMPLE","NO CUMPLE")) -> CUMPLE | AZ4: =IF(AND(X4="CUMPLE",AE4="CUMPLE",AS4="CUMPLE",OR(AY4="CUMPLE",AY4="DESPRECIABLE"),BH4="CUMPLE",BJ4="CUMPLE",COUNTIF('Todas las Vigas (592)'!$A$4:$A$595,A4)=COUNTIFS('Todas las Vigas (592)'!$A$4:$A$595,A4,'Todas las Vigas (592)'!$AZ$4:$AZ$595,"CUMPLE")),"CUMPLE","NO CUMPLE") -> CUMPLE | BA4: 9.5 | BB4: 71 | BC4: =MAX(IF(AK4=0,0,AK4*1000/('Parametros'!$B$4*MIN(U4,AB4))),MAX(0.062*SQRT('Parametros'!$B$2)*H4/'Parametros'!$B$4,0.35*H4/'Parametros'!$B$4)) -> 0.375 | BD4: =2*AV4 -> 0.30225914 | BE4: =AO4*BB4/AP4 -> 1.1833333 | BF4: =SQRT((AI4*1000/(H4*MIN(U4,AB4)))^2+(Q4*1000000*2*((H4-2*('Parametros'!$B$7+'Parametros'!$B$9/2))+(I4-2*('Parametros'!$B$7+'Parametros'!$B$9/2)))/(1.7*((H4-2*('Parametros'!$B$7+'Parametros'!$B$9/2))*(I4-2*('Parametros'!$B$7+'Parametros'!$B$9/2)))^2))^2) -> 0.83624835 | BG4: ='Parametros'!$B$6*(AJ4*1000/(H4*MIN(U4,AB4))+0.66*SQRT('Parametros'!$B$2)) -> 3.2939604 | BH4: =IF(BF4<=BG4,"CUMPLE","NO CUMPLE") -> CUMPLE | BI4: =AX4*'Parametros'!$B$8 -> 1592 | BJ4: =IF(BI4>=AW4,"CUMPLE","NO CUMPLE") -> CUMPLE
A5: VC2 | B5: 96 | C5: 40 | D5: 3.15 | E5: 3.4 | F5: 450 | G5: 550 | H5: 450 | I5: 550 | J5: 140.3658 | K5: 56 | L5: 127.2041 | M5: 55 | N5: 84.474 | O5: 359.244 | P5: 56 | Q5: 5.4386 | R5: =MAX(MAX(1.4/'Parametros'!$B$3,0.25*SQRT('Parametros'!$B$2)/'Parametros'!$B$3)*H5*U5,(0.85*'Parametros'!$B$2/'Parametros'!$B$3)*(1-SQRT(1-2*(J5*1000000/('Parametros'!$B$5*H5*U5^2))/(0.85*'Parametros'!$B$2)))*H5*U5) -> 783.43258 | S5: 4 | T5: 1 | U5: =IF(T5=1,I5-('Parametros'!$B$7+'Parametros'!$B$9+'Parametros'!$B$12/2),I5-(ROUNDUP(S5/2,0)*('Parametros'!$B$7+'Parametros'!$B$9+'Parametros'!$B$12/2)+ROUNDDOWN(S5/2,0)*('Parametros'!$B$7+'Parametros'!$B$9+'Parametros'!$B$12/2+'Parametros'!$B$12+'Parametros'!$B$10))/S5) -> 489.35 | V5: =S5*'Parametros'!$B$8 -> 796 | W5: ='Parametros'!$B$5*V5*'Parametros'!$B$3*(U5-(V5*'Parametros'!$B$3/(0.85*'Parametros'!$B$2*H5))/2)/1000000 -> 142.54333 | X5: =IF(W5>=J5,"CUMPLE","NO CUMPLE") -> CUMPLE | Y5: =MAX(MAX(1.4/'Parametros'!$B$3,0.25*SQRT('Parametros'!$B$2)/'Parametros'!$B$3)*H5*AB5,(0.85*'Parametros'!$B$2/'Parametros'!$B$3)*(1-SQRT(1-2*(L5*1000000/('Parametros'!$B$5*H5*AB5^2))/(0.85*'Parametros'!$B$2)))*H5*AB5) -> 734.025 | Z5: 4 | AA5: 1 | AB5: =IF(AA5=1,I5-('Parametros'!$B$7+'Parametros'!$B$9+'Parametros'!$B$12/2),I5-(ROUNDUP(Z5/2,0)*('Parametros'!$B$7+'Parametros'!$B$9+'Parametros'!$B$12/2)+ROUNDDOWN(Z5/2,0)*('Parametros'!$B$7+'Parametros'!$B$9+'Parametros'!$B$12/2+'Parametros'!$B$12+'Parametros'!$B$10))/Z5) -> 489.35 | AC5: =Z5*'Parametros'!$B$8 -> 796 | AD5: ='Parametros'!$B$5*AC5*'Parametros'!$B$3*(AB5-(AC5*'Parametros'!$B$3/(0.85*'Parametros'!$B$2*H5))/2)/1000000 -> 142.54333 | AE5: =IF(AD5>=L5,"CUMPLE","NO CUMPLE") -> CUMPLE | AF5: =V5*1.25*'Parametros'!$B$3*(U5-(V5*1.25*'Parametros'!$B$3/(0.85*'Parametros'!$B$2*H5))/2)/1000000 -> 196.34622 | AG5: =AC5*1.25*'Parametros'!$B$3*(AB5-(AC5*1.25*'Parametros'!$B$3/(0.85*'Parametros'!$B$2*H5))/2)/1000000 -> 196.34622 | AH5: =N5+(AF5+AG5)/D5 -> 209.13827 | AI5: =MAX(O5,AH5) -> 359.244 | AJ5: =0.17*SQRT('Parametros'!$B$2)*H5*MIN(U5,AB5)/1000 -> 198.08886 | AK5: =MAX(AI5/'Parametros'!$B$6-AJ5,0) -> 280.90314 | AL5: =0.66*SQRT('Parametros'!$B$2)*H5*MIN(U5,AB5)/1000 -> 769.05085 | AM5: =IF(AK5<=AL5,"CUMPLE","NO CUMPLE") -> CUMPLE | AN5: Nº3 cerrado | AO5: 2 | AP5: =ROUNDDOWN(MIN(IF(BC5+BD5=0,1000000000,AO5*BB5/(BC5+BD5)),MIN(U5,AB5)/4,8*'Parametros'!$B$12,24*BA5,300,IF(AV5=0,1000000000,2*((H5-2*('Parametros'!$B$7+'Parametros'!$B$9/2))+(I5-2*('Parametros'!$B$7+'Parametros'!$B$9/2)))/8))/10,0)*10 -> 100 | AQ5: =ROUNDDOWN(MIN(IF(BC5+BD5=0,1000000000,AO5*BB5/(BC5+BD5)),IF(AK5>0.33*SQRT('Parametros'!$B$2)*H5*MIN(U5,AB5)/1000,MIN(U5,AB5)/4,MIN(U5,AB5)/2),600,IF(AV5=0,1000000000,2*((H5-2*('Parametros'!$B$7+'Parametros'!$B$9/2))+(I5-2*('Parametros'!$B$7+'Parametros'!$B$9/2)))/8))/10,0)*10 -> 100 | AR5: ='Parametros'!$B$6*(AJ5+MAX(BE5-BD5,0)*'Parametros'!$B$4*MIN(U5,AB5)/1000) -> 367.4529 | AS5: =IF(AND(ISERROR(SEARCH("referencia",AN5)),AM5="CUMPLE",AR5>=AI5),"CUMPLE","NO CUMPLE") -> CUMPLE | AT5: ='Parametros'!$B$6*0.083*SQRT('Parametros'!$B$2)*(H5*I5)^2/(2*(H5+I5))/1000000 -> 10.088783 | AU5: =IF(Q5<=AT5,"DESPRECIABLE","DISEÑAR") -> DESPRECIABLE | AV5: =IF(Q5<=AT5,0,Q5*1000000/('Parametros'!$B$6*2*0.85*(H5-2*('Parametros'!$B$7+'Parametros'!$B$9/2))*(I5-2*('Parametros'!$B$7+'Parametros'!$B$9/2))*'Parametros'!$B$4)) -> 0 | AW5: =AV5*2*((H5-2*('Parametros'!$B$7+'Parametros'!$B$9/2))+(I5-2*('Parametros'!$B$7+'Parametros'!$B$9/2)))*'Parametros'!$B$4/'Parametros'!$B$3 -> 0 | AX5: 0 | AY5: =IF(AV5=0,"DESPRECIABLE",IF(AND(ISERROR(SEARCH("referencia",AN5)),BB5/AP5>=AV5,BI5>=AW5,BH5="CUMPLE"),"CUMPLE","NO CUMPLE")) -> DESPRECIABLE | AZ5: =IF(AND(X5="CUMPLE",AE5="CUMPLE",AS5="CUMPLE",OR(AY5="CUMPLE",AY5="DESPRECIABLE"),BH5="CUMPLE",BJ5="CUMPLE",COUNTIF('Todas las Vigas (592)'!$A$4:$A$595,A5)=COUNTIFS('Todas las Vigas (592)'!$A$4:$A$595,A5,'Todas las Vigas (592)'!$AZ$4:$AZ$595,"CUMPLE")),"CUMPLE","NO CUMPLE") -> CUMPLE | BA5: 9.5 | BB5: 71 | BC5: =MAX(IF(AK5=0,0,AK5*1000/('Parametros'!$B$4*MIN(U5,AB5))),MAX(0.062*SQRT('Parametros'!$B$2)*H5/'Parametros'!$B$4,0.35*H5/'Parametros'!$B$4)) -> 1.3667457 | BD5: =2*AV5 -> 0 | BE5: =AO5*BB5/AP5 -> 1.42 | BF5: =SQRT((AI5*1000/(H5*MIN(U5,AB5)))^2+(Q5*1000000*2*((H5-2*('Parametros'!$B$7+'Parametros'!$B$9/2))+(I5-2*('Parametros'!$B$7+'Parametros'!$B$9/2)))/(1.7*((H5-2*('Parametros'!$B$7+'Parametros'!$B$9/2))*(I5-2*('Parametros'!$B$7+'Parametros'!$B$9/2)))^2))^2) -> 1.6430286 | BG5: ='Parametros'!$B$6*(AJ5*1000/(H5*MIN(U5,AB5))+0.66*SQRT('Parametros'!$B$2)) -> 3.2939604 | BH5: =IF(BF5<=BG5,"CUMPLE","NO CUMPLE") -> CUMPLE | BI5: =AX5*'Parametros'!$B$8 -> 0 | BJ5: =IF(BI5>=AW5,"CUMPLE","NO CUMPLE") -> CUMPLE
A6: VC3 | B6: 60 | C6: 40 | D6: 3.4 | E6: 3.4 | F6: 450 | G6: 550 | H6: 450 | I6: 550 | J6: 174.4236 | K6: 60 | L6: 154.8853 | M6: 57 | N6: 90.89 | O6: 396.275 | P6: 58 | Q6: 2.7885 | R6: =MAX(MAX(1.4/'Parametros'!$B$3,0.25*SQRT('Parametros'!$B$2)/'Parametros'!$B$3)*H6*U6,(0.85*'Parametros'!$B$2/'Parametros'!$B$3)*(1-SQRT(1-2*(J6*1000000/('Parametros'!$B$5*H6*U6^2))/(0.85*'Parametros'!$B$2)))*H6*U6) -> 981.56684 | S6: 5 | T6: 1 | U6: =IF(T6=1,I6-('Parametros'!$B$7+'Parametros'!$B$9+'Parametros'!$B$12/2),I6-(ROUNDUP(S6/2,0)*('Parametros'!$B$7+'Parametros'!$B$9+'Parametros'!$B$12/2)+ROUNDDOWN(S6/2,0)*('Parametros'!$B$7+'Parametros'!$B$9+'Parametros'!$B$12/2+'Parametros'!$B$12+'Parametros'!$B$10))/S6) -> 489.35 | V6: =S6*'Parametros'!$B$8 -> 995 | W6: ='Parametros'!$B$5*V6*'Parametros'!$B$3*(U6-(V6*'Parametros'!$B$3/(0.85*'Parametros'!$B$2*H6))/2)/1000000 -> 176.7116 | X6: =IF(W6>=J6,"CUMPLE","NO CUMPLE") -> CUMPLE | Y6: =MAX(MAX(1.4/'Parametros'!$B$3,0.25*SQRT('Parametros'!$B$2)/'Parametros'!$B$3)*H6*AB6,(0.85*'Parametros'!$B$2/'Parametros'!$B$3)*(1-SQRT(1-2*(L6*1000000/('Parametros'!$B$5*H6*AB6^2))/(0.85*'Parametros'!$B$2)))*H6*AB6) -> 867.48759 | Z6: 5 | AA6: 1 | AB6: =IF(AA6=1,I6-('Parametros'!$B$7+'Parametros'!$B$9+'Parametros'!$B$12/2),I6-(ROUNDUP(Z6/2,0)*('Parametros'!$B$7+'Parametros'!$B$9+'Parametros'!$B$12/2)+ROUNDDOWN(Z6/2,0)*('Parametros'!$B$7+'Parametros'!$B$9+'Parametros'!$B$12/2+'Parametros'!$B$12+'Parametros'!$B$10))/Z6) -> 489.35 | AC6: =Z6*'Parametros'!$B$8 -> 995 | AD6: ='Parametros'!$B$5*AC6*'Parametros'!$B$3*(AB6-(AC6*'Parametros'!$B$3/(0.85*'Parametros'!$B$2*H6))/2)/1000000 -> 176.7116 | AE6: =IF(AD6>=L6,"CUMPLE","NO CUMPLE") -> CUMPLE | AF6: =V6*1.25*'Parametros'!$B$3*(U6-(V6*1.25*'Parametros'!$B$3/(0.85*'Parametros'!$B$2*H6))/2)/1000000 -> 242.88491 | AG6: =AC6*1.25*'Parametros'!$B$3*(AB6-(AC6*1.25*'Parametros'!$B$3/(0.85*'Parametros'!$B$2*H6))/2)/1000000 -> 242.88491 | AH6: =N6+(AF6+AG6)/D6 -> 233.76348 | AI6: =MAX(O6,AH6) -> 396.275 | AJ6: =0.17*SQRT('Parametros'!$B$2)*H6*MIN(U6,AB6)/1000 -> 198.08886 | AK6: =MAX(AI6/'Parametros'!$B$6-AJ6,0) -> 330.27781 | AL6: =0.66*SQRT('Parametros'!$B$2)*H6*MIN(U6,AB6)/1000 -> 769.05085 | AM6: =IF(AK6<=AL6,"CUMPLE","NO CUMPLE") -> CUMPLE | AN6: Nº3 cerrado | AO6: 2 | AP6: =ROUNDDOWN(MIN(IF(BC6+BD6=0,1000000000,AO6*BB6/(BC6+BD6)),MIN(U6,AB6)/4,8*'Parametros'!$B$12,24*BA6,300,IF(AV6=0,1000000000,2*((H6-2*('Parametros'!$B$7+'Parametros'!$B$9/2))+(I6-2*('Parametros'!$B$7+'Parametros'!$B$9/2)))/8))/10,0)*10 -> 80 | AQ6: =ROUNDDOWN(MIN(IF(BC6+BD6=0,1000000000,AO6*BB6/(BC6+BD6)),IF(AK6>0.33*SQRT('Parametros'!$B$2)*H6*MIN(U6,AB6)/1000,MIN(U6,AB6)/4,MIN(U6,AB6)/2),600,IF(AV6=0,1000000000,2*((H6-2*('Parametros'!$B$7+'Parametros'!$B$9/2))+(I6-2*('Parametros'!$B$7+'Parametros'!$B$9/2)))/8))/10,0)*10 -> 80 | AR6: ='Parametros'!$B$6*(AJ6+MAX(BE6-BD6,0)*'Parametros'!$B$4*MIN(U6,AB6)/1000) -> 422.17446 | AS6: =IF(AND(ISERROR(SEARCH("referencia",AN6)),AM6="CUMPLE",AR6>=AI6),"CUMPLE","NO CUMPLE") -> CUMPLE | AT6: ='Parametros'!$B$6*0.083*SQRT('Parametros'!$B$2)*(H6*I6)^2/(2*(H6+I6))/1000000 -> 10.088783 | AU6: =IF(Q6<=AT6,"DESPRECIABLE","DISEÑAR") -> DESPRECIABLE | AV6: =IF(Q6<=AT6,0,Q6*1000000/('Parametros'!$B$6*2*0.85*(H6-2*('Parametros'!$B$7+'Parametros'!$B$9/2))*(I6-2*('Parametros'!$B$7+'Parametros'!$B$9/2))*'Parametros'!$B$4)) -> 0 | AW6: =AV6*2*((H6-2*('Parametros'!$B$7+'Parametros'!$B$9/2))+(I6-2*('Parametros'!$B$7+'Parametros'!$B$9/2)))*'Parametros'!$B$4/'Parametros'!$B$3 -> 0 | AX6: 0 | AY6: =IF(AV6=0,"DESPRECIABLE",IF(AND(ISERROR(SEARCH("referencia",AN6)),BB6/AP6>=AV6,BI6>=AW6,BH6="CUMPLE"),"CUMPLE","NO CUMPLE")) -> DESPRECIABLE | AZ6: =IF(AND(X6="CUMPLE",AE6="CUMPLE",AS6="CUMPLE",OR(AY6="CUMPLE",AY6="DESPRECIABLE"),BH6="CUMPLE",BJ6="CUMPLE",COUNTIF('Todas las Vigas (592)'!$A$4:$A$595,A6)=COUNTIFS('Todas las Vigas (592)'!$A$4:$A$595,A6,'Todas las Vigas (592)'!$AZ$4:$AZ$595,"CUMPLE")),"CUMPLE","NO CUMPLE") -> CUMPLE | BA6: 9.5 | BB6: 71 | BC6: =MAX(IF(AK6=0,0,AK6*1000/('Parametros'!$B$4*MIN(U6,AB6))),MAX(0.062*SQRT('Parametros'!$B$2)*H6/'Parametros'!$B$4,0.35*H6/'Parametros'!$B$4)) -> 1.6069802 | BD6: =2*AV6 -> 0 | BE6: =AO6*BB6/AP6 -> 1.775 | BF6: =SQRT((AI6*1000/(H6*MIN(U6,AB6)))^2+(Q6*1000000*2*((H6-2*('Parametros'!$B$7+'Parametros'!$B$9/2))+(I6-2*('Parametros'!$B$7+'Parametros'!$B$9/2)))/(1.7*((H6-2*('Parametros'!$B$7+'Parametros'!$B$9/2))*(I6-2*('Parametros'!$B$7+'Parametros'!$B$9/2)))^2))^2) -> 1.8023345 | BG6: ='Parametros'!$B$6*(AJ6*1000/(H6*MIN(U6,AB6))+0.66*SQRT('Parametros'!$B$2)) -> 3.2939604 | BH6: =IF(BF6<=BG6,"CUMPLE","NO CUMPLE") -> CUMPLE | BI6: =AX6*'Parametros'!$B$8 -> 0 | BJ6: =IF(BI6>=AW6,"CUMPLE","NO CUMPLE") -> CUMPLE
A7: VC4 | B7: 88 | C7: 20 | D7: 3.25 | E7: 3.25 | F7: 450 | G7: 550 | H7: 450 | I7: 550 | J7: 204.9592 | K7: 61 | L7: 173.5868 | M7: 62 | N7: 118.968 | O7: 506.77 | P7: 61 | Q7: 74.8185 | R7: =MAX(MAX(1.4/'Parametros'!$B$3,0.25*SQRT('Parametros'!$B$2)/'Parametros'!$B$3)*H7*U7,(0.85*'Parametros'!$B$2/'Parametros'!$B$3)*(1-SQRT(1-2*(J7*1000000/('Parametros'!$B$5*H7*U7^2))/(0.85*'Parametros'!$B$2)))*H7*U7) -> 1162.1595 | S7: 6 | T7: 1 | U7: =IF(T7=1,I7-('Parametros'!$B$7+'Parametros'!$B$9+'Parametros'!$B$12/2),I7-(ROUNDUP(S7/2,0)*('Parametros'!$B$7+'Parametros'!$B$9+'Parametros'!$B$12/2)+ROUNDDOWN(S7/2,0)*('Parametros'!$B$7+'Parametros'!$B$9+'Parametros'!$B$12/2+'Parametros'!$B$12+'Parametros'!$B$10))/S7) -> 489.35 | V7: =S7*'Parametros'!$B$8 -> 1194 | W7: ='Parametros'!$B$5*V7*'Parametros'!$B$3*(U7-(V7*'Parametros'!$B$3/(0.85*'Parametros'!$B$2*H7))/2)/1000000 -> 210.29284 | X7: =IF(W7>=J7,"CUMPLE","NO CUMPLE") -> CUMPLE | Y7: =MAX(MAX(1.4/'Parametros'!$B$3,0.25*SQRT('Parametros'!$B$2)/'Parametros'!$B$3)*H7*AB7,(0.85*'Parametros'!$B$2/'Parametros'!$B$3)*(1-SQRT(1-2*(L7*1000000/('Parametros'!$B$5*H7*AB7^2))/(0.85*'Parametros'!$B$2)))*H7*AB7) -> 976.65778 | Z7: 5 | AA7: 1 | AB7: =IF(AA7=1,I7-('Parametros'!$B$7+'Parametros'!$B$9+'Parametros'!$B$12/2),I7-(ROUNDUP(Z7/2,0)*('Parametros'!$B$7+'Parametros'!$B$9+'Parametros'!$B$12/2)+ROUNDDOWN(Z7/2,0)*('Parametros'!$B$7+'Parametros'!$B$9+'Parametros'!$B$12/2+'Parametros'!$B$12+'Parametros'!$B$10))/Z7) -> 489.35 | AC7: =Z7*'Parametros'!$B$8 -> 995 | AD7: ='Parametros'!$B$5*AC7*'Parametros'!$B$3*(AB7-(AC7*'Parametros'!$B$3/(0.85*'Parametros'!$B$2*H7))/2)/1000000 -> 176.7116 | AE7: =IF(AD7>=L7,"CUMPLE","NO CUMPLE") -> CUMPLE | AF7: =V7*1.25*'Parametros'!$B$3*(U7-(V7*1.25*'Parametros'!$B$3/(0.85*'Parametros'!$B$2*H7))/2)/1000000 -> 288.40447 | AG7: =AC7*1.25*'Parametros'!$B$3*(AB7-(AC7*1.25*'Parametros'!$B$3/(0.85*'Parametros'!$B$2*H7))/2)/1000000 -> 242.88491 | AH7: =N7+(AF7+AG7)/D7 -> 282.44166 | AI7: =MAX(O7,AH7) -> 506.77 | AJ7: =0.17*SQRT('Parametros'!$B$2)*H7*MIN(U7,AB7)/1000 -> 198.08886 | AK7: =MAX(AI7/'Parametros'!$B$6-AJ7,0) -> 477.60448 | AL7: =0.66*SQRT('Parametros'!$B$2)*H7*MIN(U7,AB7)/1000 -> 769.05085 | AM7: =IF(AK7<=AL7,"CUMPLE","NO CUMPLE") -> CUMPLE | AN7: Nº4 cerrado | AO7: 4 | AP7: =ROUNDDOWN(MIN(IF(BC7+BD7=0,1000000000,AO7*BB7/(BC7+BD7)),MIN(U7,AB7)/4,8*'Parametros'!$B$12,24*BA7,300,IF(AV7=0,1000000000,2*((H7-2*('Parametros'!$B$7+'Parametros'!$B$9/2))+(I7-2*('Parametros'!$B$7+'Parametros'!$B$9/2)))/8))/10,0)*10 -> 120 | AQ7: =ROUNDDOWN(MIN(IF(BC7+BD7=0,1000000000,AO7*BB7/(BC7+BD7)),IF(AK7>0.33*SQRT('Parametros'!$B$2)*H7*MIN(U7,AB7)/1000,MIN(U7,AB7)/4,MIN(U7,AB7)/2),600,IF(AV7=0,1000000000,2*((H7-2*('Parametros'!$B$7+'Parametros'!$B$9/2))+(I7-2*('Parametros'!$B$7+'Parametros'!$B$9/2)))/8))/10,0)*10 -> 120 | AR7: ='Parametros'!$B$6*(AJ7+MAX(BE7-BD7,0)*'Parametros'!$B$4*MIN(U7,AB7)/1000) -> 547.77298 | AS7: =IF(AND(ISERROR(SEARCH("referencia",AN7)),AM7="CUMPLE",AR7>=AI7),"CUMPLE","NO CUMPLE") -> CUMPLE | AT7: ='Parametros'!$B$6*0.083*SQRT('Parametros'!$B$2)*(H7*I7)^2/(2*(H7+I7))/1000000 -> 10.088783 | AU7: =IF(Q7<=AT7,"DESPRECIABLE","DISEÑAR") -> DISEÑAR | AV7: =IF(Q7<=AT7,0,Q7*1000000/('Parametros'!$B$6*2*0.85*(H7-2*('Parametros'!$B$7+'Parametros'!$B$9/2))*(I7-2*('Parametros'!$B$7+'Parametros'!$B$9/2))*'Parametros'!$B$4)) -> 0.85509685 | AW7: =AV7*2*((H7-2*('Parametros'!$B$7+'Parametros'!$B$9/2))+(I7-2*('Parametros'!$B$7+'Parametros'!$B$9/2)))*'Parametros'!$B$4/'Parametros'!$B$3 -> 1393.1238 | AX7: 8 | AY7: =IF(AV7=0,"DESPRECIABLE",IF(AND(ISERROR(SEARCH("referencia",AN7)),BB7/AP7>=AV7,BI7>=AW7,BH7="CUMPLE"),"CUMPLE","NO CUMPLE")) -> NO CUMPLE | AZ7: =IF(AND(X7="CUMPLE",AE7="CUMPLE",AS7="CUMPLE",OR(AY7="CUMPLE",AY7="DESPRECIABLE"),BH7="CUMPLE",BJ7="CUMPLE",COUNTIF('Todas las Vigas (592)'!$A$4:$A$595,A7)=COUNTIFS('Todas las Vigas (592)'!$A$4:$A$595,A7,'Todas las Vigas (592)'!$AZ$4:$AZ$595,"CUMPLE")),"CUMPLE","NO CUMPLE") -> NO CUMPLE | BA7: 12.7 | BB7: 129 | BC7: =MAX(IF(AK7=0,0,AK7*1000/('Parametros'!$B$4*MIN(U7,AB7))),MAX(0.062*SQRT('Parametros'!$B$2)*H7/'Parametros'!$B$4,0.35*H7/'Parametros'!$B$4)) -> 2.3238041 | BD7: =2*AV7 -> 1.7101937 | BE7: =AO7*BB7/AP7 -> 4.3 | BF7: =SQRT((AI7*1000/(H7*MIN(U7,AB7)))^2+(Q7*1000000*2*((H7-2*('Parametros'!$B$7+'Parametros'!$B$9/2))+(I7-2*('Parametros'!$B$7+'Parametros'!$B$9/2)))/(1.7*((H7-2*('Parametros'!$B$7+'Parametros'!$B$9/2))*(I7-2*('Parametros'!$B$7+'Parametros'!$B$9/2)))^2))^2) -> 3.536861 | BG7: ='Parametros'!$B$6*(AJ7*1000/(H7*MIN(U7,AB7))+0.66*SQRT('Parametros'!$B$2)) -> 3.2939604 | BH7: =IF(BF7<=BG7,"CUMPLE","NO CUMPLE") -> NO CUMPLE | BI7: =AX7*'Parametros'!$B$8 -> 1592 | BJ7: =IF(BI7>=AW7,"CUMPLE","NO CUMPLE") -> CUMPLE
A8: VC5 | B8: 84 | C8: 40 | D8: 3.3 | E8: 3.3 | F8: 450 | G8: 550 | H8: 450 | I8: 550 | J8: 199.483 | K8: 84 | L8: 139.6693 | M8: 63 | N8: 140.953 | O8: 491.129 | P8: 84 | Q8: 124.2661 | R8: =MAX(MAX(1.4/'Parametros'!$B$3,0.25*SQRT('Parametros'!$B$2)/'Parametros'!$B$3)*H8*U8,(0.85*'Parametros'!$B$2/'Parametros'!$B$3)*(1-SQRT(1-2*(J8*1000000/('Parametros'!$B$5*H8*U8^2))/(0.85*'Parametros'!$B$2)))*H8*U8) -> 1129.5609 | S8: 6 | T8: 1 | U8: =IF(T8=1,I8-('Parametros'!$B$7+'Parametros'!$B$9+'Parametros'!$B$12/2),I8-(ROUNDUP(S8/2,0)*('Parametros'!$B$7+'Parametros'!$B$9+'Parametros'!$B$12/2)+ROUNDDOWN(S8/2,0)*('Parametros'!$B$7+'Parametros'!$B$9+'Parametros'!$B$12/2+'Parametros'!$B$12+'Parametros'!$B$10))/S8) -> 489.35 | V8: =S8*'Parametros'!$B$8 -> 1194 | W8: ='Parametros'!$B$5*V8*'Parametros'!$B$3*(U8-(V8*'Parametros'!$B$3/(0.85*'Parametros'!$B$2*H8))/2)/1000000 -> 210.29284 | X8: =IF(W8>=J8,"CUMPLE","NO CUMPLE") -> CUMPLE | Y8: =MAX(MAX(1.4/'Parametros'!$B$3,0.25*SQRT('Parametros'!$B$2)/'Parametros'!$B$3)*H8*AB8,(0.85*'Parametros'!$B$2/'Parametros'!$B$3)*(1-SQRT(1-2*(L8*1000000/('Parametros'!$B$5*H8*AB8^2))/(0.85*'Parametros'!$B$2)))*H8*AB8) -> 779.41565 | Z8: 4 | AA8: 1 | AB8: =IF(AA8=1,I8-('Parametros'!$B$7+'Parametros'!$B$9+'Parametros'!$B$12/2),I8-(ROUNDUP(Z8/2,0)*('Parametros'!$B$7+'Parametros'!$B$9+'Parametros'!$B$12/2)+ROUNDDOWN(Z8/2,0)*('Parametros'!$B$7+'Parametros'!$B$9+'Parametros'!$B$12/2+'Parametros'!$B$12+'Parametros'!$B$10))/Z8) -> 489.35 | AC8: =Z8*'Parametros'!$B$8 -> 796 | AD8: ='Parametros'!$B$5*AC8*'Parametros'!$B$3*(AB8-(AC8*'Parametros'!$B$3/(0.85*'Parametros'!$B$2*H8))/2)/1000000 -> 142.54333 | AE8: =IF(AD8>=L8,"CUMPLE","NO CUMPLE") -> CUMPLE | AF8: =V8*1.25*'Parametros'!$B$3*(U8-(V8*1.25*'Parametros'!$B$3/(0.85*'Parametros'!$B$2*H8))/2)/1000000 -> 288.40447 | AG8: =AC8*1.25*'Parametros'!$B$3*(AB8-(AC8*1.25*'Parametros'!$B$3/(0.85*'Parametros'!$B$2*H8))/2)/1000000 -> 196.34622 | AH8: =N8+(AF8+AG8)/D8 -> 287.84715 | AI8: =MAX(O8,AH8) -> 491.129 | AJ8: =0.17*SQRT('Parametros'!$B$2)*H8*MIN(U8,AB8)/1000 -> 198.08886 | AK8: =MAX(AI8/'Parametros'!$B$6-AJ8,0) -> 456.74981 | AL8: =0.66*SQRT('Parametros'!$B$2)*H8*MIN(U8,AB8)/1000 -> 769.05085 | AM8: =IF(AK8<=AL8,"CUMPLE","NO CUMPLE") -> CUMPLE | AN8: Nº4 cerrado (referencia) | AO8: 4 | AP8: =ROUNDDOWN(MIN(IF(BC8+BD8=0,1000000000,AO8*BB8/(BC8+BD8)),MIN(U8,AB8)/4,8*'Parametros'!$B$12,24*BA8,300,IF(AV8=0,1000000000,2*((H8-2*('Parametros'!$B$7+'Parametros'!$B$9/2))+(I8-2*('Parametros'!$B$7+'Parametros'!$B$9/2)))/8))/10,0)*10 -> 100 | AQ8: =ROUNDDOWN(MIN(IF(BC8+BD8=0,1000000000,AO8*BB8/(BC8+BD8)),IF(AK8>0.33*SQRT('Parametros'!$B$2)*H8*MIN(U8,AB8)/1000,MIN(U8,AB8)/4,MIN(U8,AB8)/2),600,IF(AV8=0,1000000000,2*((H8-2*('Parametros'!$B$7+'Parametros'!$B$9/2))+(I8-2*('Parametros'!$B$7+'Parametros'!$B$9/2)))/8))/10,0)*10 -> 100 | AR8: ='Parametros'!$B$6*(AJ8+MAX(BE8-BD8,0)*'Parametros'!$B$4*MIN(U8,AB8)/1000) -> 506.11242 | AS8: =IF(AND(ISERROR(SEARCH("referencia",AN8)),AM8="CUMPLE",AR8>=AI8),"CUMPLE","NO CUMPLE") -> NO CUMPLE | AT8: ='Parametros'!$B$6*0.083*SQRT('Parametros'!$B$2)*(H8*I8)^2/(2*(H8+I8))/1000000 -> 10.088783 | AU8: =IF(Q8<=AT8,"DESPRECIABLE","DISEÑAR") -> DISEÑAR | AV8: =IF(Q8<=AT8,0,Q8*1000000/('Parametros'!$B$6*2*0.85*(H8-2*('Parametros'!$B$7+'Parametros'!$B$9/2))*(I8-2*('Parametros'!$B$7+'Parametros'!$B$9/2))*'Parametros'!$B$4)) -> 1.420231 | AW8: =AV8*2*((H8-2*('Parametros'!$B$7+'Parametros'!$B$9/2))+(I8-2*('Parametros'!$B$7+'Parametros'!$B$9/2)))*'Parametros'!$B$4/'Parametros'!$B$3 -> 2313.8403 | AX8: 12 | AY8: =IF(AV8=0,"DESPRECIABLE",IF(AND(ISERROR(SEARCH("referencia",AN8)),BB8/AP8>=AV8,BI8>=AW8,BH8="CUMPLE"),"CUMPLE","NO CUMPLE")) -> NO CUMPLE | AZ8: =IF(AND(X8="CUMPLE",AE8="CUMPLE",AS8="CUMPLE",OR(AY8="CUMPLE",AY8="DESPRECIABLE"),BH8="CUMPLE",BJ8="CUMPLE",COUNTIF('Todas las Vigas (592)'!$A$4:$A$595,A8)=COUNTIFS('Todas las Vigas (592)'!$A$4:$A$595,A8,'Todas las Vigas (592)'!$AZ$4:$AZ$595,"CUMPLE")),"CUMPLE","NO CUMPLE") -> NO CUMPLE | BA8: 12.7 | BB8: 129 | BC8: =MAX(IF(AK8=0,0,AK8*1000/('Parametros'!$B$4*MIN(U8,AB8))),MAX(0.062*SQRT('Parametros'!$B$2)*H8/'Parametros'!$B$4,0.35*H8/'Parametros'!$B$4)) -> 2.2223348 | BD8: =2*AV8 -> 2.8404619 | BE8: =AO8*BB8/AP8 -> 5.16 | BF8: =SQRT((AI8*1000/(H8*MIN(U8,AB8)))^2+(Q8*1000000*2*((H8-2*('Parametros'!$B$7+'Parametros'!$B$9/2))+(I8-2*('Parametros'!$B$7+'Parametros'!$B$9/2)))/(1.7*((H8-2*('Parametros'!$B$7+'Parametros'!$B$9/2))*(I8-2*('Parametros'!$B$7+'Parametros'!$B$9/2)))^2))^2) -> 4.9872538 | BG8: ='Parametros'!$B$6*(AJ8*1000/(H8*MIN(U8,AB8))+0.66*SQRT('Parametros'!$B$2)) -> 3.2939604 | BH8: =IF(BF8<=BG8,"CUMPLE","NO CUMPLE") -> NO CUMPLE | BI8: =AX8*'Parametros'!$B$8 -> 2388 | BJ8: =IF(BI8>=AW8,"CUMPLE","NO CUMPLE") -> CUMPLE
A9: VC6 | B9: 81 | C9: 40 | D9: 3.3 | E9: 3.3 | F9: 450 | G9: 550 | H9: 450 | I9: 550 | J9: 171.0864 | K9: 70 | L9: 149.0401 | M9: 67 | N9: 98.239 | O9: 424.48 | P9: 70 | Q9: 123.143 | R9: =MAX(MAX(1.4/'Parametros'!$B$3,0.25*SQRT('Parametros'!$B$2)/'Parametros'!$B$3)*H9*U9,(0.85*'Parametros'!$B$2/'Parametros'!$B$3)*(1-SQRT(1-2*(J9*1000000/('Parametros'!$B$5*H9*U9^2))/(0.85*'Parametros'!$B$2)))*H9*U9) -> 962.00174 | S9: 5 | T9: 1 | U9: =IF(T9=1,I9-('Parametros'!$B$7+'Parametros'!$B$9+'Parametros'!$B$12/2),I9-(ROUNDUP(S9/2,0)*('Parametros'!$B$7+'Parametros'!$B$9+'Parametros'!$B$12/2)+ROUNDDOWN(S9/2,0)*('Parametros'!$B$7+'Parametros'!$B$9+'Parametros'!$B$12/2+'Parametros'!$B$12+'Parametros'!$B$10))/S9) -> 489.35 | V9: =S9*'Parametros'!$B$8 -> 995 | W9: ='Parametros'!$B$5*V9*'Parametros'!$B$3*(U9-(V9*'Parametros'!$B$3/(0.85*'Parametros'!$B$2*H9))/2)/1000000 -> 176.7116 | X9: =IF(W9>=J9,"CUMPLE","NO CUMPLE") -> CUMPLE | Y9: =MAX(MAX(1.4/'Parametros'!$B$3,0.25*SQRT('Parametros'!$B$2)/'Parametros'!$B$3)*H9*AB9,(0.85*'Parametros'!$B$2/'Parametros'!$B$3)*(1-SQRT(1-2*(L9*1000000/('Parametros'!$B$5*H9*AB9^2))/(0.85*'Parametros'!$B$2)))*H9*AB9) -> 833.57611 | Z9: 5 | AA9: 1 | AB9: =IF(AA9=1,I9-('Parametros'!$B$7+'Parametros'!$B$9+'Parametros'!$B$12/2),I9-(ROUNDUP(Z9/2,0)*('Parametros'!$B$7+'Parametros'!$B$9+'Parametros'!$B$12/2)+ROUNDDOWN(Z9/2,0)*('Parametros'!$B$7+'Parametros'!$B$9+'Parametros'!$B$12/2+'Parametros'!$B$12+'Parametros'!$B$10))/Z9) -> 489.35 | AC9: =Z9*'Parametros'!$B$8 -> 995 | AD9: ='Parametros'!$B$5*AC9*'Parametros'!$B$3*(AB9-(AC9*'Parametros'!$B$3/(0.85*'Parametros'!$B$2*H9))/2)/1000000 -> 176.7116 | AE9: =IF(AD9>=L9,"CUMPLE","NO CUMPLE") -> CUMPLE | AF9: =V9*1.25*'Parametros'!$B$3*(U9-(V9*1.25*'Parametros'!$B$3/(0.85*'Parametros'!$B$2*H9))/2)/1000000 -> 242.88491 | AG9: =AC9*1.25*'Parametros'!$B$3*(AB9-(AC9*1.25*'Parametros'!$B$3/(0.85*'Parametros'!$B$2*H9))/2)/1000000 -> 242.88491 | AH9: =N9+(AF9+AG9)/D9 -> 245.44198 | AI9: =MAX(O9,AH9) -> 424.48 | AJ9: =0.17*SQRT('Parametros'!$B$2)*H9*MIN(U9,AB9)/1000 -> 198.08886 | AK9: =MAX(AI9/'Parametros'!$B$6-AJ9,0) -> 367.88448 | AL9: =0.66*SQRT('Parametros'!$B$2)*H9*MIN(U9,AB9)/1000 -> 769.05085 | AM9: =IF(AK9<=AL9,"CUMPLE","NO CUMPLE") -> CUMPLE | AN9: Nº4 cerrado (referencia) | AO9: 4 | AP9: =ROUNDDOWN(MIN(IF(BC9+BD9=0,1000000000,AO9*BB9/(BC9+BD9)),MIN(U9,AB9)/4,8*'Parametros'!$B$12,24*BA9,300,IF(AV9=0,1000000000,2*((H9-2*('Parametros'!$B$7+'Parametros'!$B$9/2))+(I9-2*('Parametros'!$B$7+'Parametros'!$B$9/2)))/8))/10,0)*10 -> 110 | AQ9: =ROUNDDOWN(MIN(IF(BC9+BD9=0,1000000000,AO9*BB9/(BC9+BD9)),IF(AK9>0.33*SQRT('Parametros'!$B$2)*H9*MIN(U9,AB9)/1000,MIN(U9,AB9)/4,MIN(U9,AB9)/2),600,IF(AV9=0,1000000000,2*((H9-2*('Parametros'!$B$7+'Parametros'!$B$9/2))+(I9-2*('Parametros'!$B$7+'Parametros'!$B$9/2)))/8))/10,0)*10 -> 110 | AR9: ='Parametros'!$B$6*(AJ9+MAX(BE9-BD9,0)*'Parametros'!$B$4*MIN(U9,AB9)/1000) -> 437.76146 | AS9: =IF(AND(ISERROR(SEARCH("referencia",AN9)),AM9="CUMPLE",AR9>=AI9),"CUMPLE","NO CUMPLE") -> NO CUMPLE | AT9: ='Parametros'!$B$6*0.083*SQRT('Parametros'!$B$2)*(H9*I9)^2/(2*(H9+I9))/1000000 -> 10.088783 | AU9: =IF(Q9<=AT9,"DESPRECIABLE","DISEÑAR") -> DISEÑAR | AV9: =IF(Q9<=AT9,0,Q9*1000000/('Parametros'!$B$6*2*0.85*(H9-2*('Parametros'!$B$7+'Parametros'!$B$9/2))*(I9-2*('Parametros'!$B$7+'Parametros'!$B$9/2))*'Parametros'!$B$4)) -> 1.4073951 | AW9: =AV9*2*((H9-2*('Parametros'!$B$7+'Parametros'!$B$9/2))+(I9-2*('Parametros'!$B$7+'Parametros'!$B$9/2)))*'Parametros'!$B$4/'Parametros'!$B$3 -> 2292.9281 | AX9: 12 | AY9: =IF(AV9=0,"DESPRECIABLE",IF(AND(ISERROR(SEARCH("referencia",AN9)),BB9/AP9>=AV9,BI9>=AW9,BH9="CUMPLE"),"CUMPLE","NO CUMPLE")) -> NO CUMPLE | AZ9: =IF(AND(X9="CUMPLE",AE9="CUMPLE",AS9="CUMPLE",OR(AY9="CUMPLE",AY9="DESPRECIABLE"),BH9="CUMPLE",BJ9="CUMPLE",COUNTIF('Todas las Vigas (592)'!$A$4:$A$595,A9)=COUNTIFS('Todas las Vigas (592)'!$A$4:$A$595,A9,'Todas las Vigas (592)'!$AZ$4:$AZ$595,"CUMPLE")),"CUMPLE","NO CUMPLE") -> NO CUMPLE | BA9: 12.7 | BB9: 129 | BC9: =MAX(IF(AK9=0,0,AK9*1000/('Parametros'!$B$4*MIN(U9,AB9))),MAX(0.062*SQRT('Parametros'!$B$2)*H9/'Parametros'!$B$4,0.35*H9/'Parametros'!$B$4)) -> 1.7899569 | BD9: =2*AV9 -> 2.8147902 | BE9: =AO9*BB9/AP9 -> 4.6909091 | BF9: =SQRT((AI9*1000/(H9*MIN(U9,AB9)))^2+(Q9*1000000*2*((H9-2*('Parametros'!$B$7+'Parametros'!$B$9/2))+(I9-2*('Parametros'!$B$7+'Parametros'!$B$9/2)))/(1.7*((H9-2*('Parametros'!$B$7+'Parametros'!$B$9/2))*(I9-2*('Parametros'!$B$7+'Parametros'!$B$9/2)))^2))^2) -> 4.8224669 | BG9: ='Parametros'!$B$6*(AJ9*1000/(H9*MIN(U9,AB9))+0.66*SQRT('Parametros'!$B$2)) -> 3.2939604 | BH9: =IF(BF9<=BG9,"CUMPLE","NO CUMPLE") -> NO CUMPLE | BI9: =AX9*'Parametros'!$B$8 -> 2388 | BJ9: =IF(BI9>=AW9,"CUMPLE","NO CUMPLE") -> CUMPLE
A10: VC7 | B10: 75 | C10: 40 | D10: 2.05 | E10: 4.5 | F10: 450 | G10: 550 | H10: 450 | I10: 550 | J10: 210.2525 | K10: 74 | L10: 197.3101 | M10: 75 | N10: 163.07 | O10: 754.708 | P10: 75 | Q10: 14.1874 | R10: =MAX(MAX(1.4/'Parametros'!$B$3,0.25*SQRT('Parametros'!$B$2)/'Parametros'!$B$3)*H10*U10,(0.85*'Parametros'!$B$2/'Parametros'!$B$3)*(1-SQRT(1-2*(J10*1000000/('Parametros'!$B$5*H10*U10^2))/(0.85*'Parametros'!$B$2)))*H10*U10) -> 1193.7589 | S10: 6 | T10: 1 | U10: =IF(T10=1,I10-('Parametros'!$B$7+'Parametros'!$B$9+'Parametros'!$B$12/2),I10-(ROUNDUP(S10/2,0)*('Parametros'!$B$7+'Parametros'!$B$9+'Parametros'!$B$12/2)+ROUNDDOWN(S10/2,0)*('Parametros'!$B$7+'Parametros'!$B$9+'Parametros'!$B$12/2+'Parametros'!$B$12+'Parametros'!$B$10))/S10) -> 489.35 | V10: =S10*'Parametros'!$B$8 -> 1194 | W10: ='Parametros'!$B$5*V10*'Parametros'!$B$3*(U10-(V10*'Parametros'!$B$3/(0.85*'Parametros'!$B$2*H10))/2)/1000000 -> 210.29284 | X10: =IF(W10>=J10,"CUMPLE","NO CUMPLE") -> CUMPLE | Y10: =MAX(MAX(1.4/'Parametros'!$B$3,0.25*SQRT('Parametros'!$B$2)/'Parametros'!$B$3)*H10*AB10,(0.85*'Parametros'!$B$2/'Parametros'!$B$3)*(1-SQRT(1-2*(L10*1000000/('Parametros'!$B$5*H10*AB10^2))/(0.85*'Parametros'!$B$2)))*H10*AB10) -> 1116.652 | Z10: 6 | AA10: 1 | AB10: =IF(AA10=1,I10-('Parametros'!$B$7+'Parametros'!$B$9+'Parametros'!$B$12/2),I10-(ROUNDUP(Z10/2,0)*('Parametros'!$B$7+'Parametros'!$B$9+'Parametros'!$B$12/2)+ROUNDDOWN(Z10/2,0)*('Parametros'!$B$7+'Parametros'!$B$9+'Parametros'!$B$12/2+'Parametros'!$B$12+'Parametros'!$B$10))/Z10) -> 489.35 | AC10: =Z10*'Parametros'!$B$8 -> 1194 | AD10: ='Parametros'!$B$5*AC10*'Parametros'!$B$3*(AB10-(AC10*'Parametros'!$B$3/(0.85*'Parametros'!$B$2*H10))/2)/1000000 -> 210.29284 | AE10: =IF(AD10>=L10,"CUMPLE","NO CUMPLE") -> CUMPLE | AF10: =V10*1.25*'Parametros'!$B$3*(U10-(V10*1.25*'Parametros'!$B$3/(0.85*'Parametros'!$B$2*H10))/2)/1000000 -> 288.40447 | AG10: =AC10*1.25*'Parametros'!$B$3*(AB10-(AC10*1.25*'Parametros'!$B$3/(0.85*'Parametros'!$B$2*H10))/2)/1000000 -> 288.40447 | AH10: =N10+(AF10+AG10)/D10 -> 444.44021 | AI10: =MAX(O10,AH10) -> 754.708 | AJ10: =0.17*SQRT('Parametros'!$B$2)*H10*MIN(U10,AB10)/1000 -> 198.08886 | AK10: =MAX(AI10/'Parametros'!$B$6-AJ10,0) -> 808.18848 | AL10: =0.66*SQRT('Parametros'!$B$2)*H10*MIN(U10,AB10)/1000 -> 769.05085 | AM10: =IF(AK10<=AL10,"CUMPLE","NO CUMPLE") -> NO CUMPLE | AN10: Nº4 cerrado | AO10: 4 | AP10: =ROUNDDOWN(MIN(IF(BC10+BD10=0,1000000000,AO10*BB10/(BC10+BD10)),MIN(U10,AB10)/4,8*'Parametros'!$B$12,24*BA10,300,IF(AV10=0,1000000000,2*((H10-2*('Parametros'!$B$7+'Parametros'!$B$9/2))+(I10-2*('Parametros'!$B$7+'Parametros'!$B$9/2)))/8))/10,0)*10 -> 120 | AQ10: =ROUNDDOWN(MIN(IF(BC10+BD10=0,1000000000,AO10*BB10/(BC10+BD10)),IF(AK10>0.33*SQRT('Parametros'!$B$2)*H10*MIN(U10,AB10)/1000,MIN(U10,AB10)/4,MIN(U10,AB10)/2),600,IF(AV10=0,1000000000,2*((H10-2*('Parametros'!$B$7+'Parametros'!$B$9/2))+(I10-2*('Parametros'!$B$7+'Parametros'!$B$9/2)))/8))/10,0)*10 -> 120 | AR10: ='Parametros'!$B$6*(AJ10+MAX(BE10-BD10,0)*'Parametros'!$B$4*MIN(U10,AB10)/1000) -> 761.40281 | AS10: =IF(AND(ISERROR(SEARCH("referencia",AN10)),AM10="CUMPLE",AR10>=AI10),"CUMPLE","NO CUMPLE") -> NO CUMPLE | AT10: ='Parametros'!$B$6*0.083*SQRT('Parametros'!$B$2)*(H10*I10)^2/(2*(H10+I10))/1000000 -> 10.088783 | AU10: =IF(Q10<=AT10,"DESPRECIABLE","DISEÑAR") -> DISEÑAR | AV10: =IF(Q10<=AT10,0,Q10*1000000/('Parametros'!$B$6*2*0.85*(H10-2*('Parametros'!$B$7+'Parametros'!$B$9/2))*(I10-2*('Parametros'!$B$7+'Parametros'!$B$9/2))*'Parametros'!$B$4)) -> 0.16214708 | AW10: =AV10*2*((H10-2*('Parametros'!$B$7+'Parametros'!$B$9/2))+(I10-2*('Parametros'!$B$7+'Parametros'!$B$9/2)))*'Parametros'!$B$4/'Parametros'!$B$3 -> 264.17002 | AX10: 8 | AY10: =IF(AV10=0,"DESPRECIABLE",IF(AND(ISERROR(SEARCH("referencia",AN10)),BB10/AP10>=AV10,BI10>=AW10,BH10="CUMPLE"),"CUMPLE","NO CUMPLE")) -> NO CUMPLE | AZ10: =IF(AND(X10="CUMPLE",AE10="CUMPLE",AS10="CUMPLE",OR(AY10="CUMPLE",AY10="DESPRECIABLE"),BH10="CUMPLE",BJ10="CUMPLE",COUNTIF('Todas las Vigas (592)'!$A$4:$A$595,A10)=COUNTIFS('Todas las Vigas (592)'!$A$4:$A$595,A10,'Todas las Vigas (592)'!$AZ$4:$AZ$595,"CUMPLE")),"CUMPLE","NO CUMPLE") -> NO CUMPLE | BA10: 12.7 | BB10: 129 | BC10: =MAX(IF(AK10=0,0,AK10*1000/('Parametros'!$B$4*MIN(U10,AB10))),MAX(0.062*SQRT('Parametros'!$B$2)*H10/'Parametros'!$B$4,0.35*H10/'Parametros'!$B$4)) -> 3.932274 | BD10: =2*AV10 -> 0.32429415 | BE10: =AO10*BB10/AP10 -> 4.3 | BF10: =SQRT((AI10*1000/(H10*MIN(U10,AB10)))^2+(Q10*1000000*2*((H10-2*('Parametros'!$B$7+'Parametros'!$B$9/2))+(I10-2*('Parametros'!$B$7+'Parametros'!$B$9/2)))/(1.7*((H10-2*('Parametros'!$B$7+'Parametros'!$B$9/2))*(I10-2*('Parametros'!$B$7+'Parametros'!$B$9/2)))^2))^2) -> 3.4648911 | BG10: ='Parametros'!$B$6*(AJ10*1000/(H10*MIN(U10,AB10))+0.66*SQRT('Parametros'!$B$2)) -> 3.2939604 | BH10: =IF(BF10<=BG10,"CUMPLE","NO CUMPLE") -> NO CUMPLE | BI10: =AX10*'Parametros'!$B$8 -> 1592 | BJ10: =IF(BI10>=AW10,"CUMPLE","NO CUMPLE") -> CUMPLE

Sheet Vigas de Rigidez (5)
A1: DISEÑO DE VIGAS — VIGAS DE RIGIDEZ (5)
A2: Flexión: ENVFLEX. Cortante: ENVCORT directo. Torsión: máximo de ambas envolventes. Verificación DMO: Ve. Vu adoptado = máx(ENVCORT; Ve).
A3: Grupo | B3: Frame | C3: N vigas | D3: Ln adopt. mín (m) | E3: Ln adopt. máx (m) | F3: b modelo (mm) | G3: h modelo (mm) | H3: b adopt. (mm) | I3: h adopt. (mm) | J3: Mu− ENVFLEX (kN·m) | K3: Frame Mu− | L3: Mu+ ENVFLEX (kN·m) | M3: Frame Mu+ | N3: Vu ENVFLEX (kN) | O3: Vu ENVCORT (kN) | P3: Frame Vu | Q3: Tu diseño compat. (kN·m) | R3: As req. sup (mm²) | S3: Nº5 sup | T3: Capas sup | U3: d sup (mm) | V3: As prov. sup (mm²) | W3: φMn− (kN·m) | X3: Flexión − | Y3: As req. inf (mm²) | Z3: Nº5 inf | AA3: Capas inf | AB3: d inf (mm) | AC3: As prov. inf (mm²) | AD3: φMn+ (kN·m) | AE3: Flexión + | AF3: Mpr− (kN·m) | AG3: Mpr+ (kN·m) | AH3: Vcap (kN) | AI3: Vu diseño (kN) | AJ3: Vc (kN) | AK3: Vs req. (kN) | AL3: Vs máx. (kN) | AM3: Sección cortante | AN3: Estribo | AO3: Ramas | AP3: s extremo DMO (mm; zona 2h) | AQ3: s centro (mm) | AR3: φVn (kN) | AS3: Cortante | AT3: φTth (kN·m) | AU3: Torsión | AV3: At/s (mm²/mm) | AW3: Al adicional req. (mm²) | AX3: Nº5 torsión dedicadas | AY3: Chequeo torsión | AZ3: ESTADO | BA3: db estribo (mm) | BB3: Área rama (mm²) | BC3: Av/s req. cortante incl. mín. | BD3: 2At/s req. torsión | BE3: Av/s prov. extremo | BF3: Interacción V-T | BG3: Límite V-T | BH3: Chequeo V-T | BI3: Al provisto (mm²) | BJ3: Chequeo Al
A4: VR1 | B4: 250 | C4: 80 | D4: 3.4 | E4: 3.4 | F4: 500 | G4: 550 | H4: 500 | I4: 550 | J4: 179.0934 | K4: 254 | L4: 119.3315 | M4: 251 | N4: 136.996 | O4: 405.204 | P4: 251 | Q4: 9.2478 | R4: =MAX(MAX(1.4/'Parametros'!$B$3,0.25*SQRT('Parametros'!$B$2)/'Parametros'!$B$3)*H4*U4,(0.85*'Parametros'!$B$2/'Parametros'!$B$3)*(1-SQRT(1-2*(J4*1000000/('Parametros'!$B$5*H4*U4^2))/(0.85*'Parametros'!$B$2)))*H4*U4) -> 1004.6018 | S4: 6 | T4: 1 | U4: =IF(T4=1,I4-('Parametros'!$B$7+'Parametros'!$B$9+'Parametros'!$B$12/2),I4-(ROUNDUP(S4/2,0)*('Parametros'!$B$7+'Parametros'!$B$9+'Parametros'!$B$12/2)+ROUNDDOWN(S4/2,0)*('Parametros'!$B$7+'Parametros'!$B$9+'Parametros'!$B$12/2+'Parametros'!$B$12+'Parametros'!$B$10))/S4) -> 489.35 | V4: =S4*'Parametros'!$B$8 -> 1194 | W4: ='Parametros'!$B$5*V4*'Parametros'!$B$3*(U4-(V4*'Parametros'!$B$3/(0.85*'Parametros'!$B$2*H4))/2)/1000000 -> 211.34948 | X4: =IF(W4>=J4,"CUMPLE","NO CUMPLE") -> CUMPLE | Y4: =MAX(MAX(1.4/'Parametros'!$B$3,0.25*SQRT('Parametros'!$B$2)/'Parametros'!$B$3)*H4*AB4,(0.85*'Parametros'!$B$2/'Parametros'!$B$3)*(1-SQRT(1-2*(L4*1000000/('Parametros'!$B$5*H4*AB4^2))/(0.85*'Parametros'!$B$2)))*H4*AB4) -> 815.58333 | Z4: 5 | AA4: 1 | AB4: =IF(AA4=1,I4-('Parametros'!$B$7+'Parametros'!$B$9+'Parametros'!$B$12/2),I4-(ROUNDUP(Z4/2,0)*('Parametros'!$B$7+'Parametros'!$B$9+'Parametros'!$B$12/2)+ROUNDDOWN(Z4/2,0)*('Parametros'!$B$7+'Parametros'!$B$9+'Parametros'!$B$12/2+'Parametros'!$B$12+'Parametros'!$B$10))/Z4) -> 489.35 | AC4: =Z4*'Parametros'!$B$8 -> 995 | AD4: ='Parametros'!$B$5*AC4*'Parametros'!$B$3*(AB4-(AC4*'Parametros'!$B$3/(0.85*'Parametros'!$B$2*H4))/2)/1000000 -> 177.44538 | AE4: =IF(AD4>=L4,"CUMPLE","NO CUMPLE") -> CUMPLE | AF4: =V4*1.25*'Parametros'!$B$3*(U4-(V4*1.25*'Parametros'!$B$3/(0.85*'Parametros'!$B$2*H4))/2)/1000000 -> 290.23892 | AG4: =AC4*1.25*'Parametros'!$B$3*(AB4-(AC4*1.25*'Parametros'!$B$3/(0.85*'Parametros'!$B$2*H4))/2)/1000000 -> 244.15884 | AH4: =N4+(AF4+AG4)/D4 -> 294.17181 | AI4: =MAX(O4,AH4) -> 405.204 | AJ4: =0.17*SQRT('Parametros'!$B$2)*H4*MIN(U4,AB4)/1000 -> 220.09873 | AK4: =MAX(AI4/'Parametros'!$B$6-AJ4,0) -> 320.17327 | AL4: =0.66*SQRT('Parametros'!$B$2)*H4*MIN(U4,AB4)/1000 -> 854.50095 | AM4: =IF(AK4<=AL4,"CUMPLE","NO CUMPLE") -> CUMPLE | AN4: Nº3 cerrado | AO4: 2 | AP4: =ROUNDDOWN(MIN(IF(BC4+BD4=0,1000000000,AO4*BB4/(BC4+BD4)),MIN(U4,AB4)/4,8*'Parametros'!$B$12,24*BA4,300,IF(AV4=0,1000000000,2*((H4-2*('Parametros'!$B$7+'Parametros'!$B$9/2))+(I4-2*('Parametros'!$B$7+'Parametros'!$B$9/2)))/8))/10,0)*10 -> 90 | AQ4: =ROUNDDOWN(MIN(IF(BC4+BD4=0,1000000000,AO4*BB4/(BC4+BD4)),IF(AK4>0.33*SQRT('Parametros'!$B$2)*H4*MIN(U4,AB4)/1000,MIN(U4,AB4)/4,MIN(U4,AB4)/2),600,IF(AV4=0,1000000000,2*((H4-2*('Parametros'!$B$7+'Parametros'!$B$9/2))+(I4-2*('Parametros'!$B$7+'Parametros'!$B$9/2)))/8))/10,0)*10 -> 90 | AR4: ='Parametros'!$B$6*(AJ4+MAX(BE4-BD4,0)*'Parametros'!$B$4*MIN(U4,AB4)/1000) -> 408.281 | AS4: =IF(AND(ISERROR(SEARCH("referencia",AN4)),AM4="CUMPLE",AR4>=AI4),"CUMPLE","NO CUMPLE") -> CUMPLE | AT4: ='Parametros'!$B$6*0.083*SQRT('Parametros'!$B$2)*(H4*I4)^2/(2*(H4+I4))/1000000 -> 11.862179 | AU4: =IF(Q4<=AT4,"DESPRECIABLE","DISEÑAR") -> DESPRECIABLE | AV4: =IF(Q4<=AT4,0,Q4*1000000/('Parametros'!$B$6*2*0.85*(H4-2*('Parametros'!$B$7+'Parametros'!$B$9/2))*(I4-2*('Parametros'!$B$7+'Parametros'!$B$9/2))*'Parametros'!$B$4)) -> 0 | AW4: =AV4*2*((H4-2*('Parametros'!$B$7+'Parametros'!$B$9/2))+(I4-2*('Parametros'!$B$7+'Parametros'!$B$9/2)))*'Parametros'!$B$4/'Parametros'!$B$3 -> 0 | AX4: 0 | AY4: =IF(AV4=0,"DESPRECIABLE",IF(AND(ISERROR(SEARCH("referencia",AN4)),BB4/AP4>=AV4,BI4>=AW4,BH4="CUMPLE"),"CUMPLE","NO CUMPLE")) -> DESPRECIABLE | AZ4: =IF(AND(X4="CUMPLE",AE4="CUMPLE",AS4="CUMPLE",OR(AY4="CUMPLE",AY4="DESPRECIABLE"),BH4="CUMPLE",BJ4="CUMPLE",COUNTIF('Todas las Vigas (592)'!$A$4:$A$595,A4)=COUNTIFS('Todas las Vigas (592)'!$A$4:$A$595,A4,'Todas las Vigas (592)'!$AZ$4:$AZ$595,"CUMPLE")),"CUMPLE","NO CUMPLE") -> CUMPLE | BA4: 9.5 | BB4: 71 | BC4: =MAX(IF(AK4=0,0,AK4*1000/('Parametros'!$B$4*MIN(U4,AB4))),MAX(0.062*SQRT('Parametros'!$B$2)*H4/'Parametros'!$B$4,0.35*H4/'Parametros'!$B$4)) -> 1.5578161 | BD4: =2*AV4 -> 0 | BE4: =AO4*BB4/AP4 -> 1.5777778 | BF4: =SQRT((AI4*1000/(H4*MIN(U4,AB4)))^2+(Q4*1000000*2*((H4-2*('Parametros'!$B$7+'Parametros'!$B$9/2))+(I4-2*('Parametros'!$B$7+'Parametros'!$B$9/2)))/(1.7*((H4-2*('Parametros'!$B$7+'Parametros'!$B$9/2))*(I4-2*('Parametros'!$B$7+'Parametros'!$B$9/2)))^2))^2) -> 1.6781409 | BG4: ='Parametros'!$B$6*(AJ4*1000/(H4*MIN(U4,AB4))+0.66*SQRT('Parametros'!$B$2)) -> 3.2939604 | BH4: =IF(BF4<=BG4,"CUMPLE","NO CUMPLE") -> CUMPLE | BI4: =AX4*'Parametros'!$B$8 -> 0 | BJ4: =IF(BI4>=AW4,"CUMPLE","NO CUMPLE") -> CUMPLE
A5: VR N1 | B5: 52 | C5: 22 | D5: 2 | E5: 4.9 | F5: 500 | G5: 550 | H5: 500 | I5: 550 | J5: 175.8938 | K5: 54 | L5: 143.3015 | M5: 45 | N5: 164.744 | O5: 634.574 | P5: 54 | Q5: 10.9368 | R5: =MAX(MAX(1.4/'Parametros'!$B$3,0.25*SQRT('Parametros'!$B$2)/'Parametros'!$B$3)*H5*U5,(0.85*'Parametros'!$B$2/'Parametros'!$B$3)*(1-SQRT(1-2*(J5*1000000/('Parametros'!$B$5*H5*U5^2))/(0.85*'Parametros'!$B$2)))*H5*U5) -> 985.96659 | S5: 5 | T5: 1 | U5: =IF(T5=1,I5-('Parametros'!$B$7+'Parametros'!$B$9+'Parametros'!$B$12/2),I5-(ROUNDUP(S5/2,0)*('Parametros'!$B$7+'Parametros'!$B$9+'Parametros'!$B$12/2)+ROUNDDOWN(S5/2,0)*('Parametros'!$B$7+'Parametros'!$B$9+'Parametros'!$B$12/2+'Parametros'!$B$12+'Parametros'!$B$10))/S5) -> 489.35 | V5: =S5*'Parametros'!$B$8 -> 995 | W5: ='Parametros'!$B$5*V5*'Parametros'!$B$3*(U5-(V5*'Parametros'!$B$3/(0.85*'Parametros'!$B$2*H5))/2)/1000000 -> 177.44538 | X5: =IF(W5>=J5,"CUMPLE","NO CUMPLE") -> CUMPLE | Y5: =MAX(MAX(1.4/'Parametros'!$B$3,0.25*SQRT('Parametros'!$B$2)/'Parametros'!$B$3)*H5*AB5,(0.85*'Parametros'!$B$2/'Parametros'!$B$3)*(1-SQRT(1-2*(L5*1000000/('Parametros'!$B$5*H5*AB5^2))/(0.85*'Parametros'!$B$2)))*H5*AB5) -> 815.58333 | Z5: 5 | AA5: 1 | AB5: =IF(AA5=1,I5-('Parametros'!$B$7+'Parametros'!$B$9+'Parametros'!$B$12/2),I5-(ROUNDUP(Z5/2,0)*('Parametros'!$B$7+'Parametros'!$B$9+'Parametros'!$B$12/2)+ROUNDDOWN(Z5/2,0)*('Parametros'!$B$7+'Parametros'!$B$9+'Parametros'!$B$12/2+'Parametros'!$B$12+'Parametros'!$B$10))/Z5) -> 489.35 | AC5: =Z5*'Parametros'!$B$8 -> 995 | AD5: ='Parametros'!$B$5*AC5*'Parametros'!$B$3*(AB5-(AC5*'Parametros'!$B$3/(0.85*'Parametros'!$B$2*H5))/2)/1000000 -> 177.44538 | AE5: =IF(AD5>=L5,"CUMPLE","NO CUMPLE") -> CUMPLE | AF5: =V5*1.25*'Parametros'!$B$3*(U5-(V5*1.25*'Parametros'!$B$3/(0.85*'Parametros'!$B$2*H5))/2)/1000000 -> 244.15884 | AG5: =AC5*1.25*'Parametros'!$B$3*(AB5-(AC5*1.25*'Parametros'!$B$3/(0.85*'Parametros'!$B$2*H5))/2)/1000000 -> 244.15884 | AH5: =N5+(AF5+AG5)/D5 -> 408.90284 | AI5: =MAX(O5,AH5) -> 634.574 | AJ5: =0.17*SQRT('Parametros'!$B$2)*H5*MIN(U5,AB5)/1000 -> 220.09873 | AK5: =MAX(AI5/'Parametros'!$B$6-AJ5,0) -> 625.99994 | AL5: =0.66*SQRT('Parametros'!$B$2)*H5*MIN(U5,AB5)/1000 -> 854.50095 | AM5: =IF(AK5<=AL5,"CUMPLE","NO CUMPLE") -> CUMPLE | AN5: Nº4 cerrado | AO5: 2 | AP5: =ROUNDDOWN(MIN(IF(BC5+BD5=0,1000000000,AO5*BB5/(BC5+BD5)),MIN(U5,AB5)/4,8*'Parametros'!$B$12,24*BA5,300,IF(AV5=0,1000000000,2*((H5-2*('Parametros'!$B$7+'Parametros'!$B$9/2))+(I5-2*('Parametros'!$B$7+'Parametros'!$B$9/2)))/8))/10,0)*10 -> 80 | AQ5: =ROUNDDOWN(MIN(IF(BC5+BD5=0,1000000000,AO5*BB5/(BC5+BD5)),IF(AK5>0.33*SQRT('Parametros'!$B$2)*H5*MIN(U5,AB5)/1000,MIN(U5,AB5)/4,MIN(U5,AB5)/2),600,IF(AV5=0,1000000000,2*((H5-2*('Parametros'!$B$7+'Parametros'!$B$9/2))+(I5-2*('Parametros'!$B$7+'Parametros'!$B$9/2)))/8))/10,0)*10 -> 80 | AR5: ='Parametros'!$B$6*(AJ5+MAX(BE5-BD5,0)*'Parametros'!$B$4*MIN(U5,AB5)/1000) -> 662.19248 | AS5: =IF(AND(ISERROR(SEARCH("referencia",AN5)),AM5="CUMPLE",AR5>=AI5),"CUMPLE","NO CUMPLE") -> CUMPLE | AT5: ='Parametros'!$B$6*0.083*SQRT('Parametros'!$B$2)*(H5*I5)^2/(2*(H5+I5))/1000000 -> 11.862179 | AU5: =IF(Q5<=AT5,"DESPRECIABLE","DISEÑAR") -> DESPRECIABLE | AV5: =IF(Q5<=AT5,0,Q5*1000000/('Parametros'!$B$6*2*0.85*(H5-2*('Parametros'!$B$7+'Parametros'!$B$9/2))*(I5-2*('Parametros'!$B$7+'Parametros'!$B$9/2))*'Parametros'!$B$4)) -> 0 | AW5: =AV5*2*((H5-2*('Parametros'!$B$7+'Parametros'!$B$9/2))+(I5-2*('Parametros'!$B$7+'Parametros'!$B$9/2)))*'Parametros'!$B$4/'Parametros'!$B$3 -> 0 | AX5: 0 | AY5: =IF(AV5=0,"DESPRECIABLE",IF(AND(ISERROR(SEARCH("referencia",AN5)),BB5/AP5>=AV5,BI5>=AW5,BH5="CUMPLE"),"CUMPLE","NO CUMPLE")) -> DESPRECIABLE | AZ5: =IF(AND(X5="CUMPLE",AE5="CUMPLE",AS5="CUMPLE",OR(AY5="CUMPLE",AY5="DESPRECIABLE"),BH5="CUMPLE",BJ5="CUMPLE",COUNTIF('Todas las Vigas (592)'!$A$4:$A$595,A5)=COUNTIFS('Todas las Vigas (592)'!$A$4:$A$595,A5,'Todas las Vigas (592)'!$AZ$4:$AZ$595,"CUMPLE")),"CUMPLE","NO CUMPLE") -> CUMPLE | BA5: 12.7 | BB5: 129 | BC5: =MAX(IF(AK5=0,0,AK5*1000/('Parametros'!$B$4*MIN(U5,AB5))),MAX(0.062*SQRT('Parametros'!$B$2)*H5/'Parametros'!$B$4,0.35*H5/'Parametros'!$B$4)) -> 3.0458282 | BD5: =2*AV5 -> 0 | BE5: =AO5*BB5/AP5 -> 3.225 | BF5: =SQRT((AI5*1000/(H5*MIN(U5,AB5)))^2+(Q5*1000000*2*((H5-2*('Parametros'!$B$7+'Parametros'!$B$9/2))+(I5-2*('Parametros'!$B$7+'Parametros'!$B$9/2)))/(1.7*((H5-2*('Parametros'!$B$7+'Parametros'!$B$9/2))*(I5-2*('Parametros'!$B$7+'Parametros'!$B$9/2)))^2))^2) -> 2.613287 | BG5: ='Parametros'!$B$6*(AJ5*1000/(H5*MIN(U5,AB5))+0.66*SQRT('Parametros'!$B$2)) -> 3.2939604 | BH5: =IF(BF5<=BG5,"CUMPLE","NO CUMPLE") -> CUMPLE | BI5: =AX5*'Parametros'!$B$8 -> 0 | BJ5: =IF(BI5>=AW5,"CUMPLE","NO CUMPLE") -> CUMPLE
A6: VR2 | B6: 152 | C6: 140 | D6: 0.9 | E6: 3.57612 | F6: 500 | G6: 550 | H6: 500 | I6: 550 | J6: 71.2977 | K6: 33 | L6: 0.1306 | M6: 44 | N6: 52.863 | O6: 101.022 | P6: 11 | Q6: 140.6649 | R6: =MAX(MAX(1.4/'Parametros'!$B$3,0.25*SQRT('Parametros'!$B$2)/'Parametros'!$B$3)*H6*U6,(0.85*'Parametros'!$B$2/'Parametros'!$B$3)*(1-SQRT(1-2*(J6*1000000/('Parametros'!$B$5*H6*U6^2))/(0.85*'Parametros'!$B$2)))*H6*U6) -> 815.58333 | S6: 5 | T6: 1 | U6: =IF(T6=1,I6-('Parametros'!$B$7+'Parametros'!$B$9+'Parametros'!$B$12/2),I6-(ROUNDUP(S6/2,0)*('Parametros'!$B$7+'Parametros'!$B$9+'Parametros'!$B$12/2)+ROUNDDOWN(S6/2,0)*('Parametros'!$B$7+'Parametros'!$B$9+'Parametros'!$B$12/2+'Parametros'!$B$12+'Parametros'!$B$10))/S6) -> 489.35 | V6: =S6*'Parametros'!$B$8 -> 995 | W6: ='Parametros'!$B$5*V6*'Parametros'!$B$3*(U6-(V6*'Parametros'!$B$3/(0.85*'Parametros'!$B$2*H6))/2)/1000000 -> 177.44538 | X6: =IF(W6>=J6,"CUMPLE","NO CUMPLE") -> CUMPLE | Y6: =MAX(MAX(1.4/'Parametros'!$B$3,0.25*SQRT('Parametros'!$B$2)/'Parametros'!$B$3)*H6*AB6,(0.85*'Parametros'!$B$2/'Parametros'!$B$3)*(1-SQRT(1-2*(L6*1000000/('Parametros'!$B$5*H6*AB6^2))/(0.85*'Parametros'!$B$2)))*H6*AB6) -> 815.58333 | Z6: 5 | AA6: 1 | AB6: =IF(AA6=1,I6-('Parametros'!$B$7+'Parametros'!$B$9+'Parametros'!$B$12/2),I6-(ROUNDUP(Z6/2,0)*('Parametros'!$B$7+'Parametros'!$B$9+'Parametros'!$B$12/2)+ROUNDDOWN(Z6/2,0)*('Parametros'!$B$7+'Parametros'!$B$9+'Parametros'!$B$12/2+'Parametros'!$B$12+'Parametros'!$B$10))/Z6) -> 489.35 | AC6: =Z6*'Parametros'!$B$8 -> 995 | AD6: ='Parametros'!$B$5*AC6*'Parametros'!$B$3*(AB6-(AC6*'Parametros'!$B$3/(0.85*'Parametros'!$B$2*H6))/2)/1000000 -> 177.44538 | AE6: =IF(AD6>=L6,"CUMPLE","NO CUMPLE") -> CUMPLE | AF6: =V6*1.25*'Parametros'!$B$3*(U6-(V6*1.25*'Parametros'!$B$3/(0.85*'Parametros'!$B$2*H6))/2)/1000000 -> 244.15884 | AG6: =AC6*1.25*'Parametros'!$B$3*(AB6-(AC6*1.25*'Parametros'!$B$3/(0.85*'Parametros'!$B$2*H6))/2)/1000000 -> 244.15884 | AH6: =N6+(AF6+AG6)/D6 -> 595.43821 | AI6: =MAX(O6,AH6) -> 595.43821 | AJ6: =0.17*SQRT('Parametros'!$B$2)*H6*MIN(U6,AB6)/1000 -> 220.09873 | AK6: =MAX(AI6/'Parametros'!$B$6-AJ6,0) -> 573.81888 | AL6: =0.66*SQRT('Parametros'!$B$2)*H6*MIN(U6,AB6)/1000 -> 854.50095 | AM6: =IF(AK6<=AL6,"CUMPLE","NO CUMPLE") -> CUMPLE | AN6: Nº4 cerrado | AO6: 4 | AP6: =ROUNDDOWN(MIN(IF(BC6+BD6=0,1000000000,AO6*BB6/(BC6+BD6)),MIN(U6,AB6)/4,8*'Parametros'!$B$12,24*BA6,300,IF(AV6=0,1000000000,2*((H6-2*('Parametros'!$B$7+'Parametros'!$B$9/2))+(I6-2*('Parametros'!$B$7+'Parametros'!$B$9/2)))/8))/10,0)*10 -> 90 | AQ6: =ROUNDDOWN(MIN(IF(BC6+BD6=0,1000000000,AO6*BB6/(BC6+BD6)),IF(AK6>0.33*SQRT('Parametros'!$B$2)*H6*MIN(U6,AB6)/1000,MIN(U6,AB6)/4,MIN(U6,AB6)/2),600,IF(AV6=0,1000000000,2*((H6-2*('Parametros'!$B$7+'Parametros'!$B$9/2))+(I6-2*('Parametros'!$B$7+'Parametros'!$B$9/2)))/8))/10,0)*10 -> 90 | AR6: ='Parametros'!$B$6*(AJ6+MAX(BE6-BD6,0)*'Parametros'!$B$4*MIN(U6,AB6)/1000) -> 614.05891 | AS6: =IF(AND(ISERROR(SEARCH("referencia",AN6)),AM6="CUMPLE",AR6>=AI6),"CUMPLE","NO CUMPLE") -> CUMPLE | AT6: ='Parametros'!$B$6*0.083*SQRT('Parametros'!$B$2)*(H6*I6)^2/(2*(H6+I6))/1000000 -> 11.862179 | AU6: =IF(Q6<=AT6,"DESPRECIABLE","DISEÑAR") -> DISEÑAR | AV6: =IF(Q6<=AT6,0,Q6*1000000/('Parametros'!$B$6*2*0.85*(H6-2*('Parametros'!$B$7+'Parametros'!$B$9/2))*(I6-2*('Parametros'!$B$7+'Parametros'!$B$9/2))*'Parametros'!$B$4)) -> 1.4102972 | AW6: =AV6*2*((H6-2*('Parametros'!$B$7+'Parametros'!$B$9/2))+(I6-2*('Parametros'!$B$7+'Parametros'!$B$9/2)))*'Parametros'!$B$4/'Parametros'!$B$3 -> 2438.686 | AX6: 16 | AY6: =IF(AV6=0,"DESPRECIABLE",IF(AND(ISERROR(SEARCH("referencia",AN6)),BB6/AP6>=AV6,BI6>=AW6,BH6="CUMPLE"),"CUMPLE","NO CUMPLE")) -> NO CUMPLE | AZ6: =IF(AND(X6="CUMPLE",AE6="CUMPLE",AS6="CUMPLE",OR(AY6="CUMPLE",AY6="DESPRECIABLE"),BH6="CUMPLE",BJ6="CUMPLE",COUNTIF('Todas las Vigas (592)'!$A$4:$A$595,A6)=COUNTIFS('Todas las Vigas (592)'!$A$4:$A$595,A6,'Todas las Vigas (592)'!$AZ$4:$AZ$595,"CUMPLE")),"CUMPLE","NO CUMPLE") -> NO CUMPLE | BA6: 12.7 | BB6: 129 | BC6: =MAX(IF(AK6=0,0,AK6*1000/('Parametros'!$B$4*MIN(U6,AB6))),MAX(0.062*SQRT('Parametros'!$B$2)*H6/'Parametros'!$B$4,0.35*H6/'Parametros'!$B$4)) -> 2.7919392 | BD6: =2*AV6 -> 2.8205945 | BE6: =AO6*BB6/AP6 -> 5.7333333 | BF6: =SQRT((AI6*1000/(H6*MIN(U6,AB6)))^2+(Q6*1000000*2*((H6-2*('Parametros'!$B$7+'Parametros'!$B$9/2))+(I6-2*('Parametros'!$B$7+'Parametros'!$B$9/2)))/(1.7*((H6-2*('Parametros'!$B$7+'Parametros'!$B$9/2))*(I6-2*('Parametros'!$B$7+'Parametros'!$B$9/2)))^2))^2) -> 4.7887626 | BG6: ='Parametros'!$B$6*(AJ6*1000/(H6*MIN(U6,AB6))+0.66*SQRT('Parametros'!$B$2)) -> 3.2939604 | BH6: =IF(BF6<=BG6,"CUMPLE","NO CUMPLE") -> NO CUMPLE | BI6: =AX6*'Parametros'!$B$8 -> 3184 | BJ6: =IF(BI6>=AW6,"CUMPLE","NO CUMPLE") -> CUMPLE
