Workbook

Sheet Portada y criterio
A1: DISEÑO FINAL DE VIGAS — ENVOLVENTES DE FLEXIÓN Y CORTANTE
A3: Alcance | B3: 592 vigas: 12 grupos suministrados por el equipo y diseño individual de cada frame. No incluye viguetas.
A4: Fuente flexión | B4: ENVFLEX: M3 mínimo → Mu−; M3 máximo → Mu+; T → torsión de diseño.
A5: Fuente cortante | B5: ENVFLEX aporta el cortante de combinaciones de diseño; ENVCORT aporta el cortante elástico no reducido.
A6: Criterio DMO | B6: Vcap = Vu_ENVFLEX + (Mpr− + Mpr+)/Ln; Vu diseño = mín(Vu_ENVCORT; máx[Vu_ENVFLEX; Vcap]).
A7: Agrupación | B7: Se respetan los grupos ya definidos en ENV FLEXION/ENV CORTANTE. Cada grupo usa máximos independientes y la menor longitud, de forma conservadora.
A8: Secciones base | B8: VC: 0.30×0.40 m; VR: 0.35×0.40 m.
A9: Cambio requerido | B9: VR3 se adopta 0.40×0.55 m. Debe actualizarse en SAP y reanalizarse antes de emitir planos finales.
A10: Trazabilidad | B10: Las hojas muestran simultáneamente Mu, Vu de ambas envolventes, frames críticos, Mpr, Vcap y Vu final.
A12: RESULTADOS DE CONTROL
A13: Frames totales SAP | B13: 892
A14: Vigas diseñadas | B14: 592
A15: Columnas excluidas | B15: 300
A16: Grupos | B16: 12
A17: Grupos que cumplen | B17: 12
A18: Vigas que cumplen | B18: 592
A19: Grupos con cambio de sección | B19: 1
A20: Vigas con cambio de sección | B20: 70

Sheet Parametros
A1: PARÁMETROS GENERALES
A2: f'c | B2: 28 | C2: MPa | D2: Concreto del proyecto
A3: fy | B3: 420 | C3: MPa | D3: Acero longitudinal
A4: fyt | B4: 420 | C4: MPa | D4: Acero transversal
A5: φ flexión | B5: 0.9 | C5: — | D5: Secciones controladas por tracción
A6: φ cortante/torsión | B6: 0.75 | C6: — | D6: NSR-10 Título C
A7: Recubrimiento | B7: 40 | C7: mm | D7: Vigas interiores
A8: Área barra longitudinal | B8: 199 | C8: mm² | D8: Nº5
A9: db estribo | B9: 9.5 | C9: mm | D9: Nº3
A10: Separación libre vertical | B10: 25 | C10: mm | D10: Entre capas
A11: Área rama estribo | B11: 71 | C11: mm² | D11: Nº3
A12: db longitudinal | B12: 15.9 | C12: mm | D12: Barra Nº5

Sheet Vigas de Carga (7)
A1: DISEÑO DE VIGAS — VIGAS DE CARGA (7)
A2: ENVFLEX: flexión y torsión. ENVCORT: límite elástico de cortante. Vu diseño DMO = mín(ENVCORT; máx[ENVFLEX; Vcap]).
A3: Grupo | B3: Frame | C3: N vigas | D3: L mín (m) | E3: L máx (m) | F3: b modelo (mm) | G3: h modelo (mm) | H3: b adopt. (mm) | I3: h adopt. (mm) | J3: Mu− ENVFLEX (kN·m) | K3: Frame Mu− | L3: Mu+ ENVFLEX (kN·m) | M3: Frame Mu+ | N3: Vu ENVFLEX (kN) | O3: Vu ENVCORT (kN) | P3: Frame Vu | Q3: Tu ENVFLEX (kN·m) | R3: As req. sup (mm²) | S3: Nº5 sup | T3: Capas sup | U3: d sup (mm) | V3: As prov. sup (mm²) | W3: φMn− (kN·m) | X3: Flexión − | Y3: As req. inf (mm²) | Z3: Nº5 inf | AA3: Capas inf | AB3: d inf (mm) | AC3: As prov. inf (mm²) | AD3: φMn+ (kN·m) | AE3: Flexión + | AF3: Mpr− (kN·m) | AG3: Mpr+ (kN·m) | AH3: Vcap (kN) | AI3: Vu diseño (kN) | AJ3: Vc (kN) | AK3: Vs req. (kN) | AL3: Vs máx. (kN) | AM3: Sección cortante | AN3: Estribo | AO3: Ramas | AP3: s extremo DMO (mm) | AQ3: s centro (mm) | AR3: φVn (kN) | AS3: Cortante | AT3: φTth (kN·m) | AU3: Torsión | AV3: At/s (mm²/mm) | AW3: Al (mm²) | AX3: Nº5 torsión | AY3: Chequeo torsión | AZ3: ESTADO
A4: VC1 | B4: — | C4: 20 | D4: 3.75 | E4: 3.75 | F4: 300 | G4: 400 | H4: 300 | I4: 400 | J4: 19.2952 | K4: 178 | L4: 12.1187 | M4: 179 | N4: 14.449 | O4: 40.811 | P4: 178 | Q4: 2.5041 | R4: =MAX(MAX(1.4/'Parametros'!$B$3,0.25*SQRT('Parametros'!$B$2)/'Parametros'!$B$3)*H4*U4,(0.85*'Parametros'!$B$2/'Parametros'!$B$3)*(1-SQRT(1-2*(J4*1000000/('Parametros'!$B$5*H4*U4^2))/(0.85*'Parametros'!$B$2)))*H4*U4) -> 342.55 | S4: 2 | T4: 1 | U4: =IF(T4=1,I4-('Parametros'!$B$7+'Parametros'!$B$9+'Parametros'!$B$12/2),I4-(ROUNDUP(S4/2,0)*('Parametros'!$B$7+'Parametros'!$B$9+'Parametros'!$B$12/2)+ROUNDDOWN(S4/2,0)*('Parametros'!$B$7+'Parametros'!$B$9+'Parametros'!$B$12/2+'Parametros'!$B$12+'Parametros'!$B$10))/S4) -> 342.55 | V4: =S4*'Parametros'!$B$8 -> 398 | W4: ='Parametros'!$B$5*V4*'Parametros'!$B$3*(U4-(V4*'Parametros'!$B$3/(0.85*'Parametros'!$B$2*H4))/2)/1000000 -> 49.773512 | X4: =IF(W4>=J4,"CUMPLE","NO CUMPLE") -> CUMPLE | Y4: =MAX(MAX(1.4/'Parametros'!$B$3,0.25*SQRT('Parametros'!$B$2)/'Parametros'!$B$3)*H4*AB4,(0.85*'Parametros'!$B$2/'Parametros'!$B$3)*(1-SQRT(1-2*(L4*1000000/('Parametros'!$B$5*H4*AB4^2))/(0.85*'Parametros'!$B$2)))*H4*AB4) -> 342.55 | Z4: 2 | AA4: 1 | AB4: =IF(AA4=1,I4-('Parametros'!$B$7+'Parametros'!$B$9+'Parametros'!$B$12/2),I4-(ROUNDUP(Z4/2,0)*('Parametros'!$B$7+'Parametros'!$B$9+'Parametros'!$B$12/2)+ROUNDDOWN(Z4/2,0)*('Parametros'!$B$7+'Parametros'!$B$9+'Parametros'!$B$12/2+'Parametros'!$B$12+'Parametros'!$B$10))/Z4) -> 342.55 | AC4: =Z4*'Parametros'!$B$8 -> 398 | AD4: ='Parametros'!$B$5*AC4*'Parametros'!$B$3*(AB4-(AC4*'Parametros'!$B$3/(0.85*'Parametros'!$B$2*H4))/2)/1000000 -> 49.773512 | AE4: =IF(AD4>=L4,"CUMPLE","NO CUMPLE") -> CUMPLE | AF4: =V4*1.25*'Parametros'!$B$3*(U4-(V4*1.25*'Parametros'!$B$3/(0.85*'Parametros'!$B$2*H4))/2)/1000000 -> 68.518392 | AG4: =AC4*1.25*'Parametros'!$B$3*(AB4-(AC4*1.25*'Parametros'!$B$3/(0.85*'Parametros'!$B$2*H4))/2)/1000000 -> 68.518392 | AH4: =N4+(AF4+AG4)/D4 -> 50.992143 | AI4: =MIN(O4,MAX(N4,AH4)) -> 40.811 | AJ4: =0.17*SQRT('Parametros'!$B$2)*H4*MIN(U4,AB4)/1000 -> 92.442815 | AK4: =MAX(AI4/'Parametros'!$B$6-AJ4,0) -> 0 | AL4: =0.66*SQRT('Parametros'!$B$2)*H4*MIN(U4,AB4)/1000 -> 358.89564 | AM4: =IF(AK4<=AL4,"CUMPLE","NO CUMPLE") -> CUMPLE | AN4: Nº3 cerrado | AO4: 2 | AP4: =ROUNDDOWN(MIN(IF(AK4=0,1000000000,AO4*'Parametros'!$B$11*'Parametros'!$B$4*MIN(U4,AB4)/(AK4*1000)),IF(AV4=0,1000000000,'Parametros'!$B$11/AV4),MIN(U4,AB4)/4,8*'Parametros'!$B$12,24*'Parametros'!$B$9,300)/10,0)*10 -> 80 | AQ4: =ROUNDDOWN(MIN(IF(AK4=0,1000000000,AO4*'Parametros'!$B$11*'Parametros'!$B$4*MIN(U4,AB4)/(AK4*1000)),IF(AV4=0,1000000000,'Parametros'!$B$11/AV4),MIN(U4,AB4)/2,600)/10,0)*10 -> 170 | AR4: ='Parametros'!$B$6*(AJ4+AO4*'Parametros'!$B$11*'Parametros'!$B$4*MIN(U4,AB4)/AP4/1000) -> 260.86038 | AS4: =IF(AND(AM4="CUMPLE",AR4>=AI4),"CUMPLE","NO CUMPLE") -> CUMPLE | AT4: ='Parametros'!$B$6*0.083*SQRT('Parametros'!$B$2)*(H4*I4)^2/(2*(H4+I4))/1000000 -> 3.3880735 | AU4: =IF(Q4<=AT4,"DESPRECIABLE","DISEÑAR") -> DESPRECIABLE | AV4: =IF(Q4<=AT4,0,Q4*1000000/('Parametros'!$B$6*2*0.85*(H4-2*'Parametros'!$B$7)*(I4-2*'Parametros'!$B$7)*'Parametros'!$B$4)) -> 0 | AW4: =AV4*2*((H4-2*'Parametros'!$B$7)+(I4-2*'Parametros'!$B$7))*'Parametros'!$B$4/'Parametros'!$B$3 -> 0 | AX4: 0 | AY4: =IF(AV4=0,"DESPRECIABLE",IF('Parametros'!$B$11/AP4>=AV4,"CUMPLE","NO CUMPLE")) -> DESPRECIABLE | AZ4: =IF(AND(X4="CUMPLE",AE4="CUMPLE",AS4="CUMPLE",OR(AY4="CUMPLE",AY4="DESPRECIABLE")),IF(OR(F4<>H4,G4<>I4),"CUMPLE - REANALIZAR SAP","CUMPLE"),"NO CUMPLE") -> CUMPLE
A5: VC2 | B5: — | C5: 40 | D5: 3.75 | E5: 4 | F5: 300 | G5: 400 | H5: 300 | I5: 400 | J5: 81.9216 | K5: 1365 | L5: 73.7796 | M5: 1365 | N5: 47.882 | O5: 204.587 | P5: 1365 | Q5: 4.4669 | R5: =MAX(MAX(1.4/'Parametros'!$B$3,0.25*SQRT('Parametros'!$B$2)/'Parametros'!$B$3)*H5*U5,(0.85*'Parametros'!$B$2/'Parametros'!$B$3)*(1-SQRT(1-2*(J5*1000000/('Parametros'!$B$5*H5*U5^2))/(0.85*'Parametros'!$B$2)))*H5*U5) -> 671.37992 | S5: 4 | T5: 1 | U5: =IF(T5=1,I5-('Parametros'!$B$7+'Parametros'!$B$9+'Parametros'!$B$12/2),I5-(ROUNDUP(S5/2,0)*('Parametros'!$B$7+'Parametros'!$B$9+'Parametros'!$B$12/2)+ROUNDDOWN(S5/2,0)*('Parametros'!$B$7+'Parametros'!$B$9+'Parametros'!$B$12/2+'Parametros'!$B$12+'Parametros'!$B$10))/S5) -> 342.55 | V5: =S5*'Parametros'!$B$8 -> 796 | W5: ='Parametros'!$B$5*V5*'Parametros'!$B$3*(U5-(V5*'Parametros'!$B$3/(0.85*'Parametros'!$B$2*H5))/2)/1000000 -> 96.024865 | X5: =IF(W5>=J5,"CUMPLE","NO CUMPLE") -> CUMPLE | Y5: =MAX(MAX(1.4/'Parametros'!$B$3,0.25*SQRT('Parametros'!$B$2)/'Parametros'!$B$3)*H5*AB5,(0.85*'Parametros'!$B$2/'Parametros'!$B$3)*(1-SQRT(1-2*(L5*1000000/('Parametros'!$B$5*H5*AB5^2))/(0.85*'Parametros'!$B$2)))*H5*AB5) -> 600.78886 | Z5: 4 | AA5: 1 | AB5: =IF(AA5=1,I5-('Parametros'!$B$7+'Parametros'!$B$9+'Parametros'!$B$12/2),I5-(ROUNDUP(Z5/2,0)*('Parametros'!$B$7+'Parametros'!$B$9+'Parametros'!$B$12/2)+ROUNDDOWN(Z5/2,0)*('Parametros'!$B$7+'Parametros'!$B$9+'Parametros'!$B$12/2+'Parametros'!$B$12+'Parametros'!$B$10))/Z5) -> 342.55 | AC5: =Z5*'Parametros'!$B$8 -> 796 | AD5: ='Parametros'!$B$5*AC5*'Parametros'!$B$3*(AB5-(AC5*'Parametros'!$B$3/(0.85*'Parametros'!$B$2*H5))/2)/1000000 -> 96.024865 | AE5: =IF(AD5>=L5,"CUMPLE","NO CUMPLE") -> CUMPLE | AF5: =V5*1.25*'Parametros'!$B$3*(U5-(V5*1.25*'Parametros'!$B$3/(0.85*'Parametros'!$B$2*H5))/2)/1000000 -> 130.92192 | AG5: =AC5*1.25*'Parametros'!$B$3*(AB5-(AC5*1.25*'Parametros'!$B$3/(0.85*'Parametros'!$B$2*H5))/2)/1000000 -> 130.92192 | AH5: =N5+(AF5+AG5)/D5 -> 117.70703 | AI5: =MIN(O5,MAX(N5,AH5)) -> 117.70703 | AJ5: =0.17*SQRT('Parametros'!$B$2)*H5*MIN(U5,AB5)/1000 -> 92.442815 | AK5: =MAX(AI5/'Parametros'!$B$6-AJ5,0) -> 64.499886 | AL5: =0.66*SQRT('Parametros'!$B$2)*H5*MIN(U5,AB5)/1000 -> 358.89564 | AM5: =IF(AK5<=AL5,"CUMPLE","NO CUMPLE") -> CUMPLE | AN5: Nº3 cerrado | AO5: 2 | AP5: =ROUNDDOWN(MIN(IF(AK5=0,1000000000,AO5*'Parametros'!$B$11*'Parametros'!$B$4*MIN(U5,AB5)/(AK5*1000)),IF(AV5=0,1000000000,'Parametros'!$B$11/AV5),MIN(U5,AB5)/4,8*'Parametros'!$B$12,24*'Parametros'!$B$9,300)/10,0)*10 -> 80 | AQ5: =ROUNDDOWN(MIN(IF(AK5=0,1000000000,AO5*'Parametros'!$B$11*'Parametros'!$B$4*MIN(U5,AB5)/(AK5*1000)),IF(AV5=0,1000000000,'Parametros'!$B$11/AV5),MIN(U5,AB5)/2,600)/10,0)*10 -> 170 | AR5: ='Parametros'!$B$6*(AJ5+AO5*'Parametros'!$B$11*'Parametros'!$B$4*MIN(U5,AB5)/AP5/1000) -> 260.86038 | AS5: =IF(AND(AM5="CUMPLE",AR5>=AI5),"CUMPLE","NO CUMPLE") -> CUMPLE | AT5: ='Parametros'!$B$6*0.083*SQRT('Parametros'!$B$2)*(H5*I5)^2/(2*(H5+I5))/1000000 -> 3.3880735 | AU5: =IF(Q5<=AT5,"DESPRECIABLE","DISEÑAR") -> DISEÑAR | AV5: =IF(Q5<=AT5,0,Q5*1000000/('Parametros'!$B$6*2*0.85*(H5-2*'Parametros'!$B$7)*(I5-2*'Parametros'!$B$7)*'Parametros'!$B$4)) -> 0.11848793 | AW5: =AV5*2*((H5-2*'Parametros'!$B$7)+(I5-2*'Parametros'!$B$7))*'Parametros'!$B$4/'Parametros'!$B$3 -> 127.96696 | AX5: 1 | AY5: =IF(AV5=0,"DESPRECIABLE",IF('Parametros'!$B$11/AP5>=AV5,"CUMPLE","NO CUMPLE")) -> CUMPLE | AZ5: =IF(AND(X5="CUMPLE",AE5="CUMPLE",AS5="CUMPLE",OR(AY5="CUMPLE",AY5="DESPRECIABLE")),IF(OR(F5<>H5,G5<>I5),"CUMPLE - REANALIZAR SAP","CUMPLE"),"NO CUMPLE") -> CUMPLE
A6: VC3 | B6: — | C6: 40 | D6: 3.81477 | E6: 4 | F6: 300 | G6: 400 | H6: 300 | I6: 400 | J6: 91.0671 | K6: 290 | L6: 71.2022 | M6: 92 | N6: 52.32 | O6: 192.828 | P6: 289 | Q6: 6.8314 | R6: =MAX(MAX(1.4/'Parametros'!$B$3,0.25*SQRT('Parametros'!$B$2)/'Parametros'!$B$3)*H6*U6,(0.85*'Parametros'!$B$2/'Parametros'!$B$3)*(1-SQRT(1-2*(J6*1000000/('Parametros'!$B$5*H6*U6^2))/(0.85*'Parametros'!$B$2)))*H6*U6) -> 751.84287 | S6: 4 | T6: 1 | U6: =IF(T6=1,I6-('Parametros'!$B$7+'Parametros'!$B$9+'Parametros'!$B$12/2),I6-(ROUNDUP(S6/2,0)*('Parametros'!$B$7+'Parametros'!$B$9+'Parametros'!$B$12/2)+ROUNDDOWN(S6/2,0)*('Parametros'!$B$7+'Parametros'!$B$9+'Parametros'!$B$12/2+'Parametros'!$B$12+'Parametros'!$B$10))/S6) -> 342.55 | V6: =S6*'Parametros'!$B$8 -> 796 | W6: ='Parametros'!$B$5*V6*'Parametros'!$B$3*(U6-(V6*'Parametros'!$B$3/(0.85*'Parametros'!$B$2*H6))/2)/1000000 -> 96.024865 | X6: =IF(W6>=J6,"CUMPLE","NO CUMPLE") -> CUMPLE | Y6: =MAX(MAX(1.4/'Parametros'!$B$3,0.25*SQRT('Parametros'!$B$2)/'Parametros'!$B$3)*H6*AB6,(0.85*'Parametros'!$B$2/'Parametros'!$B$3)*(1-SQRT(1-2*(L6*1000000/('Parametros'!$B$5*H6*AB6^2))/(0.85*'Parametros'!$B$2)))*H6*AB6) -> 578.64081 | Z6: 3 | AA6: 1 | AB6: =IF(AA6=1,I6-('Parametros'!$B$7+'Parametros'!$B$9+'Parametros'!$B$12/2),I6-(ROUNDUP(Z6/2,0)*('Parametros'!$B$7+'Parametros'!$B$9+'Parametros'!$B$12/2)+ROUNDDOWN(Z6/2,0)*('Parametros'!$B$7+'Parametros'!$B$9+'Parametros'!$B$12/2+'Parametros'!$B$12+'Parametros'!$B$10))/Z6) -> 342.55 | AC6: =Z6*'Parametros'!$B$8 -> 597 | AD6: ='Parametros'!$B$5*AC6*'Parametros'!$B$3*(AB6-(AC6*'Parametros'!$B$3/(0.85*'Parametros'!$B$2*H6))/2)/1000000 -> 73.339459 | AE6: =IF(AD6>=L6,"CUMPLE","NO CUMPLE") -> CUMPLE | AF6: =V6*1.25*'Parametros'!$B$3*(U6-(V6*1.25*'Parametros'!$B$3/(0.85*'Parametros'!$B$2*H6))/2)/1000000 -> 130.92192 | AG6: =AC6*1.25*'Parametros'!$B$3*(AB6-(AC6*1.25*'Parametros'!$B$3/(0.85*'Parametros'!$B$2*H6))/2)/1000000 -> 100.48452 | AH6: =N6+(AF6+AG6)/D6 -> 112.98065 | AI6: =MIN(O6,MAX(N6,AH6)) -> 112.98065 | AJ6: =0.17*SQRT('Parametros'!$B$2)*H6*MIN(U6,AB6)/1000 -> 92.442815 | AK6: =MAX(AI6/'Parametros'!$B$6-AJ6,0) -> 58.198056 | AL6: =0.66*SQRT('Parametros'!$B$2)*H6*MIN(U6,AB6)/1000 -> 358.89564 | AM6: =IF(AK6<=AL6,"CUMPLE","NO CUMPLE") -> CUMPLE | AN6: Nº3 cerrado | AO6: 2 | AP6: =ROUNDDOWN(MIN(IF(AK6=0,1000000000,AO6*'Parametros'!$B$11*'Parametros'!$B$4*MIN(U6,AB6)/(AK6*1000)),IF(AV6=0,1000000000,'Parametros'!$B$11/AV6),MIN(U6,AB6)/4,8*'Parametros'!$B$12,24*'Parametros'!$B$9,300)/10,0)*10 -> 80 | AQ6: =ROUNDDOWN(MIN(IF(AK6=0,1000000000,AO6*'Parametros'!$B$11*'Parametros'!$B$4*MIN(U6,AB6)/(AK6*1000)),IF(AV6=0,1000000000,'Parametros'!$B$11/AV6),MIN(U6,AB6)/2,600)/10,0)*10 -> 170 | AR6: ='Parametros'!$B$6*(AJ6+AO6*'Parametros'!$B$11*'Parametros'!$B$4*MIN(U6,AB6)/AP6/1000) -> 260.86038 | AS6: =IF(AND(AM6="CUMPLE",AR6>=AI6),"CUMPLE","NO CUMPLE") -> CUMPLE | AT6: ='Parametros'!$B$6*0.083*SQRT('Parametros'!$B$2)*(H6*I6)^2/(2*(H6+I6))/1000000 -> 3.3880735 | AU6: =IF(Q6<=AT6,"DESPRECIABLE","DISEÑAR") -> DISEÑAR | AV6: =IF(Q6<=AT6,0,Q6*1000000/('Parametros'!$B$6*2*0.85*(H6-2*'Parametros'!$B$7)*(I6-2*'Parametros'!$B$7)*'Parametros'!$B$4)) -> 0.18120809 | AW6: =AV6*2*((H6-2*'Parametros'!$B$7)+(I6-2*'Parametros'!$B$7))*'Parametros'!$B$4/'Parametros'!$B$3 -> 195.70474 | AX6: 1 | AY6: =IF(AV6=0,"DESPRECIABLE",IF('Parametros'!$B$11/AP6>=AV6,"CUMPLE","NO CUMPLE")) -> CUMPLE | AZ6: =IF(AND(X6="CUMPLE",AE6="CUMPLE",AS6="CUMPLE",OR(AY6="CUMPLE",AY6="DESPRECIABLE")),IF(OR(F6<>H6,G6<>I6),"CUMPLE - REANALIZAR SAP","CUMPLE"),"NO CUMPLE") -> CUMPLE
A7: VC4 | B7: — | C7: 20 | D7: 3.85 | E7: 3.85 | F7: 300 | G7: 400 | H7: 300 | I7: 400 | J7: 94.2174 | K7: 88 | L7: 77.4126 | M7: 62 | N7: 55.131 | O7: 230.934 | P7: 88 | Q7: 6.0628 | R7: =MAX(MAX(1.4/'Parametros'!$B$3,0.25*SQRT('Parametros'!$B$2)/'Parametros'!$B$3)*H7*U7,(0.85*'Parametros'!$B$2/'Parametros'!$B$3)*(1-SQRT(1-2*(J7*1000000/('Parametros'!$B$5*H7*U7^2))/(0.85*'Parametros'!$B$2)))*H7*U7) -> 779.85674 | S7: 4 | T7: 1 | U7: =IF(T7=1,I7-('Parametros'!$B$7+'Parametros'!$B$9+'Parametros'!$B$12/2),I7-(ROUNDUP(S7/2,0)*('Parametros'!$B$7+'Parametros'!$B$9+'Parametros'!$B$12/2)+ROUNDDOWN(S7/2,0)*('Parametros'!$B$7+'Parametros'!$B$9+'Parametros'!$B$12/2+'Parametros'!$B$12+'Parametros'!$B$10))/S7) -> 342.55 | V7: =S7*'Parametros'!$B$8 -> 796 | W7: ='Parametros'!$B$5*V7*'Parametros'!$B$3*(U7-(V7*'Parametros'!$B$3/(0.85*'Parametros'!$B$2*H7))/2)/1000000 -> 96.024865 | X7: =IF(W7>=J7,"CUMPLE","NO CUMPLE") -> CUMPLE | Y7: =MAX(MAX(1.4/'Parametros'!$B$3,0.25*SQRT('Parametros'!$B$2)/'Parametros'!$B$3)*H7*AB7,(0.85*'Parametros'!$B$2/'Parametros'!$B$3)*(1-SQRT(1-2*(L7*1000000/('Parametros'!$B$5*H7*AB7^2))/(0.85*'Parametros'!$B$2)))*H7*AB7) -> 632.16833 | Z7: 4 | AA7: 1 | AB7: =IF(AA7=1,I7-('Parametros'!$B$7+'Parametros'!$B$9+'Parametros'!$B$12/2),I7-(ROUNDUP(Z7/2,0)*('Parametros'!$B$7+'Parametros'!$B$9+'Parametros'!$B$12/2)+ROUNDDOWN(Z7/2,0)*('Parametros'!$B$7+'Parametros'!$B$9+'Parametros'!$B$12/2+'Parametros'!$B$12+'Parametros'!$B$10))/Z7) -> 342.55 | AC7: =Z7*'Parametros'!$B$8 -> 796 | AD7: ='Parametros'!$B$5*AC7*'Parametros'!$B$3*(AB7-(AC7*'Parametros'!$B$3/(0.85*'Parametros'!$B$2*H7))/2)/1000000 -> 96.024865 | AE7: =IF(AD7>=L7,"CUMPLE","NO CUMPLE") -> CUMPLE | AF7: =V7*1.25*'Parametros'!$B$3*(U7-(V7*1.25*'Parametros'!$B$3/(0.85*'Parametros'!$B$2*H7))/2)/1000000 -> 130.92192 | AG7: =AC7*1.25*'Parametros'!$B$3*(AB7-(AC7*1.25*'Parametros'!$B$3/(0.85*'Parametros'!$B$2*H7))/2)/1000000 -> 130.92192 | AH7: =N7+(AF7+AG7)/D7 -> 123.14239 | AI7: =MIN(O7,MAX(N7,AH7)) -> 123.14239 | AJ7: =0.17*SQRT('Parametros'!$B$2)*H7*MIN(U7,AB7)/1000 -> 92.442815 | AK7: =MAX(AI7/'Parametros'!$B$6-AJ7,0) -> 71.747037 | AL7: =0.66*SQRT('Parametros'!$B$2)*H7*MIN(U7,AB7)/1000 -> 358.89564 | AM7: =IF(AK7<=AL7,"CUMPLE","NO CUMPLE") -> CUMPLE | AN7: Nº3 cerrado | AO7: 2 | AP7: =ROUNDDOWN(MIN(IF(AK7=0,1000000000,AO7*'Parametros'!$B$11*'Parametros'!$B$4*MIN(U7,AB7)/(AK7*1000)),IF(AV7=0,1000000000,'Parametros'!$B$11/AV7),MIN(U7,AB7)/4,8*'Parametros'!$B$12,24*'Parametros'!$B$9,300)/10,0)*10 -> 80 | AQ7: =ROUNDDOWN(MIN(IF(AK7=0,1000000000,AO7*'Parametros'!$B$11*'Parametros'!$B$4*MIN(U7,AB7)/(AK7*1000)),IF(AV7=0,1000000000,'Parametros'!$B$11/AV7),MIN(U7,AB7)/2,600)/10,0)*10 -> 170 | AR7: ='Parametros'!$B$6*(AJ7+AO7*'Parametros'!$B$11*'Parametros'!$B$4*MIN(U7,AB7)/AP7/1000) -> 260.86038 | AS7: =IF(AND(AM7="CUMPLE",AR7>=AI7),"CUMPLE","NO CUMPLE") -> CUMPLE | AT7: ='Parametros'!$B$6*0.083*SQRT('Parametros'!$B$2)*(H7*I7)^2/(2*(H7+I7))/1000000 -> 3.3880735 | AU7: =IF(Q7<=AT7,"DESPRECIABLE","DISEÑAR") -> DISEÑAR | AV7: =IF(Q7<=AT7,0,Q7*1000000/('Parametros'!$B$6*2*0.85*(H7-2*'Parametros'!$B$7)*(I7-2*'Parametros'!$B$7)*'Parametros'!$B$4)) -> 0.16082039 | AW7: =AV7*2*((H7-2*'Parametros'!$B$7)+(I7-2*'Parametros'!$B$7))*'Parametros'!$B$4/'Parametros'!$B$3 -> 173.68602 | AX7: 1 | AY7: =IF(AV7=0,"DESPRECIABLE",IF('Parametros'!$B$11/AP7>=AV7,"CUMPLE","NO CUMPLE")) -> CUMPLE | AZ7: =IF(AND(X7="CUMPLE",AE7="CUMPLE",AS7="CUMPLE",OR(AY7="CUMPLE",AY7="DESPRECIABLE")),IF(OR(F7<>H7,G7<>I7),"CUMPLE - REANALIZAR SAP","CUMPLE"),"NO CUMPLE") -> CUMPLE
A8: VC5 | B8: — | C8: 40 | D8: 3.85 | E8: 3.9 | F8: 300 | G8: 400 | H8: 300 | I8: 400 | J8: 116.2475 | K8: 284 | L8: 75.5281 | M8: 86 | N8: 89.1 | O8: 267.071 | P8: 284 | Q8: 20.0139 | R8: =MAX(MAX(1.4/'Parametros'!$B$3,0.25*SQRT('Parametros'!$B$2)/'Parametros'!$B$3)*H8*U8,(0.85*'Parametros'!$B$2/'Parametros'!$B$3)*(1-SQRT(1-2*(J8*1000000/('Parametros'!$B$5*H8*U8^2))/(0.85*'Parametros'!$B$2)))*H8*U8) -> 980.28476 | S8: 5 | T8: 1 | U8: =IF(T8=1,I8-('Parametros'!$B$7+'Parametros'!$B$9+'Parametros'!$B$12/2),I8-(ROUNDUP(S8/2,0)*('Parametros'!$B$7+'Parametros'!$B$9+'Parametros'!$B$12/2)+ROUNDDOWN(S8/2,0)*('Parametros'!$B$7+'Parametros'!$B$9+'Parametros'!$B$12/2+'Parametros'!$B$12+'Parametros'!$B$10))/S8) -> 342.55 | V8: =S8*'Parametros'!$B$8 -> 995 | W8: ='Parametros'!$B$5*V8*'Parametros'!$B$3*(U8-(V8*'Parametros'!$B$3/(0.85*'Parametros'!$B$2*H8))/2)/1000000 -> 117.82973 | X8: =IF(W8>=J8,"CUMPLE","NO CUMPLE") -> CUMPLE | Y8: =MAX(MAX(1.4/'Parametros'!$B$3,0.25*SQRT('Parametros'!$B$2)/'Parametros'!$B$3)*H8*AB8,(0.85*'Parametros'!$B$2/'Parametros'!$B$3)*(1-SQRT(1-2*(L8*1000000/('Parametros'!$B$5*H8*AB8^2))/(0.85*'Parametros'!$B$2)))*H8*AB8) -> 615.86765 | Z8: 4 | AA8: 1 | AB8: =IF(AA8=1,I8-('Parametros'!$B$7+'Parametros'!$B$9+'Parametros'!$B$12/2),I8-(ROUNDUP(Z8/2,0)*('Parametros'!$B$7+'Parametros'!$B$9+'Parametros'!$B$12/2)+ROUNDDOWN(Z8/2,0)*('Parametros'!$B$7+'Parametros'!$B$9+'Parametros'!$B$12/2+'Parametros'!$B$12+'Parametros'!$B$10))/Z8) -> 342.55 | AC8: =Z8*'Parametros'!$B$8 -> 796 | AD8: ='Parametros'!$B$5*AC8*'Parametros'!$B$3*(AB8-(AC8*'Parametros'!$B$3/(0.85*'Parametros'!$B$2*H8))/2)/1000000 -> 96.024865 | AE8: =IF(AD8>=L8,"CUMPLE","NO CUMPLE") -> CUMPLE | AF8: =V8*1.25*'Parametros'!$B$3*(U8-(V8*1.25*'Parametros'!$B$3/(0.85*'Parametros'!$B$2*H8))/2)/1000000 -> 159.83062 | AG8: =AC8*1.25*'Parametros'!$B$3*(AB8-(AC8*1.25*'Parametros'!$B$3/(0.85*'Parametros'!$B$2*H8))/2)/1000000 -> 130.92192 | AH8: =N8+(AF8+AG8)/D8 -> 164.62014 | AI8: =MIN(O8,MAX(N8,AH8)) -> 164.62014 | AJ8: =0.17*SQRT('Parametros'!$B$2)*H8*MIN(U8,AB8)/1000 -> 92.442815 | AK8: =MAX(AI8/'Parametros'!$B$6-AJ8,0) -> 127.05071 | AL8: =0.66*SQRT('Parametros'!$B$2)*H8*MIN(U8,AB8)/1000 -> 358.89564 | AM8: =IF(AK8<=AL8,"CUMPLE","NO CUMPLE") -> CUMPLE | AN8: Nº3 cerrado | AO8: 2 | AP8: =ROUNDDOWN(MIN(IF(AK8=0,1000000000,AO8*'Parametros'!$B$11*'Parametros'!$B$4*MIN(U8,AB8)/(AK8*1000)),IF(AV8=0,1000000000,'Parametros'!$B$11/AV8),MIN(U8,AB8)/4,8*'Parametros'!$B$12,24*'Parametros'!$B$9,300)/10,0)*10 -> 80 | AQ8: =ROUNDDOWN(MIN(IF(AK8=0,1000000000,AO8*'Parametros'!$B$11*'Parametros'!$B$4*MIN(U8,AB8)/(AK8*1000)),IF(AV8=0,1000000000,'Parametros'!$B$11/AV8),MIN(U8,AB8)/2,600)/10,0)*10 -> 130 | AR8: ='Parametros'!$B$6*(AJ8+AO8*'Parametros'!$B$11*'Parametros'!$B$4*MIN(U8,AB8)/AP8/1000) -> 260.86038 | AS8: =IF(AND(AM8="CUMPLE",AR8>=AI8),"CUMPLE","NO CUMPLE") -> CUMPLE | AT8: ='Parametros'!$B$6*0.083*SQRT('Parametros'!$B$2)*(H8*I8)^2/(2*(H8+I8))/1000000 -> 3.3880735 | AU8: =IF(Q8<=AT8,"DESPRECIABLE","DISEÑAR") -> DISEÑAR | AV8: =IF(Q8<=AT8,0,Q8*1000000/('Parametros'!$B$6*2*0.85*(H8-2*'Parametros'!$B$7)*(I8-2*'Parametros'!$B$7)*'Parametros'!$B$4)) -> 0.53088394 | AW8: =AV8*2*((H8-2*'Parametros'!$B$7)+(I8-2*'Parametros'!$B$7))*'Parametros'!$B$4/'Parametros'!$B$3 -> 573.35466 | AX8: 3 | AY8: =IF(AV8=0,"DESPRECIABLE",IF('Parametros'!$B$11/AP8>=AV8,"CUMPLE","NO CUMPLE")) -> CUMPLE | AZ8: =IF(AND(X8="CUMPLE",AE8="CUMPLE",AS8="CUMPLE",OR(AY8="CUMPLE",AY8="DESPRECIABLE")),IF(OR(F8<>H8,G8<>I8),"CUMPLE - REANALIZAR SAP","CUMPLE"),"NO CUMPLE") -> CUMPLE
A9: VC6 | B9: — | C9: 40 | D9: 3.85 | E9: 3.9 | F9: 300 | G9: 400 | H9: 300 | I9: 400 | J9: 86.6444 | K9: 268 | L9: 75.6101 | M9: 279 | N9: 49.435 | O9: 214.218 | P9: 281 | Q9: 10.308 | R9: =MAX(MAX(1.4/'Parametros'!$B$3,0.25*SQRT('Parametros'!$B$2)/'Parametros'!$B$3)*H9*U9,(0.85*'Parametros'!$B$2/'Parametros'!$B$3)*(1-SQRT(1-2*(J9*1000000/('Parametros'!$B$5*H9*U9^2))/(0.85*'Parametros'!$B$2)))*H9*U9) -> 712.77336 | S9: 4 | T9: 1 | U9: =IF(T9=1,I9-('Parametros'!$B$7+'Parametros'!$B$9+'Parametros'!$B$12/2),I9-(ROUNDUP(S9/2,0)*('Parametros'!$B$7+'Parametros'!$B$9+'Parametros'!$B$12/2)+ROUNDDOWN(S9/2,0)*('Parametros'!$B$7+'Parametros'!$B$9+'Parametros'!$B$12/2+'Parametros'!$B$12+'Parametros'!$B$10))/S9) -> 342.55 | V9: =S9*'Parametros'!$B$8 -> 796 | W9: ='Parametros'!$B$5*V9*'Parametros'!$B$3*(U9-(V9*'Parametros'!$B$3/(0.85*'Parametros'!$B$2*H9))/2)/1000000 -> 96.024865 | X9: =IF(W9>=J9,"CUMPLE","NO CUMPLE") -> CUMPLE | Y9: =MAX(MAX(1.4/'Parametros'!$B$3,0.25*SQRT('Parametros'!$B$2)/'Parametros'!$B$3)*H9*AB9,(0.85*'Parametros'!$B$2/'Parametros'!$B$3)*(1-SQRT(1-2*(L9*1000000/('Parametros'!$B$5*H9*AB9^2))/(0.85*'Parametros'!$B$2)))*H9*AB9) -> 616.57588 | Z9: 4 | AA9: 1 | AB9: =IF(AA9=1,I9-('Parametros'!$B$7+'Parametros'!$B$9+'Parametros'!$B$12/2),I9-(ROUNDUP(Z9/2,0)*('Parametros'!$B$7+'Parametros'!$B$9+'Parametros'!$B$12/2)+ROUNDDOWN(Z9/2,0)*('Parametros'!$B$7+'Parametros'!$B$9+'Parametros'!$B$12/2+'Parametros'!$B$12+'Parametros'!$B$10))/Z9) -> 342.55 | AC9: =Z9*'Parametros'!$B$8 -> 796 | AD9: ='Parametros'!$B$5*AC9*'Parametros'!$B$3*(AB9-(AC9*'Parametros'!$B$3/(0.85*'Parametros'!$B$2*H9))/2)/1000000 -> 96.024865 | AE9: =IF(AD9>=L9,"CUMPLE","NO CUMPLE") -> CUMPLE | AF9: =V9*1.25*'Parametros'!$B$3*(U9-(V9*1.25*'Parametros'!$B$3/(0.85*'Parametros'!$B$2*H9))/2)/1000000 -> 130.92192 | AG9: =AC9*1.25*'Parametros'!$B$3*(AB9-(AC9*1.25*'Parametros'!$B$3/(0.85*'Parametros'!$B$2*H9))/2)/1000000 -> 130.92192 | AH9: =N9+(AF9+AG9)/D9 -> 117.44639 | AI9: =MIN(O9,MAX(N9,AH9)) -> 117.44639 | AJ9: =0.17*SQRT('Parametros'!$B$2)*H9*MIN(U9,AB9)/1000 -> 92.442815 | AK9: =MAX(AI9/'Parametros'!$B$6-AJ9,0) -> 64.15237 | AL9: =0.66*SQRT('Parametros'!$B$2)*H9*MIN(U9,AB9)/1000 -> 358.89564 | AM9: =IF(AK9<=AL9,"CUMPLE","NO CUMPLE") -> CUMPLE | AN9: Nº3 cerrado | AO9: 2 | AP9: =ROUNDDOWN(MIN(IF(AK9=0,1000000000,AO9*'Parametros'!$B$11*'Parametros'!$B$4*MIN(U9,AB9)/(AK9*1000)),IF(AV9=0,1000000000,'Parametros'!$B$11/AV9),MIN(U9,AB9)/4,8*'Parametros'!$B$12,24*'Parametros'!$B$9,300)/10,0)*10 -> 80 | AQ9: =ROUNDDOWN(MIN(IF(AK9=0,1000000000,AO9*'Parametros'!$B$11*'Parametros'!$B$4*MIN(U9,AB9)/(AK9*1000)),IF(AV9=0,1000000000,'Parametros'!$B$11/AV9),MIN(U9,AB9)/2,600)/10,0)*10 -> 170 | AR9: ='Parametros'!$B$6*(AJ9+AO9*'Parametros'!$B$11*'Parametros'!$B$4*MIN(U9,AB9)/AP9/1000) -> 260.86038 | AS9: =IF(AND(AM9="CUMPLE",AR9>=AI9),"CUMPLE","NO CUMPLE") -> CUMPLE | AT9: ='Parametros'!$B$6*0.083*SQRT('Parametros'!$B$2)*(H9*I9)^2/(2*(H9+I9))/1000000 -> 3.3880735 | AU9: =IF(Q9<=AT9,"DESPRECIABLE","DISEÑAR") -> DISEÑAR | AV9: =IF(Q9<=AT9,0,Q9*1000000/('Parametros'!$B$6*2*0.85*(H9-2*'Parametros'!$B$7)*(I9-2*'Parametros'!$B$7)*'Parametros'!$B$4)) -> 0.27342755 | AW9: =AV9*2*((H9-2*'Parametros'!$B$7)+(I9-2*'Parametros'!$B$7))*'Parametros'!$B$4/'Parametros'!$B$3 -> 295.30176 | AX9: 2 | AY9: =IF(AV9=0,"DESPRECIABLE",IF('Parametros'!$B$11/AP9>=AV9,"CUMPLE","NO CUMPLE")) -> CUMPLE | AZ9: =IF(AND(X9="CUMPLE",AE9="CUMPLE",AS9="CUMPLE",OR(AY9="CUMPLE",AY9="DESPRECIABLE")),IF(OR(F9<>H9,G9<>I9),"CUMPLE - REANALIZAR SAP","CUMPLE"),"NO CUMPLE") -> CUMPLE
A10: VC7 | B10: — | C10: 40 | D10: 2.65 | E10: 5.1 | F10: 300 | G10: 400 | H10: 300 | I10: 400 | J10: 93.8347 | K10: 78 | L10: 84.9896 | M10: 274 | N10: 67.467 | O10: 311.347 | P10: 278 | Q10: 8.8961 | R10: =MAX(MAX(1.4/'Parametros'!$B$3,0.25*SQRT('Parametros'!$B$2)/'Parametros'!$B$3)*H10*U10,(0.85*'Parametros'!$B$2/'Parametros'!$B$3)*(1-SQRT(1-2*(J10*1000000/('Parametros'!$B$5*H10*U10^2))/(0.85*'Parametros'!$B$2)))*H10*U10) -> 776.4453 | S10: 4 | T10: 1 | U10: =IF(T10=1,I10-('Parametros'!$B$7+'Parametros'!$B$9+'Parametros'!$B$12/2),I10-(ROUNDUP(S10/2,0)*('Parametros'!$B$7+'Parametros'!$B$9+'Parametros'!$B$12/2)+ROUNDDOWN(S10/2,0)*('Parametros'!$B$7+'Parametros'!$B$9+'Parametros'!$B$12/2+'Parametros'!$B$12+'Parametros'!$B$10))/S10) -> 342.55 | V10: =S10*'Parametros'!$B$8 -> 796 | W10: ='Parametros'!$B$5*V10*'Parametros'!$B$3*(U10-(V10*'Parametros'!$B$3/(0.85*'Parametros'!$B$2*H10))/2)/1000000 -> 96.024865 | X10: =IF(W10>=J10,"CUMPLE","NO CUMPLE") -> CUMPLE | Y10: =MAX(MAX(1.4/'Parametros'!$B$3,0.25*SQRT('Parametros'!$B$2)/'Parametros'!$B$3)*H10*AB10,(0.85*'Parametros'!$B$2/'Parametros'!$B$3)*(1-SQRT(1-2*(L10*1000000/('Parametros'!$B$5*H10*AB10^2))/(0.85*'Parametros'!$B$2)))*H10*AB10) -> 698.23166 | Z10: 4 | AA10: 1 | AB10: =IF(AA10=1,I10-('Parametros'!$B$7+'Parametros'!$B$9+'Parametros'!$B$12/2),I10-(ROUNDUP(Z10/2,0)*('Parametros'!$B$7+'Parametros'!$B$9+'Parametros'!$B$12/2)+ROUNDDOWN(Z10/2,0)*('Parametros'!$B$7+'Parametros'!$B$9+'Parametros'!$B$12/2+'Parametros'!$B$12+'Parametros'!$B$10))/Z10) -> 342.55 | AC10: =Z10*'Parametros'!$B$8 -> 796 | AD10: ='Parametros'!$B$5*AC10*'Parametros'!$B$3*(AB10-(AC10*'Parametros'!$B$3/(0.85*'Parametros'!$B$2*H10))/2)/1000000 -> 96.024865 | AE10: =IF(AD10>=L10,"CUMPLE","NO CUMPLE") -> CUMPLE | AF10: =V10*1.25*'Parametros'!$B$3*(U10-(V10*1.25*'Parametros'!$B$3/(0.85*'Parametros'!$B$2*H10))/2)/1000000 -> 130.92192 | AG10: =AC10*1.25*'Parametros'!$B$3*(AB10-(AC10*1.25*'Parametros'!$B$3/(0.85*'Parametros'!$B$2*H10))/2)/1000000 -> 130.92192 | AH10: =N10+(AF10+AG10)/D10 -> 166.276 | AI10: =MIN(O10,MAX(N10,AH10)) -> 166.276 | AJ10: =0.17*SQRT('Parametros'!$B$2)*H10*MIN(U10,AB10)/1000 -> 92.442815 | AK10: =MAX(AI10/'Parametros'!$B$6-AJ10,0) -> 129.25852 | AL10: =0.66*SQRT('Parametros'!$B$2)*H10*MIN(U10,AB10)/1000 -> 358.89564 | AM10: =IF(AK10<=AL10,"CUMPLE","NO CUMPLE") -> CUMPLE | AN10: Nº3 cerrado | AO10: 2 | AP10: =ROUNDDOWN(MIN(IF(AK10=0,1000000000,AO10*'Parametros'!$B$11*'Parametros'!$B$4*MIN(U10,AB10)/(AK10*1000)),IF(AV10=0,1000000000,'Parametros'!$B$11/AV10),MIN(U10,AB10)/4,8*'Parametros'!$B$12,24*'Parametros'!$B$9,300)/10,0)*10 -> 80 | AQ10: =ROUNDDOWN(MIN(IF(AK10=0,1000000000,AO10*'Parametros'!$B$11*'Parametros'!$B$4*MIN(U10,AB10)/(AK10*1000)),IF(AV10=0,1000000000,'Parametros'!$B$11/AV10),MIN(U10,AB10)/2,600)/10,0)*10 -> 150 | AR10: ='Parametros'!$B$6*(AJ10+AO10*'Parametros'!$B$11*'Parametros'!$B$4*MIN(U10,AB10)/AP10/1000) -> 260.86038 | AS10: =IF(AND(AM10="CUMPLE",AR10>=AI10),"CUMPLE","NO CUMPLE") -> CUMPLE | AT10: ='Parametros'!$B$6*0.083*SQRT('Parametros'!$B$2)*(H10*I10)^2/(2*(H10+I10))/1000000 -> 3.3880735 | AU10: =IF(Q10<=AT10,"DESPRECIABLE","DISEÑAR") -> DISEÑAR | AV10: =IF(Q10<=AT10,0,Q10*1000000/('Parametros'!$B$6*2*0.85*(H10-2*'Parametros'!$B$7)*(I10-2*'Parametros'!$B$7)*'Parametros'!$B$4)) -> 0.23597583 | AW10: =AV10*2*((H10-2*'Parametros'!$B$7)+(I10-2*'Parametros'!$B$7))*'Parametros'!$B$4/'Parametros'!$B$3 -> 254.8539 | AX10: 2 | AY10: =IF(AV10=0,"DESPRECIABLE",IF('Parametros'!$B$11/AP10>=AV10,"CUMPLE","NO CUMPLE")) -> CUMPLE | AZ10: =IF(AND(X10="CUMPLE",AE10="CUMPLE",AS10="CUMPLE",OR(AY10="CUMPLE",AY10="DESPRECIABLE")),IF(OR(F10<>H10,G10<>I10),"CUMPLE - REANALIZAR SAP","CUMPLE"),"NO CUMPLE") -> CUMPLE

Sheet Vigas de Rigidez (5)
A1: DISEÑO DE VIGAS — VIGAS DE RIGIDEZ (5)
A2: ENVFLEX: flexión y torsión. ENVCORT: límite elástico de cortante. Vu diseño DMO = mín(ENVCORT; máx[ENVFLEX; Vcap]).
A3: Grupo | B3: Frame | C3: N vigas | D3: L mín (m) | E3: L máx (m) | F3: b modelo (mm) | G3: h modelo (mm) | H3: b adopt. (mm) | I3: h adopt. (mm) | J3: Mu− ENVFLEX (kN·m) | K3: Frame Mu− | L3: Mu+ ENVFLEX (kN·m) | M3: Frame Mu+ | N3: Vu ENVFLEX (kN) | O3: Vu ENVCORT (kN) | P3: Frame Vu | Q3: Tu ENVFLEX (kN·m) | R3: As req. sup (mm²) | S3: Nº5 sup | T3: Capas sup | U3: d sup (mm) | V3: As prov. sup (mm²) | W3: φMn− (kN·m) | X3: Flexión − | Y3: As req. inf (mm²) | Z3: Nº5 inf | AA3: Capas inf | AB3: d inf (mm) | AC3: As prov. inf (mm²) | AD3: φMn+ (kN·m) | AE3: Flexión + | AF3: Mpr− (kN·m) | AG3: Mpr+ (kN·m) | AH3: Vcap (kN) | AI3: Vu diseño (kN) | AJ3: Vc (kN) | AK3: Vs req. (kN) | AL3: Vs máx. (kN) | AM3: Sección cortante | AN3: Estribo | AO3: Ramas | AP3: s extremo DMO (mm) | AQ3: s centro (mm) | AR3: φVn (kN) | AS3: Cortante | AT3: φTth (kN·m) | AU3: Torsión | AV3: At/s (mm²/mm) | AW3: Al (mm²) | AX3: Nº5 torsión | AY3: Chequeo torsión | AZ3: ESTADO
A4: VR1 | B4: — | C4: 80 | D4: 2.5 | E4: 4 | F4: 350 | G4: 400 | H4: 350 | I4: 400 | J4: 111.8179 | K4: 250 | L4: 83.0823 | M4: 251 | N4: 112.744 | O4: 401.413 | P4: 251 | Q4: 4.3221 | R4: =MAX(MAX(1.4/'Parametros'!$B$3,0.25*SQRT('Parametros'!$B$2)/'Parametros'!$B$3)*H4*U4,(0.85*'Parametros'!$B$2/'Parametros'!$B$3)*(1-SQRT(1-2*(J4*1000000/('Parametros'!$B$5*H4*U4^2))/(0.85*'Parametros'!$B$2)))*H4*U4) -> 926.77843 | S4: 5 | T4: 1 | U4: =IF(T4=1,I4-('Parametros'!$B$7+'Parametros'!$B$9+'Parametros'!$B$12/2),I4-(ROUNDUP(S4/2,0)*('Parametros'!$B$7+'Parametros'!$B$9+'Parametros'!$B$12/2)+ROUNDDOWN(S4/2,0)*('Parametros'!$B$7+'Parametros'!$B$9+'Parametros'!$B$12/2+'Parametros'!$B$12+'Parametros'!$B$10))/S4) -> 342.55 | V4: =S4*'Parametros'!$B$8 -> 995 | W4: ='Parametros'!$B$5*V4*'Parametros'!$B$3*(U4-(V4*'Parametros'!$B$3/(0.85*'Parametros'!$B$2*H4))/2)/1000000 -> 119.40212 | X4: =IF(W4>=J4,"CUMPLE","NO CUMPLE") -> CUMPLE | Y4: =MAX(MAX(1.4/'Parametros'!$B$3,0.25*SQRT('Parametros'!$B$2)/'Parametros'!$B$3)*H4*AB4,(0.85*'Parametros'!$B$2/'Parametros'!$B$3)*(1-SQRT(1-2*(L4*1000000/('Parametros'!$B$5*H4*AB4^2))/(0.85*'Parametros'!$B$2)))*H4*AB4) -> 675.19299 | Z4: 4 | AA4: 1 | AB4: =IF(AA4=1,I4-('Parametros'!$B$7+'Parametros'!$B$9+'Parametros'!$B$12/2),I4-(ROUNDUP(Z4/2,0)*('Parametros'!$B$7+'Parametros'!$B$9+'Parametros'!$B$12/2)+ROUNDDOWN(Z4/2,0)*('Parametros'!$B$7+'Parametros'!$B$9+'Parametros'!$B$12/2+'Parametros'!$B$12+'Parametros'!$B$10))/Z4) -> 342.55 | AC4: =Z4*'Parametros'!$B$8 -> 796 | AD4: ='Parametros'!$B$5*AC4*'Parametros'!$B$3*(AB4-(AC4*'Parametros'!$B$3/(0.85*'Parametros'!$B$2*H4))/2)/1000000 -> 97.031197 | AE4: =IF(AD4>=L4,"CUMPLE","NO CUMPLE") -> CUMPLE | AF4: =V4*1.25*'Parametros'!$B$3*(U4-(V4*1.25*'Parametros'!$B$3/(0.85*'Parametros'!$B$2*H4))/2)/1000000 -> 162.56047 | AG4: =AC4*1.25*'Parametros'!$B$3*(AB4-(AC4*1.25*'Parametros'!$B$3/(0.85*'Parametros'!$B$2*H4))/2)/1000000 -> 132.66903 | AH4: =N4+(AF4+AG4)/D4 -> 230.8358 | AI4: =MIN(O4,MAX(N4,AH4)) -> 230.8358 | AJ4: =0.17*SQRT('Parametros'!$B$2)*H4*MIN(U4,AB4)/1000 -> 107.84995 | AK4: =MAX(AI4/'Parametros'!$B$6-AJ4,0) -> 199.93111 | AL4: =0.66*SQRT('Parametros'!$B$2)*H4*MIN(U4,AB4)/1000 -> 418.71158 | AM4: =IF(AK4<=AL4,"CUMPLE","NO CUMPLE") -> CUMPLE | AN4: Nº3 cerrado | AO4: 2 | AP4: =ROUNDDOWN(MIN(IF(AK4=0,1000000000,AO4*'Parametros'!$B$11*'Parametros'!$B$4*MIN(U4,AB4)/(AK4*1000)),IF(AV4=0,1000000000,'Parametros'!$B$11/AV4),MIN(U4,AB4)/4,8*'Parametros'!$B$12,24*'Parametros'!$B$9,300)/10,0)*10 -> 80 | AQ4: =ROUNDDOWN(MIN(IF(AK4=0,1000000000,AO4*'Parametros'!$B$11*'Parametros'!$B$4*MIN(U4,AB4)/(AK4*1000)),IF(AV4=0,1000000000,'Parametros'!$B$11/AV4),MIN(U4,AB4)/2,600)/10,0)*10 -> 100 | AR4: ='Parametros'!$B$6*(AJ4+AO4*'Parametros'!$B$11*'Parametros'!$B$4*MIN(U4,AB4)/AP4/1000) -> 272.41573 | AS4: =IF(AND(AM4="CUMPLE",AR4>=AI4),"CUMPLE","NO CUMPLE") -> CUMPLE | AT4: ='Parametros'!$B$6*0.083*SQRT('Parametros'!$B$2)*(H4*I4)^2/(2*(H4+I4))/1000000 -> 4.3041082 | AU4: =IF(Q4<=AT4,"DESPRECIABLE","DISEÑAR") -> DISEÑAR | AV4: =IF(Q4<=AT4,0,Q4*1000000/('Parametros'!$B$6*2*0.85*(H4-2*'Parametros'!$B$7)*(I4-2*'Parametros'!$B$7)*'Parametros'!$B$4)) -> 0.09341607 | AW4: =AV4*2*((H4-2*'Parametros'!$B$7)+(I4-2*'Parametros'!$B$7))*'Parametros'!$B$4/'Parametros'!$B$3 -> 110.23096 | AX4: 1 | AY4: =IF(AV4=0,"DESPRECIABLE",IF('Parametros'!$B$11/AP4>=AV4,"CUMPLE","NO CUMPLE")) -> CUMPLE | AZ4: =IF(AND(X4="CUMPLE",AE4="CUMPLE",AS4="CUMPLE",OR(AY4="CUMPLE",AY4="DESPRECIABLE")),IF(OR(F4<>H4,G4<>I4),"CUMPLE - REANALIZAR SAP","CUMPLE"),"NO CUMPLE") -> CUMPLE
A5: VR N1 | B5: — | C5: 22 | D5: 2.5 | E5: 5.5 | F5: 350 | G5: 400 | H5: 350 | I5: 400 | J5: 117.1158 | K5: 48 | L5: 92.1287 | M5: 51 | N5: 119.664 | O5: 433.097 | P5: 51 | Q5: 5.0074 | R5: =MAX(MAX(1.4/'Parametros'!$B$3,0.25*SQRT('Parametros'!$B$2)/'Parametros'!$B$3)*H5*U5,(0.85*'Parametros'!$B$2/'Parametros'!$B$3)*(1-SQRT(1-2*(J5*1000000/('Parametros'!$B$5*H5*U5^2))/(0.85*'Parametros'!$B$2)))*H5*U5) -> 974.34986 | S5: 5 | T5: 1 | U5: =IF(T5=1,I5-('Parametros'!$B$7+'Parametros'!$B$9+'Parametros'!$B$12/2),I5-(ROUNDUP(S5/2,0)*('Parametros'!$B$7+'Parametros'!$B$9+'Parametros'!$B$12/2)+ROUNDDOWN(S5/2,0)*('Parametros'!$B$7+'Parametros'!$B$9+'Parametros'!$B$12/2+'Parametros'!$B$12+'Parametros'!$B$10))/S5) -> 342.55 | V5: =S5*'Parametros'!$B$8 -> 995 | W5: ='Parametros'!$B$5*V5*'Parametros'!$B$3*(U5-(V5*'Parametros'!$B$3/(0.85*'Parametros'!$B$2*H5))/2)/1000000 -> 119.40212 | X5: =IF(W5>=J5,"CUMPLE","NO CUMPLE") -> CUMPLE | Y5: =MAX(MAX(1.4/'Parametros'!$B$3,0.25*SQRT('Parametros'!$B$2)/'Parametros'!$B$3)*H5*AB5,(0.85*'Parametros'!$B$2/'Parametros'!$B$3)*(1-SQRT(1-2*(L5*1000000/('Parametros'!$B$5*H5*AB5^2))/(0.85*'Parametros'!$B$2)))*H5*AB5) -> 753.26566 | Z5: 4 | AA5: 1 | AB5: =IF(AA5=1,I5-('Parametros'!$B$7+'Parametros'!$B$9+'Parametros'!$B$12/2),I5-(ROUNDUP(Z5/2,0)*('Parametros'!$B$7+'Parametros'!$B$9+'Parametros'!$B$12/2)+ROUNDDOWN(Z5/2,0)*('Parametros'!$B$7+'Parametros'!$B$9+'Parametros'!$B$12/2+'Parametros'!$B$12+'Parametros'!$B$10))/Z5) -> 342.55 | AC5: =Z5*'Parametros'!$B$8 -> 796 | AD5: ='Parametros'!$B$5*AC5*'Parametros'!$B$3*(AB5-(AC5*'Parametros'!$B$3/(0.85*'Parametros'!$B$2*H5))/2)/1000000 -> 97.031197 | AE5: =IF(AD5>=L5,"CUMPLE","NO CUMPLE") -> CUMPLE | AF5: =V5*1.25*'Parametros'!$B$3*(U5-(V5*1.25*'Parametros'!$B$3/(0.85*'Parametros'!$B$2*H5))/2)/1000000 -> 162.56047 | AG5: =AC5*1.25*'Parametros'!$B$3*(AB5-(AC5*1.25*'Parametros'!$B$3/(0.85*'Parametros'!$B$2*H5))/2)/1000000 -> 132.66903 | AH5: =N5+(AF5+AG5)/D5 -> 237.7558 | AI5: =MIN(O5,MAX(N5,AH5)) -> 237.7558 | AJ5: =0.17*SQRT('Parametros'!$B$2)*H5*MIN(U5,AB5)/1000 -> 107.84995 | AK5: =MAX(AI5/'Parametros'!$B$6-AJ5,0) -> 209.15778 | AL5: =0.66*SQRT('Parametros'!$B$2)*H5*MIN(U5,AB5)/1000 -> 418.71158 | AM5: =IF(AK5<=AL5,"CUMPLE","NO CUMPLE") -> CUMPLE | AN5: Nº3 cerrado | AO5: 2 | AP5: =ROUNDDOWN(MIN(IF(AK5=0,1000000000,AO5*'Parametros'!$B$11*'Parametros'!$B$4*MIN(U5,AB5)/(AK5*1000)),IF(AV5=0,1000000000,'Parametros'!$B$11/AV5),MIN(U5,AB5)/4,8*'Parametros'!$B$12,24*'Parametros'!$B$9,300)/10,0)*10 -> 80 | AQ5: =ROUNDDOWN(MIN(IF(AK5=0,1000000000,AO5*'Parametros'!$B$11*'Parametros'!$B$4*MIN(U5,AB5)/(AK5*1000)),IF(AV5=0,1000000000,'Parametros'!$B$11/AV5),MIN(U5,AB5)/2,600)/10,0)*10 -> 90 | AR5: ='Parametros'!$B$6*(AJ5+AO5*'Parametros'!$B$11*'Parametros'!$B$4*MIN(U5,AB5)/AP5/1000) -> 272.41573 | AS5: =IF(AND(AM5="CUMPLE",AR5>=AI5),"CUMPLE","NO CUMPLE") -> CUMPLE | AT5: ='Parametros'!$B$6*0.083*SQRT('Parametros'!$B$2)*(H5*I5)^2/(2*(H5+I5))/1000000 -> 4.3041082 | AU5: =IF(Q5<=AT5,"DESPRECIABLE","DISEÑAR") -> DISEÑAR | AV5: =IF(Q5<=AT5,0,Q5*1000000/('Parametros'!$B$6*2*0.85*(H5-2*'Parametros'!$B$7)*(I5-2*'Parametros'!$B$7)*'Parametros'!$B$4)) -> 0.10822786 | AW5: =AV5*2*((H5-2*'Parametros'!$B$7)+(I5-2*'Parametros'!$B$7))*'Parametros'!$B$4/'Parametros'!$B$3 -> 127.70887 | AX5: 1 | AY5: =IF(AV5=0,"DESPRECIABLE",IF('Parametros'!$B$11/AP5>=AV5,"CUMPLE","NO CUMPLE")) -> CUMPLE | AZ5: =IF(AND(X5="CUMPLE",AE5="CUMPLE",AS5="CUMPLE",OR(AY5="CUMPLE",AY5="DESPRECIABLE")),IF(OR(F5<>H5,G5<>I5),"CUMPLE - REANALIZAR SAP","CUMPLE"),"NO CUMPLE") -> CUMPLE
A6: VR2 | B6: — | C6: 140 | D6: 1.5 | E6: 4.17612 | F6: 350 | G6: 400 | H6: 350 | I6: 400 | J6: 133.5495 | K6: 35 | L6: 101.8171 | M6: 36 | N6: 128.571 | O6: 467.396 | P6: 36 | Q6: 19.643 | R6: =MAX(MAX(1.4/'Parametros'!$B$3,0.25*SQRT('Parametros'!$B$2)/'Parametros'!$B$3)*H6*U6,(0.85*'Parametros'!$B$2/'Parametros'!$B$3)*(1-SQRT(1-2*(J6*1000000/('Parametros'!$B$5*H6*U6^2))/(0.85*'Parametros'!$B$2)))*H6*U6) -> 1124.4519 | S6: 6 | T6: 1 | U6: =IF(T6=1,I6-('Parametros'!$B$7+'Parametros'!$B$9+'Parametros'!$B$12/2),I6-(ROUNDUP(S6/2,0)*('Parametros'!$B$7+'Parametros'!$B$9+'Parametros'!$B$12/2)+ROUNDDOWN(S6/2,0)*('Parametros'!$B$7+'Parametros'!$B$9+'Parametros'!$B$12/2+'Parametros'!$B$12+'Parametros'!$B$10))/S6) -> 342.55 | V6: =S6*'Parametros'!$B$8 -> 1194 | W6: ='Parametros'!$B$5*V6*'Parametros'!$B$3*(U6-(V6*'Parametros'!$B$3/(0.85*'Parametros'!$B$2*H6))/2)/1000000 -> 141.0183 | X6: =IF(W6>=J6,"CUMPLE","NO CUMPLE") -> CUMPLE | Y6: =MAX(MAX(1.4/'Parametros'!$B$3,0.25*SQRT('Parametros'!$B$2)/'Parametros'!$B$3)*H6*AB6,(0.85*'Parametros'!$B$2/'Parametros'!$B$3)*(1-SQRT(1-2*(L6*1000000/('Parametros'!$B$5*H6*AB6^2))/(0.85*'Parametros'!$B$2)))*H6*AB6) -> 838.01378 | Z6: 5 | AA6: 1 | AB6: =IF(AA6=1,I6-('Parametros'!$B$7+'Parametros'!$B$9+'Parametros'!$B$12/2),I6-(ROUNDUP(Z6/2,0)*('Parametros'!$B$7+'Parametros'!$B$9+'Parametros'!$B$12/2)+ROUNDDOWN(Z6/2,0)*('Parametros'!$B$7+'Parametros'!$B$9+'Parametros'!$B$12/2+'Parametros'!$B$12+'Parametros'!$B$10))/Z6) -> 342.55 | AC6: =Z6*'Parametros'!$B$8 -> 995 | AD6: ='Parametros'!$B$5*AC6*'Parametros'!$B$3*(AB6-(AC6*'Parametros'!$B$3/(0.85*'Parametros'!$B$2*H6))/2)/1000000 -> 119.40212 | AE6: =IF(AD6>=L6,"CUMPLE","NO CUMPLE") -> CUMPLE | AF6: =V6*1.25*'Parametros'!$B$3*(U6-(V6*1.25*'Parametros'!$B$3/(0.85*'Parametros'!$B$2*H6))/2)/1000000 -> 191.14158 | AG6: =AC6*1.25*'Parametros'!$B$3*(AB6-(AC6*1.25*'Parametros'!$B$3/(0.85*'Parametros'!$B$2*H6))/2)/1000000 -> 162.56047 | AH6: =N6+(AF6+AG6)/D6 -> 364.37236 | AI6: =MIN(O6,MAX(N6,AH6)) -> 364.37236 | AJ6: =0.17*SQRT('Parametros'!$B$2)*H6*MIN(U6,AB6)/1000 -> 107.84995 | AK6: =MAX(AI6/'Parametros'!$B$6-AJ6,0) -> 377.97987 | AL6: =0.66*SQRT('Parametros'!$B$2)*H6*MIN(U6,AB6)/1000 -> 418.71158 | AM6: =IF(AK6<=AL6,"CUMPLE","NO CUMPLE") -> CUMPLE | AN6: Nº3 cerrado | AO6: 4 | AP6: =ROUNDDOWN(MIN(IF(AK6=0,1000000000,AO6*'Parametros'!$B$11*'Parametros'!$B$4*MIN(U6,AB6)/(AK6*1000)),IF(AV6=0,1000000000,'Parametros'!$B$11/AV6),MIN(U6,AB6)/4,8*'Parametros'!$B$12,24*'Parametros'!$B$9,300)/10,0)*10 -> 80 | AQ6: =ROUNDDOWN(MIN(IF(AK6=0,1000000000,AO6*'Parametros'!$B$11*'Parametros'!$B$4*MIN(U6,AB6)/(AK6*1000)),IF(AV6=0,1000000000,'Parametros'!$B$11/AV6),MIN(U6,AB6)/2,600)/10,0)*10 -> 100 | AR6: ='Parametros'!$B$6*(AJ6+AO6*'Parametros'!$B$11*'Parametros'!$B$4*MIN(U6,AB6)/AP6/1000) -> 463.944 | AS6: =IF(AND(AM6="CUMPLE",AR6>=AI6),"CUMPLE","NO CUMPLE") -> CUMPLE | AT6: ='Parametros'!$B$6*0.083*SQRT('Parametros'!$B$2)*(H6*I6)^2/(2*(H6+I6))/1000000 -> 4.3041082 | AU6: =IF(Q6<=AT6,"DESPRECIABLE","DISEÑAR") -> DISEÑAR | AV6: =IF(Q6<=AT6,0,Q6*1000000/('Parametros'!$B$6*2*0.85*(H6-2*'Parametros'!$B$7)*(I6-2*'Parametros'!$B$7)*'Parametros'!$B$4)) -> 0.42455562 | AW6: =AV6*2*((H6-2*'Parametros'!$B$7)+(I6-2*'Parametros'!$B$7))*'Parametros'!$B$4/'Parametros'!$B$3 -> 500.97564 | AX6: 3 | AY6: =IF(AV6=0,"DESPRECIABLE",IF('Parametros'!$B$11/AP6>=AV6,"CUMPLE","NO CUMPLE")) -> CUMPLE | AZ6: =IF(AND(X6="CUMPLE",AE6="CUMPLE",AS6="CUMPLE",OR(AY6="CUMPLE",AY6="DESPRECIABLE")),IF(OR(F6<>H6,G6<>I6),"CUMPLE - REANALIZAR SAP","CUMPLE"),"NO CUMPLE") -> CUMPLE
A7: VR3 | B7: — | C7: 70 | D7: 1.5 | E7: 4 | F7: 350 | G7: 400 | H7: 400 | I7: 550 | J7: 227.053 | K7: 231 | L7: 122.8528 | M7: 969 | N7: 179.911 | O7: 490.48 | P7: 30 | Q7: 19.7225 | R7: =MAX(MAX(1.4/'Parametros'!$B$3,0.25*SQRT('Parametros'!$B$2)/'Parametros'!$B$3)*H7*U7,(0.85*'Parametros'!$B$2/'Parametros'!$B$3)*(1-SQRT(1-2*(J7*1000000/('Parametros'!$B$5*H7*U7^2))/(0.85*'Parametros'!$B$2)))*H7*U7) -> 1294.5642 | S7: 7 | T7: 1 | U7: =IF(T7=1,I7-('Parametros'!$B$7+'Parametros'!$B$9+'Parametros'!$B$12/2),I7-(ROUNDUP(S7/2,0)*('Parametros'!$B$7+'Parametros'!$B$9+'Parametros'!$B$12/2)+ROUNDDOWN(S7/2,0)*('Parametros'!$B$7+'Parametros'!$B$9+'Parametros'!$B$12/2+'Parametros'!$B$12+'Parametros'!$B$10))/S7) -> 492.55 | V7: =S7*'Parametros'!$B$8 -> 1393 | W7: ='Parametros'!$B$5*V7*'Parametros'!$B$3*(U7-(V7*'Parametros'!$B$3/(0.85*'Parametros'!$B$2*H7))/2)/1000000 -> 243.17425 | X7: =IF(W7>=J7,"CUMPLE","NO CUMPLE") -> CUMPLE | Y7: =MAX(MAX(1.4/'Parametros'!$B$3,0.25*SQRT('Parametros'!$B$2)/'Parametros'!$B$3)*H7*AB7,(0.85*'Parametros'!$B$2/'Parametros'!$B$3)*(1-SQRT(1-2*(L7*1000000/('Parametros'!$B$5*H7*AB7^2))/(0.85*'Parametros'!$B$2)))*H7*AB7) -> 680.5911 | Z7: 4 | AA7: 1 | AB7: =IF(AA7=1,I7-('Parametros'!$B$7+'Parametros'!$B$9+'Parametros'!$B$12/2),I7-(ROUNDUP(Z7/2,0)*('Parametros'!$B$7+'Parametros'!$B$9+'Parametros'!$B$12/2)+ROUNDDOWN(Z7/2,0)*('Parametros'!$B$7+'Parametros'!$B$9+'Parametros'!$B$12/2+'Parametros'!$B$12+'Parametros'!$B$10))/Z7) -> 492.55 | AC7: =Z7*'Parametros'!$B$8 -> 796 | AD7: ='Parametros'!$B$5*AC7*'Parametros'!$B$3*(AB7-(AC7*'Parametros'!$B$3/(0.85*'Parametros'!$B$2*H7))/2)/1000000 -> 142.91915 | AE7: =IF(AD7>=L7,"CUMPLE","NO CUMPLE") -> CUMPLE | AF7: =V7*1.25*'Parametros'!$B$3*(U7-(V7*1.25*'Parametros'!$B$3/(0.85*'Parametros'!$B$2*H7))/2)/1000000 -> 332.12399 | AG7: =AC7*1.25*'Parametros'!$B$3*(AB7-(AC7*1.25*'Parametros'!$B$3/(0.85*'Parametros'!$B$2*H7))/2)/1000000 -> 196.66435 | AH7: =N7+(AF7+AG7)/D7 -> 532.43656 | AI7: =MIN(O7,MAX(N7,AH7)) -> 490.48 | AJ7: =0.17*SQRT('Parametros'!$B$2)*H7*MIN(U7,AB7)/1000 -> 177.23041 | AK7: =MAX(AI7/'Parametros'!$B$6-AJ7,0) -> 476.74292 | AL7: =0.66*SQRT('Parametros'!$B$2)*H7*MIN(U7,AB7)/1000 -> 688.07102 | AM7: =IF(AK7<=AL7,"CUMPLE","NO CUMPLE") -> CUMPLE | AN7: Nº3 cerrado | AO7: 4 | AP7: =ROUNDDOWN(MIN(IF(AK7=0,1000000000,AO7*'Parametros'!$B$11*'Parametros'!$B$4*MIN(U7,AB7)/(AK7*1000)),IF(AV7=0,1000000000,'Parametros'!$B$11/AV7),MIN(U7,AB7)/4,8*'Parametros'!$B$12,24*'Parametros'!$B$9,300)/10,0)*10 -> 120 | AQ7: =ROUNDDOWN(MIN(IF(AK7=0,1000000000,AO7*'Parametros'!$B$11*'Parametros'!$B$4*MIN(U7,AB7)/(AK7*1000)),IF(AV7=0,1000000000,'Parametros'!$B$11/AV7),MIN(U7,AB7)/2,600)/10,0)*10 -> 120 | AR7: ='Parametros'!$B$6*(AJ7+AO7*'Parametros'!$B$11*'Parametros'!$B$4*MIN(U7,AB7)/AP7/1000) -> 500.11884 | AS7: =IF(AND(AM7="CUMPLE",AR7>=AI7),"CUMPLE","NO CUMPLE") -> CUMPLE | AT7: ='Parametros'!$B$6*0.083*SQRT('Parametros'!$B$2)*(H7*I7)^2/(2*(H7+I7))/1000000 -> 8.3909307 | AU7: =IF(Q7<=AT7,"DESPRECIABLE","DISEÑAR") -> DISEÑAR | AV7: =IF(Q7<=AT7,0,Q7*1000000/('Parametros'!$B$6*2*0.85*(H7-2*'Parametros'!$B$7)*(I7-2*'Parametros'!$B$7)*'Parametros'!$B$4)) -> 0.24488075 | AW7: =AV7*2*((H7-2*'Parametros'!$B$7)+(I7-2*'Parametros'!$B$7))*'Parametros'!$B$4/'Parametros'!$B$3 -> 386.91159 | AX7: 2 | AY7: =IF(AV7=0,"DESPRECIABLE",IF('Parametros'!$B$11/AP7>=AV7,"CUMPLE","NO CUMPLE")) -> CUMPLE | AZ7: =IF(AND(X7="CUMPLE",AE7="CUMPLE",AS7="CUMPLE",OR(AY7="CUMPLE",AY7="DESPRECIABLE")),IF(OR(F7<>H7,G7<>I7),"CUMPLE - REANALIZAR SAP","CUMPLE"),"NO CUMPLE") -> CUMPLE - REANALIZAR SAP
A8: VRAUX | B8: — | C8: 40 | D8: 2.5 | E8: 2.6 | F8: 350 | G8: 400 | H8: 350 | I8: 400 | J8: 37.3076 | K8: 111 | L8: 33.3104 | M8: 109 | N8: 29.603 | O8: 120.894 | P8: 109 | Q8: 3.9584 | R8: =MAX(MAX(1.4/'Parametros'!$B$3,0.25*SQRT('Parametros'!$B$2)/'Parametros'!$B$3)*H8*U8,(0.85*'Parametros'!$B$2/'Parametros'!$B$3)*(1-SQRT(1-2*(J8*1000000/('Parametros'!$B$5*H8*U8^2))/(0.85*'Parametros'!$B$2)))*H8*U8) -> 399.64167 | S8: 3 | T8: 1 | U8: =IF(T8=1,I8-('Parametros'!$B$7+'Parametros'!$B$9+'Parametros'!$B$12/2),I8-(ROUNDUP(S8/2,0)*('Parametros'!$B$7+'Parametros'!$B$9+'Parametros'!$B$12/2)+ROUNDDOWN(S8/2,0)*('Parametros'!$B$7+'Parametros'!$B$9+'Parametros'!$B$12/2+'Parametros'!$B$12+'Parametros'!$B$10))/S8) -> 342.55 | V8: =S8*'Parametros'!$B$8 -> 597 | W8: ='Parametros'!$B$5*V8*'Parametros'!$B$3*(U8-(V8*'Parametros'!$B$3/(0.85*'Parametros'!$B$2*H8))/2)/1000000 -> 73.90552 | X8: =IF(W8>=J8,"CUMPLE","NO CUMPLE") -> CUMPLE | Y8: =MAX(MAX(1.4/'Parametros'!$B$3,0.25*SQRT('Parametros'!$B$2)/'Parametros'!$B$3)*H8*AB8,(0.85*'Parametros'!$B$2/'Parametros'!$B$3)*(1-SQRT(1-2*(L8*1000000/('Parametros'!$B$5*H8*AB8^2))/(0.85*'Parametros'!$B$2)))*H8*AB8) -> 399.64167 | Z8: 3 | AA8: 1 | AB8: =IF(AA8=1,I8-('Parametros'!$B$7+'Parametros'!$B$9+'Parametros'!$B$12/2),I8-(ROUNDUP(Z8/2,0)*('Parametros'!$B$7+'Parametros'!$B$9+'Parametros'!$B$12/2)+ROUNDDOWN(Z8/2,0)*('Parametros'!$B$7+'Parametros'!$B$9+'Parametros'!$B$12/2+'Parametros'!$B$12+'Parametros'!$B$10))/Z8) -> 342.55 | AC8: =Z8*'Parametros'!$B$8 -> 597 | AD8: ='Parametros'!$B$5*AC8*'Parametros'!$B$3*(AB8-(AC8*'Parametros'!$B$3/(0.85*'Parametros'!$B$2*H8))/2)/1000000 -> 73.90552 | AE8: =IF(AD8>=L8,"CUMPLE","NO CUMPLE") -> CUMPLE | AF8: =V8*1.25*'Parametros'!$B$3*(U8-(V8*1.25*'Parametros'!$B$3/(0.85*'Parametros'!$B$2*H8))/2)/1000000 -> 101.46726 | AG8: =AC8*1.25*'Parametros'!$B$3*(AB8-(AC8*1.25*'Parametros'!$B$3/(0.85*'Parametros'!$B$2*H8))/2)/1000000 -> 101.46726 | AH8: =N8+(AF8+AG8)/D8 -> 110.77681 | AI8: =MIN(O8,MAX(N8,AH8)) -> 110.77681 | AJ8: =0.17*SQRT('Parametros'!$B$2)*H8*MIN(U8,AB8)/1000 -> 107.84995 | AK8: =MAX(AI8/'Parametros'!$B$6-AJ8,0) -> 39.852461 | AL8: =0.66*SQRT('Parametros'!$B$2)*H8*MIN(U8,AB8)/1000 -> 418.71158 | AM8: =IF(AK8<=AL8,"CUMPLE","NO CUMPLE") -> CUMPLE | AN8: Nº3 cerrado | AO8: 2 | AP8: =ROUNDDOWN(MIN(IF(AK8=0,1000000000,AO8*'Parametros'!$B$11*'Parametros'!$B$4*MIN(U8,AB8)/(AK8*1000)),IF(AV8=0,1000000000,'Parametros'!$B$11/AV8),MIN(U8,AB8)/4,8*'Parametros'!$B$12,24*'Parametros'!$B$9,300)/10,0)*10 -> 80 | AQ8: =ROUNDDOWN(MIN(IF(AK8=0,1000000000,AO8*'Parametros'!$B$11*'Parametros'!$B$4*MIN(U8,AB8)/(AK8*1000)),IF(AV8=0,1000000000,'Parametros'!$B$11/AV8),MIN(U8,AB8)/2,600)/10,0)*10 -> 170 | AR8: ='Parametros'!$B$6*(AJ8+AO8*'Parametros'!$B$11*'Parametros'!$B$4*MIN(U8,AB8)/AP8/1000) -> 272.41573 | AS8: =IF(AND(AM8="CUMPLE",AR8>=AI8),"CUMPLE","NO CUMPLE") -> CUMPLE | AT8: ='Parametros'!$B$6*0.083*SQRT('Parametros'!$B$2)*(H8*I8)^2/(2*(H8+I8))/1000000 -> 4.3041082 | AU8: =IF(Q8<=AT8,"DESPRECIABLE","DISEÑAR") -> DESPRECIABLE | AV8: =IF(Q8<=AT8,0,Q8*1000000/('Parametros'!$B$6*2*0.85*(H8-2*'Parametros'!$B$7)*(I8-2*'Parametros'!$B$7)*'Parametros'!$B$4)) -> 0 | AW8: =AV8*2*((H8-2*'Parametros'!$B$7)+(I8-2*'Parametros'!$B$7))*'Parametros'!$B$4/'Parametros'!$B$3 -> 0 | AX8: 0 | AY8: =IF(AV8=0,"DESPRECIABLE",IF('Parametros'!$B$11/AP8>=AV8,"CUMPLE","NO CUMPLE")) -> DESPRECIABLE | AZ8: =IF(AND(X8="CUMPLE",AE8="CUMPLE",AS8="CUMPLE",OR(AY8="CUMPLE",AY8="DESPRECIABLE")),IF(OR(F8<>H8,G8<>I8),"CUMPLE - REANALIZAR SAP","CUMPLE"),"NO CUMPLE") -> CUMPLE

Sheet Todas las Vigas (592)
A1: DISEÑO DE VIGAS — TODAS LAS VIGAS (592)
A2: ENVFLEX: flexión y torsión. ENVCORT: límite elástico de cortante. Vu diseño DMO = mín(ENVCORT; máx[ENVFLEX; Vcap]).
A3: Grupo | B3: Frame | C3: N vigas | D3: L mín (m) | E3: L máx (m) | F3: b modelo (mm) | G3: h modelo (mm) | H3: b adopt. (mm) | I3: h adopt. (mm) | J3: Mu− ENVFLEX (kN·m) | K3: Frame Mu− | L3: Mu+ ENVFLEX (kN·m) | M3: Frame Mu+ | N3: Vu ENVFLEX (kN) | O3: Vu ENVCORT (kN) | P3: Frame Vu | Q3: Tu ENVFLEX (kN·m) | R3: As req. sup (mm²) | S3: Nº5 sup | T3: Capas sup | U3: d sup (mm) | V3: As prov. sup (mm²) | W3: φMn− (kN·m) | X3: Flexión − | Y3: As req. inf (mm²) | Z3: Nº5 inf | AA3: Capas inf | AB3: d inf (mm) | AC3: As prov. inf (mm²) | AD3: φMn+ (kN·m) | AE3: Flexión + | AF3: Mpr− (kN·m) | AG3: Mpr+ (kN·m) | AH3: Vcap (kN) | AI3: Vu diseño (kN) | AJ3: Vc (kN) | AK3: Vs req. (kN) | AL3: Vs máx. (kN) | AM3: Sección cortante | AN3: Estribo | AO3: Ramas | AP3: s extremo DMO (mm) | AQ3: s centro (mm) | AR3: φVn (kN) | AS3: Cortante | AT3: φTth (kN·m) | AU3: Torsión | AV3: At/s (mm²/mm) | AW3: Al (mm²) | AX3: Nº5 torsión | AY3: Chequeo torsión | AZ3: ESTADO
A4: VC1 | B4: 148 | C4: 1 | D4: 3.75 | E4: 3.75 | F4: 300 | G4: 400 | H4: 300 | I4: 400 | J4: 18.5445 | K4: 148 | L4: 11.8002 | M4: 148 | N4: 13.991 | O4: 39.578 | P4: 148 | Q4: 2.504 | R4: =MAX(MAX(1.4/'Parametros'!$B$3,0.25*SQRT('Parametros'!$B$2)/'Parametros'!$B$3)*H4*U4,(0.85*'Parametros'!$B$2/'Parametros'!$B$3)*(1-SQRT(1-2*(J4*1000000/('Parametros'!$B$5*H4*U4^2))/(0.85*'Parametros'!$B$2)))*H4*U4) -> 342.55 | S4: 2 | T4: 1 | U4: =IF(T4=1,I4-('Parametros'!$B$7+'Parametros'!$B$9+'Parametros'!$B$12/2),I4-(ROUNDUP(S4/2,0)*('Parametros'!$B$7+'Parametros'!$B$9+'Parametros'!$B$12/2)+ROUNDDOWN(S4/2,0)*('Parametros'!$B$7+'Parametros'!$B$9+'Parametros'!$B$12/2+'Parametros'!$B$12+'Parametros'!$B$10))/S4) -> 342.55 | V4: =S4*'Parametros'!$B$8 -> 398 | W4: ='Parametros'!$B$5*V4*'Parametros'!$B$3*(U4-(V4*'Parametros'!$B$3/(0.85*'Parametros'!$B$2*H4))/2)/1000000 -> 49.773512 | X4: =IF(W4>=J4,"CUMPLE","NO CUMPLE") -> CUMPLE | Y4: =MAX(MAX(1.4/'Parametros'!$B$3,0.25*SQRT('Parametros'!$B$2)/'Parametros'!$B$3)*H4*AB4,(0.85*'Parametros'!$B$2/'Parametros'!$B$3)*(1-SQRT(1-2*(L4*1000000/('Parametros'!$B$5*H4*AB4^2))/(0.85*'Parametros'!$B$2)))*H4*AB4) -> 342.55 | Z4: 2 | AA4: 1 | AB4: =IF(AA4=1,I4-('Parametros'!$B$7+'Parametros'!$B$9+'Parametros'!$B$12/2),I4-(ROUNDUP(Z4/2,0)*('Parametros'!$B$7+'Parametros'!$B$9+'Parametros'!$B$12/2)+ROUNDDOWN(Z4/2,0)*('Parametros'!$B$7+'Parametros'!$B$9+'Parametros'!$B$12/2+'Parametros'!$B$12+'Parametros'!$B$10))/Z4) -> 342.55 | AC4: =Z4*'Parametros'!$B$8 -> 398 | AD4: ='Parametros'!$B$5*AC4*'Parametros'!$B$3*(AB4-(AC4*'Parametros'!$B$3/(0.85*'Parametros'!$B$2*H4))/2)/1000000 -> 49.773512 | AE4: =IF(AD4>=L4,"CUMPLE","NO CUMPLE") -> CUMPLE | AF4: =V4*1.25*'Parametros'!$B$3*(U4-(V4*1.25*'Parametros'!$B$3/(0.85*'Parametros'!$B$2*H4))/2)/1000000 -> 68.518392 | AG4: =AC4*1.25*'Parametros'!$B$3*(AB4-(AC4*1.25*'Parametros'!$B$3/(0.85*'Parametros'!$B$2*H4))/2)/1000000 -> 68.518392 | AH4: =N4+(AF4+AG4)/D4 -> 50.534143 | AI4: =MIN(O4,MAX(N4,AH4)) -> 39.578 | AJ4: =0.17*SQRT('Parametros'!$B$2)*H4*MIN(U4,AB4)/1000 -> 92.442815 | AK4: =MAX(AI4/'Parametros'!$B$6-AJ4,0) -> 0 | AL4: =0.66*SQRT('Parametros'!$B$2)*H4*MIN(U4,AB4)/1000 -> 358.89564 | AM4: =IF(AK4<=AL4,"CUMPLE","NO CUMPLE") -> CUMPLE | AN4: Nº3 cerrado | AO4: 2 | AP4: =ROUNDDOWN(MIN(IF(AK4=0,1000000000,AO4*'Parametros'!$B$11*'Parametros'!$B$4*MIN(U4,AB4)/(AK4*1000)),IF(AV4=0,1000000000,'Parametros'!$B$11/AV4),MIN(U4,AB4)/4,8*'Parametros'!$B$12,24*'Parametros'!$B$9,300)/10,0)*10 -> 80 | AQ4: =ROUNDDOWN(MIN(IF(AK4=0,1000000000,AO4*'Parametros'!$B$11*'Parametros'!$B$4*MIN(U4,AB4)/(AK4*1000)),IF(AV4=0,1000000000,'Parametros'!$B$11/AV4),MIN(U4,AB4)/2,600)/10,0)*10 -> 170 | AR4: ='Parametros'!$B$6*(AJ4+AO4*'Parametros'!$B$11*'Parametros'!$B$4*MIN(U4,AB4)/AP4/1000) -> 260.86038 | AS4: =IF(AND(AM4="CUMPLE",AR4>=AI4),"CUMPLE","NO CUMPLE") -> CUMPLE | AT4: ='Parametros'!$B$6*0.083*SQRT('Parametros'!$B$2)*(H4*I4)^2/(2*(H4+I4))/1000000 -> 3.3880735 | AU4: =IF(Q4<=AT4,"DESPRECIABLE","DISEÑAR") -> DESPRECIABLE | AV4: =IF(Q4<=AT4,0,Q4*1000000/('Parametros'!$B$6*2*0.85*(H4-2*'Parametros'!$B$7)*(I4-2*'Parametros'!$B$7)*'Parametros'!$B$4)) -> 0 | AW4: =AV4*2*((H4-2*'Parametros'!$B$7)+(I4-2*'Parametros'!$B$7))*'Parametros'!$B$4/'Parametros'!$B$3 -> 0 | AX4: 0 | AY4: =IF(AV4=0,"DESPRECIABLE",IF('Parametros'!$B$11/AP4>=AV4,"CUMPLE","NO CUMPLE")) -> DESPRECIABLE | AZ4: =IF(AND(X4="CUMPLE",AE4="CUMPLE",AS4="CUMPLE",OR(AY4="CUMPLE",AY4="DESPRECIABLE")),IF(OR(F4<>H4,G4<>I4),"CUMPLE - REANALIZAR SAP","CUMPLE"),"NO CUMPLE") -> CUMPLE
A5: VC1 | B5: 149 | C5: 1 | D5: 3.75 | E5: 3.75 | F5: 300 | G5: 400 | H5: 300 | I5: 400 | J5: 18.54 | K5: 149 | L5: 11.803 | M5: 149 | N5: 13.989 | O5: 39.576 | P5: 149 | Q5: 2.5039 | R5: =MAX(MAX(1.4/'Parametros'!$B$3,0.25*SQRT('Parametros'!$B$2)/'Parametros'!$B$3)*H5*U5,(0.85*'Parametros'!$B$2/'Parametros'!$B$3)*(1-SQRT(1-2*(J5*1000000/('Parametros'!$B$5*H5*U5^2))/(0.85*'Parametros'!$B$2)))*H5*U5) -> 342.55 | S5: 2 | T5: 1 | U5: =IF(T5=1,I5-('Parametros'!$B$7+'Parametros'!$B$9+'Parametros'!$B$12/2),I5-(ROUNDUP(S5/2,0)*('Parametros'!$B$7+'Parametros'!$B$9+'Parametros'!$B$12/2)+ROUNDDOWN(S5/2,0)*('Parametros'!$B$7+'Parametros'!$B$9+'Parametros'!$B$12/2+'Parametros'!$B$12+'Parametros'!$B$10))/S5) -> 342.55 | V5: =S5*'Parametros'!$B$8 -> 398 | W5: ='Parametros'!$B$5*V5*'Parametros'!$B$3*(U5-(V5*'Parametros'!$B$3/(0.85*'Parametros'!$B$2*H5))/2)/1000000 -> 49.773512 | X5: =IF(W5>=J5,"CUMPLE","NO CUMPLE") -> CUMPLE | Y5: =MAX(MAX(1.4/'Parametros'!$B$3,0.25*SQRT('Parametros'!$B$2)/'Parametros'!$B$3)*H5*AB5,(0.85*'Parametros'!$B$2/'Parametros'!$B$3)*(1-SQRT(1-2*(L5*1000000/('Parametros'!$B$5*H5*AB5^2))/(0.85*'Parametros'!$B$2)))*H5*AB5) -> 342.55 | Z5: 2 | AA5: 1 | AB5: =IF(AA5=1,I5-('Parametros'!$B$7+'Parametros'!$B$9+'Parametros'!$B$12/2),I5-(ROUNDUP(Z5/2,0)*('Parametros'!$B$7+'Parametros'!$B$9+'Parametros'!$B$12/2)+ROUNDDOWN(Z5/2,0)*('Parametros'!$B$7+'Parametros'!$B$9+'Parametros'!$B$12/2+'Parametros'!$B$12+'Parametros'!$B$10))/Z5) -> 342.55 | AC5: =Z5*'Parametros'!$B$8 -> 398 | AD5: ='Parametros'!$B$5*AC5*'Parametros'!$B$3*(AB5-(AC5*'Parametros'!$B$3/(0.85*'Parametros'!$B$2*H5))/2)/1000000 -> 49.773512 | AE5: =IF(AD5>=L5,"CUMPLE","NO CUMPLE") -> CUMPLE | AF5: =V5*1.25*'Parametros'!$B$3*(U5-(V5*1.25*'Parametros'!$B$3/(0.85*'Parametros'!$B$2*H5))/2)/1000000 -> 68.518392 | AG5: =AC5*1.25*'Parametros'!$B$3*(AB5-(AC5*1.25*'Parametros'!$B$3/(0.85*'Parametros'!$B$2*H5))/2)/1000000 -> 68.518392 | AH5: =N5+(AF5+AG5)/D5 -> 50.532143 | AI5: =MIN(O5,MAX(N5,AH5)) -> 39.576 | AJ5: =0.17*SQRT('Parametros'!$B$2)*H5*MIN(U5,AB5)/1000 -> 92.442815 | AK5: =MAX(AI5/'Parametros'!$B$6-AJ5,0) -> 0 | AL5: =0.66*SQRT('Parametros'!$B$2)*H5*MIN(U5,AB5)/1000 -> 358.89564 | AM5: =IF(AK5<=AL5,"CUMPLE","NO CUMPLE") -> CUMPLE | AN5: Nº3 cerrado | AO5: 2 | AP5: =ROUNDDOWN(MIN(IF(AK5=0,1000000000,AO5*'Parametros'!$B$11*'Parametros'!$B$4*MIN(U5,AB5)/(AK5*1000)),IF(AV5=0,1000000000,'Parametros'!$B$11/AV5),MIN(U5,AB5)/4,8*'Parametros'!$B$12,24*'Parametros'!$B$9,300)/10,0)*10 -> 80 | AQ5: =ROUNDDOWN(MIN(IF(AK5=0,1000000000,AO5*'Parametros'!$B$11*'Parametros'!$B$4*MIN(U5,AB5)/(AK5*1000)),IF(AV5=0,1000000000,'Parametros'!$B$11/AV5),MIN(U5,AB5)/2,600)/10,0)*10 -> 170 | AR5: ='Parametros'!$B$6*(AJ5+AO5*'Parametros'!$B$11*'Parametros'!$B$4*MIN(U5,AB5)/AP5/1000) -> 260.86038 | AS5: =IF(AND(AM5="CUMPLE",AR5>=AI5),"CUMPLE","NO CUMPLE") -> CUMPLE | AT5: ='Parametros'!$B$6*0.083*SQRT('Parametros'!$B$2)*(H5*I5)^2/(2*(H5+I5))/1000000 -> 3.3880735 | AU5: =IF(Q5<=AT5,"DESPRECIABLE","DISEÑAR") -> DESPRECIABLE | AV5: =IF(Q5<=AT5,0,Q5*1000000/('Parametros'!$B$6*2*0.85*(H5-2*'Parametros'!$B$7)*(I5-2*'Parametros'!$B$7)*'Parametros'!$B$4)) -> 0 | AW5: =AV5*2*((H5-2*'Parametros'!$B$7)+(I5-2*'Parametros'!$B$7))*'Parametros'!$B$4/'Parametros'!$B$3 -> 0 | AX5: 0 | AY5: =IF(AV5=0,"DESPRECIABLE",IF('Parametros'!$B$11/AP5>=AV5,"CUMPLE","NO CUMPLE")) -> DESPRECIABLE | AZ5: =IF(AND(X5="CUMPLE",AE5="CUMPLE",AS5="CUMPLE",OR(AY5="CUMPLE",AY5="DESPRECIABLE")),IF(OR(F5<>H5,G5<>I5),"CUMPLE - REANALIZAR SAP","CUMPLE"),"NO CUMPLE") -> CUMPLE
A6: VC1 | B6: 153 | C6: 1 | D6: 3.75 | E6: 3.75 | F6: 300 | G6: 400 | H6: 300 | I6: 400 | J6: 18.5398 | K6: 153 | L6: 11.8022 | M6: 153 | N6: 13.989 | O6: 39.575 | P6: 153 | Q6: 2.504 | R6: =MAX(MAX(1.4/'Parametros'!$B$3,0.25*SQRT('Parametros'!$B$2)/'Parametros'!$B$3)*H6*U6,(0.85*'Parametros'!$B$2/'Parametros'!$B$3)*(1-SQRT(1-2*(J6*1000000/('Parametros'!$B$5*H6*U6^2))/(0.85*'Parametros'!$B$2)))*H6*U6) -> 342.55 | S6: 2 | T6: 1 | U6: =IF(T6=1,I6-('Parametros'!$B$7+'Parametros'!$B$9+'Parametros'!$B$12/2),I6-(ROUNDUP(S6/2,0)*('Parametros'!$B$7+'Parametros'!$B$9+'Parametros'!$B$12/2)+ROUNDDOWN(S6/2,0)*('Parametros'!$B$7+'Parametros'!$B$9+'Parametros'!$B$12/2+'Parametros'!$B$12+'Parametros'!$B$10))/S6) -> 342.55 | V6: =S6*'Parametros'!$B$8 -> 398 | W6: ='Parametros'!$B$5*V6*'Parametros'!$B$3*(U6-(V6*'Parametros'!$B$3/(0.85*'Parametros'!$B$2*H6))/2)/1000000 -> 49.773512 | X6: =IF(W6>=J6,"CUMPLE","NO CUMPLE") -> CUMPLE | Y6: =MAX(MAX(1.4/'Parametros'!$B$3,0.25*SQRT('Parametros'!$B$2)/'Parametros'!$B$3)*H6*AB6,(0.85*'Parametros'!$B$2/'Parametros'!$B$3)*(1-SQRT(1-2*(L6*1000000/('Parametros'!$B$5*H6*AB6^2))/(0.85*'Parametros'!$B$2)))*H6*AB6) -> 342.55 | Z6: 2 | AA6: 1 | AB6: =IF(AA6=1,I6-('Parametros'!$B$7+'Parametros'!$B$9+'Parametros'!$B$12/2),I6-(ROUNDUP(Z6/2,0)*('Parametros'!$B$7+'Parametros'!$B$9+'Parametros'!$B$12/2)+ROUNDDOWN(Z6/2,0)*('Parametros'!$B$7+'Parametros'!$B$9+'Parametros'!$B$12/2+'Parametros'!$B$12+'Parametros'!$B$10))/Z6) -> 342.55 | AC6: =Z6*'Parametros'!$B$8 -> 398 | AD6: ='Parametros'!$B$5*AC6*'Parametros'!$B$3*(AB6-(AC6*'Parametros'!$B$3/(0.85*'Parametros'!$B$2*H6))/2)/1000000 -> 49.773512 | AE6: =IF(AD6>=L6,"CUMPLE","NO CUMPLE") -> CUMPLE | AF6: =V6*1.25*'Parametros'!$B$3*(U6-(V6*1.25*'Parametros'!$B$3/(0.85*'Parametros'!$B$2*H6))/2)/1000000 -> 68.518392 | AG6: =AC6*1.25*'Parametros'!$B$3*(AB6-(AC6*1.25*'Parametros'!$B$3/(0.85*'Parametros'!$B$2*H6))/2)/1000000 -> 68.518392 | AH6: =N6+(AF6+AG6)/D6 -> 50.532143 | AI6: =MIN(O6,MAX(N6,AH6)) -> 39.575 | AJ6: =0.17*SQRT('Parametros'!$B$2)*H6*MIN(U6,AB6)/1000 -> 92.442815 | AK6: =MAX(AI6/'Parametros'!$B$6-AJ6,0) -> 0 | AL6: =0.66*SQRT('Parametros'!$B$2)*H6*MIN(U6,AB6)/1000 -> 358.89564 | AM6: =IF(AK6<=AL6,"CUMPLE","NO CUMPLE") -> CUMPLE | AN6: Nº3 cerrado | AO6: 2 | AP6: =ROUNDDOWN(MIN(IF(AK6=0,1000000000,AO6*'Parametros'!$B$11*'Parametros'!$B$4*MIN(U6,AB6)/(AK6*1000)),IF(AV6=0,1000000000,'Parametros'!$B$11/AV6),MIN(U6,AB6)/4,8*'Parametros'!$B$12,24*'Parametros'!$B$9,300)/10,0)*10 -> 80 | AQ6: =ROUNDDOWN(MIN(IF(AK6=0,1000000000,AO6*'Parametros'!$B$11*'Parametros'!$B$4*MIN(U6,AB6)/(AK6*1000)),IF(AV6=0,1000000000,'Parametros'!$B$11/AV6),MIN(U6,AB6)/2,600)/10,0)*10 -> 170 | AR6: ='Parametros'!$B$6*(AJ6+AO6*'Parametros'!$B$11*'Parametros'!$B$4*MIN(U6,AB6)/AP6/1000) -> 260.86038 | AS6: =IF(AND(AM6="CUMPLE",AR6>=AI6),"CUMPLE","NO CUMPLE") -> CUMPLE | AT6: ='Parametros'!$B$6*0.083*SQRT('Parametros'!$B$2)*(H6*I6)^2/(2*(H6+I6))/1000000 -> 3.3880735 | AU6: =IF(Q6<=AT6,"DESPRECIABLE","DISEÑAR") -> DESPRECIABLE | AV6: =IF(Q6<=AT6,0,Q6*1000000/('Parametros'!$B$6*2*0.85*(H6-2*'Parametros'!$B$7)*(I6-2*'Parametros'!$B$7)*'Parametros'!$B$4)) -> 0 | AW6: =AV6*2*((H6-2*'Parametros'!$B$7)+(I6-2*'Parametros'!$B$7))*'Parametros'!$B$4/'Parametros'!$B$3 -> 0 | AX6: 0 | AY6: =IF(AV6=0,"DESPRECIABLE",IF('Parametros'!$B$11/AP6>=AV6,"CUMPLE","NO CUMPLE")) -> DESPRECIABLE | AZ6: =IF(AND(X6="CUMPLE",AE6="CUMPLE",AS6="CUMPLE",OR(AY6="CUMPLE",AY6="DESPRECIABLE")),IF(OR(F6<>H6,G6<>I6),"CUMPLE - REANALIZAR SAP","CUMPLE"),"NO CUMPLE") -> CUMPLE
