Workbook
Name ALT_ALETA: #REF!
Name ALT_ALMA: #REF!
Name ALT_TOT: #REF!
Name ANC_ALETA: #REF!
Name ANC_ALMA: #REF!
Name AREA_COLUMNA: #REF!
Name AREA_VIGA: #REF!
Name D_CP: #REF!
Name D_Mad: #REF!
Name D_Si: #REF!
Name DIAM_COL: #REF!
Name T0: #REF!

Sheet Ejes Grilla
B2: y | E2: x | H2: z
B3: 2.6 | C3: =+C4+B3 -> 36.2 | E3: 3.85 | F3: =+E3+F4 -> 15.5 | H3: 3 | I3: =+H3+I4 -> 15.5
B4: 3.65 | C4: =+C5+B4 -> 33.6 | E4: 3.9 | F4: =+E4+F5 -> 11.65 | H4: 3 | I4: =+H4+I5 -> 12.5
B5: 2.6 | C5: =+C6+B5 -> 29.95 | E5: 3.9 | F5: =+E5+F6 -> 7.75 | H5: 3 | I5: =+H5+I6 -> 9.5
B6: 2.5 | C6: =+C7+B6 -> 27.35 | E6: 3.85 | F6: =+E6+F7 -> 3.85 | H6: 3 | I6: =+H6+I7 -> 6.5
B7: 4 | C7: =+C8+B7 -> 24.85 | E7: 0 | F7: =+E7+F8 -> 0 | H7: 3.5 | I7: =+H7+I8 -> 3.5
B8: 2.7 | C8: =+C9+B8 -> 20.85 | H8: 0 | I8: =+H8+I9 -> 0
B9: 2.8 | C9: =+C10+B9 -> 18.15 | E9: =SUM(E3:E7) -> 15.5
B10: 4 | C10: =+C11+B10 -> 15.35
B11: 2.5 | C11: =+C12+B11 -> 11.35
B12: 2.6 | C12: =+C13+B12 -> 8.85
B13: 3.65 | C13: =+C14+B13 -> 6.25
B14: 2.6 | C14: =+C15+B14 -> 2.6
B15: 0 | C15: =+C16+B15 -> 0
B18: =SUM(B3:B14) -> 36.2

Sheet LOSA
A14: PRIMER PISO
B16: VIGUETA 1 | L16: MAX
B17: TIPO | C17: 1EC | D17: 2EC | E17: 2EC | F17: 2EC | G17: 2EC | H17: 2EC | I17: 2EC | J17: 2EC | K17: 1EC
B18: LUZ (m) | C18: 3.25 | D18: 2.2 | E18: 2.1 | F18: 3.6 | G18: 5.1 | H18: 3.6 | I18: 2.1 | J18: 2.2 | K18: 3.25
B19: C.9.5 (a) | C19: =+C18/18.5 -> 0.17567568 | D19: =+D18/21 -> 0.1047619 | E19: =+E18/21 -> 0.1 | F19: =+F18/21 -> 0.17142857 | G19: =+G18/21 -> 0.24285714 | H19: =+H18/21 -> 0.17142857 | I19: =+I18/21 -> 0.1 | J19: =+J18/21 -> 0.1047619 | K19: =+K18/18.5 -> 0.17567568 | L19: =MAX(C19:K19) -> 0.24285714
B20: C.9.5 | C20: =+C18/12 -> 0.27083333 | D20: =+D18/14 -> 0.15714286 | E20: =+E18/14 -> 0.15 | F20: =+F18/14 -> 0.25714286 | G20: =+G18/14 -> 0.36428571 | H20: =+H18/14 -> 0.25714286 | I20: =+I18/14 -> 0.15 | J20: =+J18/14 -> 0.15714286 | K20: =+K18/12 -> 0.27083333 | L20: =MAX(C20:K20) -> 0.36428571
B25: VIGUETA 2 | N25: MAX
B26: TIPO | C26: 1EC | D26: 2EC | E26: 2EC | F26: 2EC | G26: 2EC | H26: 2EC | I26: 2EC | J26: 2EC | K26: 2EC | L26: 2EC | M26: 1EC
B27: LUZ (m) | C27: 2.2 | D27: 3.25 | E27: 2.2 | F27: 2.1 | G27: 3.6 | H27: 5.1 | I27: 3.6 | J27: 2.1 | K27: 2.2 | L27: 3.25 | M27: 2.2
B28: C.9.5 (a) | C28: =+C27/(18.5) -> 0.11891892 | D28: =+D27/21 -> 0.1547619 | E28: =+E27/21 -> 0.1047619 | F28: =+F27/21 -> 0.1 | G28: =+G27/21 -> 0.17142857 | H28: =+H27/21 -> 0.24285714 | I28: =+I27/21 -> 0.17142857 | J28: =+J27/21 -> 0.1 | K28: =+K27/21 -> 0.1047619 | L28: =+L27/21 -> 0.1547619 | M28: =+M27/18.5 -> 0.11891892 | N28: =MAX(C28:M28) -> 0.24285714
B29: C.9.5 | C29: =+C27/12 -> 0.18333333 | D29: =+D27/14 -> 0.23214286 | E29: =+E27/14 -> 0.15714286 | F29: =+F27/14 -> 0.15 | G29: =+G27/14 -> 0.25714286 | H29: =+H27/14 -> 0.36428571 | I29: =+I27/14 -> 0.25714286 | J29: =+J27/14 -> 0.15 | K29: =+K27/14 -> 0.15714286 | L29: =+L27/14 -> 0.23214286 | M29: =+M27/12 -> 0.18333333 | N29: =MAX(C29:M29) -> 0.36428571
B33: VIGUETA 3 | P33: MAX
B34: TIPO | C34: V | D34: 2EC | E34: 2EC | F34: 2EC | G34: 2EC | H34: 2EC | I34: 2EC | J34: 2EC | K34: 2EC | L34: 2EC | M34: 2EC | N34: 2EC | O34: V
B35: LUZ (m) | C35: 1.5 | D35: 2.2 | E35: 3.25 | F35: 2.2 | G35: 2.1 | H35: 3.6 | I35: 5.1 | J35: 3.6 | K35: 2.1 | L35: 2.2 | M35: 3.25 | N35: 2.2 | O35: 1.5
B36: C.9.5 (a) | C36: =+C35/8 -> 0.1875 | D36: =+D35/21 -> 0.1047619 | E36: =+E35/21 -> 0.1547619 | F36: =+F35/21 -> 0.1047619 | G36: =+G35/21 -> 0.1 | H36: =+H35/21 -> 0.17142857 | I36: =+I35/21 -> 0.24285714 | J36: =+J35/21 -> 0.17142857 | K36: =+K35/21 -> 0.1 | ... N36: =+N35/21 -> 0.1047619 | O36: =+O35/8 -> 0.1875 | P36: =MAX(C36:O36) -> 0.24285714
B37: C.9.5 | C37: =+C35/5 -> 0.3 | D37: =+D35/14 -> 0.15714286 | E37: =+E35/14 -> 0.23214286 | F37: =+F35/14 -> 0.15714286 | G37: =+G35/14 -> 0.15 | H37: =+H35/14 -> 0.25714286 | I37: =+I35/14 -> 0.36428571 | J37: =+J35/14 -> 0.25714286 | K37: =+K35/14 -> 0.15 | ... N37: =+N35/14 -> 0.15714286 | O37: =+O35/8 -> 0.1875 | P37: =MAX(C37:O37) -> 0.36428571
A42: ENTREPISOS SUPERIORES | D42: VIGUETA 4 | I42: MAX
D43: TIPO | E43: 1EC | F43: 2EC | G43: 2EC | H43: 1EC
D44: LUZ (m) | E44: 3.25 | F44: 2.2 | G44: 2.1 | H44: 3.6
D45: C.9.5 (a) | E45: =+E44/18.5 -> 0.17567568 | F45: =+F44/21 -> 0.1047619 | G45: =+G44/21 -> 0.1 | H45: =+H44/18.5 -> 0.19459459 | I45: =+MAX(E45:H45) -> 0.19459459
D46: C.9.5 | E46: =+E44/12 -> 0.27083333 | F46: =+F44/14 -> 0.15714286 | G46: =+G44/14 -> 0.15 | H46: =+H44/12 -> 0.3 | I46: =+MAX(E46:H46) -> 0.3
D51: VIGUETA 5 | Q51: MAX
D52: TIPO | E52: 1EC | F52: 2EC | G52: 2EC | H52: 2EC | I52: 2EC | J52: 2EC | K52: 2EC | L52: 2EC | M52: 2EC | N52: 2EC | O52: 2EC | P52: 1EC
D53: LUZ (m) | E53: 2.2 | F53: 3.25 | G53: 2.2 | H53: 2.1 | I53: 3.8 | J53: 2.4 | K53: 2.3 | L53: 3.8 | M53: 2.1 | N53: 2.2 | O53: 3.25 | P53: 2.2
D54: C.9.5 (a) | E54: =+E53/18.5 -> 0.11891892 | F54: =+F53/21 -> 0.1547619 | G54: =+G53/21 -> 0.1047619 | H54: =+H53/21 -> 0.1 | I54: =+I53/21 -> 0.18095238 | J54: =+J53/21 -> 0.11428571 | K54: =+K53/21 -> 0.10952381 | L54: =+L53/21 -> 0.18095238 | M54: =+M53/21 -> 0.1 | ... O54: =+O53/21 -> 0.1547619 | P54: =+P53/18.5 -> 0.11891892 | Q54: =+MAX(E54:P54) -> 0.18095238
D55: C.9.5 | E55: =+E53/12 -> 0.18333333 | F55: =+F53/14 -> 0.23214286 | G55: =+G53/14 -> 0.15714286 | H55: =+H53/14 -> 0.15 | I55: =+I53/14 -> 0.27142857 | J55: =+J53/14 -> 0.17142857 | K55: =+K53/14 -> 0.16428571 | L55: =+L53/14 -> 0.27142857 | M55: =+M53/14 -> 0.15 | ... O55: =+O53/14 -> 0.23214286 | P55: =+P53/12 -> 0.18333333 | Q55: =+MAX(E55:P55) -> 0.27142857
D59: VIGUETA 6 | R59: MAX
D60: TIPO | E60: V | F60: 2EC | G60: 2EC | H60: 2EC | I60: 2EC | J60: 2EC | K60: 2EC | L60: 2EC | M60: 2EC | N60: 2EC | O60: 2EC | P60: 2EC | Q60: V
D61: LUZ (m) | E61: 1.5 | F61: 4.8 | G61: 5.15 | H61: 2.1 | I61: 3.6 | J61: 5.1 | K61: 3.6 | L61: 2.1 | M61: 3.8 | N61: 2.1 | O61: 5.15 | P61: 4.8 | Q61: 1.5
D62: C.9.5 (a) | E62: =+E61/8 -> 0.1875 | F62: =+F61/21 -> 0.22857143 | G62: =+G61/21 -> 0.2452381 | H62: =+H61/21 -> 0.1 | I62: =+I61/21 -> 0.17142857 | J62: =+J61/21 -> 0.24285714 | K62: =+K61/21 -> 0.17142857 | L62: =+L61/21 -> 0.1 | M62: =+M61/21 -> 0.18095238 | ... P62: =+P61/21 -> 0.22857143 | Q62: =+Q61/8 -> 0.1875 | R62: =+MAX(E62:Q62) -> 0.2452381
D63: C.9.5 | E63: =+E61/5 -> 0.3 | F63: =+F61/14 -> 0.34285714 | G63: =+G61/14 -> 0.36785714 | H63: =+H61/14 -> 0.15 | I63: =+I61/14 -> 0.25714286 | J63: =+J61/14 -> 0.36428571 | K63: =+K61/14 -> 0.25714286 | L63: =+L61/14 -> 0.15 | M63: =+M61/14 -> 0.27142857 | ... P63: =+P61/14 -> 0.34285714 | Q63: =+Q61/5 -> 0.3 | R63: =+MAX(E63:Q63) -> 0.36785714
D68: f´c Concreto | E68: 28 | F68: Mpa
D69: Peso especifico concreto | E69: =4700*SQRT(E68) -> 24870.062 | H69: Peso especifico guadua | I69: 6.5
E70: =E69/1000 -> 24.870062 | F70: KN/m3
E73: h vt | F73: 0.34 | G73: m
E74: b vt | F74: 0.15 | G74: m
E75: sv | F75: 0.8 | G75: m
E76: sl | F76: =F75-F74 -> 0.65 | G76: m
E77: sl/20 | F77: =F76/20 -> 0.0325 | G77: m
E79: hls | F79: 0.06
...

Sheet Vtas
B3: Base VR | C3: 0.35
B4: Luz ejes | C4: 5.1
B5: Luz libre (caras) | C5: =C4-$C$3 -> 4.75
B6: h | C6: 0.34
B7: b | C7: 0.15 | D7: =C6/5 -> 0.068
B9: Cáclulo VTAS
B12: n | C12: Se (m) | D12: Sl(m)
B13: 1 | C13: =($C$5-(B13*$C$7))/(B13+1)+$C$7 -> 2.45 | D13: =C13-$C$7 -> 2.3
B14: 2 | C14: =($C$5-(B14*$C$7))/(B14+1)+$C$7 -> 1.6333333 | D14: =C14-$C$7 -> 1.4833333
B15: 3 | C15: =($C$5-(B15*$C$7))/(B15+1)+$C$7 -> 1.225 | D15: =C15-$C$7 -> 1.075
B16: 4 | C16: =($C$5-(B16*$C$7))/(B16+1)+$C$7 -> 0.98 | D16: =C16-$C$7 -> 0.83
B17: 5 | C17: =($C$5-(B17*$C$7))/(B17+1)+$C$7 -> 0.81666667 | D17: =C17-$C$7 -> 0.66666667
B18: 6 | C18: =($C$5-(B18*$C$7))/(B18+1)+$C$7 -> 0.7 | D18: =C18-$C$7 -> 0.55
B19: 7 | C19: =($C$5-(B19*$C$7))/(B19+1)+$C$7 -> 0.6125 | D19: =C19-$C$7 -> 0.4625
B20: 8 | C20: =($C$5-(B20*$C$7))/(B20+1)+$C$7 -> 0.54444444 | D20: =C20-$C$7 -> 0.39444444
B21: 9 | C21: =($C$5-(B21*$C$7))/(B21+1)+$C$7 -> 0.49 | D21: =C21-$C$7 -> 0.34
B22: 10 | C22: =($C$5-(B22*$C$7))/(B22+1)+$C$7 -> 0.44545455 | D22: =C22-$C$7 -> 0.29545455
B25: Separación máxima (2.5*h vigas) | E25: Separación (m)
E26: =MROUND(C17,0.1) -> 0.8
B27: cm | C27: m
B28: =MIN(2.5*C6*100,120) -> 85 | C28: =B28/100 -> 0.85 | E28: Losa (m)
E29: =ROUNDUP(IF(D17/12>0.05,D17/12,0.05),2) -> 0.06

Sheet Avaluo
A1: ANÁLISIS DE CARGAS VERTICALES
A2: CARGAS MUERTAS (D) | J2: Separación | M2: =Vtas!E26 -> 0.8 | N2: m
A3: ENTREPISO | E3: Valores
B4: Peso propio de la estructura
B5: Peso losa superior | H5: 0.06 | I5: m | J5: x | K5: 2.4 | L5: Ton/m3 | M5: = | N5: =H5*K5 -> 0.144 | O5: Ton/m2 | P5: =N5*9.81 -> 1.41264 | Q5: kN/m2 | R5: =SUM(P5:P15) -> 7.039656
B6: Peso vigueta | E6: 0.15 | F6: m | G6: x | H6: 0.34 | I6: m | J6: x | K6: 2.4 | L6: Ton/m3 | M6: = | N6: =E6*H6*K6/M2 -> 0.153 | O6: Ton/m2 | P6: =N6*9.81 -> 1.50093 | Q6: kN/m2
B7: Peso caseton | K7: 0.01 | L7: Ton/m3 | M7: = | N7: 0.01 | O7: Ton/m2 | P7: =N7*9.81 -> 0.0981 | Q7: kN/m2
B8: Afinado | H8: 0.03 | I8: m | J8: x | K8: 2.3 | L8: Ton/m3 | M8: = | N8: =H8*K8 -> 0.069 | O8: Ton/m2 | P8: =N8*9.81 -> 0.67689 | Q8: kN/m2 | S8: 3cm de espesor de afinado
B9: Peso acabado piso | H9: 0.2 | I9: Ton/m3 | M9: = | N9: 0.02 | O9: Ton/m2 | P9: =N9*9.81 -> 0.1962 | Q9: kN/m2 | S9: madera densa 25 mm
B10: Peso acabado techo | H10: 0.025 | I10: Ton/m3 | M10: = | N10: 0.025 | O10: Ton/m2 | P10: =N10*9.81 -> 0.24525 | Q10: kN/m2 | S10: pañete en yeso o concreto, cielo raso
B11: Ductos | H11: 0.02 | I11: Ton/m3 | M11: = | N11: =H11 -> 0.02 | O11: Ton/m2 | P11: =N11*9.81 -> 0.1962 | Q11: kN/m2 | S11: Ductos mecánicos (Tabla B.3.4.1-1)
B12: Enchape ceramico pisos y cocina | H12: 0.015 | J12: kN/m2 | M12: = | N12: 0.0015 | O12: Ton/m2 | P12: =N12*9.81 -> 0.014715 | Q12: kN/m2
B13: Muros divisorios con Bloque No 4. | H13: 1.8 | J13: kN/m2 | M13: = | N13: 0.1834 | O13: Ton/m2 | P13: =N13*9.81 -> 1.799154 | Q13: kN/m2
B14: Muros interiores de apartamento, en muros livianos | H14: 0.9 | J14: kN/m2 | N14: 0.0917 | O14: Ton/m2 | P14: =N14*9.81 -> 0.899577 | Q14: kN/m2
M15: = | Q15: kN/m2
M16: = | N16: =SUM(N5:N15) -> 0.7176 | O16: Ton/m2 | P16: =N16*M2 -> 0.57408 | Q16: Ton/m
N17: =N16*9.81 -> 7.039656 | O17: kN/m2 | P17: =P16*9.81*2 -> 11.26345 | Q17: kN/m
R18: =586.5*N17 -> 4128.7582 | S18: 585.347
A19: Cubierta | E19: Valores | S19: 580.125
B20: Peso propio | E20: Incluído por el programa | S20: =4.906*4 -> 19.624
B21: Peso placa | H21: 0.06 | I21: m | J21: x | K21: 2.4 | L21: Ton/m3 | M21: = | N21: =H21*K21 -> 0.144 | O21: Ton/m2 | P21: =N21*9.81 -> 1.41264 | Q21: kN/m2 | S21: =13.395*2 -> 26.79
B22: Peso vigueta | E22: 0.15 | F22: m | G22: x | H22: =H6 -> 0.34 | I22: m | J22: x | K22: 2.4 | L22: Ton/m3 | M22: = | N22: =E22*H22*K22/M2 -> 0.153 | O22: Ton/m2 | P22: =N22*9.81 -> 1.50093 | Q22: kN/m3 | S22: =+S19-S20-S21 -> 533.711
B23: Afinado | H23: 0.03 | I23: m | J23: x | K23: 2.3 | L23: Ton/m3 | M23: = | N23: =H23*K23 -> 0.069 | O23: Ton/m2 | P23: =N23*9.81 -> 0.67689 | Q23: kN/m4
B24: Impermeabilización | H24: 0.01 | I24: Ton/m3 | M24: = | N24: =H24 -> 0.01 | O24: Ton/m2 | P24: =N24*9.81 -> 0.0981 | Q24: kN/m5 | R24: 1" de espesor de afinado
B25: Peso acabado techo | H25: 0.05 | I25: Ton/m3 | M25: = | N25: =H25 -> 0.05 | O25: Ton/m2 | P25: =N25*9.81 -> 0.4905 | Q25: kN/m6 | R25: Bituminosa superficie lisa (Tabla B.3.4.1-4)
B26: Ductos | H26: 0.02 | I26: Ton/m3 | M26: = | N26: =H26 -> 0.02 | O26: Ton/m2 | P26: =N26*9.81 -> 0.1962 | Q26: kN/m7 | R26: Entramado metálico con yeso (Tabla B.3.4.1-1)
M27: = | N27: =SUM(N21:N26) -> 0.446 | O27: Ton/m2 | P27: =N27*M2 -> 0.3568 | Q27: Ton/m | R27: Ductos mecánicos (Tabla B.3.4.1-1)
N28: =N27*9.81 -> 4.37526 | O28: kN(m2 | P28: =P27*9.81*2 -> 7.000416 | Q28: kN/m
R29: =N28*586.5 -> 2566.09
A33: CARGAS VIVAS
A34: ENTREPISO
B35: Carga viva | H35: 0.18 | I35: Ton/m3 | M35: = | N35: =H35 -> 0.18 | O35: Ton/m2 | P35: =N35*M2 -> 0.144 | Q35: Ton/m
N36: =N35*10 -> 1.8 | O36: kN(m2 | P36: =P35*2*9.81 -> 2.82528 | Q36: kN/m | R36: Recreativa (Tabla B.4.2.1-1)
A37: CUBIERTA
B38: Carga viva | I38: Ton/m3 | M38: = | N38: 0.5 | O38: Ton/m2 | P38: =N38*M2 -> 0.4 | Q38: Ton/m
N39: =N38*10 -> 5 | O39: kN(m2 | P39: =P38*2*9.81 -> 7.848 | Q39: kN/m | R39: Recreativa (Tabla B.4.2.1-1)
A40: BALCONES
B41: Carga viva | H41: 0.5 | I41: Ton/m3 | N41: =H41 -> 0.5 | O41: Ton/m2
N43: =+N41*10 -> 5 | O43: kN(m2
A44: CARGA DE FACHADA | E44: 3.5 | F44: m | G44: x | H44: 2.5 | I44: kN/m2 | M44: = | N44: =H44*E44 -> 8.75 | O44: kN/m | P44: =N44/2 -> 4.375 | Q44: kN/m
...

Sheet Distribucion cargas piso 1
B1: Carga Muerta | I1: Espesor enchape | S1: Carga Viva
B2: Viga | C2: Longitud viga | D2: Area aferente kN | E2: w fachada kN | F2: w cielo raso kN | I2: 1 | S2: Viga | T2: w garajes
B3: Carga | D3: kN/m2 | E3: 3 | F3: 0.25 | S3: Carga | T3: 2.5
A4: F | B4: 1 | C4: 3.85 | D4: 5 | E4: =$E$3*((D4))*3.5 -> 52.5 | F4: =$F$3*((D4)) -> 1.25 | S4: 1 | T4: =$T$3*((D4)) -> 12.5
A5: F | B5: 2 | C5: 3.9 | D5: 5.07 | E5: =$E$3*((D5))*3.5 -> 53.235 | F5: =$F$3*((D5)) -> 1.2675 | S5: 2 | T5: =$T$3*((D5)) -> 12.675
A6: F | B6: 3 | C6: 3.9 | D6: 5.07 | E6: =$E$3*((D6))*3.5 -> 53.235 | F6: =$F$3*((D6)) -> 1.2675 | S6: 3 | T6: =$T$3*((D6)) -> 12.675
A7: F | B7: 4 | C7: 3.85 | D7: 5 | E7: =$E$3*((D7))*3.5 -> 52.5 | F7: =$F$3*((D7)) -> 1.25 | S7: 4 | T7: =$T$3*((D7)) -> 12.5
B8: 5 | C8: 3.85 | D8: =5+7.02 -> 12.02 | F8: =$F$3*((D8)) -> 3.005 | S8: 5 | T8: =$T$3*((D8)) -> 30.05
B9: 6 | C9: 3.64 | D9: =5.07+17.116 -> 22.186 | F9: =$F$3*((D9)) -> 5.5465 | S9: 6 | T9: =$T$3*((D9)) -> 55.465
B10: 7 | C10: 3.64 | D10: =D9 -> 22.186 | F10: =$F$3*((D10)) -> 5.5465 | S10: 7 | T10: =$T$3*((D10)) -> 55.465
B11: 8 | C11: 3.85 | D11: =D8 -> 12.02 | F11: =$F$3*((D11)) -> 3.005 | S11: 8 | T11: =$T$3*((D11)) -> 30.05
B12: 9 | C12: 3.7 | D12: =6.75+4.81 -> 11.56 | F12: =$F$3*((D12)) -> 2.89 | S12: 9 | T12: =$T$3*((D12)) -> 28.9
B13: 10 | C13: 3.7 | D13: =D12 -> 11.56 | F13: =$F$3*((D13)) -> 2.89 | S13: 10 | T13: =$T$3*((D13)) -> 28.9
B14: 11 | C14: 3.7 | D14: =4.81*2 -> 9.62 | F14: =$F$3*((D14)) -> 2.405 | S14: 11 | T14: =$T$3*((D14)) -> 24.05
B15: 12 | C15: 3.73 | D15: =4.66+17.116 -> 21.776 | F15: =$F$3*((D15)) -> 5.444 | S15: 12 | T15: =$T$3*((D15)) -> 54.44
B16: 13 | C16: 3.73 | D16: =D15 -> 21.776 | F16: =$F$3*((D16)) -> 5.444 | S16: 13 | T16: =$T$3*((D16)) -> 54.44
B17: 14 | C17: 3.7 | D17: =D14 -> 9.62 | F17: =$F$3*((D17)) -> 2.405 | S17: 14 | T17: =$T$3*((D17)) -> 24.05
B18: 15 | C18: 3.7 | D18: =4.81+7.4 -> 12.21 | F18: =$F$3*((D18)) -> 3.0525 | S18: 15 | T18: =$T$3*((D18)) -> 30.525
B19: 16 | C19: 3.73 | D19: =4.66+7.46 -> 12.12 | F19: =$F$3*((D19)) -> 3.03 | S19: 16 | T19: =$T$3*((D19)) -> 30.3
B20: 17 | C20: 3.73 | D20: =D19 -> 12.12 | F20: =$F$3*((D20)) -> 3.03 | S20: 17 | T20: =$T$3*((D20)) -> 30.3
B21: 18 | C21: 3.7 | D21: =D18 -> 12.21 | F21: =$F$3*((D21)) -> 3.0525 | S21: 18 | T21: =$T$3*((D21)) -> 30.525
B22: 19 | C22: 2.5 | D22: =5+6.875 -> 11.875 | F22: =$F$3*((D22)) -> 2.96875 | S22: 19 | T22: =$T$3*((D22)) -> 29.6875
B23: 20 | C23: 4.92 | D23: =9.84+13.53 -> 23.37 | F23: =$F$3*((D23)) -> 5.8425 | S23: 20 | T23: =$T$3*((D23)) -> 58.425
B24: 21 | C24: 4.92 | D24: =D23 -> 23.37 | F24: =$F$3*((D24)) -> 5.8425 | S24: 21 | T24: =$T$3*((D24)) -> 58.425
B25: 22 | C25: 2.5 | D25: =5+6.875 -> 11.875 | F25: =$F$3*((D25)) -> 2.96875 | S25: 22 | T25: =$T$3*((D25)) -> 29.6875
B26: 23 | C26: 2.5 | D26: =6.875+5 -> 11.875 | F26: =$F$3*((D26)) -> 2.96875 | S26: 23 | T26: =$T$3*((D26)) -> 29.6875
B27: 24 | C27: 4.92 | D27: =13.53+9.84 -> 23.37 | F27: =$F$3*((D27)) -> 5.8425 | S27: 24 | T27: =$T$3*((D27)) -> 58.425
B28: 25 | C28: 4.92 | D28: =D27 -> 23.37 | F28: =$F$3*((D28)) -> 5.8425 | S28: 25 | T28: =$T$3*((D28)) -> 58.425
B29: 26 | C29: 2.5 | D29: =D26 -> 11.875 | F29: =$F$3*((D29)) -> 2.96875 | S29: 26 | T29: =$T$3*((D29)) -> 29.6875
B30: 27 | C30: 3.7 | D30: =7.4+4.625 -> 12.025 | F30: =$F$3*((D30)) -> 3.00625 | S30: 27 | T30: =$T$3*((D30)) -> 30.0625
B31: 28 | C31: 3.73 | D31: =7.46+4.66 -> 12.12 | F31: =$F$3*((D31)) -> 3.03 | S31: 28 | T31: =$T$3*((D31)) -> 30.3
B32: 29 | C32: 3.73 | D32: =D31 -> 12.12 | F32: =$F$3*((D32)) -> 3.03 | S32: 29 | T32: =$T$3*((D32)) -> 30.3
B33: 30 | C33: 3.7 | D33: =7.4+4.625 -> 12.025 | F33: =$F$3*((D33)) -> 3.00625 | S33: 30 | T33: =$T$3*((D33)) -> 30.0625
B34: 31 | C34: 3.7 | D34: =4.625+4.81 -> 9.435 | F34: =$F$3*((D34)) -> 2.35875 | S34: 31 | T34: =$T$3*((D34)) -> 23.5875
B35: 32 | C35: 3.73 | D35: =4.66+17.116 -> 21.776 | F35: =$F$3*((D35)) -> 5.444 | S35: 32 | T35: =$T$3*((D35)) -> 54.44
B36: 33 | C36: 3.73 | D36: =D35 -> 21.776 | F36: =$F$3*((D36)) -> 5.444 | S36: 33 | T36: =$T$3*((D36)) -> 54.44
B37: 34 | C37: 3.7 | D37: =D34 -> 9.435 | F37: =$F$3*((D37)) -> 2.35875 | S37: 34 | T37: =$T$3*((D37)) -> 23.5875
B38: 35 | C38: 3.7 | D38: =4.81+6.75 -> 11.56 | F38: =$F$3*((D38)) -> 2.89 | S38: 35 | T38: =$T$3*((D38)) -> 28.9
B39: 36 | C39: 3.7 | D39: =D38 -> 11.56 | F39: =$F$3*((D39)) -> 2.89 | S39: 36 | T39: =$T$3*((D39)) -> 28.9
B40: 37 | C40: 3.85 | D40: =7.026+5 -> 12.026 | F40: =$F$3*((D40)) -> 3.0065 | S40: 37 | T40: =$T$3*((D40)) -> 30.065
...

Sheet Distribucion cargas piso 2
B1: Carga Muerta | Z1: Carga Viva
B2: Viga | C2: Longitud | D2: Area aferente | E2: w losa kN | F2: w piso normal kN | G2: w piso cocina y baños kN | H2: w muros internos kN | I2: w fachada kN | J2: w cielo raso kN | K2: w ventanas kN | L2: Vigueta | M2: Casetón permanente | N2: Muros divisorios | O2: Afinado | P2: Ductos | S2: Espesor enchape | Z2: Viga | AA2: w terrazas | AB2: w cuartos | AC2: w escaleras | AD2: w cubierta
B3: Carga | D3: kN/m2 | E3: 1.41 | F3: 0.2 | G3: =0.015*S3 -> 0.015 | H3: 0.9 | I3: 3 | J3: 0.25 | K3: 0.5 | L3: 1.5 | M3: 0.1 | N3: 1.8 | O3: 0.68 | P3: 0.2 | S3: 1 | Z3: Carga | AA3: 5 | AB3: 2 | AC3: 5 | AD3: 5
A4: f | B4: 1 | C4: 3.85 | D4: 5 | E4: =$E$3*(D4) -> 7.05 | F4: =$F$3*((D4)) -> 1 | H4: =$H$3*3.5*C4 -> 12.1275 | I4: =$I$3*3.5*D4 -> 52.5 | J4: =$J$3*((D4)) -> 1.25 | K4: =$K$3*((D4)) -> 2.5 | L4: =$L$3*((D4)) -> 7.5 | M4: =$M$3*((D4)) -> 0.5 | N4: =$N$3*((D4))*3.5 -> 31.5 | O4: =$O$3*((D4)) -> 3.4 | P4: =$P$3*((D4)) -> 1 | Z4: 1 | AC4: =$AC$3*((D4)) -> 25 | AD4: =$AD$3*((D4)) -> 25
A5: f | B5: 2 | C5: 3.85 | D5: 5 | E5: =$E$3*(D5) -> 7.05 | F5: =$F$3*((D5)) -> 1 | H5: =$H$3*3.5*C5 -> 12.1275 | I5: =$I$3*3.5*D5 -> 52.5 | J5: =$J$3*((D5)) -> 1.25 | K5: =$K$3*((D5)) -> 2.5 | L5: =$L$3*((D5)) -> 7.5 | M5: =$M$3*((D5)) -> 0.5 | N5: =$N$3*((D5))*3.5 -> 31.5 | O5: =$O$3*((D5)) -> 3.4 | P5: =$P$3*((D5)) -> 1 | Z5: 2 | AC5: =$AC$3*((D5)) -> 25 | AD5: =$AD$3*((D5)) -> 25
B6: 3 | C6: 3.85 | D6: 12.02 | E6: =$E$3*(D6) -> 16.9482 | G6: =$G$3*((D6)) -> 0.1803 | H6: =$H$3*3.5*C6 -> 12.1275 | J6: =$J$3*((D6)) -> 3.005 | L6: =$L$3*((D6)) -> 18.03 | M6: =$M$3*((D6)) -> 1.202 | N6: =$N$3*((D6))*3.5 -> 75.726 | O6: =$O$3*((D6)) -> 8.1736 | P6: =$P$3*((D6)) -> 2.404 | Z6: 3 | AB6: =$AB$3*((D6)) -> 24.04 | AC6: =$AC$3*((D6)) -> 60.1 | AD6: =$AD$3*((D6)) -> 60.1
B7: 4 | C7: 3.64 | D7: =5.07*2+16.93475 -> 27.07475 | E7: =$E$3*(D7) -> 38.175398 | F7: =$F$3*((D7)) -> 5.41495 | H7: =$H$3*3.5*C7 -> 11.466 | J7: =$J$3*((D7)) -> 6.7686875 | K7: =$K$3*((D7)) -> 13.537375 | L7: =$L$3*((D7)) -> 40.612125 | M7: =$M$3*((D7)) -> 2.707475 | N7: =$N$3*((D7))*3.5 -> 170.57093 | O7: =$O$3*((D7)) -> 18.41083 | P7: =$P$3*((D7)) -> 5.41495 | Z7: 4 | AA7: =$AA$3*((D7)) -> 135.37375 | AD7: =$AD$3*((D7)) -> 135.37375
B8: 5 | C8: 3.64 | D8: =D7 -> 27.07475 | E8: =$E$3*(D8) -> 38.175398 | F8: =$F$3*((D8)) -> 5.41495 | H8: =$H$3*3.5*C8 -> 11.466 | J8: =$J$3*((D8)) -> 6.7686875 | K8: =$K$3*((D8)) -> 13.537375 | L8: =$L$3*((D8)) -> 40.612125 | M8: =$M$3*((D8)) -> 2.707475 | N8: =$N$3*((D8))*3.5 -> 170.57093 | O8: =$O$3*((D8)) -> 18.41083 | P8: =$P$3*((D8)) -> 5.41495 | Z8: 5 | AA8: =$AA$3*((D8)) -> 135.37375 | AD8: =$AD$3*((D8)) -> 135.37375
B9: 6 | C9: 3.85 | D9: =D6 -> 12.02 | E9: =$E$3*(D9) -> 16.9482 | G9: =$G$3*((D9)) -> 0.1803 | H9: =$H$3*3.5*C9 -> 12.1275 | J9: =$J$3*((D9)) -> 3.005 | L9: =$L$3*((D9)) -> 18.03 | M9: =$M$3*((D9)) -> 1.202 | N9: =$N$3*((D9))*3.5 -> 75.726 | O9: =$O$3*((D9)) -> 8.1736 | P9: =$P$3*((D9)) -> 2.404 | Z9: 6 | AB9: =$AB$3*((D9)) -> 24.04 | AC9: =$AC$3*((D9)) -> 60.1 | AD9: =$AD$3*((D9)) -> 60.1
B10: 7 | C10: 3.7 | D10: ='[1]Avaluo de cargas piso 1'!D12 -> 11.56 | E10: =$E$3*(D10) -> 16.2996 | G10: =$G$3*((D10)) -> 0.1734 | H10: =$H$3*3.5*C10 -> 11.655 | J10: =$J$3*((D10)) -> 2.89 | L10: =$L$3*((D10)) -> 17.34 | M10: =$M$3*((D10)) -> 1.156 | N10: =$N$3*((D10))*3.5 -> 72.828 | O10: =$O$3*((D10)) -> 7.8608 | P10: =$P$3*((D10)) -> 2.312 | Z10: 7 | AB10: =$AB$3*((D10)) -> 23.12 | AD10: =$AD$3*((D10)) -> 57.8
B11: 8 | C11: 3.7 | D11: ='[1]Avaluo de cargas piso 1'!D13 -> 11.56 | E11: =$E$3*(D11) -> 16.2996 | G11: =$G$3*((D11)) -> 0.1734 | H11: =$H$3*3.5*C11 -> 11.655 | J11: =$J$3*((D11)) -> 2.89 | L11: =$L$3*((D11)) -> 17.34 | M11: =$M$3*((D11)) -> 1.156 | N11: =$N$3*((D11))*3.5 -> 72.828 | O11: =$O$3*((D11)) -> 7.8608 | P11: =$P$3*((D11)) -> 2.312 | Z11: 8 | AB11: =$AB$3*((D11)) -> 23.12 | AD11: =$AD$3*((D11)) -> 57.8
B12: 9 | C12: 3.7 | D12: ='[1]Avaluo de cargas piso 1'!D14 -> 9.62 | E12: =$E$3*(D12) -> 13.5642 | F12: =$F$3*((D12)) -> 1.924 | H12: =$H$3*3.5*C12 -> 11.655 | J12: =$J$3*((D12)) -> 2.405 | L12: =$L$3*((D12)) -> 14.43 | M12: =$M$3*((D12)) -> 0.962 | N12: =$N$3*((D12))*3.5 -> 60.606 | O12: =$O$3*((D12)) -> 6.5416 | P12: =$P$3*((D12)) -> 1.924 | Z12: 9 | AB12: =$AB$3*((D12)) -> 19.24 | AD12: =$AD$3*((D12)) -> 48.1
B13: 10 | C13: 3.73 | D13: =4.66+16.93475 -> 21.59475 | E13: =$E$3*(D13) -> 30.448598 | F13: =$F$3*((D13)) -> 4.31895 | H13: =$H$3*3.5*C13 -> 11.7495 | J13: =$J$3*((D13)) -> 5.3986875 | L13: =$L$3*((D13)) -> 32.392125 | M13: =$M$3*((D13)) -> 2.159475 | N13: =$N$3*((D13))*3.5 -> 136.04693 | O13: =$O$3*((D13)) -> 14.68443 | P13: =$P$3*((D13)) -> 4.31895 | Z13: 10 | AB13: =$AB$3*((D13)) -> 43.1895 | AD13: =$AD$3*((D13)) -> 107.97375
B14: 11 | C14: 3.73 | D14: =D13 -> 21.59475 | E14: =$E$3*(D14) -> 30.448598 | F14: =$F$3*((D14)) -> 4.31895 | H14: =$H$3*3.5*C14 -> 11.7495 | J14: =$J$3*((D14)) -> 5.3986875 | L14: =$L$3*((D14)) -> 32.392125 | M14: =$M$3*((D14)) -> 2.159475 | N14: =$N$3*((D14))*3.5 -> 136.04693 | O14: =$O$3*((D14)) -> 14.68443 | P14: =$P$3*((D14)) -> 4.31895 | Z14: 11 | AB14: =$AB$3*((D14)) -> 43.1895 | AD14: =$AD$3*((D14)) -> 107.97375
B15: 12 | C15: 3.7 | D15: ='[1]Avaluo de cargas piso 1'!D17 -> 9.62 | E15: =$E$3*(D15) -> 13.5642 | F15: =$F$3*((D15)) -> 1.924 | H15: =$H$3*3.5*C15 -> 11.655 | J15: =$J$3*((D15)) -> 2.405 | L15: =$L$3*((D15)) -> 14.43 | M15: =$M$3*((D15)) -> 0.962 | N15: =$N$3*((D15))*3.5 -> 60.606 | O15: =$O$3*((D15)) -> 6.5416 | P15: =$P$3*((D15)) -> 1.924 | Z15: 12 | AB15: =$AB$3*((D15)) -> 19.24 | AD15: =$AD$3*((D15)) -> 48.1
B16: 13 | C16: 3.7 | D16: ='[1]Avaluo de cargas piso 1'!D18 -> 12.21 | E16: =$E$3*(D16) -> 17.2161 | F16: =$F$3*((D16)) -> 2.442 | H16: =$H$3*3.5*C16 -> 11.655 | J16: =$J$3*((D16)) -> 3.0525 | L16: =$L$3*((D16)) -> 18.315 | M16: =$M$3*((D16)) -> 1.221 | N16: =$N$3*((D16))*3.5 -> 76.923 | O16: =$O$3*((D16)) -> 8.3028 | P16: =$P$3*((D16)) -> 2.442 | Z16: 13 | AB16: =$AB$3*((D16)) -> 24.42 | AD16: =$AD$3*((D16)) -> 61.05
B17: 14 | C17: 3.73 | D17: ='[1]Avaluo de cargas piso 1'!D19 -> 12.12 | E17: =$E$3*(D17) -> 17.0892 | F17: =$F$3*((D17)) -> 2.424 | H17: =$H$3*3.5*C17 -> 11.7495 | J17: =$J$3*((D17)) -> 3.03 | L17: =$L$3*((D17)) -> 18.18 | M17: =$M$3*((D17)) -> 1.212 | N17: =$N$3*((D17))*3.5 -> 76.356 | O17: =$O$3*((D17)) -> 8.2416 | P17: =$P$3*((D17)) -> 2.424 | Z17: 14 | AB17: =$AB$3*((D17)) -> 24.24 | AD17: =$AD$3*((D17)) -> 60.6
B18: 15 | C18: 3.73 | D18: ='[1]Avaluo de cargas piso 1'!D20 -> 12.12 | E18: =$E$3*(D18) -> 17.0892 | F18: =$F$3*((D18)) -> 2.424 | H18: =$H$3*3.5*C18 -> 11.7495 | J18: =$J$3*((D18)) -> 3.03 | L18: =$L$3*((D18)) -> 18.18 | M18: =$M$3*((D18)) -> 1.212 | N18: =$N$3*((D18))*3.5 -> 76.356 | O18: =$O$3*((D18)) -> 8.2416 | P18: =$P$3*((D18)) -> 2.424 | Z18: 15 | AB18: =$AB$3*((D18)) -> 24.24 | AD18: =$AD$3*((D18)) -> 60.6
B19: 16 | C19: 3.7 | D19: ='[1]Avaluo de cargas piso 1'!D21 -> 12.21 | E19: =$E$3*(D19) -> 17.2161 | F19: =$F$3*((D19)) -> 2.442 | H19: =$H$3*3.5*C19 -> 11.655 | J19: =$J$3*((D19)) -> 3.0525 | L19: =$L$3*((D19)) -> 18.315 | M19: =$M$3*((D19)) -> 1.221 | N19: =$N$3*((D19))*3.5 -> 76.923 | O19: =$O$3*((D19)) -> 8.3028 | P19: =$P$3*((D19)) -> 2.442 | Z19: 16 | AB19: =$AB$3*((D19)) -> 24.42 | AD19: =$AD$3*((D19)) -> 61.05
B20: 17 | C20: 2.5 | D20: 5 | E20: =$E$3*(D20) -> 7.05 | F20: =$F$3*((D20)) -> 1 | J20: =$J$3*((D20)) -> 1.25 | K20: =$K$3*((D20)) -> 2.5 | L20: =$L$3*((D20)) -> 7.5 | M20: =$M$3*((D20)) -> 0.5 | N20: =$N$3*((D20))*3.5 -> 31.5 | O20: =$O$3*((D20)) -> 3.4 | P20: =$P$3*((D20)) -> 1 | Z20: 17 | AB20: =$AB$3*((D20)) -> 10 | AD20: =$AD$3*((D20)) -> 25
B21: 18 | C21: 4.92 | D21: =9.84+13.53 -> 23.37 | E21: =$E$3*(D21) -> 32.9517 | F21: =$F$3*((D21)) -> 4.674 | H21: =$H$3*3.5*C21 -> 15.498 | J21: =$J$3*((D21)) -> 5.8425 | L21: =$L$3*((D21)) -> 35.055 | M21: =$M$3*((D21)) -> 2.337 | N21: =$N$3*((D21))*3.5 -> 147.231 | O21: =$O$3*((D21)) -> 15.8916 | P21: =$P$3*((D21)) -> 4.674 | Z21: 18 | AB21: =$AB$3*((D21)) -> 46.74 | AD21: =$AD$3*((D21)) -> 116.85
B22: 19 | C22: 4.92 | D22: =D21 -> 23.37 | E22: =$E$3*(D22) -> 32.9517 | F22: =$F$3*((D22)) -> 4.674 | H22: =$H$3*3.5*C22 -> 15.498 | J22: =$J$3*((D22)) -> 5.8425 | L22: =$L$3*((D22)) -> 35.055 | M22: =$M$3*((D22)) -> 2.337 | N22: =$N$3*((D22))*3.5 -> 147.231 | O22: =$O$3*((D22)) -> 15.8916 | P22: =$P$3*((D22)) -> 4.674 | Z22: 19 | AB22: =$AB$3*((D22)) -> 46.74 | AD22: =$AD$3*((D22)) -> 116.85
B23: 20 | C23: 2.5 | D23: 5 | E23: =$E$3*(D23) -> 7.05 | F23: =$F$3*((D23)) -> 1 | J23: =$J$3*((D23)) -> 1.25 | K23: =$K$3*((D23)) -> 2.5 | L23: =$L$3*((D23)) -> 7.5 | M23: =$M$3*((D23)) -> 0.5 | N23: =$N$3*((D23))*3.5 -> 31.5 | O23: =$O$3*((D23)) -> 3.4 | P23: =$P$3*((D23)) -> 1 | Z23: 20 | AB23: =$AB$3*((D23)) -> 10 | AD23: =$AD$3*((D23)) -> 25
B24: 21 | C24: 2.5 | D24: =D23 -> 5 | E24: =$E$3*(D24) -> 7.05 | F24: =$F$3*((D24)) -> 1 | J24: =$J$3*((D24)) -> 1.25 | K24: =$K$3*((D24)) -> 2.5 | L24: =$L$3*((D24)) -> 7.5 | M24: =$M$3*((D24)) -> 0.5 | N24: =$N$3*((D24))*3.5 -> 31.5 | O24: =$O$3*((D24)) -> 3.4 | P24: =$P$3*((D24)) -> 1 | Z24: 21 | AB24: =$AB$3*((D24)) -> 10 | AD24: =$AD$3*((D24)) -> 25
B25: 22 | C25: 4.92 | D25: =13.53+9.84 -> 23.37 | E25: =$E$3*(D25) -> 32.9517 | F25: =$F$3*((D25)) -> 4.674 | H25: =$H$3*3.5*C25 -> 15.498 | J25: =$J$3*((D25)) -> 5.8425 | L25: =$L$3*((D25)) -> 35.055 | M25: =$M$3*((D25)) -> 2.337 | N25: =$N$3*((D25))*3.5 -> 147.231 | O25: =$O$3*((D25)) -> 15.8916 | P25: =$P$3*((D25)) -> 4.674 | Z25: 22 | AB25: =$AB$3*((D25)) -> 46.74 | AD25: =$AD$3*((D25)) -> 116.85
B26: 23 | C26: 4.92 | D26: =D25 -> 23.37 | E26: =$E$3*(D26) -> 32.9517 | F26: =$F$3*((D26)) -> 4.674 | H26: =$H$3*3.5*C26 -> 15.498 | J26: =$J$3*((D26)) -> 5.8425 | L26: =$L$3*((D26)) -> 35.055 | M26: =$M$3*((D26)) -> 2.337 | N26: =$N$3*((D26))*3.5 -> 147.231 | O26: =$O$3*((D26)) -> 15.8916 | P26: =$P$3*((D26)) -> 4.674 | Z26: 23 | AB26: =$AB$3*((D26)) -> 46.74 | AD26: =$AD$3*((D26)) -> 116.85
B27: 24 | C27: 2.5 | D27: 5 | E27: =$E$3*(D27) -> 7.05 | F27: =$F$3*((D27)) -> 1 | J27: =$J$3*((D27)) -> 1.25 | K27: =$K$3*((D27)) -> 2.5 | L27: =$L$3*((D27)) -> 7.5 | M27: =$M$3*((D27)) -> 0.5 | N27: =$N$3*((D27))*3.5 -> 31.5 | O27: =$O$3*((D27)) -> 3.4 | P27: =$P$3*((D27)) -> 1 | Z27: 24 | AB27: =$AB$3*((D27)) -> 10 | AD27: =$AD$3*((D27)) -> 25
B28: 25 | C28: 3.7 | D28: =7.4+4.625 -> 12.025 | E28: =$E$3*(D28) -> 16.95525 | F28: =$F$3*((D28)) -> 2.405 | H28: =$H$3*3.5*C28 -> 11.655 | J28: =$J$3*((D28)) -> 3.00625 | L28: =$L$3*((D28)) -> 18.0375 | M28: =$M$3*((D28)) -> 1.2025 | N28: =$N$3*((D28))*3.5 -> 75.7575 | O28: =$O$3*((D28)) -> 8.177 | P28: =$P$3*((D28)) -> 2.405 | Z28: 25 | AB28: =$AB$3*((D28)) -> 24.05 | AD28: =$AD$3*((D28)) -> 60.125
B29: 26 | C29: 3.73 | D29: =7.46+4.66 -> 12.12 | E29: =$E$3*(D29) -> 17.0892 | F29: =$F$3*((D29)) -> 2.424 | H29: =$H$3*3.5*C29 -> 11.7495 | J29: =$J$3*((D29)) -> 3.03 | L29: =$L$3*((D29)) -> 18.18 | M29: =$M$3*((D29)) -> 1.212 | N29: =$N$3*((D29))*3.5 -> 76.356 | O29: =$O$3*((D29)) -> 8.2416 | P29: =$P$3*((D29)) -> 2.424 | Z29: 26 | AB29: =$AB$3*((D29)) -> 24.24 | AD29: =$AD$3*((D29)) -> 60.6
B30: 27 | C30: 3.73 | D30: =D29 -> 12.12 | E30: =$E$3*(D30) -> 17.0892 | F30: =$F$3*((D30)) -> 2.424 | H30: =$H$3*3.5*C30 -> 11.7495 | J30: =$J$3*((D30)) -> 3.03 | L30: =$L$3*((D30)) -> 18.18 | M30: =$M$3*((D30)) -> 1.212 | N30: =$N$3*((D30))*3.5 -> 76.356 | O30: =$O$3*((D30)) -> 8.2416 | P30: =$P$3*((D30)) -> 2.424 | Z30: 27 | AB30: =$AB$3*((D30)) -> 24.24 | AD30: =$AD$3*((D30)) -> 60.6
B31: 28 | C31: 3.7 | D31: =7.4+4.625 -> 12.025 | E31: =$E$3*(D31) -> 16.95525 | F31: =$F$3*((D31)) -> 2.405 | H31: =$H$3*3.5*C31 -> 11.655 | J31: =$J$3*((D31)) -> 3.00625 | L31: =$L$3*((D31)) -> 18.0375 | M31: =$M$3*((D31)) -> 1.2025 | N31: =$N$3*((D31))*3.5 -> 75.7575 | O31: =$O$3*((D31)) -> 8.177 | P31: =$P$3*((D31)) -> 2.405 | Z31: 28 | AB31: =$AB$3*((D31)) -> 24.05 | AD31: =$AD$3*((D31)) -> 60.125
B32: 29 | C32: 3.7 | D32: =4.625+4.81 -> 9.435 | E32: =$E$3*(D32) -> 13.30335 | G32: =$G$3*((D32)) -> 0.141525 | H32: =$H$3*3.5*C32 -> 11.655 | J32: =$J$3*((D32)) -> 2.35875 | L32: =$L$3*((D32)) -> 14.1525 | M32: =$M$3*((D32)) -> 0.9435 | N32: =$N$3*((D32))*3.5 -> 59.4405 | O32: =$O$3*((D32)) -> 6.4158 | P32: =$P$3*((D32)) -> 1.887 | Z32: 29 | AB32: =$AB$3*((D32)) -> 18.87 | AD32: =$AD$3*((D32)) -> 47.175
B33: 30 | C33: 3.73 | D33: =4.66+16.93475 -> 21.59475 | E33: =$E$3*(D33) -> 30.448598 | F33: =$F$3*((D33)) -> 4.31895 | H33: =$H$3*3.5*C33 -> 11.7495 | J33: =$J$3*((D33)) -> 5.3986875 | L33: =$L$3*((D33)) -> 32.392125 | M33: =$M$3*((D33)) -> 2.159475 | N33: =$N$3*((D33))*3.5 -> 136.04693 | O33: =$O$3*((D33)) -> 14.68443 | P33: =$P$3*((D33)) -> 4.31895 | Z33: 30 | AB33: =$AB$3*((D33)) -> 43.1895 | AD33: =$AD$3*((D33)) -> 107.97375
B34: 31 | C34: 3.73 | D34: =D33 -> 21.59475 | E34: =$E$3*(D34) -> 30.448598 | F34: =$F$3*((D34)) -> 4.31895 | H34: =$H$3*3.5*C34 -> 11.7495 | J34: =$J$3*((D34)) -> 5.3986875 | L34: =$L$3*((D34)) -> 32.392125 | M34: =$M$3*((D34)) -> 2.159475 | N34: =$N$3*((D34))*3.5 -> 136.04693 | O34: =$O$3*((D34)) -> 14.68443 | P34: =$P$3*((D34)) -> 4.31895 | Z34: 31 | AB34: =$AB$3*((D34)) -> 43.1895 | AD34: =$AD$3*((D34)) -> 107.97375
B35: 32 | C35: 3.7 | D35: =D32 -> 9.435 | E35: =$E$3*(D35) -> 13.30335 | G35: =$G$3*((D35)) -> 0.141525 | H35: =$H$3*3.5*C35 -> 11.655 | J35: =$J$3*((D35)) -> 2.35875 | L35: =$L$3*((D35)) -> 14.1525 | M35: =$M$3*((D35)) -> 0.9435 | N35: =$N$3*((D35))*3.5 -> 59.4405 | O35: =$O$3*((D35)) -> 6.4158 | P35: =$P$3*((D35)) -> 1.887 | Z35: 32 | AB35: =$AB$3*((D35)) -> 18.87 | AD35: =$AD$3*((D35)) -> 47.175
B36: 33 | C36: 3.7 | D36: =4.81+6.75 -> 11.56 | E36: =$E$3*(D36) -> 16.2996 | G36: =$G$3*((D36)) -> 0.1734 | H36: =$H$3*3.5*C36 -> 11.655 | J36: =$J$3*((D36)) -> 2.89 | L36: =$L$3*((D36)) -> 17.34 | M36: =$M$3*((D36)) -> 1.156 | N36: =$N$3*((D36))*3.5 -> 72.828 | O36: =$O$3*((D36)) -> 7.8608 | P36: =$P$3*((D36)) -> 2.312 | Z36: 33 | AB36: =$AB$3*((D36)) -> 23.12 | AD36: =$AD$3*((D36)) -> 57.8
B37: 34 | C37: 3.7 | D37: =D36 -> 11.56 | E37: =$E$3*(D37) -> 16.2996 | F37: =$F$3*((D37)) -> 2.312 | H37: =$H$3*3.5*C37 -> 11.655 | J37: =$J$3*((D37)) -> 2.89 | L37: =$L$3*((D37)) -> 17.34 | M37: =$M$3*((D37)) -> 1.156 | N37: =$N$3*((D37))*3.5 -> 72.828 | O37: =$O$3*((D37)) -> 7.8608 | P37: =$P$3*((D37)) -> 2.312 | Z37: 34 | AB37: =$AB$3*((D37)) -> 23.12 | AD37: =$AD$3*((D37)) -> 57.8
B38: 35 | C38: 3.85 | D38: =7.026+5 -> 12.026 | E38: =$E$3*(D38) -> 16.95666 | G38: =$G$3*((D38)) -> 0.18039 | H38: =$H$3*3.5*C38 -> 12.1275 | J38: =$J$3*((D38)) -> 3.0065 | L38: =$L$3*((D38)) -> 18.039 | M38: =$M$3*((D38)) -> 1.2026 | N38: =$N$3*((D38))*3.5 -> 75.7638 | O38: =$O$3*((D38)) -> 8.17768 | P38: =$P$3*((D38)) -> 2.4052 | Z38: 35 | AB38: =$AB$3*((D38)) -> 24.052 | AC38: =$AC$3*((D38)) -> 60.13 | AD38: =$AD$3*((D38)) -> 60.13
B39: 36 | C39: 3.64 | D39: =5.07*2+16.93475 -> 27.07475 | E39: =$E$3*(D39) -> 38.175398 | F39: =$F$3*((D39)) -> 5.41495 | H39: =$H$3*3.5*C39 -> 11.466 | J39: =$J$3*((D39)) -> 6.7686875 | K39: =$K$3*((D39)) -> 13.537375 | L39: =$L$3*((D39)) -> 40.612125 | M39: =$M$3*((D39)) -> 2.707475 | N39: =$N$3*((D39))*3.5 -> 170.57093 | O39: =$O$3*((D39)) -> 18.41083 | P39: =$P$3*((D39)) -> 5.41495 | Z39: 36 | AA39: =$AA$3*((D39)) -> 135.37375 | AD39: =$AD$3*((D39)) -> 135.37375
B40: 37 | C40: 3.64 | D40: =D39 -> 27.07475 | E40: =$E$3*(D40) -> 38.175398 | F40: =$F$3*((D40)) -> 5.41495 | H40: =$H$3*3.5*C40 -> 11.466 | J40: =$J$3*((D40)) -> 6.7686875 | K40: =$K$3*((D40)) -> 13.537375 | L40: =$L$3*((D40)) -> 40.612125 | M40: =$M$3*((D40)) -> 2.707475 | N40: =$N$3*((D40))*3.5 -> 170.57093 | O40: =$O$3*((D40)) -> 18.41083 | P40: =$P$3*((D40)) -> 5.41495 | Z40: 37 | AA40: =$AA$3*((D40)) -> 135.37375 | AD40: =$AD$3*((D40)) -> 135.37375
...

Sheet Escalera
B3: ESCALERAS
B6: Escalera Tipo 1 | F6: # Contrahuella | G6: Contrahuella | I6: Ch | J6: =+G11 -> 25 | L6: cm
B7: 62 | C7: 2CH + Hll | D7: 64 | F7: 10 | G7: =+$C$10/F7 -> 35 | I7: Huella | J7: 25 | K7: =+D7-2*J6 -> 14 | L7: cm
B8: 10 | C8: CH | D8: 18 | F8: 11 | G8: =+$C$10/F8 -> 31.818182 | I8: # Escalones | J8: 14
B9: Altura | C9: 3.5 | D9: m | F9: 12 | G9: =+$C$10/F9 -> 29.166667 | I9: Descanso | J9: 1
C10: =+C9*100 -> 350 | D10: cm | F10: 13 | G10: =+$C$10/F10 -> 26.923077 | I10: Diferencia | J10: =+C10-(J6*J8) -> 0 | K10: cm
B11: Huella | C11: 25 | D11: cm | F11: 14 | G11: =+$C$10/F11 -> 25
F12: 15 | G12: =+$C$10/F12 -> 23.333333 | I12: # de Huellas | J12: =+J8-1 -> 13 | K12: Impar
F13: 16 | G13: =+$C$10/F13 -> 21.875 | J13: =+J8 -> 14 | K13: Par | W13: =+O13*10 -> 0
B14: #VALUE! | F14: 17 | G14: =+$C$10/F14 -> 20.588235
F15: 18 | G15: =+$C$10/F15 -> 19.444444 | I15: # Huellas a cada lado | K15: =(J13-2)/2 -> 6
F16: 19 | G16: =+$C$10/F16 -> 18.421053 | I16: Ancho del descanso | K16: 100 | L16: cm
F17: 20 | G17: =+$C$10/F17 -> 17.5
F18: 21 | G18: =+$C$10/F18 -> 16.666667 | L18: cm | M18: m
F19: 22 | G19: =+$C$10/F19 -> 15.909091 | I19: Longitud Vacio Huella | K19: =+J7 -> 25 | L19: =+K19*$K$15+$K$16 -> 250 | M19: =+L19/100 -> 2.5 | O19: 1
F20: 23 | G20: =+$C$10/F20 -> 15.217391
F21: 24 | G21: =+$C$10/F21 -> 14.583333
F22: 25 | G22: =+$C$10/F22 -> 14
F23: 26 | G23: =+$C$10/F23 -> 13.461538
F24: 27 | G24: =+$C$10/F24 -> 12.962963
F25: 28 | G25: =+$C$10/F25 -> 12.5
F26: 29 | G26: =+$C$10/F26 -> 12.068966
F27: 30 | G27: =+$C$10/F27 -> 11.666667
F28: 31 | G28: =+$C$10/F28 -> 11.290323
F29: 32 | G29: =+$C$10/F29 -> 10.9375
F30: 33 | G30: =+$C$10/F30 -> 10.606061
F31: 34 | G31: =+$C$10/F31 -> 10.294118
B33: ANALISIS DE CARGAS ESCALERA
B36: #VALUE! | G36: m | I36: Tramo Inclinado | L36: Tramo del descanso
F37: Alt. Escalera | G37: 3 | I37: Tipo | J37: Carga KN/m2 | L37: Tipo | M37: Carga KN/m2 | P37: CM | Q37: CV
F38: Long. Escalera | G38: =M19 -> 2.5 | I38: PP Losa | J38: =+(G43*G42)/COS(RADIANS(G41)) -> 4.2426407 | L38: PP Losa | M38: =+G43*G42 -> 3 | O38: 1
F39: h Ch | G39: =+J6/100 -> 0.25 | I39: PP Escalon | J39: =+(G43*(G40*G39))/(2*G40) -> 3 | L39: Acabado | M39: =0.02*20 -> 0.4 | O39: 2 5
F40: b Huella | G40: =+J7/100 -> 0.25 | I40: Acabado | J40: =0.02*20 -> 0.4 | L40: Piso Madera | M40: 0.8
F41: α | G41: =DEGREES(ATAN(G39/G40)) -> 45 | I41: Piso Madera | J41: =+(0.8*(G40+G39))/G40 -> 1.6 | L41: ∑ Carga Muerta | M41: =+SUM(M38:M40) -> 4.2
F42: t losa | G42: =+G38/20 -> 0.125 | I42: ∑ Carga Muerta | J42: =+SUM(J38:J41) -> 9.2426407 | L42: ∑ Carga Viva | M42: =3 -> 3
F43: Concreto (Kn/m3) | G43: 24 | I43: ∑ Carga Viva | J43: =3 -> 3
M44: =+M41+M42 -> 7.2
J45: =+J42+J43 -> 12.242641
L46: =+J42+M41 -> 13.442641
B50: DIAGRAMA CARGAS TRAMO INCLINADO Y TRAMO DE DESCANSO
...

Sheet COLUMNAS
C1: DIMENSIONES
B2: COLUMNAS | C2: dx | D2: dy | E2: ÁREA (m2)
B3: C1 | C3: 0.35 | D3: 0.3 | E3: =C3*D3 -> 0.105
B4: C2 | C4: 0.5 | D4: 0.45 | E4: =C4*D4 -> 0.225
B5: C3 | C5: 0.55 | D5: 0.5 | E5: =C5*D5 -> 0.275
B6: C4 | C6: 0.45 | D6: 0.4 | E6: =C6*D6 -> 0.18

Sheet Pesos
E2: Carga Muerta Entrepiso kN | F2: Carga Viva kN | G2: Peso columnas kN | H2: Peso Vigas kN | I2: Carga Fachada kN | J2: kN
D3: Piso 1 | E3: =O3*Avaluo!N17 -> 4120.6415 | F3: =O3*Avaluo!$N$36 -> 1053.6246 | G3: =E18 -> 453.6 | H3: =G18+I18 -> 1235.2896 | I3: =105.21/2*Avaluo!N47 -> 394.5375 | J3: =SUM(E3:I3) -> 7257.6932 | O3: 585.347
D4: Piso 2-4 | E4: =O4*Avaluo!N17 -> 3757.0644 | F4: =O4*Avaluo!$N$36+O3*Avaluo!N43 -> 3887.395 | G4: =E38 -> 388.8 | H4: =G38+I38 -> 1136.2176 | I4: =115.95/2*Avaluo!N47 -> 434.8125 | J4: =SUM(E4:I4) -> 9604.2895 | O4: 533.7
D5: Cubierta | E5: =O5*Avaluo!N28 -> 2335.0763 | F5: =O5*Avaluo!N39 -> 2668.5 | J5: =SUM(E5:I5) -> 5003.5763 | O5: 533.7
D6: Total edificio | H6: =SUM(J3+J4*3+J5) -> 41074.138
D10: Piso 1 | K10: Carga por viento
B11: Entrepiso | D11: Columnas | F11: Vigas de carga | H11: Vigas de Rigidez | K11: Ciudad | L11: Santa Marta
B12: 3.5 | K12: Exposicion | L12: C
K13: Kzt | L13: 1
D14: base | E14: 0.3 | F14: base | G14: 0.4 | H14: base | I14: 0.4 | K14: Kd | L14: 0.85
D15: altura | E15: 0.3 | F15: altura | G15: 0.4 | H15: altura | I15: 0.4 | K15: I | L15: 1
D16: Cantidad | E16: 60 | F16: Cantidad | G16: 44 | H16: Cantidad | I16: 54 | K16: V | L16: 50
D17: longitud | E17: =E16*B12 -> 210 | F17: longitud | G17: ='[1]Avaluo de cargas piso 1'!C48 -> 164.88 | H17: longitud | I17: ='[1]Vigas rigidez'!C56 -> 156.81 | K17: h | L17: 15.5
D18: Peso kN | E18: =E14*E15*E17*24 -> 453.6 | F18: Peso kN | G18: =G14*G15*G17*24 -> 633.1392 | H18: Peso kN | I18: =I14*I15*I17*24 -> 602.1504 | K18: Kz | L18: =2.01*((15.3)/(274.3))^((2)/(9.5)) -> 1.0946974
K28: Kc | L28: 1
K29: q | L29: =(1/2)*1.2*L18*L13*L28*L14*L16^2*L15 -> 1395.7392
D30: Piso 2-cubierta | K30: q (Kn/m2) | L30: 1.4
B31: Entrepiso | D31: Columnas | F31: Vigas de carga | H31: Vigas de Rigidez
B32: 3
D34: base | E34: 0.3 | F34: base | G34: 0.4 | H34: base | I34: 0.4
D35: altura | E35: 0.3 | F35: altura | G35: 0.4 | H35: altura | I35: 0.4
D36: Cantidad | E36: 60 | F36: Cantidad | G36: 40 | H36: Cantidad | I36: 52
D37: longitud | E37: =E36*B32 -> 180 | F37: longitud | G37: ='[1]Avaluo de cargas piso 2'!C44 -> 149.28 | H37: longitud | I37: ='[1]Vigas rigidez'!C56-'[1]Vigas rigidez'!C25-'[1]Vigas rigidez'!C29 -> 146.61
D38: Peso kN | E38: =E34*E35*E37*24 -> 388.8 | F38: Peso kN | G38: =G34*G35*G37*24 -> 573.2352 | H38: Peso kN | I38: =I34*I35*I37*24 -> 562.9824

Sheet Espectro
B7: Paso 1. Selección de coeficiente de aceleración y velocidad
B9: Aa | C9: 0.15
B10: Av | C10: 0.1
B12: Paso 2. Tipologia de suelo
B14: Tipo | C14: C
B16: Paso 3. Selección de coeficiente de amplificación
B18: Fa | C18: 1.2
B19: Fv | C19: 1.7
B22: Paso 4. Coeficiente de importancia
B24: I | C24: 1 | J24: Uso residencial
B26: Paso 5.1. Espectro de diseño
B28: Limite Tc (s) | C28: =0.48*((C10*C19)/(C9*C18)) -> 0.45333333
B29: Limite TL (s) | C29: =2.4*C19 -> 4.08
B32: Paso 5.2. Espectro de diseño
B34: Perido | C34: Aceleración espectral
B35: 0 | C35: =2.5*C9*C18*C24 -> 0.45
B36: =0.1*C10*C19/(C9*C18) -> 0.094444444 | C36: =C35 -> 0.45
B37: =0.48*(C10*C19)/(C9*C18) -> 0.45333333 | C37: =C36 -> 0.45 | N37: -
B38: =B37 -> 0.45333333 | C38: =1.2*($C$10*$C$19*$C$24)/B38 -> 0.45
B39: =0.13+B38 -> 0.58333333 | C39: =1.2*($C$10*$C$19*$C$24)/B39 -> 0.34971429
B40: =0.13+B39 -> 0.71333333 | C40: =1.2*($C$10*$C$19*$C$24)/B40 -> 0.28598131
B41: =0.13+B40 -> 0.84333333 | C41: =1.2*($C$10*$C$19*$C$24)/B41 -> 0.24189723
B42: =0.13+B41 -> 0.97333333 | C42: =1.2*($C$10*$C$19*$C$24)/B42 -> 0.20958904
B43: =0.13+B42 -> 1.1033333 | C43: =1.2*($C$10*$C$19*$C$24)/B43 -> 0.18489426
B44: =0.13+B43 -> 1.2333333 | C44: =1.2*($C$10*$C$19*$C$24)/B44 -> 0.16540541
B45: =0.13+B44 -> 1.3633333 | C45: =1.2*($C$10*$C$19*$C$24)/B45 -> 0.14963325
B46: =0.13+B45 -> 1.4933333 | C46: =1.2*($C$10*$C$19*$C$24)/B46 -> 0.13660714
B47: =0.13+B46 -> 1.6233333 | C47: =1.2*($C$10*$C$19*$C$24)/B47 -> 0.12566735
B48: =0.13+B47 -> 1.7533333 | C48: =1.2*($C$10*$C$19*$C$24)/B48 -> 0.11634981
B49: =0.13+B48 -> 1.8833333 | C49: =1.2*($C$10*$C$19*$C$24)/B49 -> 0.10831858
B50: =0.13+B49 -> 2.0133333 | C50: =1.2*($C$10*$C$19*$C$24)/B50 -> 0.1013245
... B61: =0.13+B60 -> 3.4433333 | C61: =1.2*($C$10*$C$19*$C$24)/B61 -> 0.059244918
B62: =2.4*C19 -> 4.08 | C62: =1.2*($C$10*$C$19*$C$24)/B62 -> 0.05
B63: =B62 -> 4.08 | C63: =1.2*($C$10*$C$19*$C$24*$B$62)/B63^2 -> 0.05
B64: =B63+0.1 -> 4.18 | C64: =1.2*($C$10*$C$19*$C$24*$B$62)/B64^2 -> 0.047636272
B65: =B64+0.1 -> 4.28 | C65: =1.2*($C$10*$C$19*$C$24*$B$62)/B65^2 -> 0.045436283
B66: =B65+0.1 -> 4.38 | C66: =1.2*($C$10*$C$19*$C$24*$B$62)/B66^2 -> 0.043385251
B67: =B66+0.1 -> 4.48 | C67: =1.2*($C$10*$C$19*$C$24*$B$62)/B67^2 -> 0.041470026
B68: =B67+0.1 -> 4.58 | C68: =1.2*($C$10*$C$19*$C$24*$B$62)/B68^2 -> 0.039678877
B69: =B68+0.1 -> 4.68 | C69: =1.2*($C$10*$C$19*$C$24*$B$62)/B69^2 -> 0.038001315
...

Sheet FHE 
B1: Parametros | I1: calculo h
B2: h | C2: =SUM(J2:J6) -> 15.5 | I2: 1 | J2: 3.5
B3: Cu | C3: =1.75-1.2*Espectro!C10*Espectro!C19 -> 1.546 | I3: 2 | J3: 3
B4: Ct | C4: 0.047 | I4: 3 | J4: 3
B5: α | C5: 0.9 | I5: 4 | J5: 3
B6: Ta (s) | C6: =C4*C2^C5 -> 0.55385539 | I6: 5 | J6: 3
B7: T (s) | C7: =C4*C2^C5 -> 0.55385539 | I7: Total | J7: =SUM(J2:J6) -> 15.5
B8: Cu*T | C8: =+C3*C7 -> 0.85626043
B9: a(m/s2) | C9: =C10*9.81 -> 3.6132897 | I9: Ly max | J9: Lx max
B10: Sa | C10: =IF(C7<=Espectro!B37,Espectro!C37,IF(C7<Espectro!B61,1.2*Espectro!C10*Espectro!C19*Espectro!C24/C7,1.2*Espectro!C10*Espectro!C19*Espectro!B62/C7^2)) -> 0.36832719 | I10: 16 | J10: 36.6
B11: Vs (KN) | C11: =+C10*C13 -> 15128.722 | I11: 5%Ly | J11: 5%Lx
B12: k | C12: =0.75+0.5*C7 -> 1.0269277 | I12: =I10*0.05 -> 0.8 | J12: =J10*0.05 -> 1.83
B13: m | C13: =D22 -> 41074.138
B15: Calculo FHE
B16: Piso | C16: h(m) | D16: m(KN) | E16: m*h^k | F16: Cvx | G16: Fx=Fy(KN) | H16: MFx | I16: MFy | J16: Xcm | K16: Ycm
B17: 1 | C17: =J2 -> 3.5 | D17: =Pesos!J3 -> 7257.6932 | E17: =D17*C17^$C$12 -> 26273.453 | F17: =E17/$E$22 -> 0.065541035 | G17: =F17*$C$11 -> 991.55209 | H17: =G17*$I$12 -> 793.24167 | I17: =G17*$J$12 -> 1814.5403 | J17: =16/2 -> 8 | K17: =36.6/2 -> 18.3
B18: 2 | C18: =J3+J2 -> 6.5 | D18: =Pesos!$J$4 -> 9604.2895 | E18: =D18*C18^$C$12 -> 65655.102 | F18: =E18/$E$22 -> 0.16378142 | G18: =F18*$C$11 -> 2477.8035 | H18: =G18*$I$12 -> 1982.2428 | I18: =G18*$J$12 -> 4534.3804 | J18: =16/2 -> 8 | K18: =36.6/2 -> 18.3
B19: 3 | C19: =J4+J3+J2 -> 9.5 | D19: =Pesos!$J$4 -> 9604.2895 | E19: =D19*C19^$C$12 -> 96943.053 | F19: =E19/$E$22 -> 0.24183148 | G19: =F19*$C$11 -> 3658.6012 | H19: =G19*$I$12 -> 2926.881 | I19: =G19*$J$12 -> 6695.2402 | J19: =16/2 -> 8 | K19: =36.6/2 -> 18.3
B20: 4 | C20: =J5+J4+J3+J2 -> 12.5 | D20: =Pesos!$J$4 -> 9604.2895 | E20: =D20*C20^$C$12 -> 128502.78 | F20: =E20/$E$22 -> 0.3205595 | G20: =F20*$C$11 -> 4849.6556 | H20: =G20*$I$12 -> 3879.7245 | I20: =G20*$J$12 -> 8874.8697 | J20: =16/2 -> 8 | K20: =36.6/2 -> 18.3
B21: 5 | C21: =J6+J5+J4+J3+J2 -> 15.5 | D21: =Pesos!J5 -> 5003.5763 | E21: =D21*C21^$C$12 -> 83495.892 | F21: =E21/$E$22 -> 0.20828656 | G21: =F21*$C$11 -> 3151.1095 | H21: =G21*$I$12 -> 2520.8876 | I21: =G21*$J$12 -> 5766.5304 | J21: =16/2 -> 8 | K21: =36.6/2 -> 18.3
B22: SUMA | C22: =J7 -> 15.5 | D22: =SUM(D17:D21) -> 41074.138 | E22: =SUM(E17:E21) -> 400870.28 | F22: =SUM(F17:F21) -> 1 | G22: =SUM(G17:G21) -> 15128.722 | H22: =SUM(H17:H21) -> 12102.978 | I22: =SUM(I17:I21) -> 27685.561

Sheet FHE  (2)
B1: Parametros | I1: calculo h
B2: h | C2: =SUM(J2:J6) -> 15.5 | I2: 1 | J2: 3.5
B3: Cu | C3: =1.75-1.2*Espectro!C10*Espectro!C19 -> 1.546 | I3: 2 | J3: 3
B4: Ct | C4: 0.047 | I4: 3 | J4: 3
B5: α | C5: 0.9 | I5: 4 | J5: 3
B6: Ta (s) | C6: =C4*C2^C5 -> 0.55385539 | I6: 5 | J6: 3
B7: T (s) | C7: 0.40591 | I7: Total | J7: =SUM(J2:J6) -> 15.5
B8: Cu*T | C8: =+C3*C7 -> 0.62753686
B9: a(m/s2) | C9: =C10*9.81 -> 4.4145 | I9: Ly max | J9: Lx max
B10: Sa | C10: =IF(C7<=Espectro!B37,Espectro!C37,IF(C7<Espectro!B61,1.2*Espectro!C10*Espectro!C19*Espectro!C24/C7,1.2*Espectro!C10*Espectro!C19*Espectro!B62/C7^2)) -> 0.45 | I10: 16 | J10: 36.6
B11: Vs (KN) | C11: =+C10*C13 -> 18483.362 | I11: 5%Ly | J11: 5%Lx
B12: k | C12: =0.75+0.5*C7 -> 0.952955 | I12: =I10*0.05 -> 0.8 | J12: =J10*0.05 -> 1.83
B13: m | C13: =D22 -> 41074.138
B15: Calculo FHE
B16: Piso | C16: h(m) | D16: m(KN) | E16: m*h^k | F16: Cvx | G16: Fx=Fy(KN) | H16: MFx | I16: MFy | J16: Xcm | K16: Ycm
B17: 1 | C17: =J2 -> 3.5 | D17: =Pesos!J3 -> 7257.6932 | E17: =D17*C17^$C$12 -> 23948.095 | F17: =E17/$E$22 -> 0.07086039 | G17: =F17*$C$11 -> 1309.7382 | H17: =G17*$I$12 -> 1047.7906 | I17: =G17*$J$12 -> 2396.821 | J17: =16/2 -> 8 | K17: =36.6/2 -> 18.3
B18: 2 | C18: =J3+J2 -> 6.5 | D18: =Pesos!$J$4 -> 9604.2895 | E18: =D18*C18^$C$12 -> 57165.643 | F18: =E18/$E$22 -> 0.16914831 | G18: =F18*$C$11 -> 3126.4294 | H18: =G18*$I$12 -> 2501.1435 | I18: =G18*$J$12 -> 5721.3659 | J18: =16/2 -> 8 | K18: =36.6/2 -> 18.3
B19: 3 | C19: =J4+J3+J2 -> 9.5 | D19: =Pesos!$J$4 -> 9604.2895 | E19: =D19*C19^$C$12 -> 82071.4 | F19: =E19/$E$22 -> 0.24284234 | G19: =F19*$C$11 -> 4488.5429 | H19: =G19*$I$12 -> 3590.8343 | I19: =G19*$J$12 -> 8214.0335 | J19: =16/2 -> 8 | K19: =36.6/2 -> 18.3
B20: 4 | C20: =J5+J4+J3+J2 -> 12.5 | D20: =Pesos!$J$4 -> 9604.2895 | E20: =D20*C20^$C$12 -> 106603.42 | F20: =E20/$E$22 -> 0.31543051 | G20: =F20*$C$11 -> 5830.2163 | H20: =G20*$I$12 -> 4664.173 | I20: =G20*$J$12 -> 10669.296 | J20: =16/2 -> 8 | K20: =36.6/2 -> 18.3
B21: 5 | C21: =J6+J5+J4+J3+J2 -> 15.5 | D21: =Pesos!J5 -> 5003.5763 | E21: =D21*C21^$C$12 -> 68173.104 | F21: =E21/$E$22 -> 0.20171846 | G21: =F21*$C$11 -> 3728.4353 | H21: =G21*$I$12 -> 2982.7482 | I21: =G21*$J$12 -> 6823.0365 | J21: =16/2 -> 8 | K21: =36.6/2 -> 18.3
B22: SUMA | C22: =J7 -> 15.5 | D22: =SUM(D17:D21) -> 41074.138 | E22: =SUM(E17:E21) -> 337961.66 | F22: =SUM(F17:F21) -> 1 | G22: =SUM(G17:G21) -> 18483.362 | H22: =SUM(H17:H21) -> 14786.69 | I22: =SUM(I17:I21) -> 33824.553

Sheet Derivas
A1: TABLE: Joint Displacements
A2: Joint | B2: OutputCase | C2: CaseType | D2: U1 | E2: U2 | F2: Dx | G2: Dy
A3: Text | B3: Text | C3: Text | D3: m | E3: m | H3: |DxFx|+|DxM| | I3: |DyFy|+|DyM|
A4: 61 | B4: Fx | C4: LinStatic | D4: 0.020357 | E4: -0.000187 | F4: =D4 -> 0.020357 | G4: =E4 -> -0.000187 | H4: =ABS(F4)+ABS(F19) -> 0.02211 | I4: =ABS(G4)+ABS(G19) -> 0.000938
A5: 187 | B5: Fx | C5: LinStatic | D5: 0.04685 | E5: -0.000416 | F5: =D5-D4 -> 0.026493 | G5: =E5-E4 -> -0.000229 | H5: =ABS(F5)+ABS(F20) -> 0.028631 | I5: =ABS(G5)+ABS(G20) -> 0.001144 | L5: D+Sx | M5: Dx | N5: Dy | O5: D | P5: Dperm | S5: D+Sy | T5: Dx | U5: Dy | V5: D | W5: Dperm
A6: 551 | B6: Fx | C6: LinStatic | D6: 0.070889 | E6: -0.000618 | F6: =D6-D5 -> 0.024039 | G6: =E6-E5 -> -0.000202 | H6: =ABS(F6)+ABS(F21) -> 0.025927 | I6: =ABS(G6)+ABS(G21) -> 0.00101 | J6: Sx | L6: N1 | M6: =F14+H4 -> 0.022110261 | N6: =G14+I4 -> 0.0009385578 | O6: =SQRT(SUMSQ(M6:N6)) -> 0.022130172 | P6: =1/100*3 -> 0.03 | Q6: =IF(O6>P6,"X","Ok") -> Ok | S6: N1 | T6: =+F14+H9 -> 0.0045582605 | U6: =+G14+I9 -> 0.019662558 | V6: =SQRT(SUMSQ(T6:U6)) -> 0.020184002 | W6: =1/100*3 -> 0.03 | X6: =IF(V6>W6,"X","Ok") -> Ok
A7: 612 | B7: Fx | C7: LinStatic | D7: 0.088551 | E7: -0.000763 | F7: =D7-D6 -> 0.017662 | G7: =E7-E6 -> -0.000145 | H7: =ABS(F7)+ABS(F22) -> 0.019015 | I7: =ABS(G7)+ABS(G22) -> 0.000725 | L7: N2 | M7: =F15+H5 -> 0.028631199 | N7: =G15+I5 -> 0.0011472552 | O7: =SQRT(SUMSQ(M7:N7)) -> 0.028654175 | P7: =1/100*3 -> 0.03 | Q7: =IF(O7>P7,"X","Ok") -> Ok | S7: N2 | T7: =+F15+H10 -> 0.0055591992 | U7: =+G15+I10 -> 0.022045255 | V7: =SQRT(SUMSQ(T7:U7)) -> 0.02273539 | W7: =1/100*3 -> 0.03 | X7: =IF(V7>W7,"X","Ok") -> Ok
A8: 673 | B8: Fx | C8: LinStatic | D8: 0.098842 | E8: -0.000843 | F8: =D8-D7 -> 0.010291 | G8: =E8-E7 -> -8e-05 | H8: =ABS(F8)+ABS(F24) -> 0.014301 | I8: =ABS(G8)+ABS(G24) -> 0.001797 | L8: N3 | M8: =F16+H6 -> 0.025927276 | N8: =G16+I6 -> 0.00101372 | O8: =SQRT(SUMSQ(M8:N8)) -> 0.025947086 | P8: =1/100*3 -> 0.03 | Q8: =IF(O8>P8,"X","Ok") -> Ok | S8: N3 | T8: =+F16+H11 -> 0.0049082763 | U8: =+G16+I11 -> 0.01913372 | V8: =SQRT(SUMSQ(T8:U8)) -> 0.019753238 | W8: =1/100*3 -> 0.03 | X8: =IF(V8>W8,"X","Ok") -> Ok
A9: 61 | B9: Fy | C9: LinStatic | D9: -0.000548 | E9: 0.017945 | F9: =D9 -> -0.000548 | G9: =E9 -> 0.017945 | H9: =ABS(F9)+ABS(F24) -> 0.004558 | I9: =ABS(G9)+ABS(G24) -> 0.019662 | L9: N4 | M9: =F17+H7 -> 0.019015581 | N9: =G17+I7 -> 0.000727063 | O9: =SQRT(SUMSQ(M9:N9)) -> 0.019029476 | P9: =1/100*3 -> 0.03 | Q9: =IF(O9>P9,"X","Ok") -> Ok | S9: N4 | T9: =+F17+H12 -> 0.003518581 | U9: =+G17+I12 -> 0.013644063 | V9: =SQRT(SUMSQ(T9:U9)) -> 0.014090453 | W9: =1/100*3 -> 0.03 | X9: =IF(V9>W9,"X","Ok") -> Ok
A10: 187 | B10: Fy | C10: LinStatic | D10: -0.001216 | E10: 0.037893 | F10: =D10-D9 -> -0.000668 | G10: =E10-E9 -> 0.019948 | H10: =ABS(F10)+ABS(F25) -> 0.005559 | I10: =ABS(G10)+ABS(G25) -> 0.022042 | J10: Sy | L10: N5 | M10: =F18+H8 -> 0.014301529 | N10: =G18+I8 -> 0.001799404 | O10: =SQRT(SUMSQ(M10:N10)) -> 0.014414284 | P10: =1/100*3 -> 0.03 | Q10: =IF(O10>P10,"X","Ok") -> Ok | S10: N5 | T10: =+F18+H13 -> 0.001925529 | U10: =+G18+I13 -> 0.007225404 | V10: =SQRT(SUMSQ(T10:U10)) -> 0.0074775748 | W10: =1/100*3 -> 0.03 | X10: =IF(V10>W10,"X","Ok") -> Ok
A11: 551 | B11: Fy | C11: LinStatic | D11: -0.001806 | E11: 0.055174 | F11: =D11-D10 -> -0.00059 | G11: =E11-E10 -> 0.017281 | H11: =ABS(F11)+ABS(F26) -> 0.004908 | I11: =ABS(G11)+ABS(G26) -> 0.01913
A12: 612 | B12: Fy | C12: LinStatic | D12: -0.002229 | E12: 0.067491 | F12: =D12-D11 -> -0.000423 | G12: =E12-E11 -> 0.012317 | H12: =ABS(F12)+ABS(F27) -> 0.003518 | I12: =ABS(G12)+ABS(G27) -> 0.013642
A13: 673 | B13: Fy | C13: LinStatic | D13: -0.00246 | E13: 0.073988 | F13: =D13-D12 -> -0.000231 | G13: =E13-E12 -> 0.006497 | H13: =ABS(F13)+ABS(F28) -> 0.001925 | I13: =ABS(G13)+ABS(G28) -> 0.007223 | L13: D+.75L+.75Sx | M13: Dx | N13: Dy | O13: D | P13: Dperm | S13: D+.75L+.75Sy | T13: Dx | U13: Dy | V13: D | W13: Dperm
A14: 61 | B14: DTOTAL | C14: Combination | D14: 2.605e-07 | E14: 5.578e-07 | F14: =D14 -> 2.605e-07 | G14: =E14 -> 5.578e-07 | L14: N1 | M14: =D14+0.75*D29+0.75*H4 -> 0.016582775 | N14: =E14+0.75*E29+0.75*I4 -> 0.0007041403 | O14: =SQRT(SUMSQ(M14:N14)) -> 0.016597717 | P14: =1/100*3 -> 0.03 | Q14: =IF(O14>P14,"X","Ok") -> Ok | S14: N1 | T14: =D14+0.75*D29+0.75*H9 -> 0.0034187746 | U14: =E14+0.75*E29+0.75*I9 -> 0.01474714 | V14: =SQRT(SUMSQ(T14:U14)) -> 0.015138235 | W14: =1/100*3 -> 0.03 | X14: =IF(V14>W14,"X","Ok") -> Ok
A15: 187 | B15: DTOTAL | C15: Combination | D15: 4.597e-07 | E15: 3.813e-06 | F15: =D15-D14 -> 1.992e-07 | G15: =E15-E14 -> 3.2552e-06 | L15: N2 | M15: =D15+0.75*D30+0.75*H5 -> 0.021473738 | N15: =E15+0.75*E30+0.75*I5 -> 0.00086217847 | O15: =SQRT(SUMSQ(M15:N15)) -> 0.021491039 | P15: =1/100*3 -> 0.03 | Q15: =IF(O15>P15,"X","Ok") -> Ok | S15: N2 | T15: =D15+0.75*D30+0.75*H10 -> 0.0041697379 | U15: =E15+0.75*E30+0.75*I10 -> 0.016535678 | V15: =SQRT(SUMSQ(T15:U15)) -> 0.01705331 | W15: =1/100*3 -> 0.03 | X15: =IF(V15>W15,"X","Ok") -> Ok
A16: 551 | B16: DTOTAL | C16: Combination | D16: 7.36e-07 | E16: 7.533e-06 | F16: =D16-D15 -> 2.763e-07 | G16: =E16-E15 -> 3.72e-06 | L16: N3 | M16: =D16+0.75*D31+0.75*H6 -> 0.019446035 | N16: =E16+0.75*E31+0.75*I6 -> 0.00076576598 | O16: =SQRT(SUMSQ(M16:N16)) -> 0.019461107 | P16: =1/100*3 -> 0.03 | Q16: =IF(O16>P16,"X","Ok") -> Ok | S16: N3 | T16: =D16+0.75*D31+0.75*H11 -> 0.0036817855 | U16: =E16+0.75*E31+0.75*I11 -> 0.014355766 | V16: =SQRT(SUMSQ(T16:U16)) -> 0.014820377 | W16: =1/100*3 -> 0.03 | X16: =IF(V16>W16,"X","Ok") -> Ok
A17: 612 | B17: DTOTAL | C17: Combination | D17: 1.317e-06 | E17: 9.596e-06 | F17: =D17-D16 -> 5.81e-07 | G17: =E17-E16 -> 2.063e-06 | L17: N4 | M17: =D17+0.75*D32+0.75*H7 -> 0.014262658 | N17: =E17+0.75*E32+0.75*I7 -> 0.00055442225 | O17: =SQRT(SUMSQ(M17:N17)) -> 0.01427343 | P17: =1/100*3 -> 0.03 | Q17: =IF(O17>P17,"X","Ok") -> Ok | S17: N4 | T17: =D17+0.75*D32+0.75*H12 -> 0.002639908 | U17: =E17+0.75*E32+0.75*I12 -> 0.010242172 | V17: =SQRT(SUMSQ(T17:U17)) -> 0.010576919 | W17: =1/100*3 -> 0.03 | X17: =IF(V17>W17,"X","Ok") -> Ok
A18: 673 | B18: DTOTAL | C18: Combination | D18: 1.846e-06 | E18: 1.2e-05 | F18: =D18-D17 -> 5.29e-07 | G18: =E18-E17 -> 2.404e-06 | L18: N5 | M18: =D18+0.75*D33+0.75*H8 -> 0.010727745 | N18: =E18+0.75*E33+0.75*I8 -> 0.0013612418 | O18: =SQRT(SUMSQ(M18:N18)) -> 0.010813764 | P18: =1/100*3 -> 0.03 | Q18: =IF(O18>P18,"X","Ok") -> Ok | S18: N5 | T18: =D18+0.75*D33+0.75*H13 -> 0.0014457453 | U18: =E18+0.75*E33+0.75*I13 -> 0.0054307418 | V18: =SQRT(SUMSQ(T18:U18)) -> 0.0056198875 | W18: =1/100*3 -> 0.03 | X18: =IF(V18>W18,"X","Ok") -> Ok
A19: 61 | B19: MFx | C19: LinStatic | D19: -0.001753 | E19: 0.000751 | F19: =D19 -> -0.001753 | G19: =E19 -> 0.000751
A20: 187 | B20: MFx | C20: LinStatic | D20: -0.003891 | E20: 0.001666 | F20: =D20-D19 -> -0.002138 | G20: =E20-E19 -> 0.000915
A21: 551 | B21: MFx | C21: LinStatic | D21: -0.005779 | E21: 0.002474 | F21: =D21-D20 -> -0.001888 | G21: =E21-E20 -> 0.000808
A22: 612 | B22: MFx | C22: LinStatic | D22: -0.007132 | E22: 0.003054 | F22: =D22-D21 -> -0.001353 | G22: =E22-E21 -> 0.00058
A23: 673 | B23: MFx | C23: LinStatic | D23: -0.007872 | E23: 0.003371 | F23: =D23-D22 -> -0.00074 | G23: =E23-E22 -> 0.000317
A24: 61 | B24: MFy | C24: LinStatic | D24: -0.00401 | E24: 0.001717 | F24: =D24 -> -0.00401 | G24: =E24 -> 0.001717
A25: 187 | B25: MFy | C25: LinStatic | D25: -0.008901 | E25: 0.003811 | F25: =D25-D24 -> -0.004891 | G25: =E25-E24 -> 0.002094
A26: 551 | B26: MFy | C26: LinStatic | D26: -0.013219 | E26: 0.00566 | F26: =D26-D25 -> -0.004318 | G26: =E26-E25 -> 0.001849
A27: 612 | B27: MFy | C27: LinStatic | D27: -0.016314 | E27: 0.006985 | F27: =D27-D26 -> -0.003095 | G27: =E27-E26 -> 0.001325
A28: 673 | B28: MFy | C28: LinStatic | D28: -0.018008 | E28: 0.007711 | F28: =D28-D27 -> -0.001694 | G28: =E28-E27 -> 0.000726
A29: 61 | B29: LTOTAL | C29: Combination | D29: 1.875e-08 | E29: 1.1e-07 | F29: =D29 -> 1.875e-08 | G29: =E29 -> 1.1e-07
A30: 187 | B30: LTOTAL | C30: Combination | D30: 3.76e-08 | E30: 4.873e-07 | F30: =D30-D29 -> 1.885e-08 | G30: =E30-E29 -> 3.773e-07
A31: 551 | B31: LTOTAL | C31: Combination | D31: 6.597e-08 | E31: 9.773e-07 | F31: =D31-D30 -> 2.837e-08 | G31: =E31-E30 -> 4.9e-07
A32: 612 | B32: LTOTAL | C32: Combination | D32: 1.214e-07 | E32: 1.435e-06 | F32: =D32-D31 -> 5.543e-08 | G32: =E32-E31 -> 4.577e-07
A33: 673 | B33: LTOTAL | C33: Combination | D33: 1.991e-07 | E33: 1.989e-06 | F33: =D33-D32 -> 7.77e-08 | G33: =E33-E32 -> 5.54e-07
A57: Irregularidad del diafragma
A58: A | B58: 36.6
A59: B | B59: 15.99
A60: C | B60: 5.1
A61: D | B61: 2.65
A62: E | B62: 2.65
A65: (c*d+c*e) | B65: =+B60*B61+B60*B62 -> 27.03
...

Sheet Irreg. Torsional
A1: VERIFICACIÓN DE IRREGULARIDAD TORSIONAL EN PLANTA (NSR-10 A.3.6.7 — Tipo 1aP/1bP)
A3: Criterio: razón = δmax / δprom , con δprom = (δmax + δmin)/2 entre los dos bordes del diafragma.
A4: Regular si razón ≤ 1.20 | Torsional 1aP (φp=0.9) si 1.20 < razón ≤ 1.40 | Extrema 1bP (φp=0.8) si > 1.40
A5: Desplazamientos de SAP2000 (Joint Displacements), TODOS los nudos de cada diafragma. U1 para Fx, U2 para Fy.
A7: SISMO EN X (Fx)
A8: Piso Z (m) | B8: N° nudos | C8: δmax (mm) | D8: δmin (mm) | E8: δprom (mm) | F8: razón | G8: Estado
A9: 3.5 | B9: 183 | C9: 24.099 | D9: 22.986 | E9: 23.543 | F9: 1.024 | G9: Regular
A10: 6.5 | B10: 183 | C10: 54.676 | D10: 52.244 | E10: 53.46 | F10: 1.023 | G10: Regular
A11: 9.5 | B11: 183 | C11: 81.98 | D11: 78.404 | E11: 80.192 | F11: 1.022 | G11: Regular
A12: 12.5 | B12: 183 | C12: 101.698 | D12: 97.317 | E12: 99.507 | F12: 1.022 | G12: Regular
A13: 15.5 | B13: 183 | C13: 112.878 | D13: 108.069 | E13: 110.474 | F13: 1.022 | G13: Regular
A15: SISMO EN Y (Fy)
A16: Piso Z (m) | B16: N° nudos | C16: δmax (mm) | D16: δmin (mm) | E16: δprom (mm) | F16: razón | G16: Estado
A17: 3.5 | B17: 183 | C17: 20.97 | D17: 20.419 | E17: 20.694 | F17: 1.013 | G17: Regular
A18: 6.5 | B18: 183 | C18: 43.378 | D18: 42.175 | E18: 42.776 | F18: 1.014 | G18: Regular
A19: 9.5 | B19: 183 | C19: 62.5 | D19: 60.732 | E19: 61.616 | F19: 1.014 | G19: Regular
A20: 12.5 | B20: 183 | C20: 75.919 | D20: 73.753 | E20: 74.836 | F20: 1.014 | G20: Regular
A21: 15.5 | B21: 183 | C21: 82.785 | D21: 80.409 | E21: 81.597 | F21: 1.015 | G21: Regular
A23: RAZÓN MÁXIMA = 1.024 < 1.20 → NO HAY IRREGULARIDAD TORSIONAL → φp = 1.0
A25: Con planta, altura y redundancia regulares: R = R0·φa·φp·φr = 5·1·1·1 = 5.0

Sheet Viguetas C.8.3.3
A1: DISEÑO DE VIGUETAS — Momentos por coeficientes NSR-10 C.8.3.3 (según tipo de apoyo)
A3: Losa aligerada en una dirección. Nervio 0.15 x 0.34 m + loseta 0.06 m. Sep. 0.80 m. d=304 mm. As_min=152 mm². 2 Nº4 = 258 mm².
A5: Código de apoyo | B5: Condición | C5: M+ (positivo) | D5: M- (negativo)
A6: 1EC | B6: Vano extremo (un extremo continuo) | C6: wu·ln²/14 | D6: 1er apoyo interior: wu·ln²/10
A7: 2EC | B7: Vano interior (dos extremos continuos) | C7: wu·ln²/16 | D7: en apoyos: wu·ln²/11
A8: (ext.) | B8: Apoyo exterior monolítico con viga | C8: — | D8: wu·ln²/24
A9: V | B9: Voladizo | C9: — | D9: wu·L²/2
A11: Verificación de los casos gobernantes (wu entrepiso=9.06 kN/m; cubierta terraza=10.6 kN/m):
A12: Caso gobernante | B12: ln (m) | C12: wu (kN/m) | D12: M- (kN·m) | E12: M+ (kN·m) | F12: As req (mm²) | G12: Refuerzo
A13: Entrepiso, vano extremo 1EC | B13: 4.75 | C13: 9.06 | D13: 20.4 | E13: 14.6 | F13: 185 | G13: 2 Nº4
A14: Cubierta, vano 1EC (terraza L=5) | B14: 4.75 | C14: 10.6 | D14: 23.9 | E14: 17.1 | F14: 217 | G14: 2 Nº4
A15: Voladizo V 1.5 m | B15: 1.27 | C15: 9.06 | D15: 10.2 | E15: — | F15: 152 | G15: 2 Nº4
A17: CONCLUSIÓN: aun con el coeficiente más exigente de cada apoyo, As req (máx 217 mm²) < 2 Nº4 (258) → gobierna acero mínimo.
A18: Cortante: Vu,máx = 29.3 kN < φ·(1.1·Vc) → no se requieren estribos (C.8.3.3 permite incrementar Vc 10% en viguetas).
