Workbook

Sheet Inicio
A1: MI SISTEMA DE VIDA - TABLERO MAESTRO
A2: Todo en un archivo. Llena cada pestana y este tablero se actualiza solo.
A4: ACADEMICO
A5: PAPA del semestre | B5: ='Resumen Semestre'!C10
A6: Materias en riesgo | B6: ='Resumen Semestre'!B12
A7: Entregas esta semana | B7: =Entregas!C29
A8: Entregas este mes | B8: =Entregas!C30
A10: FINANZAS
A11: Ingresos del mes | B11: =Ingresos!D23
A12: Egresos del mes | B12: =Egresos!D28
A13: Balance del mes | B13: =Ingresos!D23-Egresos!D28
A14: Deuda total | B14: =Deudas!C15
A16: FUTURO
A17: Avance plan pasantia | B17: ='Pasantia - Plan'!C16
A18: Aplicaciones enviadas | B18: ='Pasantia - Aplicaciones'!I3
A19: Cursos terminados | B19: ='Cursos CV'!E14
A20: Libros leidos | B20: =Libros!D14
A22: Revisa este tablero cada domingo en tu planeacion semanal.

Sheet Horario
A1: MI HORARIO SEMANAL
A2: Hora | B2: Lunes | C2: Martes | D2: Miercoles | E2: Jueves | F2: Viernes | G2: Sabado | H2: Domingo
A3: 06:00 | B3: Ingles (virtual) | C3: Ingles (virtual) | D3: Ingles (virtual) | E3: Ingles (virtual) | F3: Ingles (virtual)
A4: 06:30
A5: 07:00
A6: 07:30
A7: 08:00 | B7: Gimnasio (fuerza) | C7: Viaje a la U | D7: Viaje a la U | E7: Viaje a la U | F7: Viaje a la U | G7: Gimnasio (fuerza)
A8: 08:30
A9: 09:00 | C9: Clase OBLIGATORIA | D9: Clase OBLIGATORIA | E9: Clase OBLIGATORIA | F9: Clase OBLIGATORIA
A10: 09:30
A11: 10:00 | B11: PROYECTO estructural | G11: PROYECTO (bloque largo) | H11: Descanso / recargar
A12: 10:30
A13: 11:00 | C13: Estudio / pasantia | D13: Repaso / tareas | E13: Estudio / pasantia
A14: 11:30
A15: 12:00
A16: 12:30 | C16: Almuerzo con novia | D16: Almuerzo con novia | E16: Almuerzo con novia | F16: Almuerzo con novia
A17: 13:00 | B17: Lectura 30 min
A18: 13:30 | C18: PROYECTO estructural | E18: PROYECTO estructural
A19: 14:00 | B19: PROYECTO / estudio | D19: ESTRUCTURAL - NO FALTAR | F19: ESTRUCTURAL - NO FALTAR | G19: Tiempo con novia / social
A20: 14:30
A21: 15:00
A22: 15:30
A23: 16:00 | D23: Estudio / dudas profe
A24: 16:30 | B24: Psicologia
A25: 17:00 | H25: Revision y planeacion semanal
A26: 17:30 | C26: Recoger a novia | D26: Recoger a novia | E26: Recoger a novia | F26: Recoger a novia
A27: 18:00 | B27: Clase opcional
A28: 18:30
A29: 19:00 | F29: Tiempo de calidad con novia
A30: 19:30 | C30: Box | E30: Box
A31: 20:00 | G31: Lectura 30 min
A32: 20:30

Sheet Habitos
A1: TRACKER SEMANAL DE HABITOS
A2: Habito | B2: L | C2: M | D2: X | E2: J | F2: V | G2: S | H2: D
A3: Dormir 7-8h
A4: Ingles
A5: Proyecto estructural
A6: Gym / Box
A7: Lectura 30 min
A8: Tiempo c/ novia
A9: Agua + comer bien

Sheet Resumen Semestre
A1: RESUMEN DEL SEMESTRE (9o) - Aprueba 3.0
A3: Materia | B3: Creditos | C3: Nota Definitiva | D3: Aporte | E3: Estado | F3: Prioridad | G3: Falta %
A4: Diseno Estructural | B4: 3 | C4: ='Calculadora Notas'!D14 | D4: =B4*C4 | E4: =IF(C4="","-",IF(C4>=3.0,"Aprobada","EN RIESGO")) | F4: =IF(C4="","-",IF(C4<3.0,"ALTA",IF(C4<3.5,"MEDIA","OK"))) | G4: ='Calculadora Notas'!D16
A5: Uitoto | B5: 3 | C5: ='Calculadora Notas'!D30 | D5: =B5*C5 | E5: =IF(C5="","-",IF(C5>=3.0,"Aprobada","EN RIESGO")) | F5: =IF(C5="","-",IF(C5<3.0,"ALTA",IF(C5<3.5,"MEDIA","OK"))) | G5: ='Calculadora Notas'!D32
A6: PEPI | B6: 3 | C6: ='Calculadora Notas'!D46 | D6: =B6*C6 | E6: =IF(C6="","-",IF(C6>=3.0,"Aprobada","EN RIESGO")) | F6: =IF(C6="","-",IF(C6<3.0,"ALTA",IF(C6<3.5,"MEDIA","OK"))) | G6: ='Calculadora Notas'!D48
A7: Saneamiento Ambiental | B7: 3 | C7: ='Calculadora Notas'!D62 | D7: =B7*C7 | E7: =IF(C7="","-",IF(C7>=3.0,"Aprobada","EN RIESGO")) | F7: =IF(C7="","-",IF(C7<3.0,"ALTA",IF(C7<3.5,"MEDIA","OK"))) | G7: ='Calculadora Notas'!D64
A8: Alcantarillados | B8: 3 | C8: ='Calculadora Notas'!D78 | D8: =B8*C8 | E8: =IF(C8="","-",IF(C8>=3.0,"Aprobada","EN RIESGO")) | F8: =IF(C8="","-",IF(C8<3.0,"ALTA",IF(C8<3.5,"MEDIA","OK"))) | G8: ='Calculadora Notas'!D80
A9: Fundamentos de Construccion | B9: 3 | C9: ='Calculadora Notas'!D94 | D9: =B9*C9 | E9: =IF(C9="","-",IF(C9>=3.0,"Aprobada","EN RIESGO")) | F9: =IF(C9="","-",IF(C9<3.0,"ALTA",IF(C9<3.5,"MEDIA","OK"))) | G9: ='Calculadora Notas'!D96
A10: PAPA SEMESTRE | B10: =SUM(B4:B9) | C10: =IFERROR(ROUND(SUMPRODUCT(B4:B9,C4:C9)/SUM(B4:B9),2),0)
A12: Materias EN RIESGO: | B12: =COUNTIF(E4:E9,"EN RIESGO")

Sheet Calculadora Notas
A1: CALCULADORA POR MATERIA (pon % y nota 0-5)
A3: MATERIA: Diseno Estructural
A4: Evaluacion | B4: % (peso) | C4: Nota (0-5) | D4: Aporte
A5: Parcial 1 | B5: 20 | D5: =IFERROR(B5*C5/100,0)
A6: Parcial 2 | B6: 20 | D6: =IFERROR(B6*C6/100,0)
A7: Parcial 3 | B7: 20 | D7: =IFERROR(B7*C7/100,0)
A8: Primera entrega proyecto | B8: 10 | D8: =IFERROR(B8*C8/100,0)
A9: Entrega final proyecto | B9: 30 | D9: =IFERROR(B9*C9/100,0)
A10: Eval 6 | D10: =IFERROR(B10*C10/100,0)
A11: Eval 7 | D11: =IFERROR(B11*C11/100,0)
A12: Suma % (debe dar 100) | B12: =SUM(B5:B11) | C12: =IF(B12=100,"OK","REVISAR")
A13: Nota acumulada | D13: =ROUND(SUM(D5:D11),2)
A14: NOTA DEFINITIVA | D14: =ROUND(SUM(D5:D11),2)
A15: % ya cursado | D15: =SUMIF(C5:C11,">0",B5:B11)
A16: % que falta | D16: =100-D15
A17: Nota que necesito (en lo que falta) para pasar 3.0 | D17: =IFERROR(IF(D16=0,"-",ROUND((3.0-D13)/(D16/100),2)),"-")
A19: MATERIA: Uitoto
A20: Evaluacion | B20: % (peso) | C20: Nota (0-5) | D20: Aporte
A21: Mito | B21: 30 | D21: =IFERROR(B21*C21/100,0)
A22: Talleres grupales | B22: 30 | D22: =IFERROR(B22*C22/100,0)
A23: Propuesta final | B23: 40 | D23: =IFERROR(B23*C23/100,0)
A24: Eval 4 | D24: =IFERROR(B24*C24/100,0)
A25: Eval 5 | D25: =IFERROR(B25*C25/100,0)
A26: Eval 6 | D26: =IFERROR(B26*C26/100,0)
A27: Eval 7 | D27: =IFERROR(B27*C27/100,0)
A28: Suma % (debe dar 100) | B28: =SUM(B21:B27) | C28: =IF(B28=100,"OK","REVISAR")
A29: Nota acumulada | D29: =ROUND(SUM(D21:D27),2)
A30: NOTA DEFINITIVA | D30: =ROUND(SUM(D21:D27),2)
A31: % ya cursado | D31: =SUMIF(C21:C27,">0",B21:B27)
A32: % que falta | D32: =100-D31
A33: Nota que necesito (en lo que falta) para pasar 3.0 | D33: =IFERROR(IF(D32=0,"-",ROUND((3.0-D29)/(D32/100),2)),"-")
A35: MATERIA: PEPI
A36: Evaluacion | B36: % (peso) | C36: Nota (0-5) | D36: Aporte
A37: Parcial 1 | B37: 20 | D37: =IFERROR(B37*C37/100,0)
A38: Talleres | B38: 40 | D38: =IFERROR(B38*C38/100,0)
A39: Quices | B39: 10 | D39: =IFERROR(B39*C39/100,0)
A40: Proyecto | B40: 30 | D40: =IFERROR(B40*C40/100,0)
A41: Eval 5 | D41: =IFERROR(B41*C41/100,0)
A42: Eval 6 | D42: =IFERROR(B42*C42/100,0)
A43: Eval 7 | D43: =IFERROR(B43*C43/100,0)
...

Sheet Entregas
A1: ENTREGAS - que debo entregar (semana / mes)
A2: Materia | B2: Entregable | C2: Tipo | D2: % nota | E2: Fecha | F2: Dias restantes | G2: Estado | H2: Alerta
A3: Diseno Estructural | B3: Parcial 1 | C3: Parcial | D3: 20 | F3: =IF(E3="","",E3-TODAY()) | G3: Pendiente | H3: =IF(G3="Entregado","Listo",IF(E3="","",IF(F3<0,"VENCIDO",IF(F3<=3,"Vence pronto",IF(F3<=7,"Esta semana","Mas adelante")))))
A4: Diseno Estructural | B4: Parcial 2 | C4: Parcial | D4: 20 | F4: =IF(E4="","",E4-TODAY()) | G4: Pendiente | H4: =IF(G4="Entregado","Listo",IF(E4="","",IF(F4<0,"VENCIDO",IF(F4<=3,"Vence pronto",IF(F4<=7,"Esta semana","Mas adelante")))))
A5: Diseno Estructural | B5: Parcial 3 | C5: Parcial | D5: 20 | F5: =IF(E5="","",E5-TODAY()) | G5: Pendiente | H5: =IF(G5="Entregado","Listo",IF(E5="","",IF(F5<0,"VENCIDO",IF(F5<=3,"Vence pronto",IF(F5<=7,"Esta semana","Mas adelante")))))
A6: Diseno Estructural | B6: Primera entrega proyecto | C6: Proyecto | D6: 10 | F6: =IF(E6="","",E6-TODAY()) | G6: Pendiente | H6: =IF(G6="Entregado","Listo",IF(E6="","",IF(F6<0,"VENCIDO",IF(F6<=3,"Vence pronto",IF(F6<=7,"Esta semana","Mas adelante")))))
A7: Diseno Estructural | B7: Entrega final proyecto | C7: Proyecto | D7: 30 | F7: =IF(E7="","",E7-TODAY()) | G7: Pendiente | H7: =IF(G7="Entregado","Listo",IF(E7="","",IF(F7<0,"VENCIDO",IF(F7<=3,"Vence pronto",IF(F7<=7,"Esta semana","Mas adelante")))))
F8: =IF(E8="","",E8-TODAY()) | H8: =IF(G8="Entregado","Listo",IF(E8="","",IF(F8<0,"VENCIDO",IF(F8<=3,"Vence pronto",IF(F8<=7,"Esta semana","Mas adelante")))))
F9: =IF(E9="","",E9-TODAY()) | H9: =IF(G9="Entregado","Listo",IF(E9="","",IF(F9<0,"VENCIDO",IF(F9<=3,"Vence pronto",IF(F9<=7,"Esta semana","Mas adelante")))))
F10: =IF(E10="","",E10-TODAY()) | H10: =IF(G10="Entregado","Listo",IF(E10="","",IF(F10<0,"VENCIDO",IF(F10<=3,"Vence pronto",IF(F10<=7,"Esta semana","Mas adelante")))))
F11: =IF(E11="","",E11-TODAY()) | H11: =IF(G11="Entregado","Listo",IF(E11="","",IF(F11<0,"VENCIDO",IF(F11<=3,"Vence pronto",IF(F11<=7,"Esta semana","Mas adelante")))))
F12: =IF(E12="","",E12-TODAY()) | H12: =IF(G12="Entregado","Listo",IF(E12="","",IF(F12<0,"VENCIDO",IF(F12<=3,"Vence pronto",IF(F12<=7,"Esta semana","Mas adelante")))))
F13: =IF(E13="","",E13-TODAY()) | H13: =IF(G13="Entregado","Listo",IF(E13="","",IF(F13<0,"VENCIDO",IF(F13<=3,"Vence pronto",IF(F13<=7,"Esta semana","Mas adelante")))))
F14: =IF(E14="","",E14-TODAY()) | H14: =IF(G14="Entregado","Listo",IF(E14="","",IF(F14<0,"VENCIDO",IF(F14<=3,"Vence pronto",IF(F14<=7,"Esta semana","Mas adelante")))))
F15: =IF(E15="","",E15-TODAY()) | H15: =IF(G15="Entregado","Listo",IF(E15="","",IF(F15<0,"VENCIDO",IF(F15<=3,"Vence pronto",IF(F15<=7,"Esta semana","Mas adelante")))))
F16: =IF(E16="","",E16-TODAY()) | H16: =IF(G16="Entregado","Listo",IF(E16="","",IF(F16<0,"VENCIDO",IF(F16<=3,"Vence pronto",IF(F16<=7,"Esta semana","Mas adelante")))))
F17: =IF(E17="","",E17-TODAY()) | H17: =IF(G17="Entregado","Listo",IF(E17="","",IF(F17<0,"VENCIDO",IF(F17<=3,"Vence pronto",IF(F17<=7,"Esta semana","Mas adelante")))))
F18: =IF(E18="","",E18-TODAY()) | H18: =IF(G18="Entregado","Listo",IF(E18="","",IF(F18<0,"VENCIDO",IF(F18<=3,"Vence pronto",IF(F18<=7,"Esta semana","Mas adelante")))))
F19: =IF(E19="","",E19-TODAY()) | H19: =IF(G19="Entregado","Listo",IF(E19="","",IF(F19<0,"VENCIDO",IF(F19<=3,"Vence pronto",IF(F19<=7,"Esta semana","Mas adelante")))))
... F27: =IF(E27="","",E27-TODAY()) | H27: =IF(G27="Entregado","Listo",IF(E27="","",IF(F27<0,"VENCIDO",IF(F27<=3,"Vence pronto",IF(F27<=7,"Esta semana","Mas adelante")))))
A29: Entregas esta semana (<=7 dias): | C29: =SUMPRODUCT((E3:E27<>"")*(E3:E27>=TODAY())*(E3:E27<=TODAY()+7)*(G3:G27<>"Entregado"))
A30: Entregas este mes (<=30 dias): | C30: =SUMPRODUCT((E3:E27<>"")*(E3:E27>=TODAY())*(E3:E27<=TODAY()+30)*(G3:G27<>"Entregado"))
A31: VENCIDAS sin entregar: | C31: =SUMPRODUCT((E3:E27<>"")*(E3:E27<TODAY())*(G3:G27<>"Entregado"))

Sheet PAPA Carrera
A1: PAPA - actual y PROYECTADO tras este semestre
A3: PAPA actual (antes de este semestre) | B3: 4.2
A4: % de avance actual | B4: 0.817
A5: Creditos totales del plan (editable) | B5: 180
A6: Creditos ya cursados (calculado) | B6: =ROUND(B4*B5,0)
A7: Promedio de ESTE semestre (de tus notas) | B7: ='Resumen Semestre'!C10
A8: Creditos de este semestre | B8: ='Resumen Semestre'!B10
A9: PAPA PROYECTADO al terminar el semestre | B9: =IFERROR(ROUND((B3*B6+B7*B8)/(B6+B8),2),0)
A10: Nuevo % de avance | B10: =IFERROR(ROUND((B6+B8)/B5,3),0)
A12: SI tu promedio del semestre es... | B12: ...tu PAPA quedaria
A13: 3 | B13: =IFERROR(ROUND((B3*B6+3.0*B8)/(B6+B8),2),0)
A14: 3.5 | B14: =IFERROR(ROUND((B3*B6+3.5*B8)/(B6+B8),2),0)
A15: 4 | B15: =IFERROR(ROUND((B3*B6+4.0*B8)/(B6+B8),2),0)
A16: 4.2 | B16: =IFERROR(ROUND((B3*B6+4.2*B8)/(B6+B8),2),0)
A17: 4.5 | B17: =IFERROR(ROUND((B3*B6+4.5*B8)/(B6+B8),2),0)
A18: 5 | B18: =IFERROR(ROUND((B3*B6+5.0*B8)/(B6+B8),2),0)
A20: Todas tus materias tienen 3 creditos -> el promedio del semestre = promedio simple de las 6 notas.
A21: Ajusta 'Creditos totales del plan' si conoces el numero exacto de tu pensum (UNAL Ing. Civil ~180).

Sheet Prioridades
A1: PRIORIDADES ACADEMICAS (automatico)
A3: Materia | B3: Nota | C3: Prioridad | D3: Que hacer
A4: ='Resumen Semestre'!A4 | B4: ='Resumen Semestre'!C4 | C4: ='Resumen Semestre'!F4 | D4: =IF(B4="","-",IF(B4<3.0,"URGENTE: bloques diarios + hablar con el profe",IF(B4<3.5,"Reforzar esta semana","Mantener, repaso ligero")))
A5: ='Resumen Semestre'!A5 | B5: ='Resumen Semestre'!C5 | C5: ='Resumen Semestre'!F5 | D5: =IF(B5="","-",IF(B5<3.0,"URGENTE: bloques diarios + hablar con el profe",IF(B5<3.5,"Reforzar esta semana","Mantener, repaso ligero")))
A6: ='Resumen Semestre'!A6 | B6: ='Resumen Semestre'!C6 | C6: ='Resumen Semestre'!F6 | D6: =IF(B6="","-",IF(B6<3.0,"URGENTE: bloques diarios + hablar con el profe",IF(B6<3.5,"Reforzar esta semana","Mantener, repaso ligero")))
A7: ='Resumen Semestre'!A7 | B7: ='Resumen Semestre'!C7 | C7: ='Resumen Semestre'!F7 | D7: =IF(B7="","-",IF(B7<3.0,"URGENTE: bloques diarios + hablar con el profe",IF(B7<3.5,"Reforzar esta semana","Mantener, repaso ligero")))
A8: ='Resumen Semestre'!A8 | B8: ='Resumen Semestre'!C8 | C8: ='Resumen Semestre'!F8 | D8: =IF(B8="","-",IF(B8<3.0,"URGENTE: bloques diarios + hablar con el profe",IF(B8<3.5,"Reforzar esta semana","Mantener, repaso ligero")))
A9: ='Resumen Semestre'!A9 | B9: ='Resumen Semestre'!C9 | C9: ='Resumen Semestre'!F9 | D9: =IF(B9="","-",IF(B9<3.0,"URGENTE: bloques diarios + hablar con el profe",IF(B9<3.5,"Reforzar esta semana","Mantener, repaso ligero")))

Sheet Ingresos
A1: INGRESOS DEL MES
A2: Fecha | B2: Concepto | C2: Categoria | D2: Monto | E2: Recurrente
B3: Mesada / apoyo familiar | C3: Familia | D3: 0 | E3: Si
B4: Trabajo / freelance | C4: Trabajo | D4: 0 | E4: No
B5: Otro | C5: Otro | D5: 0 | E5: No
C23: TOTAL INGRESOS | D23: =SUM(D3:D22)

Sheet Egresos
A1: EGRESOS DEL MES
A2: Fecha | B2: Concepto | C2: Categoria | D2: Monto | E2: Necesario?
B3: Transporte (TM/SITP) | C3: Transporte | D3: 0 | E3: Si
B4: Alimentacion | C4: Comida | D4: 0 | E4: Si
B5: Gimnasio + Box | C5: Salud | D5: 0 | E5: Si
B6: Clases de ingles | C6: Educacion | D6: 0 | E6: Si
B7: Universidad / materiales | C7: Educacion | D7: 0 | E7: Si
B8: Salidas con novia | C8: Ocio | D8: 0 | E8: No
B9: Suscripciones | C9: Ocio | D9: 0 | E9: No
C28: TOTAL EGRESOS | D28: =SUM(D3:D27)
C29: Gasto evitable (No) | D29: =SUMIF(E3:E27,"No",D3:D27)

Sheet Deudas
A1: DEUDAS Y PLAN DE PAGO
A2: Acreedor | B2: Monto total | C2: Saldo actual | D2: Tasa % mes | E2: Cuota mensual | F2: Meses restantes | G2: Prioridad
F3: =IFERROR(IF(E3=0,"-",ROUNDUP(C3/E3,0)),"-") | G3: =IF(C3="","-",IF(D3>=3,"ALTA (tasa alta)",IF(C3>0,"Normal","Pagada")))
F4: =IFERROR(IF(E4=0,"-",ROUNDUP(C4/E4,0)),"-") | G4: =IF(C4="","-",IF(D4>=3,"ALTA (tasa alta)",IF(C4>0,"Normal","Pagada")))
F5: =IFERROR(IF(E5=0,"-",ROUNDUP(C5/E5,0)),"-") | G5: =IF(C5="","-",IF(D5>=3,"ALTA (tasa alta)",IF(C5>0,"Normal","Pagada")))
F6: =IFERROR(IF(E6=0,"-",ROUNDUP(C6/E6,0)),"-") | G6: =IF(C6="","-",IF(D6>=3,"ALTA (tasa alta)",IF(C6>0,"Normal","Pagada")))
F7: =IFERROR(IF(E7=0,"-",ROUNDUP(C7/E7,0)),"-") | G7: =IF(C7="","-",IF(D7>=3,"ALTA (tasa alta)",IF(C7>0,"Normal","Pagada")))
F8: =IFERROR(IF(E8=0,"-",ROUNDUP(C8/E8,0)),"-") | G8: =IF(C8="","-",IF(D8>=3,"ALTA (tasa alta)",IF(C8>0,"Normal","Pagada")))
F9: =IFERROR(IF(E9=0,"-",ROUNDUP(C9/E9,0)),"-") | G9: =IF(C9="","-",IF(D9>=3,"ALTA (tasa alta)",IF(C9>0,"Normal","Pagada")))
F10: =IFERROR(IF(E10=0,"-",ROUNDUP(C10/E10,0)),"-") | G10: =IF(C10="","-",IF(D10>=3,"ALTA (tasa alta)",IF(C10>0,"Normal","Pagada")))
F11: =IFERROR(IF(E11=0,"-",ROUNDUP(C11/E11,0)),"-") | G11: =IF(C11="","-",IF(D11>=3,"ALTA (tasa alta)",IF(C11>0,"Normal","Pagada")))
F12: =IFERROR(IF(E12=0,"-",ROUNDUP(C12/E12,0)),"-") | G12: =IF(C12="","-",IF(D12>=3,"ALTA (tasa alta)",IF(C12>0,"Normal","Pagada")))
F13: =IFERROR(IF(E13=0,"-",ROUNDUP(C13/E13,0)),"-") | G13: =IF(C13="","-",IF(D13>=3,"ALTA (tasa alta)",IF(C13>0,"Normal","Pagada")))
F14: =IFERROR(IF(E14=0,"-",ROUNDUP(C14/E14,0)),"-") | G14: =IF(C14="","-",IF(D14>=3,"ALTA (tasa alta)",IF(C14>0,"Normal","Pagada")))
A15: DEUDA TOTAL | C15: =SUM(C3:C14)
A17: Estrategia avalancha: paga primero la deuda de MAYOR tasa. Bola de nieve: la mas pequena primero (motivacion).

Sheet Presupuesto 50-30-20
A1: PRESUPUESTO 50 / 30 / 20
A3: Ingreso mensual total | B3: =Ingresos!D23
A5: Categoria | B5: Ideal | C5: Sugerido | D5: Para que
A6: Necesidades (50%) | B6: 0.5 | C6: =$B$3*B6 | D6: Arriendo, comida, transporte, U
A7: Gustos / ocio (30%) | B7: 0.3 | C7: =$B$3*B7 | D7: Salidas, suscripciones, hobbies
A8: Ahorro + deudas (20%) | B8: 0.2 | C8: =$B$3*B8 | D8: Fondo emergencia, abonos a deuda
A10: Gasto real del mes | C10: =Egresos!D28
A11: BALANCE (ingreso - gasto) | C11: =Ingresos!D23-Egresos!D28

Sheet Pasantia - Plan
A1: PLAN DE PASANTIA - PASO A PASO
A2: Paso | B2: Que hacer | C2: Estado | D2: Fecha meta
A3: 1 | B3: Definir objetivo: area (estructuras, vias, hidraulica, construccion, interventoria) y ciudad. | C3: Pendiente
A4: 2 | B4: Actualizar hoja de vida a 1 pagina, enfocada en logros y el proyecto estructural. | C4: Pendiente
A5: 3 | B5: Optimizar LinkedIn: foto, titular claro, activar 'Open to work'. | C5: Pendiente
A6: 4 | B6: Armar lista de 25-30 empresas objetivo (constructoras, consultoras, interventoria). | C6: Pendiente
A7: 5 | B7: Conseguir contactos/referidos: profes, egresados, oficina de practicas de la U. | C7: Pendiente
A8: 6 | B8: Crear carta de presentacion base personalizable. | C8: Pendiente
A9: 7 | B9: Armar portafolio con proyectos academicos (incluye el de estructural). | C9: Pendiente
A10: 8 | B10: Aplicar minimo 5 vacantes por semana (registrar en 'Aplicaciones'). | C10: Pendiente
A11: 9 | B11: Revisar portales: LinkedIn, elempleo, Computrabajo, Magneto365, bolsa de la U. | C11: Pendiente
A12: 10 | B12: Preparar entrevista: tecnicas + comportamentales (metodo STAR). | C12: Pendiente
A13: 11 | B13: Seguimiento a cada aplicacion a los 7 dias. | C13: Pendiente
A14: 12 | B14: Al recibir oferta: revisar convenio U, ARL y afiliacion antes de firmar. | C14: Pendiente
B16: Progreso del plan | C16: =ROUND(COUNTIF(C3:C14,"Hecho")/12,2)

Sheet Pasantia - Aplicaciones
A1: RASTREADOR DE APLICACIONES
A2: Empresa | B2: Cargo | C2: Fecha | D2: Estado | E2: Contacto | F2: Proximo paso | G2: Notas | I2: Aplicadas
I3: =COUNTIF(D3:D42,"Aplicada")+COUNTIF(D3:D42,"En proceso")+COUNTIF(D3:D42,"Entrevista")+COUNTIF(D3:D42,"Oferta")
I4: Entrevistas
I5: =COUNTIF(D3:D42,"Entrevista")
I6: Ofertas
I7: =COUNTIF(D3:D42,"Oferta")

Sheet Becas
A1: BECAS PARA TU MAESTRIA (revisar fechas cada ano)
A2: Beca/Programa | B2: Pais/Region | C2: Que cubre | D2: Requisito clave | E2: Link | F2: Estado
A3: COLFUTURO | B3: Colombia->mundo | C3: Credito-beca hasta US$25k/ano (max 2 anos) | D3: Admision + excelencia | E3: colfuturo.org | F3: Por investigar
A4: Fulbright Colombia | B4: EE.UU. | C4: Matricula + sostenimiento | D4: Ingles (TOEFL), liderazgo | E4: fulbright.edu.co | F4: Por investigar
A5: Chevening | B5: Reino Unido | C5: Totalmente financiada | D5: Experiencia + admision | E5: chevening.org | F5: Por investigar
A6: DAAD | B6: Alemania | C6: Becas maestria (EPOS) | D6: Buen promedio + propuesta | E6: daad.de | F6: Por investigar
A7: Erasmus Mundus | B7: Europa (varios) | C7: Maestrias conjuntas 100% | D7: Admision al programa | E7: erasmus-plus.ec.europa.eu | F7: Por investigar
A8: Becas de la universidad | B8: Destino | C8: Descuentos/becas parciales | D8: Admision temprana | E8: Web de cada U | F8: Por investigar
A9: ICETEX | B9: Colombia | C9: Creditos y becas | D9: Segun convocatoria | E9: icetex.gov.co | F9: Por investigar
A11: Confirma SIEMPRE fechas en la web oficial; cambian cada ano.

Sheet Destinos Maestria
A1: MEJORES DESTINOS POR COSTO (2026, confirmar)
A2: Pais | B2: Costo matricula aprox. | C2: Idioma | D2: A favor | E2: En contra
A3: Alemania | B3: Gratis (~250-350 EUR/sem) | C3: Aleman/Ingles | D3: Top calidad-costo, industria fuerte | E3: Algunos piden aleman
A4: Austria | B4: ~726 EUR/semestre (no-UE) | C4: Aleman | D4: Muy economica | E4: Cupos y idioma
A5: Francia | B5: ~2.770-3.770 EUR/ano (no-UE) | C5: Frances/Ingles | D5: Ingenieria prestigiosa | E5: Idioma frances util
A6: Italia | B6: ~900-4.000 EUR/ano (segun renta) | C6: Italiano/Ingles | D6: Becas por renta | E6: Tramites lentos
A7: Espana | B7: Medio | C7: Espanol | D7: Sin barrera de idioma | E7: Menos becas full
A8: Noruega | B8: YA cobra a no-UE desde 2023 | C8: Ingles/Noruego | D8: Alta calidad de vida | E8: Dejo de ser gratis
A9: Reino Unido | B9: Alto | C9: Ingles | D9: Maestrias de 1 ano | E9: Caro: depende de Chevening/Colfuturo
A10: EE.UU. | B10: Alto | C10: Ingles | D10: Investigacion top | E10: Caro: depende de Fulbright
A11: Canada | B11: Medio-alto | C11: Ingles/Frances | D11: Buena via a residencia | E11: Costo de vida
A13: Si el costo manda: Alemania/Austria. Si quieres beca full: Chevening (UK), Fulbright (USA) o Erasmus Mundus.
A14: Fuentes: mastersportal.com, thecollegemonk.com, leapscholar.com (reformulado).

Sheet Cursos CV
A1: CURSOS ONLINE PARA TU HOJA DE VIDA
A2: Curso | B2: Plataforma | C2: Por que sirve | D2: Prioridad | E2: Estado | F2: % avance
A3: Construction Management Specialization (Columbia) | B3: Coursera | C3: Gestion de obra, muy valorado | D3: ALTA | E3: Por empezar | F3: 0
A4: BIM Fundamentals for Engineers | B4: Coursera | C4: BIM: el futuro del diseno | D4: ALTA | E4: Por empezar | F4: 0
A5: Autodesk Revit / AutoCAD | B5: Coursera/Udemy | C5: Software clave en ofertas | D5: ALTA | E5: Por empezar | F5: 0
A6: Engineering Project Management Specialization | B6: Coursera | C6: Liderar proyectos | D6: MEDIA | E6: Por empezar | F6: 0
A7: Google Project Management Certificate | B7: Coursera | C7: Respetado por reclutadores | D7: MEDIA | E7: Por empezar | F7: 0
A8: Preparacion IELTS/TOEFL | B8: Coursera/edX | C8: Ingles certificado = becas | D8: ALTA | E8: Por empezar | F8: 0
A9: Excel + analisis de datos | B9: Coursera | C9: Productividad y datos | D9: MEDIA | E9: Por empezar | F9: 0
A10: Python para ingenieros | B10: Coursera/edX | C10: Automatizar calculos | D10: BAJA | E10: Por empezar | F10: 0
A11: SAP2000 / ETABS (modelado) | B11: Udemy/YouTube | C11: Directo a tu area | D11: ALTA | E11: Por empezar | F11: 0
A13: Tip: pide 'financial aid' en Coursera para certificados gratis.
A14: Cursos terminados: | E14: =COUNTIF(E3:E11,"Terminado")&" / "&9

Sheet Ruta Posgrado
A1: RUTA HACIA LA MAESTRIA (linea de tiempo)
A2: Cuando | B2: Que hacer | C2: Estado
A3: Ahora (9o sem) | B3: Subir el PAPA y salvar la materia critica | C3: Pendiente
A4: Ahora | B4: Empezar ingles y apuntar a IELTS/TOEFL | C4: Pendiente
A5: 3-6 meses | B5: Definir pais y 5-8 universidades objetivo | C5: Pendiente
A6: 3-6 meses | B6: Tomar 1-2 cursos de 'Cursos CV' | C6: Pendiente
A7: 6-9 meses | B7: Conseguir cartas de recomendacion | C7: Pendiente
A8: 6-9 meses | B8: Escribir carta de motivacion (statement of purpose) | C8: Pendiente
A9: 9-12 meses | B9: Aplicar a becas (Colfuturo, Chevening, DAAD...) | C9: Pendiente
A10: 9-12 meses | B10: Aplicar a admisiones de universidades | C10: Pendiente
A11: 12-15 meses | B11: Entrevistas y resultados | C11: Pendiente
A12: Tras el grado | B12: Pasantia/experiencia que suma para la beca | C12: Pendiente

Sheet Libros
A1: BIBLIOTECA RECOMENDADA PARA TI
A2: Titulo | B2: Autor | C2: Categoria | D2: Estado | E2: % avance | F2: Para que sirve
A3: Habitos Atomicos | B3: James Clear | C3: Habitos | D3: Por leer | E3: 0 | F3: Disciplina (empieza por este)
A4: Enfocate (Deep Work) | B4: Cal Newport | C4: Productividad | D4: Por leer | E4: 0 | F4: Concentracion para proyecto e ingles
A5: Los 7 habitos | B5: Stephen Covey | C5: Desarrollo | D5: Por leer | E5: 0 | F5: Priorizar y vivir con proposito
A6: Padre Rico, Padre Pobre | B6: R. Kiyosaki | C6: Finanzas | D6: Por leer | E6: 0 | F6: Educacion financiera
A7: El hombre mas rico de Babilonia | B7: George Clason | C7: Finanzas | D7: Por leer | E7: 0 | F7: Ahorro e inversion
A8: Como ganar amigos... | B8: Dale Carnegie | C8: Relaciones | D8: Por leer | E8: 0 | F8: Comunicacion (pareja y entrevistas)
A9: Mindset | B9: Carol Dweck | C9: Mentalidad | D9: Por leer | E9: 0 | F9: Mentalidad de crecimiento
A10: El poder del ahora | B10: Eckhart Tolle | C10: Bienestar | D10: Por leer | E10: 0 | F10: Manejar ansiedad
A11: Inteligencia emocional | B11: Daniel Goleman | C11: Bienestar | D11: Por leer | E11: 0 | F11: Gestionar el estres
A12: Despertando al gigante interior | B12: Tony Robbins | C12: Motivacion | D12: Por leer | E12: 0 | F12: Motivacion y decisiones
A14: Leidos / Total | D14: =COUNTIF(D3:D12,"Leido")&" / "&10

Sheet Rutina Gym
A1: RUTINA DE GIMNASIO - TONIFICAR (Lun y Sab)
A2: Tonificar = peso moderado, 10-15 reps, baja controlada, descanso 45-60s. El Box (Mar/Jue) cubre tu cardio.
A4: DIA A - LUNES (full body, enfasis tren superior)
A5: Ejercicio | B5: Series | C5: Reps | D5: Descanso | E5: Peso / notas
A6: Calentamiento (cardio + movilidad) | B6: - | C6: 5-10 min | D6: -
A7: Sentadilla (barra/mancuernas) | B7: 3 | C7: 12 | D7: 60s
A8: Press de banca / pecho en maquina | B8: 3 | C8: 12 | D8: 60s
A9: Remo sentado (espalda) | B9: 3 | C9: 12 | D9: 60s
A10: Press militar (hombros) | B10: 3 | C10: 12 | D10: 60s
A11: Curl de biceps | B11: 3 | C11: 15 | D11: 45s
A12: Extension de triceps | B12: 3 | C12: 15 | D12: 45s
A13: Plancha abdominal | B13: 3 | C13: 40 s | D13: 30s
A14: Cardio final (caminadora/eliptica) | B14: - | C14: 10 min | D14: -
A16: DIA B - SABADO (full body, enfasis tren inferior + core)
A17: Ejercicio | B17: Series | C17: Reps | D17: Descanso | E17: Peso / notas
A18: Calentamiento (cardio + movilidad) | B18: - | C18: 5-10 min | D18: -
A19: Peso muerto rumano | B19: 3 | C19: 12 | D19: 60s
A20: Zancadas (lunges) | B20: 3 | C20: 12 x pierna | D20: 60s
A21: Jalon al pecho (dorsales) | B21: 3 | C21: 12 | D21: 60s
A22: Aperturas / pec deck | B22: 3 | C22: 15 | D22: 45s
A23: Elevaciones laterales (hombro) | B23: 3 | C23: 15 | D23: 45s
A24: Hip thrust / gluteo | B24: 3 | C24: 15 | D24: 45s
A25: Elevacion de piernas + crunch | B25: 3 | C25: 20 | D25: 30s
A26: Cardio final | B26: - | C26: 15 min | D26: -
A28: Progresion: sube un poco el peso cada 2 semanas si completas todas las reps con buena tecnica.

Sheet Comidas Diarias
A1: PLAN DE COMIDAS DIARIO (enfoque tonificar)
A2: Proteina en cada comida + carbohidrato bueno + verduras. Ajusta porciones a tu hambre. 2-2.5 L de agua al dia.
A3: Dia | B3: Desayuno (5:30-7) | C3: Media manana | D3: Almuerzo (12:30) | E3: Pre/Post entreno | F3: Cena
A4: Lunes | B4: Huevos + arepa + fruta + cafe | C4: Yogur + frutos secos | D4: Pollo + arroz + ensalada | E4: Banano + agua | F4: Crema de verduras + huevo
A5: Martes | B5: Avena con leche + fruta | C5: Manzana | D5: Carne magra + papa + verduras | E5: Batido proteina (post-box) | F5: Atun + ensalada
A6: Miercoles | B6: Huevos + pan integral + jugo | C6: Yogur griego | D6: Pescado + arroz + brocoli | E6: Frutos secos | F6: Sopa + pollo desmechado
A7: Jueves | B7: Tostadas + aguacate + huevo | C7: Fruta | D7: Lentejas + arroz + ensalada | E7: Batido (post-box) | F7: Tortilla de huevo + verduras
A8: Viernes | B8: Avena + banano + mani | C8: Yogur | D8: Pollo a la plancha + quinua | E8: Fruta | F8: Ensalada grande + atun
A9: Sabado | B9: Huevos + arepa (post-gym) | C9: Batido proteina | D9: Carne + arroz + patacon | E9: Fruta | F9: Wrap integral de pollo
A10: Domingo | B10: Desayuno libre (con medida) | C10: Fruta | D10: Almuerzo familiar | E10: - | F10: Algo ligero: sopa o ensalada

Sheet Mercado Semanal
A1: LISTA DE MERCADO SEMANAL
A2: Categoria | B2: Producto | C2: Cantidad | D2: Precio aprox (COP) | E2: Comprado
A3: Proteina | B3: Huevos | C3: 30 und | D3: 0
A4: Proteina | B4: Pechuga de pollo | C4: 1.5 kg | D4: 0
A5: Proteina | B5: Carne magra | C5: 1 kg | D5: 0
A6: Proteina | B6: Pescado / atun | C6: 4 latas / 0.5 kg | D6: 0
A7: Proteina | B7: Lentejas / frijol | C7: 500 g | D7: 0
A8: Proteina | B8: Proteina en polvo (opc.) | C8: 1 bolsa | D8: 0
A9: Carbohidrato | B9: Arroz | C9: 1 kg | D9: 0
A10: Carbohidrato | B10: Avena | C10: 500 g | D10: 0
A11: Carbohidrato | B11: Pan integral | C11: 1 paquete | D11: 0
A12: Carbohidrato | B12: Arepas / maiz | C12: 1 paquete | D12: 0
A13: Carbohidrato | B13: Papa / yuca / platano | C13: 2 kg | D13: 0
A14: Carbohidrato | B14: Quinua (opc.) | C14: 250 g | D14: 0
... A26: Otros | B26: Agua / hidratacion | C26: - | D26: 0
C27: TOTAL ESTIMADO | D27: =SUM(D3:D26)
A29: Tip: llena el precio una vez y reutiliza la lista cada semana. El total alimenta tu pestana de Egresos.
