Workbook

Sheet Control
A1: CONTROL AUTOMÁTICO
A2: Control | B2: Resultado | C2: Criterio | D2: Estado
A3: CAPEX | B3: =Presupuesto!B9-SUM(Presupuesto!B3:B8) -> 0 | C3: =0 -> 0 | D3: =IF(ABS(B3)<0.01,"OK","REVISAR") -> OK
A4: Participaciones | B4: =SUM(Financiacion!B3:B5)-1 -> 0 | C4: =0 -> 0 | D4: =IF(ABS(B4)<0.000001,"OK","REVISAR") -> OK
A5: Financiación | B5: =SUM(Financiacion!C3:C5)-Presupuesto!B9 -> 0 | C5: =0 -> 0 | D5: =IF(ABS(B5)<0.01,"OK","REVISAR") -> OK
A6: Saldo deuda | B6: ='Amortizacion Deuda'!F27 -> 2.1032065e-12 | C6: ≈0 | D6: =IF(ABS(B6)<0.01,"OK","REVISAR") -> OK
A7: Años | B7: =COUNT('Flujos de Caja'!A4:A28) -> 25 | C7: =25 -> 25 | D7: =IF(B7=25,"OK","REVISAR") -> OK
A8: Riesgos | B8: =COUNT(Riesgos!A3:A22) -> 20 | C8: =20 -> 20 | D8: =IF(B8=20,"OK","REVISAR") -> OK
A9: Intervenciones | B9: =COUNT(Riesgos!A27:A36) -> 10 | C9: =10 -> 10 | D9: =IF(B9=10,"OK","REVISAR") -> OK
A10: Ambientales | B10: =COUNTIF(Riesgos!C27:C36,"Ambiental") -> 5 | C10: =5 -> 5 | D10: =IF(B10=5,"OK","REVISAR") -> OK
A11: PTAP-QMD | B11: ='Diseno Caudal'!B11-'Diseno Caudal'!B9 -> 3.5331681 | C11: >=0 | D11: =IF(B11>=0,"OK","REVISAR") -> OK
A12: TIR banco-Kd | B12: =Indicadores!B10-Supuestos!B21 -> -4.111711e-13 | C12: ≈0 | D12: =IF(ABS(B12)<0.000001,"OK","REVISAR") -> OK
A13: B/C | B13: =Indicadores!B9 -> 1.5583457 | C13: >1 | D13: =IF(B13>1,"OK","REVISAR") -> OK

Sheet Supuestos
A1: SUPUESTOS — AMARILLO = ENTRADA EDITABLE
A2: Parámetro | B2: Valor | C2: Unidad | D2: Criterio
A3: Población municipal | B3: 17000 | C3: hab | D3: Contexto
A4: Población urbana base | B4: 10957 | C4: hab | D4: Base adoptada; no equivale a 60 %
A5: Crecimiento población | B5: 0.012 | C5: % anual | D5: Supuesto
A6: Horizonte diseño | B6: 25 | C6: años | D6: Diseño hidráulico
A7: Dotación neta | B7: 140 | C7: L/hab·día | D7: RAS adoptado
A8: Pérdidas | B8: 0.25 | C8: % | D8: Supuesto
A9: k1 | B9: 1.3 | C9: factor | D9: Máximo diario
A10: k2 | B10: 1.6 | C10: factor | D10: Máximo horario
A11: PTAP | B11: 45 | C11: L/s | D11: Debe cubrir QMD
A12: Horizonte evaluación | B12: 25 | C12: años | D12: Flujos
A13: Ingresos año 1 | B13: 1500 | C13: COP MM | D13: Validar tarifa/demanda
A14: OPEX año 1 | B14: 1150 | C14: COP MM | D14: Validar operación
... A26: Vida útil | B26: 25 | C26: años | D26: Depreciación lineal

Sheet Diseno Caudal
A1: DISEÑO DE CAUDAL — RAS
A2: Concepto | B2: Valor | C2: Fórmula/criterio
A3: Población municipal | B3: =Supuestos!B3 -> 17000 | C3: Contexto
A4: Población urbana | B4: =Supuestos!B4 -> 10957 | C4: Entrada
A5: Población diseño | B5: =B4*(1+Supuestos!$B$5)^Supuestos!$B$6 -> 14764.015 | C5: P(1+g)^n
A6: Dotación neta | B6: =Supuestos!B7 -> 140 | C6: Entrada
A7: Dotación bruta | B7: =B6/(1-Supuestos!$B$8) -> 186.66667 | C7: Dn/(1-pérdidas)
A8: Qmd | B8: =B5*B7/86400 -> 31.897563 | C8: P×Db/86400
A9: QMD | B9: =B8*Supuestos!$B$9 -> 41.466832 | C9: Qmd×k1
A10: QMH | B10: =B9*Supuestos!$B$10 -> 66.346931 | C10: QMD×k2
A11: PTAP | B11: =Supuestos!B11 -> 45 | C11: PTAP≥QMD

Sheet Presupuesto
A1: CAPEX — COP MM
A2: Capítulo | B2: COP MM | C2: % total
A3: Captación (bocatoma) y línea de aducción | B3: 2400 | C3: =B3/$B$9 -> 0.12017425
A4: PTAP 45 L/s (obra civil + equipos) | B4: 6300 | C4: =B4/$B$9 -> 0.31545741
A5: Almacenamiento (tanques) y estaciones de bombeo | B5: 2800 | C5: =B5/$B$9 -> 0.14020329
A6: Redes de distribución, conexiones y micromedición | B6: 4200 | C6: =B6/$B$9 -> 0.21030494
A7: Optimización del alcantarillado (componente asociado) | B7: 2471 | C7: =B7/$B$9 -> 0.12372941
A8: Estudios, diseños, interventoría y gestión ambiental/social | B8: 1800 | C8: =B8/$B$9 -> 0.090130689
A9: TOTAL | B9: =SUM(B3:B8) -> 19971 | C9: =SUM(C3:C8) -> 1

Sheet Financiacion
A1: FINANCIACIÓN Y WACC AJUSTADO
A2: Fuente | B2: Participación | C2: Monto | D2: Costo | E2: Tratamiento
A3: Aporte público | B3: =Supuestos!B17 -> 0.8 | C3: =B3*Presupuesto!$B$9 -> 15976.8 | D3: =Supuestos!B20 -> 0.09 | E3: Oportunidad social
A4: Deuda | B4: =Supuestos!B18 -> 0.1 | C4: =B4*Presupuesto!$B$9 -> 1997.1 | D4: =Supuestos!B21 -> 0.11 | E4: Kd posimpuesto
A5: Equity | B5: =Supuestos!B19 -> 0.1 | C5: =B5*Presupuesto!$B$9 -> 1997.1 | D5: =Supuestos!B22 -> 0.14 | E5: Ke
A6: TOTAL | B6: =SUM(B3:B5) -> 1 | C6: =SUM(C3:C5) -> 19971 | E6: Concilia CAPEX
A8: WACC ajustado | B8: =B3*D3+B4*D4*(1-Supuestos!$B$23)+B5*D5 -> 0.09315 | C8: Proyecto

Sheet Amortizacion Deuda
A1: AMORTIZACIÓN — SISTEMA FRANCÉS
A2: Año | B2: Saldo inicial | C2: Interés | D2: Capital | E2: Cuota | F2: Saldo final
A3: 1 | B3: =Financiacion!$C$4 -> 1997.1 | C3: =IF(A3<=Supuestos!$B$24,B3*Supuestos!$B$21,0) -> 219.681 | D3: =IF(A3<=Supuestos!$B$24,MIN(B3,E3-C3),0) -> 119.42943 | E3: =IF(A3<=Supuestos!$B$24,-PMT(Supuestos!$B$21,Supuestos!$B$24,Financiacion!$C$4),0) -> 339.11043 | F3: =MAX(0,B3-D3) -> 1877.6706
A4: =A3+1 -> 2 | B4: =F3 -> 1877.6706 | C4: =IF(A4<=Supuestos!$B$24,B4*Supuestos!$B$21,0) -> 206.54376 | D4: =IF(A4<=Supuestos!$B$24,MIN(B4,E4-C4),0) -> 132.56667 | E4: =IF(A4<=Supuestos!$B$24,-PMT(Supuestos!$B$21,Supuestos!$B$24,Financiacion!$C$4),0) -> 339.11043 | F4: =MAX(0,B4-D4) -> 1745.1039
A5: =A4+1 -> 3 | B5: =F4 -> 1745.1039 | C5: =IF(A5<=Supuestos!$B$24,B5*Supuestos!$B$21,0) -> 191.96143 | D5: =IF(A5<=Supuestos!$B$24,MIN(B5,E5-C5),0) -> 147.149 | E5: =IF(A5<=Supuestos!$B$24,-PMT(Supuestos!$B$21,Supuestos!$B$24,Financiacion!$C$4),0) -> 339.11043 | F5: =MAX(0,B5-D5) -> 1597.9549
A6: =A5+1 -> 4 | B6: =F5 -> 1597.9549 | C6: =IF(A6<=Supuestos!$B$24,B6*Supuestos!$B$21,0) -> 175.77504 | D6: =IF(A6<=Supuestos!$B$24,MIN(B6,E6-C6),0) -> 163.33539 | E6: =IF(A6<=Supuestos!$B$24,-PMT(Supuestos!$B$21,Supuestos!$B$24,Financiacion!$C$4),0) -> 339.11043 | F6: =MAX(0,B6-D6) -> 1434.6195
A7: =A6+1 -> 5 | B7: =F6 -> 1434.6195 | C7: =IF(A7<=Supuestos!$B$24,B7*Supuestos!$B$21,0) -> 157.80815 | D7: =IF(A7<=Supuestos!$B$24,MIN(B7,E7-C7),0) -> 181.30228 | E7: =IF(A7<=Supuestos!$B$24,-PMT(Supuestos!$B$21,Supuestos!$B$24,Financiacion!$C$4),0) -> 339.11043 | F7: =MAX(0,B7-D7) -> 1253.3172
A8: =A7+1 -> 6 | B8: =F7 -> 1253.3172 | C8: =IF(A8<=Supuestos!$B$24,B8*Supuestos!$B$21,0) -> 137.86489 | D8: =IF(A8<=Supuestos!$B$24,MIN(B8,E8-C8),0) -> 201.24554 | E8: =IF(A8<=Supuestos!$B$24,-PMT(Supuestos!$B$21,Supuestos!$B$24,Financiacion!$C$4),0) -> 339.11043 | F8: =MAX(0,B8-D8) -> 1052.0717
A9: =A8+1 -> 7 | B9: =F8 -> 1052.0717 | C9: =IF(A9<=Supuestos!$B$24,B9*Supuestos!$B$21,0) -> 115.72789 | D9: =IF(A9<=Supuestos!$B$24,MIN(B9,E9-C9),0) -> 223.38254 | E9: =IF(A9<=Supuestos!$B$24,-PMT(Supuestos!$B$21,Supuestos!$B$24,Financiacion!$C$4),0) -> 339.11043 | F9: =MAX(0,B9-D9) -> 828.68915
A10: =A9+1 -> 8 | B10: =F9 -> 828.68915 | C10: =IF(A10<=Supuestos!$B$24,B10*Supuestos!$B$21,0) -> 91.155806 | D10: =IF(A10<=Supuestos!$B$24,MIN(B10,E10-C10),0) -> 247.95462 | E10: =IF(A10<=Supuestos!$B$24,-PMT(Supuestos!$B$21,Supuestos!$B$24,Financiacion!$C$4),0) -> 339.11043 | F10: =MAX(0,B10-D10) -> 580.73452
A11: =A10+1 -> 9 | B11: =F10 -> 580.73452 | C11: =IF(A11<=Supuestos!$B$24,B11*Supuestos!$B$21,0) -> 63.880798 | D11: =IF(A11<=Supuestos!$B$24,MIN(B11,E11-C11),0) -> 275.22963 | E11: =IF(A11<=Supuestos!$B$24,-PMT(Supuestos!$B$21,Supuestos!$B$24,Financiacion!$C$4),0) -> 339.11043 | F11: =MAX(0,B11-D11) -> 305.50489
A12: =A11+1 -> 10 | B12: =F11 -> 305.50489 | C12: =IF(A12<=Supuestos!$B$24,B12*Supuestos!$B$21,0) -> 33.605538 | D12: =IF(A12<=Supuestos!$B$24,MIN(B12,E12-C12),0) -> 305.50489 | E12: =IF(A12<=Supuestos!$B$24,-PMT(Supuestos!$B$21,Supuestos!$B$24,Financiacion!$C$4),0) -> 339.11043 | F12: =MAX(0,B12-D12) -> 2.1032065e-12
A13: =A12+1 -> 11 | B13: =F12 -> 2.1032065e-12 | C13: =IF(A13<=Supuestos!$B$24,B13*Supuestos!$B$21,0) -> 0 | D13: =IF(A13<=Supuestos!$B$24,MIN(B13,E13-C13),0) -> 0 | E13: =IF(A13<=Supuestos!$B$24,-PMT(Supuestos!$B$21,Supuestos!$B$24,Financiacion!$C$4),0) -> 0 | F13: =MAX(0,B13-D13) -> 2.1032065e-12
A14: =A13+1 -> 12 | B14: =F13 -> 2.1032065e-12 | C14: =IF(A14<=Supuestos!$B$24,B14*Supuestos!$B$21,0) -> 0 | D14: =IF(A14<=Supuestos!$B$24,MIN(B14,E14-C14),0) -> 0 | E14: =IF(A14<=Supuestos!$B$24,-PMT(Supuestos!$B$21,Supuestos!$B$24,Financiacion!$C$4),0) -> 0 | F14: =MAX(0,B14-D14) -> 2.1032065e-12
A15: =A14+1 -> 13 | B15: =F14 -> 2.1032065e-12 | C15: =IF(A15<=Supuestos!$B$24,B15*Supuestos!$B$21,0) -> 0 | D15: =IF(A15<=Supuestos!$B$24,MIN(B15,E15-C15),0) -> 0 | E15: =IF(A15<=Supuestos!$B$24,-PMT(Supuestos!$B$21,Supuestos!$B$24,Financiacion!$C$4),0) -> 0 | F15: =MAX(0,B15-D15) -> 2.1032065e-12
... A27: =A26+1 -> 25 | B27: =F26 -> 2.1032065e-12 | C27: =IF(A27<=Supuestos!$B$24,B27*Supuestos!$B$21,0) -> 0 | D27: =IF(A27<=Supuestos!$B$24,MIN(B27,E27-C27),0) -> 0 | E27: =IF(A27<=Supuestos!$B$24,-PMT(Supuestos!$B$21,Supuestos!$B$24,Financiacion!$C$4),0) -> 0 | F27: =MAX(0,B27-D27) -> 2.1032065e-12

Sheet Flujos de Caja
A1: FLUJOS — COP MM
A2: Año | B2: Ingresos | C2: OPEX | D2: EBITDA | E2: Deprec. | F2: EBIT | G2: Interés | H2: Imp. proyecto | I2: Imp. equity | J2: Capital | K2: Saldo deuda | L2: FC Proyecto | M2: FC Inversionista | N2: FC Banco | O2: Beneficio social | P2: FC Social
A3: 0 | B3: 0 | C3: 0 | D3: 0 | E3: 0 | F3: 0 | G3: 0 | H3: 0 | I3: 0 | J3: 0 | K3: =Financiacion!$C$4 -> 1997.1 | L3: =-Presupuesto!$B$9 -> -19971 | M3: =-Financiacion!$C$5 -> -1997.1 | N3: =-Financiacion!$C$4 -> -1997.1 | O3: 0 | P3: =-Presupuesto!$B$9 -> -19971
A4: 1 | B4: =Supuestos!$B$13*(1+Supuestos!$B$15)^(A4-1) -> 1500 | C4: =Supuestos!$B$14*(1+Supuestos!$B$15)^(A4-1) -> 1150 | D4: =B4-C4 -> 350 | E4: =Presupuesto!$B$9/Supuestos!$B$26 -> 798.84 | F4: =D4-E4 -> -448.84 | G4: ='Amortizacion Deuda'!C3 -> 219.681 | H4: =MAX(0,F4)*Supuestos!$B$23 -> 0 | I4: =MAX(0,F4-G4)*Supuestos!$B$23 -> 0 | J4: ='Amortizacion Deuda'!D3 -> 119.42943 | K4: ='Amortizacion Deuda'!F3 -> 1877.6706 | L4: =D4-H4 -> 350 | M4: =D4-G4-I4-J4 -> 10.88957 | N4: =G4+J4 -> 339.11043 | O4: =Supuestos!$B$16*(1+Supuestos!$B$15)^(A4-1) -> 4150 | P4: =O4-C4 -> 3000
A5: =A4+1 -> 2 | B5: =Supuestos!$B$13*(1+Supuestos!$B$15)^(A5-1) -> 1552.5 | C5: =Supuestos!$B$14*(1+Supuestos!$B$15)^(A5-1) -> 1190.25 | D5: =B5-C5 -> 362.25 | E5: =Presupuesto!$B$9/Supuestos!$B$26 -> 798.84 | F5: =D5-E5 -> -436.59 | G5: ='Amortizacion Deuda'!C4 -> 206.54376 | H5: =MAX(0,F5)*Supuestos!$B$23 -> 0 | I5: =MAX(0,F5-G5)*Supuestos!$B$23 -> 0 | J5: ='Amortizacion Deuda'!D4 -> 132.56667 | K5: ='Amortizacion Deuda'!F4 -> 1745.1039 | L5: =D5-H5 -> 362.25 | M5: =D5-G5-I5-J5 -> 23.13957 | N5: =G5+J5 -> 339.11043 | O5: =Supuestos!$B$16*(1+Supuestos!$B$15)^(A5-1) -> 4295.25 | P5: =O5-C5 -> 3105
A6: =A5+1 -> 3 | B6: =Supuestos!$B$13*(1+Supuestos!$B$15)^(A6-1) -> 1606.8375 | C6: =Supuestos!$B$14*(1+Supuestos!$B$15)^(A6-1) -> 1231.9088 | D6: =B6-C6 -> 374.92875 | E6: =Presupuesto!$B$9/Supuestos!$B$26 -> 798.84 | F6: =D6-E6 -> -423.91125 | G6: ='Amortizacion Deuda'!C5 -> 191.96143 | H6: =MAX(0,F6)*Supuestos!$B$23 -> 0 | I6: =MAX(0,F6-G6)*Supuestos!$B$23 -> 0 | J6: ='Amortizacion Deuda'!D5 -> 147.149 | K6: ='Amortizacion Deuda'!F5 -> 1597.9549 | L6: =D6-H6 -> 374.92875 | M6: =D6-G6-I6-J6 -> 35.81832 | N6: =G6+J6 -> 339.11043 | O6: =Supuestos!$B$16*(1+Supuestos!$B$15)^(A6-1) -> 4445.5837 | P6: =O6-C6 -> 3213.675
A7: =A6+1 -> 4 | B7: =Supuestos!$B$13*(1+Supuestos!$B$15)^(A7-1) -> 1663.0768 | C7: =Supuestos!$B$14*(1+Supuestos!$B$15)^(A7-1) -> 1275.0256 | D7: =B7-C7 -> 388.05126 | E7: =Presupuesto!$B$9/Supuestos!$B$26 -> 798.84 | F7: =D7-E7 -> -410.78874 | G7: ='Amortizacion Deuda'!C6 -> 175.77504 | H7: =MAX(0,F7)*Supuestos!$B$23 -> 0 | I7: =MAX(0,F7-G7)*Supuestos!$B$23 -> 0 | J7: ='Amortizacion Deuda'!D6 -> 163.33539 | K7: ='Amortizacion Deuda'!F6 -> 1434.6195 | L7: =D7-H7 -> 388.05126 | M7: =D7-G7-I7-J7 -> 48.940826 | N7: =G7+J7 -> 339.11043 | O7: =Supuestos!$B$16*(1+Supuestos!$B$15)^(A7-1) -> 4601.1792 | P7: =O7-C7 -> 3326.1536
A8: =A7+1 -> 5 | B8: =Supuestos!$B$13*(1+Supuestos!$B$15)^(A8-1) -> 1721.2845 | C8: =Supuestos!$B$14*(1+Supuestos!$B$15)^(A8-1) -> 1319.6515 | D8: =B8-C8 -> 401.63305 | E8: =Presupuesto!$B$9/Supuestos!$B$26 -> 798.84 | F8: =D8-E8 -> -397.20695 | G8: ='Amortizacion Deuda'!C7 -> 157.80815 | H8: =MAX(0,F8)*Supuestos!$B$23 -> 0 | I8: =MAX(0,F8-G8)*Supuestos!$B$23 -> 0 | J8: ='Amortizacion Deuda'!D7 -> 181.30228 | K8: ='Amortizacion Deuda'!F7 -> 1253.3172 | L8: =D8-H8 -> 401.63305 | M8: =D8-G8-I8-J8 -> 62.52262 | N8: =G8+J8 -> 339.11043 | O8: =Supuestos!$B$16*(1+Supuestos!$B$15)^(A8-1) -> 4762.2205 | P8: =O8-C8 -> 3442.569
A9: =A8+1 -> 6 | B9: =Supuestos!$B$13*(1+Supuestos!$B$15)^(A9-1) -> 1781.5295 | C9: =Supuestos!$B$14*(1+Supuestos!$B$15)^(A9-1) -> 1365.8393 | D9: =B9-C9 -> 415.69021 | E9: =Presupuesto!$B$9/Supuestos!$B$26 -> 798.84 | F9: =D9-E9 -> -383.14979 | G9: ='Amortizacion Deuda'!C8 -> 137.86489 | H9: =MAX(0,F9)*Supuestos!$B$23 -> 0 | I9: =MAX(0,F9-G9)*Supuestos!$B$23 -> 0 | J9: ='Amortizacion Deuda'!D8 -> 201.24554 | K9: ='Amortizacion Deuda'!F8 -> 1052.0717 | L9: =D9-H9 -> 415.69021 | M9: =D9-G9-I9-J9 -> 76.579777 | N9: =G9+J9 -> 339.11043 | O9: =Supuestos!$B$16*(1+Supuestos!$B$15)^(A9-1) -> 4928.8982 | P9: =O9-C9 -> 3563.0589
A10: =A9+1 -> 7 | B10: =Supuestos!$B$13*(1+Supuestos!$B$15)^(A10-1) -> 1843.883 | C10: =Supuestos!$B$14*(1+Supuestos!$B$15)^(A10-1) -> 1413.6436 | D10: =B10-C10 -> 430.23936 | E10: =Presupuesto!$B$9/Supuestos!$B$26 -> 798.84 | F10: =D10-E10 -> -368.60064 | G10: ='Amortizacion Deuda'!C9 -> 115.72789 | H10: =MAX(0,F10)*Supuestos!$B$23 -> 0 | I10: =MAX(0,F10-G10)*Supuestos!$B$23 -> 0 | J10: ='Amortizacion Deuda'!D9 -> 223.38254 | K10: ='Amortizacion Deuda'!F9 -> 828.68915 | L10: =D10-H10 -> 430.23936 | M10: =D10-G10-I10-J10 -> 91.128934 | N10: =G10+J10 -> 339.11043 | O10: =Supuestos!$B$16*(1+Supuestos!$B$15)^(A10-1) -> 5101.4096 | P10: =O10-C10 -> 3687.766
A11: =A10+1 -> 8 | B11: =Supuestos!$B$13*(1+Supuestos!$B$15)^(A11-1) -> 1908.4189 | C11: =Supuestos!$B$14*(1+Supuestos!$B$15)^(A11-1) -> 1463.1212 | D11: =B11-C11 -> 445.29774 | E11: =Presupuesto!$B$9/Supuestos!$B$26 -> 798.84 | F11: =D11-E11 -> -353.54226 | G11: ='Amortizacion Deuda'!C10 -> 91.155806 | H11: =MAX(0,F11)*Supuestos!$B$23 -> 0 | I11: =MAX(0,F11-G11)*Supuestos!$B$23 -> 0 | J11: ='Amortizacion Deuda'!D10 -> 247.95462 | K11: ='Amortizacion Deuda'!F10 -> 580.73452 | L11: =D11-H11 -> 445.29774 | M11: =D11-G11-I11-J11 -> 106.18731 | N11: =G11+J11 -> 339.11043 | O11: =Supuestos!$B$16*(1+Supuestos!$B$15)^(A11-1) -> 5279.9589 | P11: =O11-C11 -> 3816.8378
A12: =A11+1 -> 9 | B12: =Supuestos!$B$13*(1+Supuestos!$B$15)^(A12-1) -> 1975.2136 | C12: =Supuestos!$B$14*(1+Supuestos!$B$15)^(A12-1) -> 1514.3304 | D12: =B12-C12 -> 460.88316 | E12: =Presupuesto!$B$9/Supuestos!$B$26 -> 798.84 | F12: =D12-E12 -> -337.95684 | G12: ='Amortizacion Deuda'!C11 -> 63.880798 | H12: =MAX(0,F12)*Supuestos!$B$23 -> 0 | I12: =MAX(0,F12-G12)*Supuestos!$B$23 -> 0 | J12: ='Amortizacion Deuda'!D11 -> 275.22963 | K12: ='Amortizacion Deuda'!F11 -> 305.50489 | L12: =D12-H12 -> 460.88316 | M12: =D12-G12-I12-J12 -> 121.77273 | N12: =G12+J12 -> 339.11043 | O12: =Supuestos!$B$16*(1+Supuestos!$B$15)^(A12-1) -> 5464.7575 | P12: =O12-C12 -> 3950.4271
A13: =A12+1 -> 10 | B13: =Supuestos!$B$13*(1+Supuestos!$B$15)^(A13-1) -> 2044.346 | C13: =Supuestos!$B$14*(1+Supuestos!$B$15)^(A13-1) -> 1567.332 | D13: =B13-C13 -> 477.01407 | E13: =Presupuesto!$B$9/Supuestos!$B$26 -> 798.84 | F13: =D13-E13 -> -321.82593 | G13: ='Amortizacion Deuda'!C12 -> 33.605538 | H13: =MAX(0,F13)*Supuestos!$B$23 -> 0 | I13: =MAX(0,F13-G13)*Supuestos!$B$23 -> 0 | J13: ='Amortizacion Deuda'!D12 -> 305.50489 | K13: ='Amortizacion Deuda'!F12 -> 2.1032065e-12 | L13: =D13-H13 -> 477.01407 | M13: =D13-G13-I13-J13 -> 137.90364 | N13: =G13+J13 -> 339.11043 | O13: =Supuestos!$B$16*(1+Supuestos!$B$15)^(A13-1) -> 5656.024 | P13: =O13-C13 -> 4088.6921
A14: =A13+1 -> 11 | B14: =Supuestos!$B$13*(1+Supuestos!$B$15)^(A14-1) -> 2115.8981 | C14: =Supuestos!$B$14*(1+Supuestos!$B$15)^(A14-1) -> 1622.1886 | D14: =B14-C14 -> 493.70957 | E14: =Presupuesto!$B$9/Supuestos!$B$26 -> 798.84 | F14: =D14-E14 -> -305.13043 | G14: ='Amortizacion Deuda'!C13 -> 0 | H14: =MAX(0,F14)*Supuestos!$B$23 -> 0 | I14: =MAX(0,F14-G14)*Supuestos!$B$23 -> 0 | J14: ='Amortizacion Deuda'!D13 -> 0 | K14: ='Amortizacion Deuda'!F13 -> 2.1032065e-12 | L14: =D14-H14 -> 493.70957 | M14: =D14-G14-I14-J14 -> 493.70957 | N14: =G14+J14 -> 0 | O14: =Supuestos!$B$16*(1+Supuestos!$B$15)^(A14-1) -> 5853.9849 | P14: =O14-C14 -> 4231.7963
A15: =A14+1 -> 12 | B15: =Supuestos!$B$13*(1+Supuestos!$B$15)^(A15-1) -> 2189.9546 | C15: =Supuestos!$B$14*(1+Supuestos!$B$15)^(A15-1) -> 1678.9652 | D15: =B15-C15 -> 510.9894 | E15: =Presupuesto!$B$9/Supuestos!$B$26 -> 798.84 | F15: =D15-E15 -> -287.8506 | G15: ='Amortizacion Deuda'!C14 -> 0 | H15: =MAX(0,F15)*Supuestos!$B$23 -> 0 | I15: =MAX(0,F15-G15)*Supuestos!$B$23 -> 0 | J15: ='Amortizacion Deuda'!D14 -> 0 | K15: ='Amortizacion Deuda'!F14 -> 2.1032065e-12 | L15: =D15-H15 -> 510.9894 | M15: =D15-G15-I15-J15 -> 510.9894 | N15: =G15+J15 -> 0 | O15: =Supuestos!$B$16*(1+Supuestos!$B$15)^(A15-1) -> 6058.8743 | P15: =O15-C15 -> 4379.9092
A16: =A15+1 -> 13 | B16: =Supuestos!$B$13*(1+Supuestos!$B$15)^(A16-1) -> 2266.603 | C16: =Supuestos!$B$14*(1+Supuestos!$B$15)^(A16-1) -> 1737.729 | D16: =B16-C16 -> 528.87403 | E16: =Presupuesto!$B$9/Supuestos!$B$26 -> 798.84 | F16: =D16-E16 -> -269.96597 | G16: ='Amortizacion Deuda'!C15 -> 0 | H16: =MAX(0,F16)*Supuestos!$B$23 -> 0 | I16: =MAX(0,F16-G16)*Supuestos!$B$23 -> 0 | J16: ='Amortizacion Deuda'!D15 -> 0 | K16: ='Amortizacion Deuda'!F15 -> 2.1032065e-12 | L16: =D16-H16 -> 528.87403 | M16: =D16-G16-I16-J16 -> 528.87403 | N16: =G16+J16 -> 0 | O16: =Supuestos!$B$16*(1+Supuestos!$B$15)^(A16-1) -> 6270.9349 | P16: =O16-C16 -> 4533.206
... A28: =A27+1 -> 25 | B28: =Supuestos!$B$13*(1+Supuestos!$B$15)^(A28-1) -> 3424.9927 | C28: =Supuestos!$B$14*(1+Supuestos!$B$15)^(A28-1) -> 2625.8278 | D28: =B28-C28 -> 799.16497 | E28: =Presupuesto!$B$9/Supuestos!$B$26 -> 798.84 | F28: =D28-E28 -> 0.32497053 | G28: ='Amortizacion Deuda'!C27 -> 0 | H28: =MAX(0,F28)*Supuestos!$B$23 -> 0.11373968 | I28: =MAX(0,F28-G28)*Supuestos!$B$23 -> 0.11373968 | J28: ='Amortizacion Deuda'!D27 -> 0 | K28: ='Amortizacion Deuda'!F27 -> 2.1032065e-12 | L28: =D28-H28 -> 799.05123 | M28: =D28-G28-I28-J28 -> 799.05123 | N28: =G28+J28 -> 0 | O28: =Supuestos!$B$16*(1+Supuestos!$B$15)^(A28-1) -> 9475.8132 | P28: =O28-C28 -> 6849.9855

Sheet Sensibilidad
A1: APORTE PÚBLICO VS TIR INVERSIONISTA
A2: Aporte | B2: Deuda | C2: Equity | D2: TIR | E2: VPN @ Ke | F2: Criterio | G2: 0 | H2: 1 | I2: 2 | J2: 3 | K2: 4 | L2: 5 | M2: 6 | N2: 7 | O2: 8 | P2: 9 | Q2: 10 | R2: 11 | S2: 12 | T2: 13 | U2: 14 | V2: 15 | W2: 16 | X2: 17 | Y2: 18 | Z2: 19 | AA2: 20 | AB2: 21 | AC2: 22 | AD2: 23 | AE2: 24 | AF2: 25
A3: 0 | B3: =(1-A3)/2*Presupuesto!$B$9 -> 9985.5 | C3: =(1-A3)/2*Presupuesto!$B$9 -> 9985.5 | D3: =IRR(G3:AF3) -> -0.053979407 | E3: =NPV(Supuestos!$B$22,H3:AF3)+G3 -> -15794.058 | F3: =IF(D3>=Supuestos!$B$22,"Viable","No viable") -> No viable | G3: =-C3 -> -9985.5 | H3: ='Flujos de Caja'!D4-('Amortizacion Deuda'!C3*B3/Financiacion!$C$4)-('Amortizacion Deuda'!D3*B3/Financiacion!$C$4)-MAX(0,'Flujos de Caja'!F4-('Amortizacion Deuda'!C3*B3/Financiacion!$C$4))*Supuestos!$B$23 -> -1345.5522 | I3: ='Flujos de Caja'!D5-('Amortizacion Deuda'!C4*B3/Financiacion!$C$4)-('Amortizacion Deuda'!D4*B3/Financiacion!$C$4)-MAX(0,'Flujos de Caja'!F5-('Amortizacion Deuda'!C4*B3/Financiacion!$C$4))*Supuestos!$B$23 -> -1333.3022 | J3: ='Flujos de Caja'!D6-('Amortizacion Deuda'!C5*B3/Financiacion!$C$4)-('Amortizacion Deuda'!D5*B3/Financiacion!$C$4)-MAX(0,'Flujos de Caja'!F6-('Amortizacion Deuda'!C5*B3/Financiacion!$C$4))*Supuestos!$B$23 -> -1320.6234 | K3: ='Flujos de Caja'!D7-('Amortizacion Deuda'!C6*B3/Financiacion!$C$4)-('Amortizacion Deuda'!D6*B3/Financiacion!$C$4)-MAX(0,'Flujos de Caja'!F7-('Amortizacion Deuda'!C6*B3/Financiacion!$C$4))*Supuestos!$B$23 -> -1307.5009 | L3: ='Flujos de Caja'!D8-('Amortizacion Deuda'!C7*B3/Financiacion!$C$4)-('Amortizacion Deuda'!D7*B3/Financiacion!$C$4)-MAX(0,'Flujos de Caja'!F8-('Amortizacion Deuda'!C7*B3/Financiacion!$C$4))*Supuestos!$B$23 -> -1293.9191 | M3: ='Flujos de Caja'!D9-('Amortizacion Deuda'!C8*B3/Financiacion!$C$4)-('Amortizacion Deuda'!D8*B3/Financiacion!$C$4)-MAX(0,'Flujos de Caja'!F9-('Amortizacion Deuda'!C8*B3/Financiacion!$C$4))*Supuestos!$B$23 -> -1279.8619 | N3: ='Flujos de Caja'!D10-('Amortizacion Deuda'!C9*B3/Financiacion!$C$4)-('Amortizacion Deuda'!D9*B3/Financiacion!$C$4)-MAX(0,'Flujos de Caja'!F10-('Amortizacion Deuda'!C9*B3/Financiacion!$C$4))*Supuestos!$B$23 -> -1265.3128 | O3: ='Flujos de Caja'!D11-('Amortizacion Deuda'!C10*B3/Financiacion!$C$4)-('Amortizacion Deuda'!D10*B3/Financiacion!$C$4)-MAX(0,'Flujos de Caja'!F11-('Amortizacion Deuda'!C10*B3/Financiacion!$C$4))*Supuestos!$B$23 -> -1250.2544 | P3: ='Flujos de Caja'!D12-('Amortizacion Deuda'!C11*B3/Financiacion!$C$4)-('Amortizacion Deuda'!D11*B3/Financiacion!$C$4)-MAX(0,'Flujos de Caja'!F12-('Amortizacion Deuda'!C11*B3/Financiacion!$C$4))*Supuestos!$B$23 -> -1234.669 | Q3: ='Flujos de Caja'!D13-('Amortizacion Deuda'!C12*B3/Financiacion!$C$4)-('Amortizacion Deuda'!D12*B3/Financiacion!$C$4)-MAX(0,'Flujos de Caja'!F13-('Amortizacion Deuda'!C12*B3/Financiacion!$C$4))*Supuestos!$B$23 -> -1218.5381 | R3: ='Flujos de Caja'!D14-('Amortizacion Deuda'!C13*B3/Financiacion!$C$4)-('Amortizacion Deuda'!D13*B3/Financiacion!$C$4)-MAX(0,'Flujos de Caja'!F14-('Amortizacion Deuda'!C13*B3/Financiacion!$C$4))*Supuestos!$B$23 -> 493.70957 | S3: ='Flujos de Caja'!D15-('Amortizacion Deuda'!C14*B3/Financiacion!$C$4)-('Amortizacion Deuda'!D14*B3/Financiacion!$C$4)-MAX(0,'Flujos de Caja'!F15-('Amortizacion Deuda'!C14*B3/Financiacion!$C$4))*Supuestos!$B$23 -> 510.9894 | T3: ='Flujos de Caja'!D16-('Amortizacion Deuda'!C15*B3/Financiacion!$C$4)-('Amortizacion Deuda'!D15*B3/Financiacion!$C$4)-MAX(0,'Flujos de Caja'!F16-('Amortizacion Deuda'!C15*B3/Financiacion!$C$4))*Supuestos!$B$23 -> 528.87403 | U3: ='Flujos de Caja'!D17-('Amortizacion Deuda'!C16*B3/Financiacion!$C$4)-('Amortizacion Deuda'!D16*B3/Financiacion!$C$4)-MAX(0,'Flujos de Caja'!F17-('Amortizacion Deuda'!C16*B3/Financiacion!$C$4))*Supuestos!$B$23 -> 547.38462 | V3: ='Flujos de Caja'!D18-('Amortizacion Deuda'!C17*B3/Financiacion!$C$4)-('Amortizacion Deuda'!D17*B3/Financiacion!$C$4)-MAX(0,'Flujos de Caja'!F18-('Amortizacion Deuda'!C17*B3/Financiacion!$C$4))*Supuestos!$B$23 -> 566.54308 | W3: ='Flujos de Caja'!D19-('Amortizacion Deuda'!C18*B3/Financiacion!$C$4)-('Amortizacion Deuda'!D18*B3/Financiacion!$C$4)-MAX(0,'Flujos de Caja'!F19-('Amortizacion Deuda'!C18*B3/Financiacion!$C$4))*Supuestos!$B$23 -> 586.37209 | X3: ='Flujos de Caja'!D20-('Amortizacion Deuda'!C19*B3/Financiacion!$C$4)-('Amortizacion Deuda'!D19*B3/Financiacion!$C$4)-MAX(0,'Flujos de Caja'!F20-('Amortizacion Deuda'!C19*B3/Financiacion!$C$4))*Supuestos!$B$23 -> 606.89511 | Y3: ='Flujos de Caja'!D21-('Amortizacion Deuda'!C20*B3/Financiacion!$C$4)-('Amortizacion Deuda'!D20*B3/Financiacion!$C$4)-MAX(0,'Flujos de Caja'!F21-('Amortizacion Deuda'!C20*B3/Financiacion!$C$4))*Supuestos!$B$23 -> 628.13644 | Z3: ='Flujos de Caja'!D22-('Amortizacion Deuda'!C21*B3/Financiacion!$C$4)-('Amortizacion Deuda'!D21*B3/Financiacion!$C$4)-MAX(0,'Flujos de Caja'!F22-('Amortizacion Deuda'!C21*B3/Financiacion!$C$4))*Supuestos!$B$23 -> 650.12122 | AA3: ='Flujos de Caja'!D23-('Amortizacion Deuda'!C22*B3/Financiacion!$C$4)-('Amortizacion Deuda'!D22*B3/Financiacion!$C$4)-MAX(0,'Flujos de Caja'!F23-('Amortizacion Deuda'!C22*B3/Financiacion!$C$4))*Supuestos!$B$23 -> 672.87546 | AB3: ='Flujos de Caja'!D24-('Amortizacion Deuda'!C23*B3/Financiacion!$C$4)-('Amortizacion Deuda'!D23*B3/Financiacion!$C$4)-MAX(0,'Flujos de Caja'!F24-('Amortizacion Deuda'!C23*B3/Financiacion!$C$4))*Supuestos!$B$23 -> 696.4261 | AC3: ='Flujos de Caja'!D25-('Amortizacion Deuda'!C24*B3/Financiacion!$C$4)-('Amortizacion Deuda'!D24*B3/Financiacion!$C$4)-MAX(0,'Flujos de Caja'!F25-('Amortizacion Deuda'!C24*B3/Financiacion!$C$4))*Supuestos!$B$23 -> 720.80102 | AD3: ='Flujos de Caja'!D26-('Amortizacion Deuda'!C25*B3/Financiacion!$C$4)-('Amortizacion Deuda'!D25*B3/Financiacion!$C$4)-MAX(0,'Flujos de Caja'!F26-('Amortizacion Deuda'!C25*B3/Financiacion!$C$4))*Supuestos!$B$23 -> 746.02905 | AE3: ='Flujos de Caja'!D27-('Amortizacion Deuda'!C26*B3/Financiacion!$C$4)-('Amortizacion Deuda'!D26*B3/Financiacion!$C$4)-MAX(0,'Flujos de Caja'!F27-('Amortizacion Deuda'!C26*B3/Financiacion!$C$4))*Supuestos!$B$23 -> 772.14007 | AF3: ='Flujos de Caja'!D28-('Amortizacion Deuda'!C27*B3/Financiacion!$C$4)-('Amortizacion Deuda'!D27*B3/Financiacion!$C$4)-MAX(0,'Flujos de Caja'!F28-('Amortizacion Deuda'!C27*B3/Financiacion!$C$4))*Supuestos!$B$23 -> 799.05123
A4: 0.4 | B4: =(1-A4)/2*Presupuesto!$B$9 -> 5991.3 | C4: =(1-A4)/2*Presupuesto!$B$9 -> 5991.3 | D4: =IRR(G4:AF4) -> -0.014606346 | E4: =NPV(Supuestos!$B$22,H4:AF4)+G4 -> -8262.18 | F4: =IF(D4>=Supuestos!$B$22,"Viable","No viable") -> No viable | G4: =-C4 -> -5991.3 | H4: ='Flujos de Caja'!D4-('Amortizacion Deuda'!C3*B4/Financiacion!$C$4)-('Amortizacion Deuda'!D3*B4/Financiacion!$C$4)-MAX(0,'Flujos de Caja'!F4-('Amortizacion Deuda'!C3*B4/Financiacion!$C$4))*Supuestos!$B$23 -> -667.33129 | I4: ='Flujos de Caja'!D5-('Amortizacion Deuda'!C4*B4/Financiacion!$C$4)-('Amortizacion Deuda'!D4*B4/Financiacion!$C$4)-MAX(0,'Flujos de Caja'!F5-('Amortizacion Deuda'!C4*B4/Financiacion!$C$4))*Supuestos!$B$23 -> -655.08129 | J4: ='Flujos de Caja'!D6-('Amortizacion Deuda'!C5*B4/Financiacion!$C$4)-('Amortizacion Deuda'!D5*B4/Financiacion!$C$4)-MAX(0,'Flujos de Caja'!F6-('Amortizacion Deuda'!C5*B4/Financiacion!$C$4))*Supuestos!$B$23 -> -642.40254 | K4: ='Flujos de Caja'!D7-('Amortizacion Deuda'!C6*B4/Financiacion!$C$4)-('Amortizacion Deuda'!D6*B4/Financiacion!$C$4)-MAX(0,'Flujos de Caja'!F7-('Amortizacion Deuda'!C6*B4/Financiacion!$C$4))*Supuestos!$B$23 -> -629.28003 | L4: ='Flujos de Caja'!D8-('Amortizacion Deuda'!C7*B4/Financiacion!$C$4)-('Amortizacion Deuda'!D7*B4/Financiacion!$C$4)-MAX(0,'Flujos de Caja'!F8-('Amortizacion Deuda'!C7*B4/Financiacion!$C$4))*Supuestos!$B$23 -> -615.69824 | M4: ='Flujos de Caja'!D9-('Amortizacion Deuda'!C8*B4/Financiacion!$C$4)-('Amortizacion Deuda'!D8*B4/Financiacion!$C$4)-MAX(0,'Flujos de Caja'!F9-('Amortizacion Deuda'!C8*B4/Financiacion!$C$4))*Supuestos!$B$23 -> -601.64108 | N4: ='Flujos de Caja'!D10-('Amortizacion Deuda'!C9*B4/Financiacion!$C$4)-('Amortizacion Deuda'!D9*B4/Financiacion!$C$4)-MAX(0,'Flujos de Caja'!F10-('Amortizacion Deuda'!C9*B4/Financiacion!$C$4))*Supuestos!$B$23 -> -587.09193 | O4: ='Flujos de Caja'!D11-('Amortizacion Deuda'!C10*B4/Financiacion!$C$4)-('Amortizacion Deuda'!D10*B4/Financiacion!$C$4)-MAX(0,'Flujos de Caja'!F11-('Amortizacion Deuda'!C10*B4/Financiacion!$C$4))*Supuestos!$B$23 -> -572.03355 | P4: ='Flujos de Caja'!D12-('Amortizacion Deuda'!C11*B4/Financiacion!$C$4)-('Amortizacion Deuda'!D11*B4/Financiacion!$C$4)-MAX(0,'Flujos de Caja'!F12-('Amortizacion Deuda'!C11*B4/Financiacion!$C$4))*Supuestos!$B$23 -> -556.44813 | Q4: ='Flujos de Caja'!D13-('Amortizacion Deuda'!C12*B4/Financiacion!$C$4)-('Amortizacion Deuda'!D12*B4/Financiacion!$C$4)-MAX(0,'Flujos de Caja'!F13-('Amortizacion Deuda'!C12*B4/Financiacion!$C$4))*Supuestos!$B$23 -> -540.31722 | R4: ='Flujos de Caja'!D14-('Amortizacion Deuda'!C13*B4/Financiacion!$C$4)-('Amortizacion Deuda'!D13*B4/Financiacion!$C$4)-MAX(0,'Flujos de Caja'!F14-('Amortizacion Deuda'!C13*B4/Financiacion!$C$4))*Supuestos!$B$23 -> 493.70957 | S4: ='Flujos de Caja'!D15-('Amortizacion Deuda'!C14*B4/Financiacion!$C$4)-('Amortizacion Deuda'!D14*B4/Financiacion!$C$4)-MAX(0,'Flujos de Caja'!F15-('Amortizacion Deuda'!C14*B4/Financiacion!$C$4))*Supuestos!$B$23 -> 510.9894 | T4: ='Flujos de Caja'!D16-('Amortizacion Deuda'!C15*B4/Financiacion!$C$4)-('Amortizacion Deuda'!D15*B4/Financiacion!$C$4)-MAX(0,'Flujos de Caja'!F16-('Amortizacion Deuda'!C15*B4/Financiacion!$C$4))*Supuestos!$B$23 -> 528.87403 | U4: ='Flujos de Caja'!D17-('Amortizacion Deuda'!C16*B4/Financiacion!$C$4)-('Amortizacion Deuda'!D16*B4/Financiacion!$C$4)-MAX(0,'Flujos de Caja'!F17-('Amortizacion Deuda'!C16*B4/Financiacion!$C$4))*Supuestos!$B$23 -> 547.38462 | V4: ='Flujos de Caja'!D18-('Amortizacion Deuda'!C17*B4/Financiacion!$C$4)-('Amortizacion Deuda'!D17*B4/Financiacion!$C$4)-MAX(0,'Flujos de Caja'!F18-('Amortizacion Deuda'!C17*B4/Financiacion!$C$4))*Supuestos!$B$23 -> 566.54308 | W4: ='Flujos de Caja'!D19-('Amortizacion Deuda'!C18*B4/Financiacion!$C$4)-('Amortizacion Deuda'!D18*B4/Financiacion!$C$4)-MAX(0,'Flujos de Caja'!F19-('Amortizacion Deuda'!C18*B4/Financiacion!$C$4))*Supuestos!$B$23 -> 586.37209 | X4: ='Flujos de Caja'!D20-('Amortizacion Deuda'!C19*B4/Financiacion!$C$4)-('Amortizacion Deuda'!D19*B4/Financiacion!$C$4)-MAX(0,'Flujos de Caja'!F20-('Amortizacion Deuda'!C19*B4/Financiacion!$C$4))*Supuestos!$B$23 -> 606.89511 | Y4: ='Flujos de Caja'!D21-('Amortizacion Deuda'!C20*B4/Financiacion!$C$4)-('Amortizacion Deuda'!D20*B4/Financiacion!$C$4)-MAX(0,'Flujos de Caja'!F21-('Amortizacion Deuda'!C20*B4/Financiacion!$C$4))*Supuestos!$B$23 -> 628.13644 | Z4: ='Flujos de Caja'!D22-('Amortizacion Deuda'!C21*B4/Financiacion!$C$4)-('Amortizacion Deuda'!D21*B4/Financiacion!$C$4)-MAX(0,'Flujos de Caja'!F22-('Amortizacion Deuda'!C21*B4/Financiacion!$C$4))*Supuestos!$B$23 -> 650.12122 | AA4: ='Flujos de Caja'!D23-('Amortizacion Deuda'!C22*B4/Financiacion!$C$4)-('Amortizacion Deuda'!D22*B4/Financiacion!$C$4)-MAX(0,'Flujos de Caja'!F23-('Amortizacion Deuda'!C22*B4/Financiacion!$C$4))*Supuestos!$B$23 -> 672.87546 | AB4: ='Flujos de Caja'!D24-('Amortizacion Deuda'!C23*B4/Financiacion!$C$4)-('Amortizacion Deuda'!D23*B4/Financiacion!$C$4)-MAX(0,'Flujos de Caja'!F24-('Amortizacion Deuda'!C23*B4/Financiacion!$C$4))*Supuestos!$B$23 -> 696.4261 | AC4: ='Flujos de Caja'!D25-('Amortizacion Deuda'!C24*B4/Financiacion!$C$4)-('Amortizacion Deuda'!D24*B4/Financiacion!$C$4)-MAX(0,'Flujos de Caja'!F25-('Amortizacion Deuda'!C24*B4/Financiacion!$C$4))*Supuestos!$B$23 -> 720.80102 | AD4: ='Flujos de Caja'!D26-('Amortizacion Deuda'!C25*B4/Financiacion!$C$4)-('Amortizacion Deuda'!D25*B4/Financiacion!$C$4)-MAX(0,'Flujos de Caja'!F26-('Amortizacion Deuda'!C25*B4/Financiacion!$C$4))*Supuestos!$B$23 -> 746.02905 | AE4: ='Flujos de Caja'!D27-('Amortizacion Deuda'!C26*B4/Financiacion!$C$4)-('Amortizacion Deuda'!D26*B4/Financiacion!$C$4)-MAX(0,'Flujos de Caja'!F27-('Amortizacion Deuda'!C26*B4/Financiacion!$C$4))*Supuestos!$B$23 -> 772.14007 | AF4: ='Flujos de Caja'!D28-('Amortizacion Deuda'!C27*B4/Financiacion!$C$4)-('Amortizacion Deuda'!D27*B4/Financiacion!$C$4)-MAX(0,'Flujos de Caja'!F28-('Amortizacion Deuda'!C27*B4/Financiacion!$C$4))*Supuestos!$B$23 -> 799.05123
A5: 0.6 | B5: =(1-A5)/2*Presupuesto!$B$9 -> 3994.2 | C5: =(1-A5)/2*Presupuesto!$B$9 -> 3994.2 | D5: =IRR(G5:AF5) -> 0.021826211 | E5: =NPV(Supuestos!$B$22,H5:AF5)+G5 -> -4496.2407 | F5: =IF(D5>=Supuestos!$B$22,"Viable","No viable") -> No viable | G5: =-C5 -> -3994.2 | H5: ='Flujos de Caja'!D4-('Amortizacion Deuda'!C3*B5/Financiacion!$C$4)-('Amortizacion Deuda'!D3*B5/Financiacion!$C$4)-MAX(0,'Flujos de Caja'!F4-('Amortizacion Deuda'!C3*B5/Financiacion!$C$4))*Supuestos!$B$23 -> -328.22086 | I5: ='Flujos de Caja'!D5-('Amortizacion Deuda'!C4*B5/Financiacion!$C$4)-('Amortizacion Deuda'!D4*B5/Financiacion!$C$4)-MAX(0,'Flujos de Caja'!F5-('Amortizacion Deuda'!C4*B5/Financiacion!$C$4))*Supuestos!$B$23 -> -315.97086 | J5: ='Flujos de Caja'!D6-('Amortizacion Deuda'!C5*B5/Financiacion!$C$4)-('Amortizacion Deuda'!D5*B5/Financiacion!$C$4)-MAX(0,'Flujos de Caja'!F6-('Amortizacion Deuda'!C5*B5/Financiacion!$C$4))*Supuestos!$B$23 -> -303.29211 | K5: ='Flujos de Caja'!D7-('Amortizacion Deuda'!C6*B5/Financiacion!$C$4)-('Amortizacion Deuda'!D6*B5/Financiacion!$C$4)-MAX(0,'Flujos de Caja'!F7-('Amortizacion Deuda'!C6*B5/Financiacion!$C$4))*Supuestos!$B$23 -> -290.1696 | L5: ='Flujos de Caja'!D8-('Amortizacion Deuda'!C7*B5/Financiacion!$C$4)-('Amortizacion Deuda'!D7*B5/Financiacion!$C$4)-MAX(0,'Flujos de Caja'!F8-('Amortizacion Deuda'!C7*B5/Financiacion!$C$4))*Supuestos!$B$23 -> -276.58781 | M5: ='Flujos de Caja'!D9-('Amortizacion Deuda'!C8*B5/Financiacion!$C$4)-('Amortizacion Deuda'!D8*B5/Financiacion!$C$4)-MAX(0,'Flujos de Caja'!F9-('Amortizacion Deuda'!C8*B5/Financiacion!$C$4))*Supuestos!$B$23 -> -262.53065 | N5: ='Flujos de Caja'!D10-('Amortizacion Deuda'!C9*B5/Financiacion!$C$4)-('Amortizacion Deuda'!D9*B5/Financiacion!$C$4)-MAX(0,'Flujos de Caja'!F10-('Amortizacion Deuda'!C9*B5/Financiacion!$C$4))*Supuestos!$B$23 -> -247.9815 | O5: ='Flujos de Caja'!D11-('Amortizacion Deuda'!C10*B5/Financiacion!$C$4)-('Amortizacion Deuda'!D10*B5/Financiacion!$C$4)-MAX(0,'Flujos de Caja'!F11-('Amortizacion Deuda'!C10*B5/Financiacion!$C$4))*Supuestos!$B$23 -> -232.92312 | P5: ='Flujos de Caja'!D12-('Amortizacion Deuda'!C11*B5/Financiacion!$C$4)-('Amortizacion Deuda'!D11*B5/Financiacion!$C$4)-MAX(0,'Flujos de Caja'!F12-('Amortizacion Deuda'!C11*B5/Financiacion!$C$4))*Supuestos!$B$23 -> -217.3377 | Q5: ='Flujos de Caja'!D13-('Amortizacion Deuda'!C12*B5/Financiacion!$C$4)-('Amortizacion Deuda'!D12*B5/Financiacion!$C$4)-MAX(0,'Flujos de Caja'!F13-('Amortizacion Deuda'!C12*B5/Financiacion!$C$4))*Supuestos!$B$23 -> -201.20679 | R5: ='Flujos de Caja'!D14-('Amortizacion Deuda'!C13*B5/Financiacion!$C$4)-('Amortizacion Deuda'!D13*B5/Financiacion!$C$4)-MAX(0,'Flujos de Caja'!F14-('Amortizacion Deuda'!C13*B5/Financiacion!$C$4))*Supuestos!$B$23 -> 493.70957 | S5: ='Flujos de Caja'!D15-('Amortizacion Deuda'!C14*B5/Financiacion!$C$4)-('Amortizacion Deuda'!D14*B5/Financiacion!$C$4)-MAX(0,'Flujos de Caja'!F15-('Amortizacion Deuda'!C14*B5/Financiacion!$C$4))*Supuestos!$B$23 -> 510.9894 | T5: ='Flujos de Caja'!D16-('Amortizacion Deuda'!C15*B5/Financiacion!$C$4)-('Amortizacion Deuda'!D15*B5/Financiacion!$C$4)-MAX(0,'Flujos de Caja'!F16-('Amortizacion Deuda'!C15*B5/Financiacion!$C$4))*Supuestos!$B$23 -> 528.87403 | U5: ='Flujos de Caja'!D17-('Amortizacion Deuda'!C16*B5/Financiacion!$C$4)-('Amortizacion Deuda'!D16*B5/Financiacion!$C$4)-MAX(0,'Flujos de Caja'!F17-('Amortizacion Deuda'!C16*B5/Financiacion!$C$4))*Supuestos!$B$23 -> 547.38462 | V5: ='Flujos de Caja'!D18-('Amortizacion Deuda'!C17*B5/Financiacion!$C$4)-('Amortizacion Deuda'!D17*B5/Financiacion!$C$4)-MAX(0,'Flujos de Caja'!F18-('Amortizacion Deuda'!C17*B5/Financiacion!$C$4))*Supuestos!$B$23 -> 566.54308 | W5: ='Flujos de Caja'!D19-('Amortizacion Deuda'!C18*B5/Financiacion!$C$4)-('Amortizacion Deuda'!D18*B5/Financiacion!$C$4)-MAX(0,'Flujos de Caja'!F19-('Amortizacion Deuda'!C18*B5/Financiacion!$C$4))*Supuestos!$B$23 -> 586.37209 | X5: ='Flujos de Caja'!D20-('Amortizacion Deuda'!C19*B5/Financiacion!$C$4)-('Amortizacion Deuda'!D19*B5/Financiacion!$C$4)-MAX(0,'Flujos de Caja'!F20-('Amortizacion Deuda'!C19*B5/Financiacion!$C$4))*Supuestos!$B$23 -> 606.89511 | Y5: ='Flujos de Caja'!D21-('Amortizacion Deuda'!C20*B5/Financiacion!$C$4)-('Amortizacion Deuda'!D20*B5/Financiacion!$C$4)-MAX(0,'Flujos de Caja'!F21-('Amortizacion Deuda'!C20*B5/Financiacion!$C$4))*Supuestos!$B$23 -> 628.13644 | Z5: ='Flujos de Caja'!D22-('Amortizacion Deuda'!C21*B5/Financiacion!$C$4)-('Amortizacion Deuda'!D21*B5/Financiacion!$C$4)-MAX(0,'Flujos de Caja'!F22-('Amortizacion Deuda'!C21*B5/Financiacion!$C$4))*Supuestos!$B$23 -> 650.12122 | AA5: ='Flujos de Caja'!D23-('Amortizacion Deuda'!C22*B5/Financiacion!$C$4)-('Amortizacion Deuda'!D22*B5/Financiacion!$C$4)-MAX(0,'Flujos de Caja'!F23-('Amortizacion Deuda'!C22*B5/Financiacion!$C$4))*Supuestos!$B$23 -> 672.87546 | AB5: ='Flujos de Caja'!D24-('Amortizacion Deuda'!C23*B5/Financiacion!$C$4)-('Amortizacion Deuda'!D23*B5/Financiacion!$C$4)-MAX(0,'Flujos de Caja'!F24-('Amortizacion Deuda'!C23*B5/Financiacion!$C$4))*Supuestos!$B$23 -> 696.4261 | AC5: ='Flujos de Caja'!D25-('Amortizacion Deuda'!C24*B5/Financiacion!$C$4)-('Amortizacion Deuda'!D24*B5/Financiacion!$C$4)-MAX(0,'Flujos de Caja'!F25-('Amortizacion Deuda'!C24*B5/Financiacion!$C$4))*Supuestos!$B$23 -> 720.80102 | AD5: ='Flujos de Caja'!D26-('Amortizacion Deuda'!C25*B5/Financiacion!$C$4)-('Amortizacion Deuda'!D25*B5/Financiacion!$C$4)-MAX(0,'Flujos de Caja'!F26-('Amortizacion Deuda'!C25*B5/Financiacion!$C$4))*Supuestos!$B$23 -> 746.02905 | AE5: ='Flujos de Caja'!D27-('Amortizacion Deuda'!C26*B5/Financiacion!$C$4)-('Amortizacion Deuda'!D26*B5/Financiacion!$C$4)-MAX(0,'Flujos de Caja'!F27-('Amortizacion Deuda'!C26*B5/Financiacion!$C$4))*Supuestos!$B$23 -> 772.14007 | AF5: ='Flujos de Caja'!D28-('Amortizacion Deuda'!C27*B5/Financiacion!$C$4)-('Amortizacion Deuda'!D27*B5/Financiacion!$C$4)-MAX(0,'Flujos de Caja'!F28-('Amortizacion Deuda'!C27*B5/Financiacion!$C$4))*Supuestos!$B$23 -> 799.05123
A6: 0.7 | B6: =(1-A6)/2*Presupuesto!$B$9 -> 2995.65 | C6: =(1-A6)/2*Presupuesto!$B$9 -> 2995.65 | D6: =IRR(G6:AF6) -> 0.052036324 | E6: =NPV(Supuestos!$B$22,H6:AF6)+G6 -> -2613.2711 | F6: =IF(D6>=Supuestos!$B$22,"Viable","No viable") -> No viable | G6: =-C6 -> -2995.65 | H6: ='Flujos de Caja'!D4-('Amortizacion Deuda'!C3*B6/Financiacion!$C$4)-('Amortizacion Deuda'!D3*B6/Financiacion!$C$4)-MAX(0,'Flujos de Caja'!F4-('Amortizacion Deuda'!C3*B6/Financiacion!$C$4))*Supuestos!$B$23 -> -158.66565 | I6: ='Flujos de Caja'!D5-('Amortizacion Deuda'!C4*B6/Financiacion!$C$4)-('Amortizacion Deuda'!D4*B6/Financiacion!$C$4)-MAX(0,'Flujos de Caja'!F5-('Amortizacion Deuda'!C4*B6/Financiacion!$C$4))*Supuestos!$B$23 -> -146.41565 | J6: ='Flujos de Caja'!D6-('Amortizacion Deuda'!C5*B6/Financiacion!$C$4)-('Amortizacion Deuda'!D5*B6/Financiacion!$C$4)-MAX(0,'Flujos de Caja'!F6-('Amortizacion Deuda'!C5*B6/Financiacion!$C$4))*Supuestos!$B$23 -> -133.7369 | K6: ='Flujos de Caja'!D7-('Amortizacion Deuda'!C6*B6/Financiacion!$C$4)-('Amortizacion Deuda'!D6*B6/Financiacion!$C$4)-MAX(0,'Flujos de Caja'!F7-('Amortizacion Deuda'!C6*B6/Financiacion!$C$4))*Supuestos!$B$23 -> -120.61439 | L6: ='Flujos de Caja'!D8-('Amortizacion Deuda'!C7*B6/Financiacion!$C$4)-('Amortizacion Deuda'!D7*B6/Financiacion!$C$4)-MAX(0,'Flujos de Caja'!F8-('Amortizacion Deuda'!C7*B6/Financiacion!$C$4))*Supuestos!$B$23 -> -107.03259 | M6: ='Flujos de Caja'!D9-('Amortizacion Deuda'!C8*B6/Financiacion!$C$4)-('Amortizacion Deuda'!D8*B6/Financiacion!$C$4)-MAX(0,'Flujos de Caja'!F9-('Amortizacion Deuda'!C8*B6/Financiacion!$C$4))*Supuestos!$B$23 -> -92.975438 | N6: ='Flujos de Caja'!D10-('Amortizacion Deuda'!C9*B6/Financiacion!$C$4)-('Amortizacion Deuda'!D9*B6/Financiacion!$C$4)-MAX(0,'Flujos de Caja'!F10-('Amortizacion Deuda'!C9*B6/Financiacion!$C$4))*Supuestos!$B$23 -> -78.426281 | O6: ='Flujos de Caja'!D11-('Amortizacion Deuda'!C10*B6/Financiacion!$C$4)-('Amortizacion Deuda'!D10*B6/Financiacion!$C$4)-MAX(0,'Flujos de Caja'!F11-('Amortizacion Deuda'!C10*B6/Financiacion!$C$4))*Supuestos!$B$23 -> -63.367903 | P6: ='Flujos de Caja'!D12-('Amortizacion Deuda'!C11*B6/Financiacion!$C$4)-('Amortizacion Deuda'!D11*B6/Financiacion!$C$4)-MAX(0,'Flujos de Caja'!F12-('Amortizacion Deuda'!C11*B6/Financiacion!$C$4))*Supuestos!$B$23 -> -47.782482 | Q6: ='Flujos de Caja'!D13-('Amortizacion Deuda'!C12*B6/Financiacion!$C$4)-('Amortizacion Deuda'!D12*B6/Financiacion!$C$4)-MAX(0,'Flujos de Caja'!F13-('Amortizacion Deuda'!C12*B6/Financiacion!$C$4))*Supuestos!$B$23 -> -31.651571 | R6: ='Flujos de Caja'!D14-('Amortizacion Deuda'!C13*B6/Financiacion!$C$4)-('Amortizacion Deuda'!D13*B6/Financiacion!$C$4)-MAX(0,'Flujos de Caja'!F14-('Amortizacion Deuda'!C13*B6/Financiacion!$C$4))*Supuestos!$B$23 -> 493.70957 | S6: ='Flujos de Caja'!D15-('Amortizacion Deuda'!C14*B6/Financiacion!$C$4)-('Amortizacion Deuda'!D14*B6/Financiacion!$C$4)-MAX(0,'Flujos de Caja'!F15-('Amortizacion Deuda'!C14*B6/Financiacion!$C$4))*Supuestos!$B$23 -> 510.9894 | T6: ='Flujos de Caja'!D16-('Amortizacion Deuda'!C15*B6/Financiacion!$C$4)-('Amortizacion Deuda'!D15*B6/Financiacion!$C$4)-MAX(0,'Flujos de Caja'!F16-('Amortizacion Deuda'!C15*B6/Financiacion!$C$4))*Supuestos!$B$23 -> 528.87403 | U6: ='Flujos de Caja'!D17-('Amortizacion Deuda'!C16*B6/Financiacion!$C$4)-('Amortizacion Deuda'!D16*B6/Financiacion!$C$4)-MAX(0,'Flujos de Caja'!F17-('Amortizacion Deuda'!C16*B6/Financiacion!$C$4))*Supuestos!$B$23 -> 547.38462 | V6: ='Flujos de Caja'!D18-('Amortizacion Deuda'!C17*B6/Financiacion!$C$4)-('Amortizacion Deuda'!D17*B6/Financiacion!$C$4)-MAX(0,'Flujos de Caja'!F18-('Amortizacion Deuda'!C17*B6/Financiacion!$C$4))*Supuestos!$B$23 -> 566.54308 | W6: ='Flujos de Caja'!D19-('Amortizacion Deuda'!C18*B6/Financiacion!$C$4)-('Amortizacion Deuda'!D18*B6/Financiacion!$C$4)-MAX(0,'Flujos de Caja'!F19-('Amortizacion Deuda'!C18*B6/Financiacion!$C$4))*Supuestos!$B$23 -> 586.37209 | X6: ='Flujos de Caja'!D20-('Amortizacion Deuda'!C19*B6/Financiacion!$C$4)-('Amortizacion Deuda'!D19*B6/Financiacion!$C$4)-MAX(0,'Flujos de Caja'!F20-('Amortizacion Deuda'!C19*B6/Financiacion!$C$4))*Supuestos!$B$23 -> 606.89511 | Y6: ='Flujos de Caja'!D21-('Amortizacion Deuda'!C20*B6/Financiacion!$C$4)-('Amortizacion Deuda'!D20*B6/Financiacion!$C$4)-MAX(0,'Flujos de Caja'!F21-('Amortizacion Deuda'!C20*B6/Financiacion!$C$4))*Supuestos!$B$23 -> 628.13644 | Z6: ='Flujos de Caja'!D22-('Amortizacion Deuda'!C21*B6/Financiacion!$C$4)-('Amortizacion Deuda'!D21*B6/Financiacion!$C$4)-MAX(0,'Flujos de Caja'!F22-('Amortizacion Deuda'!C21*B6/Financiacion!$C$4))*Supuestos!$B$23 -> 650.12122 | AA6: ='Flujos de Caja'!D23-('Amortizacion Deuda'!C22*B6/Financiacion!$C$4)-('Amortizacion Deuda'!D22*B6/Financiacion!$C$4)-MAX(0,'Flujos de Caja'!F23-('Amortizacion Deuda'!C22*B6/Financiacion!$C$4))*Supuestos!$B$23 -> 672.87546 | AB6: ='Flujos de Caja'!D24-('Amortizacion Deuda'!C23*B6/Financiacion!$C$4)-('Amortizacion Deuda'!D23*B6/Financiacion!$C$4)-MAX(0,'Flujos de Caja'!F24-('Amortizacion Deuda'!C23*B6/Financiacion!$C$4))*Supuestos!$B$23 -> 696.4261 | AC6: ='Flujos de Caja'!D25-('Amortizacion Deuda'!C24*B6/Financiacion!$C$4)-('Amortizacion Deuda'!D24*B6/Financiacion!$C$4)-MAX(0,'Flujos de Caja'!F25-('Amortizacion Deuda'!C24*B6/Financiacion!$C$4))*Supuestos!$B$23 -> 720.80102 | AD6: ='Flujos de Caja'!D26-('Amortizacion Deuda'!C25*B6/Financiacion!$C$4)-('Amortizacion Deuda'!D25*B6/Financiacion!$C$4)-MAX(0,'Flujos de Caja'!F26-('Amortizacion Deuda'!C25*B6/Financiacion!$C$4))*Supuestos!$B$23 -> 746.02905 | AE6: ='Flujos de Caja'!D27-('Amortizacion Deuda'!C26*B6/Financiacion!$C$4)-('Amortizacion Deuda'!D26*B6/Financiacion!$C$4)-MAX(0,'Flujos de Caja'!F27-('Amortizacion Deuda'!C26*B6/Financiacion!$C$4))*Supuestos!$B$23 -> 772.14007 | AF6: ='Flujos de Caja'!D28-('Amortizacion Deuda'!C27*B6/Financiacion!$C$4)-('Amortizacion Deuda'!D27*B6/Financiacion!$C$4)-MAX(0,'Flujos de Caja'!F28-('Amortizacion Deuda'!C27*B6/Financiacion!$C$4))*Supuestos!$B$23 -> 799.05123
A7: 0.8 | B7: =(1-A7)/2*Presupuesto!$B$9 -> 1997.1 | C7: =(1-A7)/2*Presupuesto!$B$9 -> 1997.1 | D7: =IRR(G7:AF7) -> 0.10461089 | E7: =NPV(Supuestos!$B$22,H7:AF7)+G7 -> -730.30153 | F7: =IF(D7>=Supuestos!$B$22,"Viable","No viable") -> No viable | G7: =-C7 -> -1997.1 | H7: ='Flujos de Caja'!D4-('Amortizacion Deuda'!C3*B7/Financiacion!$C$4)-('Amortizacion Deuda'!D3*B7/Financiacion!$C$4)-MAX(0,'Flujos de Caja'!F4-('Amortizacion Deuda'!C3*B7/Financiacion!$C$4))*Supuestos!$B$23 -> 10.88957 | I7: ='Flujos de Caja'!D5-('Amortizacion Deuda'!C4*B7/Financiacion!$C$4)-('Amortizacion Deuda'!D4*B7/Financiacion!$C$4)-MAX(0,'Flujos de Caja'!F5-('Amortizacion Deuda'!C4*B7/Financiacion!$C$4))*Supuestos!$B$23 -> 23.13957 | J7: ='Flujos de Caja'!D6-('Amortizacion Deuda'!C5*B7/Financiacion!$C$4)-('Amortizacion Deuda'!D5*B7/Financiacion!$C$4)-MAX(0,'Flujos de Caja'!F6-('Amortizacion Deuda'!C5*B7/Financiacion!$C$4))*Supuestos!$B$23 -> 35.81832 | K7: ='Flujos de Caja'!D7-('Amortizacion Deuda'!C6*B7/Financiacion!$C$4)-('Amortizacion Deuda'!D6*B7/Financiacion!$C$4)-MAX(0,'Flujos de Caja'!F7-('Amortizacion Deuda'!C6*B7/Financiacion!$C$4))*Supuestos!$B$23 -> 48.940826 | L7: ='Flujos de Caja'!D8-('Amortizacion Deuda'!C7*B7/Financiacion!$C$4)-('Amortizacion Deuda'!D7*B7/Financiacion!$C$4)-MAX(0,'Flujos de Caja'!F8-('Amortizacion Deuda'!C7*B7/Financiacion!$C$4))*Supuestos!$B$23 -> 62.52262 | M7: ='Flujos de Caja'!D9-('Amortizacion Deuda'!C8*B7/Financiacion!$C$4)-('Amortizacion Deuda'!D8*B7/Financiacion!$C$4)-MAX(0,'Flujos de Caja'!F9-('Amortizacion Deuda'!C8*B7/Financiacion!$C$4))*Supuestos!$B$23 -> 76.579777 | N7: ='Flujos de Caja'!D10-('Amortizacion Deuda'!C9*B7/Financiacion!$C$4)-('Amortizacion Deuda'!D9*B7/Financiacion!$C$4)-MAX(0,'Flujos de Caja'!F10-('Amortizacion Deuda'!C9*B7/Financiacion!$C$4))*Supuestos!$B$23 -> 91.128934 | O7: ='Flujos de Caja'!D11-('Amortizacion Deuda'!C10*B7/Financiacion!$C$4)-('Amortizacion Deuda'!D10*B7/Financiacion!$C$4)-MAX(0,'Flujos de Caja'!F11-('Amortizacion Deuda'!C10*B7/Financiacion!$C$4))*Supuestos!$B$23 -> 106.18731 | P7: ='Flujos de Caja'!D12-('Amortizacion Deuda'!C11*B7/Financiacion!$C$4)-('Amortizacion Deuda'!D11*B7/Financiacion!$C$4)-MAX(0,'Flujos de Caja'!F12-('Amortizacion Deuda'!C11*B7/Financiacion!$C$4))*Supuestos!$B$23 -> 121.77273 | Q7: ='Flujos de Caja'!D13-('Amortizacion Deuda'!C12*B7/Financiacion!$C$4)-('Amortizacion Deuda'!D12*B7/Financiacion!$C$4)-MAX(0,'Flujos de Caja'!F13-('Amortizacion Deuda'!C12*B7/Financiacion!$C$4))*Supuestos!$B$23 -> 137.90364 | R7: ='Flujos de Caja'!D14-('Amortizacion Deuda'!C13*B7/Financiacion!$C$4)-('Amortizacion Deuda'!D13*B7/Financiacion!$C$4)-MAX(0,'Flujos de Caja'!F14-('Amortizacion Deuda'!C13*B7/Financiacion!$C$4))*Supuestos!$B$23 -> 493.70957 | S7: ='Flujos de Caja'!D15-('Amortizacion Deuda'!C14*B7/Financiacion!$C$4)-('Amortizacion Deuda'!D14*B7/Financiacion!$C$4)-MAX(0,'Flujos de Caja'!F15-('Amortizacion Deuda'!C14*B7/Financiacion!$C$4))*Supuestos!$B$23 -> 510.9894 | T7: ='Flujos de Caja'!D16-('Amortizacion Deuda'!C15*B7/Financiacion!$C$4)-('Amortizacion Deuda'!D15*B7/Financiacion!$C$4)-MAX(0,'Flujos de Caja'!F16-('Amortizacion Deuda'!C15*B7/Financiacion!$C$4))*Supuestos!$B$23 -> 528.87403 | U7: ='Flujos de Caja'!D17-('Amortizacion Deuda'!C16*B7/Financiacion!$C$4)-('Amortizacion Deuda'!D16*B7/Financiacion!$C$4)-MAX(0,'Flujos de Caja'!F17-('Amortizacion Deuda'!C16*B7/Financiacion!$C$4))*Supuestos!$B$23 -> 547.38462 | V7: ='Flujos de Caja'!D18-('Amortizacion Deuda'!C17*B7/Financiacion!$C$4)-('Amortizacion Deuda'!D17*B7/Financiacion!$C$4)-MAX(0,'Flujos de Caja'!F18-('Amortizacion Deuda'!C17*B7/Financiacion!$C$4))*Supuestos!$B$23 -> 566.54308 | W7: ='Flujos de Caja'!D19-('Amortizacion Deuda'!C18*B7/Financiacion!$C$4)-('Amortizacion Deuda'!D18*B7/Financiacion!$C$4)-MAX(0,'Flujos de Caja'!F19-('Amortizacion Deuda'!C18*B7/Financiacion!$C$4))*Supuestos!$B$23 -> 586.37209 | X7: ='Flujos de Caja'!D20-('Amortizacion Deuda'!C19*B7/Financiacion!$C$4)-('Amortizacion Deuda'!D19*B7/Financiacion!$C$4)-MAX(0,'Flujos de Caja'!F20-('Amortizacion Deuda'!C19*B7/Financiacion!$C$4))*Supuestos!$B$23 -> 606.89511 | Y7: ='Flujos de Caja'!D21-('Amortizacion Deuda'!C20*B7/Financiacion!$C$4)-('Amortizacion Deuda'!D20*B7/Financiacion!$C$4)-MAX(0,'Flujos de Caja'!F21-('Amortizacion Deuda'!C20*B7/Financiacion!$C$4))*Supuestos!$B$23 -> 628.13644 | Z7: ='Flujos de Caja'!D22-('Amortizacion Deuda'!C21*B7/Financiacion!$C$4)-('Amortizacion Deuda'!D21*B7/Financiacion!$C$4)-MAX(0,'Flujos de Caja'!F22-('Amortizacion Deuda'!C21*B7/Financiacion!$C$4))*Supuestos!$B$23 -> 650.12122 | AA7: ='Flujos de Caja'!D23-('Amortizacion Deuda'!C22*B7/Financiacion!$C$4)-('Amortizacion Deuda'!D22*B7/Financiacion!$C$4)-MAX(0,'Flujos de Caja'!F23-('Amortizacion Deuda'!C22*B7/Financiacion!$C$4))*Supuestos!$B$23 -> 672.87546 | AB7: ='Flujos de Caja'!D24-('Amortizacion Deuda'!C23*B7/Financiacion!$C$4)-('Amortizacion Deuda'!D23*B7/Financiacion!$C$4)-MAX(0,'Flujos de Caja'!F24-('Amortizacion Deuda'!C23*B7/Financiacion!$C$4))*Supuestos!$B$23 -> 696.4261 | AC7: ='Flujos de Caja'!D25-('Amortizacion Deuda'!C24*B7/Financiacion!$C$4)-('Amortizacion Deuda'!D24*B7/Financiacion!$C$4)-MAX(0,'Flujos de Caja'!F25-('Amortizacion Deuda'!C24*B7/Financiacion!$C$4))*Supuestos!$B$23 -> 720.80102 | AD7: ='Flujos de Caja'!D26-('Amortizacion Deuda'!C25*B7/Financiacion!$C$4)-('Amortizacion Deuda'!D25*B7/Financiacion!$C$4)-MAX(0,'Flujos de Caja'!F26-('Amortizacion Deuda'!C25*B7/Financiacion!$C$4))*Supuestos!$B$23 -> 746.02905 | AE7: ='Flujos de Caja'!D27-('Amortizacion Deuda'!C26*B7/Financiacion!$C$4)-('Amortizacion Deuda'!D26*B7/Financiacion!$C$4)-MAX(0,'Flujos de Caja'!F27-('Amortizacion Deuda'!C26*B7/Financiacion!$C$4))*Supuestos!$B$23 -> 772.14007 | AF7: ='Flujos de Caja'!D28-('Amortizacion Deuda'!C27*B7/Financiacion!$C$4)-('Amortizacion Deuda'!D27*B7/Financiacion!$C$4)-MAX(0,'Flujos de Caja'!F28-('Amortizacion Deuda'!C27*B7/Financiacion!$C$4))*Supuestos!$B$23 -> 799.05123
A8: 0.9 | B8: =(1-A8)/2*Presupuesto!$B$9 -> 998.55 | C8: =(1-A8)/2*Presupuesto!$B$9 -> 998.55 | D8: =IRR(G8:AF8) -> 0.25176856 | E8: =NPV(Supuestos!$B$22,H8:AF8)+G8 -> 1152.6681 | F8: =IF(D8>=Supuestos!$B$22,"Viable","No viable") -> Viable | G8: =-C8 -> -998.55 | H8: ='Flujos de Caja'!D4-('Amortizacion Deuda'!C3*B8/Financiacion!$C$4)-('Amortizacion Deuda'!D3*B8/Financiacion!$C$4)-MAX(0,'Flujos de Caja'!F4-('Amortizacion Deuda'!C3*B8/Financiacion!$C$4))*Supuestos!$B$23 -> 180.44478 | I8: ='Flujos de Caja'!D5-('Amortizacion Deuda'!C4*B8/Financiacion!$C$4)-('Amortizacion Deuda'!D4*B8/Financiacion!$C$4)-MAX(0,'Flujos de Caja'!F5-('Amortizacion Deuda'!C4*B8/Financiacion!$C$4))*Supuestos!$B$23 -> 192.69478 | J8: ='Flujos de Caja'!D6-('Amortizacion Deuda'!C5*B8/Financiacion!$C$4)-('Amortizacion Deuda'!D5*B8/Financiacion!$C$4)-MAX(0,'Flujos de Caja'!F6-('Amortizacion Deuda'!C5*B8/Financiacion!$C$4))*Supuestos!$B$23 -> 205.37353 | K8: ='Flujos de Caja'!D7-('Amortizacion Deuda'!C6*B8/Financiacion!$C$4)-('Amortizacion Deuda'!D6*B8/Financiacion!$C$4)-MAX(0,'Flujos de Caja'!F7-('Amortizacion Deuda'!C6*B8/Financiacion!$C$4))*Supuestos!$B$23 -> 218.49604 | L8: ='Flujos de Caja'!D8-('Amortizacion Deuda'!C7*B8/Financiacion!$C$4)-('Amortizacion Deuda'!D7*B8/Financiacion!$C$4)-MAX(0,'Flujos de Caja'!F8-('Amortizacion Deuda'!C7*B8/Financiacion!$C$4))*Supuestos!$B$23 -> 232.07784 | M8: ='Flujos de Caja'!D9-('Amortizacion Deuda'!C8*B8/Financiacion!$C$4)-('Amortizacion Deuda'!D8*B8/Financiacion!$C$4)-MAX(0,'Flujos de Caja'!F9-('Amortizacion Deuda'!C8*B8/Financiacion!$C$4))*Supuestos!$B$23 -> 246.13499 | N8: ='Flujos de Caja'!D10-('Amortizacion Deuda'!C9*B8/Financiacion!$C$4)-('Amortizacion Deuda'!D9*B8/Financiacion!$C$4)-MAX(0,'Flujos de Caja'!F10-('Amortizacion Deuda'!C9*B8/Financiacion!$C$4))*Supuestos!$B$23 -> 260.68415 | O8: ='Flujos de Caja'!D11-('Amortizacion Deuda'!C10*B8/Financiacion!$C$4)-('Amortizacion Deuda'!D10*B8/Financiacion!$C$4)-MAX(0,'Flujos de Caja'!F11-('Amortizacion Deuda'!C10*B8/Financiacion!$C$4))*Supuestos!$B$23 -> 275.74253 | P8: ='Flujos de Caja'!D12-('Amortizacion Deuda'!C11*B8/Financiacion!$C$4)-('Amortizacion Deuda'!D11*B8/Financiacion!$C$4)-MAX(0,'Flujos de Caja'!F12-('Amortizacion Deuda'!C11*B8/Financiacion!$C$4))*Supuestos!$B$23 -> 291.32795 | Q8: ='Flujos de Caja'!D13-('Amortizacion Deuda'!C12*B8/Financiacion!$C$4)-('Amortizacion Deuda'!D12*B8/Financiacion!$C$4)-MAX(0,'Flujos de Caja'!F13-('Amortizacion Deuda'!C12*B8/Financiacion!$C$4))*Supuestos!$B$23 -> 307.45886 | R8: ='Flujos de Caja'!D14-('Amortizacion Deuda'!C13*B8/Financiacion!$C$4)-('Amortizacion Deuda'!D13*B8/Financiacion!$C$4)-MAX(0,'Flujos de Caja'!F14-('Amortizacion Deuda'!C13*B8/Financiacion!$C$4))*Supuestos!$B$23 -> 493.70957 | S8: ='Flujos de Caja'!D15-('Amortizacion Deuda'!C14*B8/Financiacion!$C$4)-('Amortizacion Deuda'!D14*B8/Financiacion!$C$4)-MAX(0,'Flujos de Caja'!F15-('Amortizacion Deuda'!C14*B8/Financiacion!$C$4))*Supuestos!$B$23 -> 510.9894 | T8: ='Flujos de Caja'!D16-('Amortizacion Deuda'!C15*B8/Financiacion!$C$4)-('Amortizacion Deuda'!D15*B8/Financiacion!$C$4)-MAX(0,'Flujos de Caja'!F16-('Amortizacion Deuda'!C15*B8/Financiacion!$C$4))*Supuestos!$B$23 -> 528.87403 | U8: ='Flujos de Caja'!D17-('Amortizacion Deuda'!C16*B8/Financiacion!$C$4)-('Amortizacion Deuda'!D16*B8/Financiacion!$C$4)-MAX(0,'Flujos de Caja'!F17-('Amortizacion Deuda'!C16*B8/Financiacion!$C$4))*Supuestos!$B$23 -> 547.38462 | V8: ='Flujos de Caja'!D18-('Amortizacion Deuda'!C17*B8/Financiacion!$C$4)-('Amortizacion Deuda'!D17*B8/Financiacion!$C$4)-MAX(0,'Flujos de Caja'!F18-('Amortizacion Deuda'!C17*B8/Financiacion!$C$4))*Supuestos!$B$23 -> 566.54308 | W8: ='Flujos de Caja'!D19-('Amortizacion Deuda'!C18*B8/Financiacion!$C$4)-('Amortizacion Deuda'!D18*B8/Financiacion!$C$4)-MAX(0,'Flujos de Caja'!F19-('Amortizacion Deuda'!C18*B8/Financiacion!$C$4))*Supuestos!$B$23 -> 586.37209 | X8: ='Flujos de Caja'!D20-('Amortizacion Deuda'!C19*B8/Financiacion!$C$4)-('Amortizacion Deuda'!D19*B8/Financiacion!$C$4)-MAX(0,'Flujos de Caja'!F20-('Amortizacion Deuda'!C19*B8/Financiacion!$C$4))*Supuestos!$B$23 -> 606.89511 | Y8: ='Flujos de Caja'!D21-('Amortizacion Deuda'!C20*B8/Financiacion!$C$4)-('Amortizacion Deuda'!D20*B8/Financiacion!$C$4)-MAX(0,'Flujos de Caja'!F21-('Amortizacion Deuda'!C20*B8/Financiacion!$C$4))*Supuestos!$B$23 -> 628.13644 | Z8: ='Flujos de Caja'!D22-('Amortizacion Deuda'!C21*B8/Financiacion!$C$4)-('Amortizacion Deuda'!D21*B8/Financiacion!$C$4)-MAX(0,'Flujos de Caja'!F22-('Amortizacion Deuda'!C21*B8/Financiacion!$C$4))*Supuestos!$B$23 -> 650.12122 | AA8: ='Flujos de Caja'!D23-('Amortizacion Deuda'!C22*B8/Financiacion!$C$4)-('Amortizacion Deuda'!D22*B8/Financiacion!$C$4)-MAX(0,'Flujos de Caja'!F23-('Amortizacion Deuda'!C22*B8/Financiacion!$C$4))*Supuestos!$B$23 -> 672.87546 | AB8: ='Flujos de Caja'!D24-('Amortizacion Deuda'!C23*B8/Financiacion!$C$4)-('Amortizacion Deuda'!D23*B8/Financiacion!$C$4)-MAX(0,'Flujos de Caja'!F24-('Amortizacion Deuda'!C23*B8/Financiacion!$C$4))*Supuestos!$B$23 -> 696.4261 | AC8: ='Flujos de Caja'!D25-('Amortizacion Deuda'!C24*B8/Financiacion!$C$4)-('Amortizacion Deuda'!D24*B8/Financiacion!$C$4)-MAX(0,'Flujos de Caja'!F25-('Amortizacion Deuda'!C24*B8/Financiacion!$C$4))*Supuestos!$B$23 -> 720.80102 | AD8: ='Flujos de Caja'!D26-('Amortizacion Deuda'!C25*B8/Financiacion!$C$4)-('Amortizacion Deuda'!D25*B8/Financiacion!$C$4)-MAX(0,'Flujos de Caja'!F26-('Amortizacion Deuda'!C25*B8/Financiacion!$C$4))*Supuestos!$B$23 -> 746.02905 | AE8: ='Flujos de Caja'!D27-('Amortizacion Deuda'!C26*B8/Financiacion!$C$4)-('Amortizacion Deuda'!D26*B8/Financiacion!$C$4)-MAX(0,'Flujos de Caja'!F27-('Amortizacion Deuda'!C26*B8/Financiacion!$C$4))*Supuestos!$B$23 -> 772.14007 | AF8: ='Flujos de Caja'!D28-('Amortizacion Deuda'!C27*B8/Financiacion!$C$4)-('Amortizacion Deuda'!D27*B8/Financiacion!$C$4)-MAX(0,'Flujos de Caja'!F28-('Amortizacion Deuda'!C27*B8/Financiacion!$C$4))*Supuestos!$B$23 -> 799.05123

Sheet Indicadores
A1: INDICADORES
A2: Indicador | B2: Valor | C2: Criterio | D2: Conclusión
A3: WACC | B3: =Financiacion!B8 -> 0.09315 | C3: Tasa proyecto | D3: Referencia
A4: VPN Proyecto | B4: =NPV(B3,'Flujos de Caja'!L4:L28)+'Flujos de Caja'!L3 -> -15486.83 | C4: >0 | D4: =IF(B4>0,"Viable","No viable") -> No viable
A5: TIR Proyecto | B5: =IRR('Flujos de Caja'!L3:L28) -> -0.024525934 | C5: >WACC | D5: =IF(B5>B3,"Viable","No viable") -> No viable
A6: VPN Inversionista | B6: =NPV(Supuestos!B22,'Flujos de Caja'!M4:M28)+'Flujos de Caja'!M3 -> -730.30153 | C6: >0 | D6: =IF(B6>0,"Viable","No alcanza Ke") -> No alcanza Ke
A7: TIR Inversionista | B7: =IRR('Flujos de Caja'!M3:M28) -> 0.10461089 | C7: >Ke | D7: =IF(B7>Supuestos!B22,"Viable","No alcanza Ke") -> No alcanza Ke
A8: VPN Social | B8: =NPV(Supuestos!B25,'Flujos de Caja'!P4:P28)+'Flujos de Caja'!P3 -> 19625.705 | C8: >0 | D8: =IF(B8>0,"Viable","No viable") -> Viable
A9: B/C | B9: =NPV(Supuestos!B25,'Flujos de Caja'!O4:O28)/(Presupuesto!B9+NPV(Supuestos!B25,'Flujos de Caja'!C4:C28)) -> 1.5583457 | C9: >1 | D9: =IF(B9>1,"Viable","No viable") -> Viable
A10: TIR Banco | B10: =IRR('Flujos de Caja'!N3:N28) -> 0.11 | C10: Kd = 11 % | D10: =IF(ABS(B10-Supuestos!B21)<0.000001,"Concilia","Revisar") -> Concilia

Sheet Riesgos
A1: MATRIZ 20 RIESGOS E INTERVENCIÓN 10 (5 AMBIENTALES)
A2: # | B2: Riesgo | C2: Tipo | D2: P | E2: I | F2: P×I | G2: Nivel | H2: Observación
A3: 1 | B3: Sobrecostos en la construcción | C3: Financiero | D3: 4 | E3: 4 | F3: =D3*E3 -> 16 | G3: =IF(F3<=6,"Bajo",IF(F3<=12,"Medio","Alto")) -> Alto | H3: Prioritario
A4: 2 | B4: Retrasos en el cronograma de obra | C4: Operativo | D4: 4 | E4: 3 | F4: =D4*E4 -> 12 | G4: =IF(F4<=6,"Bajo",IF(F4<=12,"Medio","Alto")) -> Medio
A5: 3 | B5: Demoras en gestión predial y servidumbres | C5: Legal | D5: 3 | E5: 4 | F5: =D5*E5 -> 12 | G5: =IF(F5<=6,"Bajo",IF(F5<=12,"Medio","Alto")) -> Medio
A6: 4 | B6: Insuficiencia/retraso del aporte público | C6: Financiero | D6: 3 | E6: 5 | F6: =D6*E6 -> 15 | G6: =IF(F6<=6,"Bajo",IF(F6<=12,"Medio","Alto")) -> Alto | H6: Prioritario
A7: 5 | B7: Incremento de tasas de interés | C7: Financiero | D7: 3 | E7: 4 | F7: =D7*E7 -> 12 | G7: =IF(F7<=6,"Bajo",IF(F7<=12,"Medio","Alto")) -> Medio
A8: 6 | B8: Recaudo tarifario inferior al proyectado | C8: Comercial | D8: 4 | E8: 4 | F8: =D8*E8 -> 16 | G8: =IF(F8<=6,"Bajo",IF(F8<=12,"Medio","Alto")) -> Alto | H8: Prioritario
A9: 7 | B9: Cambios regulatorios del marco tarifario | C9: Regulatorio | D9: 2 | E9: 4 | F9: =D9*E9 -> 8 | G9: =IF(F9<=6,"Bajo",IF(F9<=12,"Medio","Alto")) -> Medio
A10: 8 | B10: Alta turbiedad/mercurio del río San Juan | C10: Ambiental | D10: 4 | E10: 5 | F10: =D10*E10 -> 20 | G10: =IF(F10<=6,"Bajo",IF(F10<=12,"Medio","Alto")) -> Alto | H10: Prioritario
A11: 9 | B11: Inundaciones por lluvias extremas | C11: Ambiental | D11: 4 | E11: 4 | F11: =D11*E11 -> 16 | G11: =IF(F11<=6,"Bajo",IF(F11<=12,"Medio","Alto")) -> Alto | H11: Prioritario
A12: 10 | B12: Disposición inadecuada de lodos PTAP | C12: Ambiental | D12: 3 | E12: 4 | F12: =D12*E12 -> 12 | G12: =IF(F12<=6,"Bajo",IF(F12<=12,"Medio","Alto")) -> Medio
A13: 11 | B13: Aguas de lavado vertidas sin tratar | C13: Ambiental | D13: 3 | E13: 4 | F13: =D13*E13 -> 12 | G13: =IF(F13<=6,"Bajo",IF(F13<=12,"Medio","Alto")) -> Medio
A14: 12 | B14: Afectación de fauna y flora en obras | C14: Ambiental | D14: 2 | E14: 3 | F14: =D14*E14 -> 6 | G14: =IF(F14<=6,"Bajo",IF(F14<=12,"Medio","Alto")) -> Bajo
A15: 13 | B15: Fallas de equipos de bombeo | C15: Operativo | D15: 3 | E15: 3 | F15: =D15*E15 -> 9 | G15: =IF(F15<=6,"Bajo",IF(F15<=12,"Medio","Alto")) -> Medio
A16: 14 | B16: Interrupción del suministro eléctrico | C16: Operativo | D16: 3 | E16: 4 | F16: =D16*E16 -> 12 | G16: =IF(F16<=6,"Bajo",IF(F16<=12,"Medio","Alto")) -> Medio
A17: 15 | B17: Accidentes laborales en obra | C17: SST | D17: 3 | E17: 4 | F17: =D17*E17 -> 12 | G17: =IF(F17<=6,"Bajo",IF(F17<=12,"Medio","Alto")) -> Medio
A18: 16 | B18: Dificultad logística y de acceso | C18: Operativo | D18: 4 | E18: 3 | F18: =D18*E18 -> 12 | G18: =IF(F18<=6,"Bajo",IF(F18<=12,"Medio","Alto")) -> Medio
A19: 17 | B19: Alteraciones de orden público | C19: Social | D19: 3 | E19: 4 | F19: =D19*E19 -> 12 | G19: =IF(F19<=6,"Bajo",IF(F19<=12,"Medio","Alto")) -> Medio
A20: 18 | B20: Errores en estudios y diseños | C20: Técnico | D20: 2 | E20: 4 | F20: =D20*E20 -> 8 | G20: =IF(F20<=6,"Bajo",IF(F20<=12,"Medio","Alto")) -> Medio
A21: 19 | B21: Incumplimiento del contratista | C21: Contractual | D21: 2 | E21: 4 | F21: =D21*E21 -> 8 | G21: =IF(F21<=6,"Bajo",IF(F21<=12,"Medio","Alto")) -> Medio
A22: 20 | B22: Inflación de costos operativos | C22: Financiero | D22: 3 | E22: 3 | F22: =D22*E22 -> 9 | G22: =IF(F22<=6,"Bajo",IF(F22<=12,"Medio","Alto")) -> Medio
A23: Escalas: P1 <5 %, P2 5–20 %, P3 21–40 %, P4 41–70 %, P5 >70 %. Impacto: I1 menor, I2 bajo, I3 moderado, I4 mayor, I5 crítico; se evalúa por la consecuencia más severa en costo, plazo, ambiente, servicio o SST.
A25: INTERVENCIÓN Y RECALIFICACIÓN
A26: # | B26: Riesgo | C26: Tipo | D26: Intervención | E26: Pr | F26: Ir | G26: Pr×Ir | H26: Nivel residual
A27: 1 | B27: Sobrecostos | C27: Financiero | D27: Precios/alcance definidos, contingencia 10 % y control de cambios | E27: 2 | F27: 3 | G27: =E27*F27 -> 6 | H27: =IF(G27<=6,"Bajo",IF(G27<=12,"Medio","Alto")) -> Bajo
