Workbook

Sheet Control
A1: CONTROL AUTOMÁTICO
A2: Control | B2: Resultado | C2: Criterio | D2: Estado
A3: CAPEX | B3: =Presupuesto!B9-SUM(Presupuesto!B3:B8) | C3: =0 | D3: =IF(ABS(B3)<0.01,"OK","REVISAR")
A4: Participaciones | B4: =SUM(Financiacion!B3:B5)-1 | C4: =0 | D4: =IF(ABS(B4)<0.000001,"OK","REVISAR")
A5: Financiación | B5: =SUM(Financiacion!C3:C5)-Presupuesto!B9 | C5: =0 | D5: =IF(ABS(B5)<0.01,"OK","REVISAR")
A6: Saldo deuda | B6: ='Amortizacion Deuda'!F27 | C6: ≈0 | D6: =IF(ABS(B6)<0.01,"OK","REVISAR")
A7: Años | B7: =COUNT('Flujos de Caja'!A4:A28) | C7: =25 | D7: =IF(B7=25,"OK","REVISAR")
A8: Riesgos | B8: =COUNT(Riesgos!A3:A22) | C8: =20 | D8: =IF(B8=20,"OK","REVISAR")
A9: Intervenciones | B9: =COUNT(Riesgos!A27:A36) | C9: =10 | D9: =IF(B9=10,"OK","REVISAR")
A10: Ambientales | B10: =COUNTIF(Riesgos!C27:C36,"Ambiental") | C10: =5 | D10: =IF(B10=5,"OK","REVISAR")
A11: PTAP-QMD | B11: ='Diseno Caudal'!B11-'Diseno Caudal'!B9 | C11: >=0 | D11: =IF(B11>=0,"OK","REVISAR")
A12: TIR banco-Kd | B12: =Indicadores!B10-Supuestos!B21 | C12: ≈0 | D12: =IF(ABS(B12)<0.000001,"OK","REVISAR")
A13: B/C | B13: =Indicadores!B9 | C13: >1 | D13: =IF(B13>1,"OK","REVISAR")
A14: APU vs. CAPEX | B14: ='APU Referencial'!M46-Presupuesto!B9 | C14: =0 | D14: =IF(ABS(B14)<0.01,"OK","REVISAR")
A15: Actividades APU | B15: =COUNTA('APU Referencial'!A3:A44) | C15: =42 | D15: =IF(B15=42,"OK","REVISAR")
A16: Registros de trazabilidad | B16: =COUNTA(Fuentes!A3:A26) | C16: =24 | D16: =IF(B16=24,"OK","REVISAR")

Sheet Supuestos
A1: SUPUESTOS — AMARILLO = ENTRADA EDITABLE
A2: Parámetro | B2: Valor | C2: Unidad | D2: Criterio
A3: Población municipal | B3: 17000 | C3: hab | D3: Contexto
A4: Población urbana base | B4: 10957 | C4: hab | D4: Base adoptada; no equivale a 60 %
A5: Crecimiento población | B5: 0.012 | C5: % anual | D5: Supuesto
A6: Horizonte diseño | B6: 25 | C6: años | D6: Diseño hidráulico
A7: Dotación neta | B7: 140 | C7: L/hab·día | D7: RAS adoptado
A8: Pérdidas | B8: 0.25 | C8: % | D8: Supuesto
A9: k1 | B9: 1.3 | C9: factor | D9: Máximo diario
A10: k2 | B10: 1.6 | C10: factor | D10: Máximo horario
A11: PTAP | B11: 45 | C11: L/s | D11: Debe cubrir QMD
A12: Horizonte evaluación | B12: 25 | C12: años | D12: Flujos
A13: Ingresos año 1 | B13: 1500 | C13: COP MM | D13: Validar tarifa/demanda
A14: OPEX año 1 | B14: 1150 | C14: COP MM | D14: Validar operación
... A26: Vida útil | B26: 25 | C26: años | D26: Depreciación lineal

Sheet Diseno Caudal
A1: DISEÑO DE CAUDAL — RAS
A2: Concepto | B2: Valor | C2: Fórmula/criterio
A3: Población municipal | B3: =Supuestos!B3 | C3: Contexto
A4: Población urbana | B4: =Supuestos!B4 | C4: Entrada
A5: Población diseño | B5: =B4*(1+Supuestos!$B$5)^Supuestos!$B$6 | C5: P(1+g)^n
A6: Dotación neta | B6: =Supuestos!B7 | C6: Entrada
A7: Dotación bruta | B7: =B6/(1-Supuestos!$B$8) | C7: Dn/(1-pérdidas)
A8: Qmd | B8: =B5*B7/86400 | C8: P×Db/86400
A9: QMD | B9: =B8*Supuestos!$B$9 | C9: Qmd×k1
A10: QMH | B10: =B9*Supuestos!$B$10 | C10: QMD×k2
A11: PTAP | B11: =Supuestos!B11 | C11: PTAP≥QMD

Sheet APU Referencial
A1: APU ACADÉMICO REFERENCIAL — COP MILLONES — NO ES APU OFICIAL NI APTO PARA CONTRATACIÓN
A2: Código | B2: Capítulo | C2: Actividad | D2: Unidad | E2: Cantidad | F2: Materiales/U | G2: Mano de obra/U | H2: Equipo/U | I2: Transporte/U | J2: Costo directo/U | K2: AIU | L2: Precio unitario | M2: Costo parcial | N2: Base / advertencia
A3: 1.01 | B3: Captación (bocatoma) y línea de aducción | C3: Replanteo, campamento y obras provisionales | D3: GLB | E3: 1 | F3: 64.8 | G3: 36 | H3: 28.8 | I3: 14.4 | J3: =SUM(F3:I3) | K3: 0.25 | L3: =J3*(1+K3) | M3: =E3*L3 | N3: Alcance preliminar referencial
A4: 1.02 | B4: Captación (bocatoma) y línea de aducción | C4: Bocatoma: excavación, concreto y protección estructural | D4: m³ | E4: 300 | F4: 1.08 | G4: 0.6 | H4: 0.48 | I4: 0.24 | J4: =SUM(F4:I4) | K4: 0.25 | L4: =J4*(1+K4) | M4: =E4*L4 | N4: Cantidad conceptual, sin planos definitivos
A5: 1.03 | B5: Captación (bocatoma) y línea de aducción | C5: Rejillas, compuertas y elementos metálicos | D5: und | E5: 2 | F5: 62.4 | G5: 14.4 | H5: 14.4 | I5: 4.8 | J5: =SUM(F5:I5) | K5: 0.25 | L5: =J5*(1+K5) | M5: =E5*L5 | N5: Dos líneas operativas referenciales
A6: 1.04 | B6: Captación (bocatoma) y línea de aducción | C6: Desarenador y canal de entrada | D6: GLB | E6: 1 | F6: 126 | G6: 70 | H6: 56 | I6: 28 | J6: =SUM(F6:I6) | K6: 0.25 | L6: =J6*(1+K6) | M6: =E6*L6 | N6: Configuración conceptual
A7: 1.05 | B7: Captación (bocatoma) y línea de aducción | C7: Tubería de aducción instalada | D7: m | E7: 3000 | F7: 0.0792 | G7: 0.0288 | H7: 0.0216 | I7: 0.0144 | J7: =SUM(F7:I7) | K7: 0.25 | L7: =J7*(1+K7) | M7: =E7*L7 | N7: Longitud y diámetro por validar
A8: 1.06 | B8: Captación (bocatoma) y línea de aducción | C8: Protección de orillas y control de erosión | D8: m | E8: 500 | F8: 0.0864 | G8: 0.048 | H8: 0.0384 | I8: 0.0192 | J8: =SUM(F8:I8) | K8: 0.25 | L8: =J8*(1+K8) | M8: =E8*L8 | N8: Longitud conceptual
A9: 1.07 | B9: Captación (bocatoma) y línea de aducción | C9: Pruebas, desinfección y puesta en servicio | D9: GLB | E9: 1 | F9: 8.4 | G9: 30.8 | H9: 11.2 | I9: 5.6 | J9: =SUM(F9:I9) | K9: 0.25 | L9: =J9*(1+K9) | M9: =E9*L9 | N9: Actividad global referencial
A10: 2.01 | B10: PTAP 45 L/s (obra civil + equipos) | C10: Preparación del lote, excavaciones y drenajes | D10: GLB | E10: 1 | F10: 126 | G10: 70 | H10: 56 | I10: 28 | J10: =SUM(F10:I10) | K10: 0.25 | L10: =J10*(1+K10) | M10: =E10*L10 | N10: Sin levantamiento topográfico definitivo
A11: 2.02 | B11: PTAP 45 L/s (obra civil + equipos) | C11: Estructuras hidráulicas y edificios de proceso | D11: GLB | E11: 1 | F11: 504 | G11: 280 | H11: 224 | I11: 112 | J11: =SUM(F11:I11) | K11: 0.25 | L11: =J11*(1+K11) | M11: =E11*L11 | N11: Dimensionamiento conceptual 45 L/s
A12: 2.03 | B12: PTAP 45 L/s (obra civil + equipos) | C12: Trenes de coagulación, floculación y sedimentación | D12: und | E12: 2 | F12: 286 | G12: 66 | H12: 66 | I12: 22 | J12: =SUM(F12:I12) | K12: 0.25 | L12: =J12*(1+K12) | M12: =E12*L12 | N12: Dos trenes para flexibilidad operativa
A13: 2.04 | B13: PTAP 45 L/s (obra civil + equipos) | C13: Filtros rápidos, medios filtrantes y accesorios | D13: und | E13: 4 | F13: 110.5 | G13: 25.5 | H13: 25.5 | I13: 8.5 | J13: =SUM(F13:I13) | K13: 0.25 | L13: =J13*(1+K13) | M13: =E13*L13 | N13: Número referencial de filtros
A14: 2.05 | B14: PTAP 45 L/s (obra civil + equipos) | C14: Preparación y dosificación de químicos | D14: GLB | E14: 1 | F14: 338 | G14: 78 | H14: 78 | I14: 26 | J14: =SUM(F14:I14) | K14: 0.25 | L14: =J14*(1+K14) | M14: =E14*L14 | N14: Incluye almacenamiento y dosificación
... A44: 6.07 | B44: Estudios, diseños, interventoría y gestión ambiental/social | C44: Capacitación institucional y cierre | D44: GLB | E44: 1 | F44: 8 | G44: 56 | H44: 8 | I44: 8 | J44: =SUM(F44:I44) | K44: 0.25 | L44: =J44*(1+K44) | M44: =E44*L44 | N44: Fortalecimiento del operador
A46: TOTAL APU | M46: =SUM(M3:M44) | N46: Debe conciliar exactamente con Presupuesto!B9
A48: RESUMEN POR CAPÍTULO
A49: Captación (bocatoma) y línea de aducción | B49: =SUMIF($B$3:$B$44,A49,$M$3:$M$44) | C49: =B49/$M$46 | D49: Referencial
A50: PTAP 45 L/s (obra civil + equipos) | B50: =SUMIF($B$3:$B$44,A50,$M$3:$M$44) | C50: =B50/$M$46 | D50: Referencial
A51: Almacenamiento (tanques) y estaciones de bombeo | B51: =SUMIF($B$3:$B$44,A51,$M$3:$M$44) | C51: =B51/$M$46 | D51: Referencial
A52: Redes de distribución, conexiones y micromedición | B52: =SUMIF($B$3:$B$44,A52,$M$3:$M$44) | C52: =B52/$M$46 | D52: Referencial
A53: Optimización del alcantarillado (componente asociado) | B53: =SUMIF($B$3:$B$44,A53,$M$3:$M$44) | C53: =B53/$M$46 | D53: Referencial
A54: Estudios, diseños, interventoría y gestión ambiental/social | B54: =SUMIF($B$3:$B$44,A54,$M$3:$M$44) | C54: =B54/$M$46 | D54: Referencial

Sheet Fuentes
A1: TRAZABILIDAD DE DATOS, FUENTES Y SUPUESTOS
A2: Elemento | B2: Dato usado | C2: Procedencia declarada | D2: Nivel de soporte / observación | E2: ¿Fuente verificable adjunta?
A3: Enunciado y entregables | B3: Estructura, matrices y límite de 10 páginas | C3: PROYECTO PEPI.pdf suministrado en el repositorio | D3: Fuente primaria del encargo | E3: Sí — archivo adjunto
A4: Caso de estudio | B4: Optimización/ampliación del acueducto de Tadó, Chocó | C4: Informe previo suministrado; atribuía el caso a MinVivienda, cooperación española y una nota de Agencia Anadolu sin título, fecha ni URL | D4: Caso académico inspirado en una referencia secundaria no verificada | E4: No
A5: Inversión ancla | B5: COP 19.971 MM | C5: Informe y modelo anteriores; atribuían el dato a la misma referencia secundaria no recuperable | D5: No es presupuesto contractual ni APU oficial | E5: No
A6: Población municipal | B6: ≈17.000 habitantes | C6: Atribuida en el informe previo a DANE, CNPV 2018, consulta municipal de Tadó | D6: Referencia identificada pero no adjunta; validar cifra exacta | E6: No — referencia no adjunta
A7: Población urbana base | B7: 10.957 habitantes | C7: Entrada heredada del modelo anterior | D7: No había soporte adjunto en el repositorio | E7: No
A8: Crecimiento poblacional | B8: 1,2 % anual | C8: Supuesto del modelo | D8: Debe reemplazarse con proyección oficial | E8: No
A9: Horizonte de diseño | B9: 25 años | C9: Supuesto del modelo | D9: No había memoria de selección adjunta | E9: No
A10: Criterios hidráulicos | B10: Dotación 140; pérdidas 25 %; k1=1,30; k2=1,60 | C10: Parámetros adoptados con referencia general a Resolución 0330 de 2017 — RAS | D10: La norma no está adjunta; confirmar valores y aplicabilidad | E10: No — referencia no adjunta
A11: Capacidad PTAP | B11: 45 L/s | C11: Alcance heredado del informe/modelo anterior | D11: No hay diseño, balance horario ni ficha técnica adjunta | E11: No
A12: Calidad de agua | B12: IRCA y criterios de potabilidad | C12: Resolución 2115 de 2007 | D12: Referencia normativa identificada pero no adjunta | E12: No — referencia no adjunta
A13: Marco tarifario | B13: Estructura tarifaria del servicio | C13: Resolución CRA 943 de 2021 | D13: Referencia normativa identificada pero no adjunta | E13: No — referencia no adjunta
... A26: Riesgos | B26: 20 riesgos y 10 intervenciones | C26: Análisis académico del equipo a partir del alcance | D26: No es matriz contractual ni estudio ambiental | E26: No — referencial

Sheet Presupuesto
A1: CAPEX — COP MM
A2: Capítulo | B2: COP MM | C2: % total
A3: Captación (bocatoma) y línea de aducción | B3: =SUMIF('APU Referencial'!$B$3:$B$44,A3,'APU Referencial'!$M$3:$M$44) | C3: =B3/$B$9
A4: PTAP 45 L/s (obra civil + equipos) | B4: =SUMIF('APU Referencial'!$B$3:$B$44,A4,'APU Referencial'!$M$3:$M$44) | C4: =B4/$B$9
A5: Almacenamiento (tanques) y estaciones de bombeo | B5: =SUMIF('APU Referencial'!$B$3:$B$44,A5,'APU Referencial'!$M$3:$M$44) | C5: =B5/$B$9
A6: Redes de distribución, conexiones y micromedición | B6: =SUMIF('APU Referencial'!$B$3:$B$44,A6,'APU Referencial'!$M$3:$M$44) | C6: =B6/$B$9
A7: Optimización del alcantarillado (componente asociado) | B7: =SUMIF('APU Referencial'!$B$3:$B$44,A7,'APU Referencial'!$M$3:$M$44) | C7: =B7/$B$9
A8: Estudios, diseños, interventoría y gestión ambiental/social | B8: =SUMIF('APU Referencial'!$B$3:$B$44,A8,'APU Referencial'!$M$3:$M$44) | C8: =B8/$B$9
A9: TOTAL | B9: =SUM(B3:B8) | C9: =SUM(C3:C8)
A11: Nota: el CAPEX ahora se obtiene del APU referencial. Las cantidades, rendimientos, componentes y AIU no proceden de diseños, SECOP ni cotizaciones; deben reemplazarse antes de cualquier uso contractual.

Sheet Financiacion
A1: FINANCIACIÓN Y WACC AJUSTADO
A2: Fuente | B2: Participación | C2: Monto | D2: Costo | E2: Tratamiento
A3: Aporte público | B3: =Supuestos!B17 | C3: =B3*Presupuesto!$B$9 | D3: =Supuestos!B20 | E3: Oportunidad social
A4: Deuda | B4: =Supuestos!B18 | C4: =B4*Presupuesto!$B$9 | D4: =Supuestos!B21 | E4: Kd posimpuesto
A5: Equity | B5: =Supuestos!B19 | C5: =B5*Presupuesto!$B$9 | D5: =Supuestos!B22 | E5: Ke
A6: TOTAL | B6: =SUM(B3:B5) | C6: =SUM(C3:C5) | E6: Concilia CAPEX
A8: WACC ajustado | B8: =B3*D3+B4*D4*(1-Supuestos!$B$23)+B5*D5 | C8: Proyecto

Sheet Amortizacion Deuda
A1: AMORTIZACIÓN — SISTEMA FRANCÉS
A2: Año | B2: Saldo inicial | C2: Interés | D2: Capital | E2: Cuota | F2: Saldo final
A3: 1 | B3: =Financiacion!$C$4 | C3: =IF(A3<=Supuestos!$B$24,B3*Supuestos!$B$21,0) | D3: =IF(A3<=Supuestos!$B$24,MIN(B3,E3-C3),0) | E3: =IF(A3<=Supuestos!$B$24,-PMT(Supuestos!$B$21,Supuestos!$B$24,Financiacion!$C$4),0) | F3: =MAX(0,B3-D3)
A4: =A3+1 | B4: =F3 | C4: =IF(A4<=Supuestos!$B$24,B4*Supuestos!$B$21,0) | D4: =IF(A4<=Supuestos!$B$24,MIN(B4,E4-C4),0) | E4: =IF(A4<=Supuestos!$B$24,-PMT(Supuestos!$B$21,Supuestos!$B$24,Financiacion!$C$4),0) | F4: =MAX(0,B4-D4)
A5: =A4+1 | B5: =F4 | C5: =IF(A5<=Supuestos!$B$24,B5*Supuestos!$B$21,0) | D5: =IF(A5<=Supuestos!$B$24,MIN(B5,E5-C5),0) | E5: =IF(A5<=Supuestos!$B$24,-PMT(Supuestos!$B$21,Supuestos!$B$24,Financiacion!$C$4),0) | F5: =MAX(0,B5-D5)
A6: =A5+1 | B6: =F5 | C6: =IF(A6<=Supuestos!$B$24,B6*Supuestos!$B$21,0) | D6: =IF(A6<=Supuestos!$B$24,MIN(B6,E6-C6),0) | E6: =IF(A6<=Supuestos!$B$24,-PMT(Supuestos!$B$21,Supuestos!$B$24,Financiacion!$C$4),0) | F6: =MAX(0,B6-D6)
A7: =A6+1 | B7: =F6 | C7: =IF(A7<=Supuestos!$B$24,B7*Supuestos!$B$21,0) | D7: =IF(A7<=Supuestos!$B$24,MIN(B7,E7-C7),0) | E7: =IF(A7<=Supuestos!$B$24,-PMT(Supuestos!$B$21,Supuestos!$B$24,Financiacion!$C$4),0) | F7: =MAX(0,B7-D7)
A8: =A7+1 | B8: =F7 | C8: =IF(A8<=Supuestos!$B$24,B8*Supuestos!$B$21,0) | D8: =IF(A8<=Supuestos!$B$24,MIN(B8,E8-C8),0) | E8: =IF(A8<=Supuestos!$B$24,-PMT(Supuestos!$B$21,Supuestos!$B$24,Financiacion!$C$4),0) | F8: =MAX(0,B8-D8)
A9: =A8+1 | B9: =F8 | C9: =IF(A9<=Supuestos!$B$24,B9*Supuestos!$B$21,0) | D9: =IF(A9<=Supuestos!$B$24,MIN(B9,E9-C9),0) | E9: =IF(A9<=Supuestos!$B$24,-PMT(Supuestos!$B$21,Supuestos!$B$24,Financiacion!$C$4),0) | F9: =MAX(0,B9-D9)
A10: =A9+1 | B10: =F9 | C10: =IF(A10<=Supuestos!$B$24,B10*Supuestos!$B$21,0) | D10: =IF(A10<=Supuestos!$B$24,MIN(B10,E10-C10),0) | E10: =IF(A10<=Supuestos!$B$24,-PMT(Supuestos!$B$21,Supuestos!$B$24,Financiacion!$C$4),0) | F10: =MAX(0,B10-D10)
A11: =A10+1 | B11: =F10 | C11: =IF(A11<=Supuestos!$B$24,B11*Supuestos!$B$21,0) | D11: =IF(A11<=Supuestos!$B$24,MIN(B11,E11-C11),0) | E11: =IF(A11<=Supuestos!$B$24,-PMT(Supuestos!$B$21,Supuestos!$B$24,Financiacion!$C$4),0) | F11: =MAX(0,B11-D11)
A12: =A11+1 | B12: =F11 | C12: =IF(A12<=Supuestos!$B$24,B12*Supuestos!$B$21,0) | D12: =IF(A12<=Supuestos!$B$24,MIN(B12,E12-C12),0) | E12: =IF(A12<=Supuestos!$B$24,-PMT(Supuestos!$B$21,Supuestos!$B$24,Financiacion!$C$4),0) | F12: =MAX(0,B12-D12)
A13: =A12+1 | B13: =F12 | C13: =IF(A13<=Supuestos!$B$24,B13*Supuestos!$B$21,0) | D13: =IF(A13<=Supuestos!$B$24,MIN(B13,E13-C13),0) | E13: =IF(A13<=Supuestos!$B$24,-PMT(Supuestos!$B$21,Supuestos!$B$24,Financiacion!$C$4),0) | F13: =MAX(0,B13-D13)
A14: =A13+1 | B14: =F13 | C14: =IF(A14<=Supuestos!$B$24,B14*Supuestos!$B$21,0) | D14: =IF(A14<=Supuestos!$B$24,MIN(B14,E14-C14),0) | E14: =IF(A14<=Supuestos!$B$24,-PMT(Supuestos!$B$21,Supuestos!$B$24,Financiacion!$C$4),0) | F14: =MAX(0,B14-D14)
A15: =A14+1 | B15: =F14 | C15: =IF(A15<=Supuestos!$B$24,B15*Supuestos!$B$21,0) | D15: =IF(A15<=Supuestos!$B$24,MIN(B15,E15-C15),0) | E15: =IF(A15<=Supuestos!$B$24,-PMT(Supuestos!$B$21,Supuestos!$B$24,Financiacion!$C$4),0) | F15: =MAX(0,B15-D15)
... A27: =A26+1 | B27: =F26 | C27: =IF(A27<=Supuestos!$B$24,B27*Supuestos!$B$21,0) | D27: =IF(A27<=Supuestos!$B$24,MIN(B27,E27-C27),0) | E27: =IF(A27<=Supuestos!$B$24,-PMT(Supuestos!$B$21,Supuestos!$B$24,Financiacion!$C$4),0) | F27: =MAX(0,B27-D27)

Sheet Flujos de Caja
A1: FLUJOS — COP MM
A2: Año | B2: Ingresos | C2: OPEX | D2: EBITDA | E2: Deprec. | F2: EBIT | G2: Interés | H2: Imp. proyecto | I2: Imp. equity | J2: Capital | K2: Saldo deuda | L2: FC Proyecto | M2: FC Inversionista | N2: FC Banco | O2: Beneficio social | P2: FC Social
A3: 0 | B3: 0 | C3: 0 | D3: 0 | E3: 0 | F3: 0 | G3: 0 | H3: 0 | I3: 0 | J3: 0 | K3: =Financiacion!$C$4 | L3: =-Presupuesto!$B$9 | M3: =-Financiacion!$C$5 | N3: =-Financiacion!$C$4 | O3: 0 | P3: =-Presupuesto!$B$9
A4: 1 | B4: =Supuestos!$B$13*(1+Supuestos!$B$15)^(A4-1) | C4: =Supuestos!$B$14*(1+Supuestos!$B$15)^(A4-1) | D4: =B4-C4 | E4: =Presupuesto!$B$9/Supuestos!$B$26 | F4: =D4-E4 | G4: ='Amortizacion Deuda'!C3 | H4: =MAX(0,F4)*Supuestos!$B$23 | I4: =MAX(0,F4-G4)*Supuestos!$B$23 | J4: ='Amortizacion Deuda'!D3 | K4: ='Amortizacion Deuda'!F3 | L4: =D4-H4 | M4: =D4-G4-I4-J4 | N4: =G4+J4 | O4: =Supuestos!$B$16*(1+Supuestos!$B$15)^(A4-1) | P4: =O4-C4
A5: =A4+1 | B5: =Supuestos!$B$13*(1+Supuestos!$B$15)^(A5-1) | C5: =Supuestos!$B$14*(1+Supuestos!$B$15)^(A5-1) | D5: =B5-C5 | E5: =Presupuesto!$B$9/Supuestos!$B$26 | F5: =D5-E5 | G5: ='Amortizacion Deuda'!C4 | H5: =MAX(0,F5)*Supuestos!$B$23 | I5: =MAX(0,F5-G5)*Supuestos!$B$23 | J5: ='Amortizacion Deuda'!D4 | K5: ='Amortizacion Deuda'!F4 | L5: =D5-H5 | M5: =D5-G5-I5-J5 | N5: =G5+J5 | O5: =Supuestos!$B$16*(1+Supuestos!$B$15)^(A5-1) | P5: =O5-C5
A6: =A5+1 | B6: =Supuestos!$B$13*(1+Supuestos!$B$15)^(A6-1) | C6: =Supuestos!$B$14*(1+Supuestos!$B$15)^(A6-1) | D6: =B6-C6 | E6: =Presupuesto!$B$9/Supuestos!$B$26 | F6: =D6-E6 | G6: ='Amortizacion Deuda'!C5 | H6: =MAX(0,F6)*Supuestos!$B$23 | I6: =MAX(0,F6-G6)*Supuestos!$B$23 | J6: ='Amortizacion Deuda'!D5 | K6: ='Amortizacion Deuda'!F5 | L6: =D6-H6 | M6: =D6-G6-I6-J6 | N6: =G6+J6 | O6: =Supuestos!$B$16*(1+Supuestos!$B$15)^(A6-1) | P6: =O6-C6
A7: =A6+1 | B7: =Supuestos!$B$13*(1+Supuestos!$B$15)^(A7-1) | C7: =Supuestos!$B$14*(1+Supuestos!$B$15)^(A7-1) | D7: =B7-C7 | E7: =Presupuesto!$B$9/Supuestos!$B$26 | F7: =D7-E7 | G7: ='Amortizacion Deuda'!C6 | H7: =MAX(0,F7)*Supuestos!$B$23 | I7: =MAX(0,F7-G7)*Supuestos!$B$23 | J7: ='Amortizacion Deuda'!D6 | K7: ='Amortizacion Deuda'!F6 | L7: =D7-H7 | M7: =D7-G7-I7-J7 | N7: =G7+J7 | O7: =Supuestos!$B$16*(1+Supuestos!$B$15)^(A7-1) | P7: =O7-C7
A8: =A7+1 | B8: =Supuestos!$B$13*(1+Supuestos!$B$15)^(A8-1) | C8: =Supuestos!$B$14*(1+Supuestos!$B$15)^(A8-1) | D8: =B8-C8 | E8: =Presupuesto!$B$9/Supuestos!$B$26 | F8: =D8-E8 | G8: ='Amortizacion Deuda'!C7 | H8: =MAX(0,F8)*Supuestos!$B$23 | I8: =MAX(0,F8-G8)*Supuestos!$B$23 | J8: ='Amortizacion Deuda'!D7 | K8: ='Amortizacion Deuda'!F7 | L8: =D8-H8 | M8: =D8-G8-I8-J8 | N8: =G8+J8 | O8: =Supuestos!$B$16*(1+Supuestos!$B$15)^(A8-1) | P8: =O8-C8
A9: =A8+1 | B9: =Supuestos!$B$13*(1+Supuestos!$B$15)^(A9-1) | C9: =Supuestos!$B$14*(1+Supuestos!$B$15)^(A9-1) | D9: =B9-C9 | E9: =Presupuesto!$B$9/Supuestos!$B$26 | F9: =D9-E9 | G9: ='Amortizacion Deuda'!C8 | H9: =MAX(0,F9)*Supuestos!$B$23 | I9: =MAX(0,F9-G9)*Supuestos!$B$23 | J9: ='Amortizacion Deuda'!D8 | K9: ='Amortizacion Deuda'!F8 | L9: =D9-H9 | M9: =D9-G9-I9-J9 | N9: =G9+J9 | O9: =Supuestos!$B$16*(1+Supuestos!$B$15)^(A9-1) | P9: =O9-C9
A10: =A9+1 | B10: =Supuestos!$B$13*(1+Supuestos!$B$15)^(A10-1) | C10: =Supuestos!$B$14*(1+Supuestos!$B$15)^(A10-1) | D10: =B10-C10 | E10: =Presupuesto!$B$9/Supuestos!$B$26 | F10: =D10-E10 | G10: ='Amortizacion Deuda'!C9 | H10: =MAX(0,F10)*Supuestos!$B$23 | I10: =MAX(0,F10-G10)*Supuestos!$B$23 | J10: ='Amortizacion Deuda'!D9 | K10: ='Amortizacion Deuda'!F9 | L10: =D10-H10 | M10: =D10-G10-I10-J10 | N10: =G10+J10 | O10: =Supuestos!$B$16*(1+Supuestos!$B$15)^(A10-1) | P10: =O10-C10
A11: =A10+1 | B11: =Supuestos!$B$13*(1+Supuestos!$B$15)^(A11-1) | C11: =Supuestos!$B$14*(1+Supuestos!$B$15)^(A11-1) | D11: =B11-C11 | E11: =Presupuesto!$B$9/Supuestos!$B$26 | F11: =D11-E11 | G11: ='Amortizacion Deuda'!C10 | H11: =MAX(0,F11)*Supuestos!$B$23 | I11: =MAX(0,F11-G11)*Supuestos!$B$23 | J11: ='Amortizacion Deuda'!D10 | K11: ='Amortizacion Deuda'!F10 | L11: =D11-H11 | M11: =D11-G11-I11-J11 | N11: =G11+J11 | O11: =Supuestos!$B$16*(1+Supuestos!$B$15)^(A11-1) | P11: =O11-C11
A12: =A11+1 | B12: =Supuestos!$B$13*(1+Supuestos!$B$15)^(A12-1) | C12: =Supuestos!$B$14*(1+Supuestos!$B$15)^(A12-1) | D12: =B12-C12 | E12: =Presupuesto!$B$9/Supuestos!$B$26 | F12: =D12-E12 | G12: ='Amortizacion Deuda'!C11 | H12: =MAX(0,F12)*Supuestos!$B$23 | I12: =MAX(0,F12-G12)*Supuestos!$B$23 | J12: ='Amortizacion Deuda'!D11 | K12: ='Amortizacion Deuda'!F11 | L12: =D12-H12 | M12: =D12-G12-I12-J12 | N12: =G12+J12 | O12: =Supuestos!$B$16*(1+Supuestos!$B$15)^(A12-1) | P12: =O12-C12
A13: =A12+1 | B13: =Supuestos!$B$13*(1+Supuestos!$B$15)^(A13-1) | C13: =Supuestos!$B$14*(1+Supuestos!$B$15)^(A13-1) | D13: =B13-C13 | E13: =Presupuesto!$B$9/Supuestos!$B$26 | F13: =D13-E13 | G13: ='Amortizacion Deuda'!C12 | H13: =MAX(0,F13)*Supuestos!$B$23 | I13: =MAX(0,F13-G13)*Supuestos!$B$23 | J13: ='Amortizacion Deuda'!D12 | K13: ='Amortizacion Deuda'!F12 | L13: =D13-H13 | M13: =D13-G13-I13-J13 | N13: =G13+J13 | O13: =Supuestos!$B$16*(1+Supuestos!$B$15)^(A13-1) | P13: =O13-C13
A14: =A13+1 | B14: =Supuestos!$B$13*(1+Supuestos!$B$15)^(A14-1) | C14: =Supuestos!$B$14*(1+Supuestos!$B$15)^(A14-1) | D14: =B14-C14 | E14: =Presupuesto!$B$9/Supuestos!$B$26 | F14: =D14-E14 | G14: ='Amortizacion Deuda'!C13 | H14: =MAX(0,F14)*Supuestos!$B$23 | I14: =MAX(0,F14-G14)*Supuestos!$B$23 | J14: ='Amortizacion Deuda'!D13 | K14: ='Amortizacion Deuda'!F13 | L14: =D14-H14 | M14: =D14-G14-I14-J14 | N14: =G14+J14 | O14: =Supuestos!$B$16*(1+Supuestos!$B$15)^(A14-1) | P14: =O14-C14
A15: =A14+1 | B15: =Supuestos!$B$13*(1+Supuestos!$B$15)^(A15-1) | C15: =Supuestos!$B$14*(1+Supuestos!$B$15)^(A15-1) | D15: =B15-C15 | E15: =Presupuesto!$B$9/Supuestos!$B$26 | F15: =D15-E15 | G15: ='Amortizacion Deuda'!C14 | H15: =MAX(0,F15)*Supuestos!$B$23 | I15: =MAX(0,F15-G15)*Supuestos!$B$23 | J15: ='Amortizacion Deuda'!D14 | K15: ='Amortizacion Deuda'!F14 | L15: =D15-H15 | M15: =D15-G15-I15-J15 | N15: =G15+J15 | O15: =Supuestos!$B$16*(1+Supuestos!$B$15)^(A15-1) | P15: =O15-C15
A16: =A15+1 | B16: =Supuestos!$B$13*(1+Supuestos!$B$15)^(A16-1) | C16: =Supuestos!$B$14*(1+Supuestos!$B$15)^(A16-1) | D16: =B16-C16 | E16: =Presupuesto!$B$9/Supuestos!$B$26 | F16: =D16-E16 | G16: ='Amortizacion Deuda'!C15 | H16: =MAX(0,F16)*Supuestos!$B$23 | I16: =MAX(0,F16-G16)*Supuestos!$B$23 | J16: ='Amortizacion Deuda'!D15 | K16: ='Amortizacion Deuda'!F15 | L16: =D16-H16 | M16: =D16-G16-I16-J16 | N16: =G16+J16 | O16: =Supuestos!$B$16*(1+Supuestos!$B$15)^(A16-1) | P16: =O16-C16
... A28: =A27+1 | B28: =Supuestos!$B$13*(1+Supuestos!$B$15)^(A28-1) | C28: =Supuestos!$B$14*(1+Supuestos!$B$15)^(A28-1) | D28: =B28-C28 | E28: =Presupuesto!$B$9/Supuestos!$B$26 | F28: =D28-E28 | G28: ='Amortizacion Deuda'!C27 | H28: =MAX(0,F28)*Supuestos!$B$23 | I28: =MAX(0,F28-G28)*Supuestos!$B$23 | J28: ='Amortizacion Deuda'!D27 | K28: ='Amortizacion Deuda'!F27 | L28: =D28-H28 | M28: =D28-G28-I28-J28 | N28: =G28+J28 | O28: =Supuestos!$B$16*(1+Supuestos!$B$15)^(A28-1) | P28: =O28-C28

Sheet Sensibilidad
A1: APORTE PÚBLICO VS TIR INVERSIONISTA
A2: Aporte | B2: Deuda | C2: Equity | D2: TIR | E2: VPN @ Ke | F2: Criterio | G2: 0 | H2: 1 | I2: 2 | J2: 3 | K2: 4 | L2: 5 | M2: 6 | N2: 7 | O2: 8 | P2: 9 | Q2: 10 | R2: 11 | S2: 12 | T2: 13 | U2: 14 | V2: 15 | W2: 16 | X2: 17 | Y2: 18 | Z2: 19 | AA2: 20 | AB2: 21 | AC2: 22 | AD2: 23 | AE2: 24 | AF2: 25
A3: 0 | B3: =(1-A3)/2*Presupuesto!$B$9 | C3: =(1-A3)/2*Presupuesto!$B$9 | D3: =IRR(G3:AF3) | E3: =NPV(Supuestos!$B$22,H3:AF3)+G3 | F3: =IF(D3>=Supuestos!$B$22,"Viable","No viable") | G3: =-C3 | H3: ='Flujos de Caja'!D4-('Amortizacion Deuda'!C3*B3/Financiacion!$C$4)-('Amortizacion Deuda'!D3*B3/Financiacion!$C$4)-MAX(0,'Flujos de Caja'!F4-('Amortizacion Deuda'!C3*B3/Financiacion!$C$4))*Supuestos!$B$23 | I3: ='Flujos de Caja'!D5-('Amortizacion Deuda'!C4*B3/Financiacion!$C$4)-('Amortizacion Deuda'!D4*B3/Financiacion!$C$4)-MAX(0,'Flujos de Caja'!F5-('Amortizacion Deuda'!C4*B3/Financiacion!$C$4))*Supuestos!$B$23 | J3: ='Flujos de Caja'!D6-('Amortizacion Deuda'!C5*B3/Financiacion!$C$4)-('Amortizacion Deuda'!D5*B3/Financiacion!$C$4)-MAX(0,'Flujos de Caja'!F6-('Amortizacion Deuda'!C5*B3/Financiacion!$C$4))*Supuestos!$B$23 | K3: ='Flujos de Caja'!D7-('Amortizacion Deuda'!C6*B3/Financiacion!$C$4)-('Amortizacion Deuda'!D6*B3/Financiacion!$C$4)-MAX(0,'Flujos de Caja'!F7-('Amortizacion Deuda'!C6*B3/Financiacion!$C$4))*Supuestos!$B$23 | L3: ='Flujos de Caja'!D8-('Amortizacion Deuda'!C7*B3/Financiacion!$C$4)-('Amortizacion Deuda'!D7*B3/Financiacion!$C$4)-MAX(0,'Flujos de Caja'!F8-('Amortizacion Deuda'!C7*B3/Financiacion!$C$4))*Supuestos!$B$23 | M3: ='Flujos de Caja'!D9-('Amortizacion Deuda'!C8*B3/Financiacion!$C$4)-('Amortizacion Deuda'!D8*B3/Financiacion!$C$4)-MAX(0,'Flujos de Caja'!F9-('Amortizacion Deuda'!C8*B3/Financiacion!$C$4))*Supuestos!$B$23 | N3: ='Flujos de Caja'!D10-('Amortizacion Deuda'!C9*B3/Financiacion!$C$4)-('Amortizacion Deuda'!D9*B3/Financiacion!$C$4)-MAX(0,'Flujos de Caja'!F10-('Amortizacion Deuda'!C9*B3/Financiacion!$C$4))*Supuestos!$B$23 | O3: ='Flujos de Caja'!D11-('Amortizacion Deuda'!C10*B3/Financiacion!$C$4)-('Amortizacion Deuda'!D10*B3/Financiacion!$C$4)-MAX(0,'Flujos de Caja'!F11-('Amortizacion Deuda'!C10*B3/Financiacion!$C$4))*Supuestos!$B$23 | P3: ='Flujos de Caja'!D12-('Amortizacion Deuda'!C11*B3/Financiacion!$C$4)-('Amortizacion Deuda'!D11*B3/Financiacion!$C$4)-MAX(0,'Flujos de Caja'!F12-('Amortizacion Deuda'!C11*B3/Financiacion!$C$4))*Supuestos!$B$23 | Q3: ='Flujos de Caja'!D13-('Amortizacion Deuda'!C12*B3/Financiacion!$C$4)-('Amortizacion Deuda'!D12*B3/Financiacion!$C$4)-MAX(0,'Flujos de Caja'!F13-('Amortizacion Deuda'!C12*B3/Financiacion!$C$4))*Supuestos!$B$23 | R3: ='Flujos de Caja'!D14-('Amortizacion Deuda'!C13*B3/Financiacion!$C$4)-('Amortizacion Deuda'!D13*B3/Financiacion!$C$4)-MAX(0,'Flujos de Caja'!F14-('Amortizacion Deuda'!C13*B3/Financiacion!$C$4))*Supuestos!$B$23 | S3: ='Flujos de Caja'!D15-('Amortizacion Deuda'!C14*B3/Financiacion!$C$4)-('Amortizacion Deuda'!D14*B3/Financiacion!$C$4)-MAX(0,'Flujos de Caja'!F15-('Amortizacion Deuda'!C14*B3/Financiacion!$C$4))*Supuestos!$B$23 | T3: ='Flujos de Caja'!D16-('Amortizacion Deuda'!C15*B3/Financiacion!$C$4)-('Amortizacion Deuda'!D15*B3/Financiacion!$C$4)-MAX(0,'Flujos de Caja'!F16-('Amortizacion Deuda'!C15*B3/Financiacion!$C$4))*Supuestos!$B$23 | U3: ='Flujos de Caja'!D17-('Amortizacion Deuda'!C16*B3/Financiacion!$C$4)-('Amortizacion Deuda'!D16*B3/Financiacion!$C$4)-MAX(0,'Flujos de Caja'!F17-('Amortizacion Deuda'!C16*B3/Financiacion!$C$4))*Supuestos!$B$23 | V3: ='Flujos de Caja'!D18-('Amortizacion Deuda'!C17*B3/Financiacion!$C$4)-('Amortizacion Deuda'!D17*B3/Financiacion!$C$4)-MAX(0,'Flujos de Caja'!F18-('Amortizacion Deuda'!C17*B3/Financiacion!$C$4))*Supuestos!$B$23 | W3: ='Flujos de Caja'!D19-('Amortizacion Deuda'!C18*B3/Financiacion!$C$4)-('Amortizacion Deuda'!D18*B3/Financiacion!$C$4)-MAX(0,'Flujos de Caja'!F19-('Amortizacion Deuda'!C18*B3/Financiacion!$C$4))*Supuestos!$B$23 | X3: ='Flujos de Caja'!D20-('Amortizacion Deuda'!C19*B3/Financiacion!$C$4)-('Amortizacion Deuda'!D19*B3/Financiacion!$C$4)-MAX(0,'Flujos de Caja'!F20-('Amortizacion Deuda'!C19*B3/Financiacion!$C$4))*Supuestos!$B$23 | Y3: ='Flujos de Caja'!D21-('Amortizacion Deuda'!C20*B3/Financiacion!$C$4)-('Amortizacion Deuda'!D20*B3/Financiacion!$C$4)-MAX(0,'Flujos de Caja'!F21-('Amortizacion Deuda'!C20*B3/Financiacion!$C$4))*Supuestos!$B$23 | Z3: ='Flujos de Caja'!D22-('Amortizacion Deuda'!C21*B3/Financiacion!$C$4)-('Amortizacion Deuda'!D21*B3/Financiacion!$C$4)-MAX(0,'Flujos de Caja'!F22-('Amortizacion Deuda'!C21*B3/Financiacion!$C$4))*Supuestos!$B$23 | AA3: ='Flujos de Caja'!D23-('Amortizacion Deuda'!C22*B3/Financiacion!$C$4)-('Amortizacion Deuda'!D22*B3/Financiacion!$C$4)-MAX(0,'Flujos de Caja'!F23-('Amortizacion Deuda'!C22*B3/Financiacion!$C$4))*Supuestos!$B$23 | AB3: ='Flujos de Caja'!D24-('Amortizacion Deuda'!C23*B3/Financiacion!$C$4)-('Amortizacion Deuda'!D23*B3/Financiacion!$C$4)-MAX(0,'Flujos de Caja'!F24-('Amortizacion Deuda'!C23*B3/Financiacion!$C$4))*Supuestos!$B$23 | AC3: ='Flujos de Caja'!D25-('Amortizacion Deuda'!C24*B3/Financiacion!$C$4)-('Amortizacion Deuda'!D24*B3/Financiacion!$C$4)-MAX(0,'Flujos de Caja'!F25-('Amortizacion Deuda'!C24*B3/Financiacion!$C$4))*Supuestos!$B$23 | AD3: ='Flujos de Caja'!D26-('Amortizacion Deuda'!C25*B3/Financiacion!$C$4)-('Amortizacion Deuda'!D25*B3/Financiacion!$C$4)-MAX(0,'Flujos de Caja'!F26-('Amortizacion Deuda'!C25*B3/Financiacion!$C$4))*Supuestos!$B$23 | AE3: ='Flujos de Caja'!D27-('Amortizacion Deuda'!C26*B3/Financiacion!$C$4)-('Amortizacion Deuda'!D26*B3/Financiacion!$C$4)-MAX(0,'Flujos de Caja'!F27-('Amortizacion Deuda'!C26*B3/Financiacion!$C$4))*Supuestos!$B$23 | AF3: ='Flujos de Caja'!D28-('Amortizacion Deuda'!C27*B3/Financiacion!$C$4)-('Amortizacion Deuda'!D27*B3/Financiacion!$C$4)-MAX(0,'Flujos de Caja'!F28-('Amortizacion Deuda'!C27*B3/Financiacion!$C$4))*Supuestos!$B$23
A4: 0.4 | B4: =(1-A4)/2*Presupuesto!$B$9 | C4: =(1-A4)/2*Presupuesto!$B$9 | D4: =IRR(G4:AF4) | E4: =NPV(Supuestos!$B$22,H4:AF4)+G4 | F4: =IF(D4>=Supuestos!$B$22,"Viable","No viable") | G4: =-C4 | H4: ='Flujos de Caja'!D4-('Amortizacion Deuda'!C3*B4/Financiacion!$C$4)-('Amortizacion Deuda'!D3*B4/Financiacion!$C$4)-MAX(0,'Flujos de Caja'!F4-('Amortizacion Deuda'!C3*B4/Financiacion!$C$4))*Supuestos!$B$23 | I4: ='Flujos de Caja'!D5-('Amortizacion Deuda'!C4*B4/Financiacion!$C$4)-('Amortizacion Deuda'!D4*B4/Financiacion!$C$4)-MAX(0,'Flujos de Caja'!F5-('Amortizacion Deuda'!C4*B4/Financiacion!$C$4))*Supuestos!$B$23 | J4: ='Flujos de Caja'!D6-('Amortizacion Deuda'!C5*B4/Financiacion!$C$4)-('Amortizacion Deuda'!D5*B4/Financiacion!$C$4)-MAX(0,'Flujos de Caja'!F6-('Amortizacion Deuda'!C5*B4/Financiacion!$C$4))*Supuestos!$B$23 | K4: ='Flujos de Caja'!D7-('Amortizacion Deuda'!C6*B4/Financiacion!$C$4)-('Amortizacion Deuda'!D6*B4/Financiacion!$C$4)-MAX(0,'Flujos de Caja'!F7-('Amortizacion Deuda'!C6*B4/Financiacion!$C$4))*Supuestos!$B$23 | L4: ='Flujos de Caja'!D8-('Amortizacion Deuda'!C7*B4/Financiacion!$C$4)-('Amortizacion Deuda'!D7*B4/Financiacion!$C$4)-MAX(0,'Flujos de Caja'!F8-('Amortizacion Deuda'!C7*B4/Financiacion!$C$4))*Supuestos!$B$23 | M4: ='Flujos de Caja'!D9-('Amortizacion Deuda'!C8*B4/Financiacion!$C$4)-('Amortizacion Deuda'!D8*B4/Financiacion!$C$4)-MAX(0,'Flujos de Caja'!F9-('Amortizacion Deuda'!C8*B4/Financiacion!$C$4))*Supuestos!$B$23 | N4: ='Flujos de Caja'!D10-('Amortizacion Deuda'!C9*B4/Financiacion!$C$4)-('Amortizacion Deuda'!D9*B4/Financiacion!$C$4)-MAX(0,'Flujos de Caja'!F10-('Amortizacion Deuda'!C9*B4/Financiacion!$C$4))*Supuestos!$B$23 | O4: ='Flujos de Caja'!D11-('Amortizacion Deuda'!C10*B4/Financiacion!$C$4)-('Amortizacion Deuda'!D10*B4/Financiacion!$C$4)-MAX(0,'Flujos de Caja'!F11-('Amortizacion Deuda'!C10*B4/Financiacion!$C$4))*Supuestos!$B$23 | P4: ='Flujos de Caja'!D12-('Amortizacion Deuda'!C11*B4/Financiacion!$C$4)-('Amortizacion Deuda'!D11*B4/Financiacion!$C$4)-MAX(0,'Flujos de Caja'!F12-('Amortizacion Deuda'!C11*B4/Financiacion!$C$4))*Supuestos!$B$23 | Q4: ='Flujos de Caja'!D13-('Amortizacion Deuda'!C12*B4/Financiacion!$C$4)-('Amortizacion Deuda'!D12*B4/Financiacion!$C$4)-MAX(0,'Flujos de Caja'!F13-('Amortizacion Deuda'!C12*B4/Financiacion!$C$4))*Supuestos!$B$23 | R4: ='Flujos de Caja'!D14-('Amortizacion Deuda'!C13*B4/Financiacion!$C$4)-('Amortizacion Deuda'!D13*B4/Financiacion!$C$4)-MAX(0,'Flujos de Caja'!F14-('Amortizacion Deuda'!C13*B4/Financiacion!$C$4))*Supuestos!$B$23 | S4: ='Flujos de Caja'!D15-('Amortizacion Deuda'!C14*B4/Financiacion!$C$4)-('Amortizacion Deuda'!D14*B4/Financiacion!$C$4)-MAX(0,'Flujos de Caja'!F15-('Amortizacion Deuda'!C14*B4/Financiacion!$C$4))*Supuestos!$B$23 | T4: ='Flujos de Caja'!D16-('Amortizacion Deuda'!C15*B4/Financiacion!$C$4)-('Amortizacion Deuda'!D15*B4/Financiacion!$C$4)-MAX(0,'Flujos de Caja'!F16-('Amortizacion Deuda'!C15*B4/Financiacion!$C$4))*Supuestos!$B$23 | U4: ='Flujos de Caja'!D17-('Amortizacion Deuda'!C16*B4/Financiacion!$C$4)-('Amortizacion Deuda'!D16*B4/Financiacion!$C$4)-MAX(0,'Flujos de Caja'!F17-('Amortizacion Deuda'!C16*B4/Financiacion!$C$4))*Supuestos!$B$23 | V4: ='Flujos de Caja'!D18-('Amortizacion Deuda'!C17*B4/Financiacion!$C$4)-('Amortizacion Deuda'!D17*B4/Financiacion!$C$4)-MAX(0,'Flujos de Caja'!F18-('Amortizacion Deuda'!C17*B4/Financiacion!$C$4))*Supuestos!$B$23 | W4: ='Flujos de Caja'!D19-('Amortizacion Deuda'!C18*B4/Financiacion!$C$4)-('Amortizacion Deuda'!D18*B4/Financiacion!$C$4)-MAX(0,'Flujos de Caja'!F19-('Amortizacion Deuda'!C18*B4/Financiacion!$C$4))*Supuestos!$B$23 | X4: ='Flujos de Caja'!D20-('Amortizacion Deuda'!C19*B4/Financiacion!$C$4)-('Amortizacion Deuda'!D19*B4/Financiacion!$C$4)-MAX(0,'Flujos de Caja'!F20-('Amortizacion Deuda'!C19*B4/Financiacion!$C$4))*Supuestos!$B$23 | Y4: ='Flujos de Caja'!D21-('Amortizacion Deuda'!C20*B4/Financiacion!$C$4)-('Amortizacion Deuda'!D20*B4/Financiacion!$C$4)-MAX(0,'Flujos de Caja'!F21-('Amortizacion Deuda'!C20*B4/Financiacion!$C$4))*Supuestos!$B$23 | Z4: ='Flujos de Caja'!D22-('Amortizacion Deuda'!C21*B4/Financiacion!$C$4)-('Amortizacion Deuda'!D21*B4/Financiacion!$C$4)-MAX(0,'Flujos de Caja'!F22-('Amortizacion Deuda'!C21*B4/Financiacion!$C$4))*Supuestos!$B$23 | AA4: ='Flujos de Caja'!D23-('Amortizacion Deuda'!C22*B4/Financiacion!$C$4)-('Amortizacion Deuda'!D22*B4/Financiacion!$C$4)-MAX(0,'Flujos de Caja'!F23-('Amortizacion Deuda'!C22*B4/Financiacion!$C$4))*Supuestos!$B$23 | AB4: ='Flujos de Caja'!D24-('Amortizacion Deuda'!C23*B4/Financiacion!$C$4)-('Amortizacion Deuda'!D23*B4/Financiacion!$C$4)-MAX(0,'Flujos de Caja'!F24-('Amortizacion Deuda'!C23*B4/Financiacion!$C$4))*Supuestos!$B$23 | AC4: ='Flujos de Caja'!D25-('Amortizacion Deuda'!C24*B4/Financiacion!$C$4)-('Amortizacion Deuda'!D24*B4/Financiacion!$C$4)-MAX(0,'Flujos de Caja'!F25-('Amortizacion Deuda'!C24*B4/Financiacion!$C$4))*Supuestos!$B$23 | AD4: ='Flujos de Caja'!D26-('Amortizacion Deuda'!C25*B4/Financiacion!$C$4)-('Amortizacion Deuda'!D25*B4/Financiacion!$C$4)-MAX(0,'Flujos de Caja'!F26-('Amortizacion Deuda'!C25*B4/Financiacion!$C$4))*Supuestos!$B$23 | AE4: ='Flujos de Caja'!D27-('Amortizacion Deuda'!C26*B4/Financiacion!$C$4)-('Amortizacion Deuda'!D26*B4/Financiacion!$C$4)-MAX(0,'Flujos de Caja'!F27-('Amortizacion Deuda'!C26*B4/Financiacion!$C$4))*Supuestos!$B$23 | AF4: ='Flujos de Caja'!D28-('Amortizacion Deuda'!C27*B4/Financiacion!$C$4)-('Amortizacion Deuda'!D27*B4/Financiacion!$C$4)-MAX(0,'Flujos de Caja'!F28-('Amortizacion Deuda'!C27*B4/Financiacion!$C$4))*Supuestos!$B$23
A5: 0.6 | B5: =(1-A5)/2*Presupuesto!$B$9 | C5: =(1-A5)/2*Presupuesto!$B$9 | D5: =IRR(G5:AF5) | E5: =NPV(Supuestos!$B$22,H5:AF5)+G5 | F5: =IF(D5>=Supuestos!$B$22,"Viable","No viable") | G5: =-C5 | H5: ='Flujos de Caja'!D4-('Amortizacion Deuda'!C3*B5/Financiacion!$C$4)-('Amortizacion Deuda'!D3*B5/Financiacion!$C$4)-MAX(0,'Flujos de Caja'!F4-('Amortizacion Deuda'!C3*B5/Financiacion!$C$4))*Supuestos!$B$23 | I5: ='Flujos de Caja'!D5-('Amortizacion Deuda'!C4*B5/Financiacion!$C$4)-('Amortizacion Deuda'!D4*B5/Financiacion!$C$4)-MAX(0,'Flujos de Caja'!F5-('Amortizacion Deuda'!C4*B5/Financiacion!$C$4))*Supuestos!$B$23 | J5: ='Flujos de Caja'!D6-('Amortizacion Deuda'!C5*B5/Financiacion!$C$4)-('Amortizacion Deuda'!D5*B5/Financiacion!$C$4)-MAX(0,'Flujos de Caja'!F6-('Amortizacion Deuda'!C5*B5/Financiacion!$C$4))*Supuestos!$B$23 | K5: ='Flujos de Caja'!D7-('Amortizacion Deuda'!C6*B5/Financiacion!$C$4)-('Amortizacion Deuda'!D6*B5/Financiacion!$C$4)-MAX(0,'Flujos de Caja'!F7-('Amortizacion Deuda'!C6*B5/Financiacion!$C$4))*Supuestos!$B$23 | L5: ='Flujos de Caja'!D8-('Amortizacion Deuda'!C7*B5/Financiacion!$C$4)-('Amortizacion Deuda'!D7*B5/Financiacion!$C$4)-MAX(0,'Flujos de Caja'!F8-('Amortizacion Deuda'!C7*B5/Financiacion!$C$4))*Supuestos!$B$23 | M5: ='Flujos de Caja'!D9-('Amortizacion Deuda'!C8*B5/Financiacion!$C$4)-('Amortizacion Deuda'!D8*B5/Financiacion!$C$4)-MAX(0,'Flujos de Caja'!F9-('Amortizacion Deuda'!C8*B5/Financiacion!$C$4))*Supuestos!$B$23 | N5: ='Flujos de Caja'!D10-('Amortizacion Deuda'!C9*B5/Financiacion!$C$4)-('Amortizacion Deuda'!D9*B5/Financiacion!$C$4)-MAX(0,'Flujos de Caja'!F10-('Amortizacion Deuda'!C9*B5/Financiacion!$C$4))*Supuestos!$B$23 | O5: ='Flujos de Caja'!D11-('Amortizacion Deuda'!C10*B5/Financiacion!$C$4)-('Amortizacion Deuda'!D10*B5/Financiacion!$C$4)-MAX(0,'Flujos de Caja'!F11-('Amortizacion Deuda'!C10*B5/Financiacion!$C$4))*Supuestos!$B$23 | P5: ='Flujos de Caja'!D12-('Amortizacion Deuda'!C11*B5/Financiacion!$C$4)-('Amortizacion Deuda'!D11*B5/Financiacion!$C$4)-MAX(0,'Flujos de Caja'!F12-('Amortizacion Deuda'!C11*B5/Financiacion!$C$4))*Supuestos!$B$23 | Q5: ='Flujos de Caja'!D13-('Amortizacion Deuda'!C12*B5/Financiacion!$C$4)-('Amortizacion Deuda'!D12*B5/Financiacion!$C$4)-MAX(0,'Flujos de Caja'!F13-('Amortizacion Deuda'!C12*B5/Financiacion!$C$4))*Supuestos!$B$23 | R5: ='Flujos de Caja'!D14-('Amortizacion Deuda'!C13*B5/Financiacion!$C$4)-('Amortizacion Deuda'!D13*B5/Financiacion!$C$4)-MAX(0,'Flujos de Caja'!F14-('Amortizacion Deuda'!C13*B5/Financiacion!$C$4))*Supuestos!$B$23 | S5: ='Flujos de Caja'!D15-('Amortizacion Deuda'!C14*B5/Financiacion!$C$4)-('Amortizacion Deuda'!D14*B5/Financiacion!$C$4)-MAX(0,'Flujos de Caja'!F15-('Amortizacion Deuda'!C14*B5/Financiacion!$C$4))*Supuestos!$B$23 | T5: ='Flujos de Caja'!D16-('Amortizacion Deuda'!C15*B5/Financiacion!$C$4)-('Amortizacion Deuda'!D15*B5/Financiacion!$C$4)-MAX(0,'Flujos de Caja'!F16-('Amortizacion Deuda'!C15*B5/Financiacion!$C$4))*Supuestos!$B$23 | U5: ='Flujos de Caja'!D17-('Amortizacion Deuda'!C16*B5/Financiacion!$C$4)-('Amortizacion Deuda'!D16*B5/Financiacion!$C$4)-MAX(0,'Flujos de Caja'!F17-('Amortizacion Deuda'!C16*B5/Financiacion!$C$4))*Supuestos!$B$23 | V5: ='Flujos de Caja'!D18-('Amortizacion Deuda'!C17*B5/Financiacion!$C$4)-('Amortizacion Deuda'!D17*B5/Financiacion!$C$4)-MAX(0,'Flujos de Caja'!F18-('Amortizacion Deuda'!C17*B5/Financiacion!$C$4))*Supuestos!$B$23 | W5: ='Flujos de Caja'!D19-('Amortizacion Deuda'!C18*B5/Financiacion!$C$4)-('Amortizacion Deuda'!D18*B5/Financiacion!$C$4)-MAX(0,'Flujos de Caja'!F19-('Amortizacion Deuda'!C18*B5/Financiacion!$C$4))*Supuestos!$B$23 | X5: ='Flujos de Caja'!D20-('Amortizacion Deuda'!C19*B5/Financiacion!$C$4)-('Amortizacion Deuda'!D19*B5/Financiacion!$C$4)-MAX(0,'Flujos de Caja'!F20-('Amortizacion Deuda'!C19*B5/Financiacion!$C$4))*Supuestos!$B$23 | Y5: ='Flujos de Caja'!D21-('Amortizacion Deuda'!C20*B5/Financiacion!$C$4)-('Amortizacion Deuda'!D20*B5/Financiacion!$C$4)-MAX(0,'Flujos de Caja'!F21-('Amortizacion Deuda'!C20*B5/Financiacion!$C$4))*Supuestos!$B$23 | Z5: ='Flujos de Caja'!D22-('Amortizacion Deuda'!C21*B5/Financiacion!$C$4)-('Amortizacion Deuda'!D21*B5/Financiacion!$C$4)-MAX(0,'Flujos de Caja'!F22-('Amortizacion Deuda'!C21*B5/Financiacion!$C$4))*Supuestos!$B$23 | AA5: ='Flujos de Caja'!D23-('Amortizacion Deuda'!C22*B5/Financiacion!$C$4)-('Amortizacion Deuda'!D22*B5/Financiacion!$C$4)-MAX(0,'Flujos de Caja'!F23-('Amortizacion Deuda'!C22*B5/Financiacion!$C$4))*Supuestos!$B$23 | AB5: ='Flujos de Caja'!D24-('Amortizacion Deuda'!C23*B5/Financiacion!$C$4)-('Amortizacion Deuda'!D23*B5/Financiacion!$C$4)-MAX(0,'Flujos de Caja'!F24-('Amortizacion Deuda'!C23*B5/Financiacion!$C$4))*Supuestos!$B$23 | AC5: ='Flujos de Caja'!D25-('Amortizacion Deuda'!C24*B5/Financiacion!$C$4)-('Amortizacion Deuda'!D24*B5/Financiacion!$C$4)-MAX(0,'Flujos de Caja'!F25-('Amortizacion Deuda'!C24*B5/Financiacion!$C$4))*Supuestos!$B$23 | AD5: ='Flujos de Caja'!D26-('Amortizacion Deuda'!C25*B5/Financiacion!$C$4)-('Amortizacion Deuda'!D25*B5/Financiacion!$C$4)-MAX(0,'Flujos de Caja'!F26-('Amortizacion Deuda'!C25*B5/Financiacion!$C$4))*Supuestos!$B$23 | AE5: ='Flujos de Caja'!D27-('Amortizacion Deuda'!C26*B5/Financiacion!$C$4)-('Amortizacion Deuda'!D26*B5/Financiacion!$C$4)-MAX(0,'Flujos de Caja'!F27-('Amortizacion Deuda'!C26*B5/Financiacion!$C$4))*Supuestos!$B$23 | AF5: ='Flujos de Caja'!D28-('Amortizacion Deuda'!C27*B5/Financiacion!$C$4)-('Amortizacion Deuda'!D27*B5/Financiacion!$C$4)-MAX(0,'Flujos de Caja'!F28-('Amortizacion Deuda'!C27*B5/Financiacion!$C$4))*Supuestos!$B$23
A6: 0.7 | B6: =(1-A6)/2*Presupuesto!$B$9 | C6: =(1-A6)/2*Presupuesto!$B$9 | D6: =IRR(G6:AF6) | E6: =NPV(Supuestos!$B$22,H6:AF6)+G6 | F6: =IF(D6>=Supuestos!$B$22,"Viable","No viable") | G6: =-C6 | H6: ='Flujos de Caja'!D4-('Amortizacion Deuda'!C3*B6/Financiacion!$C$4)-('Amortizacion Deuda'!D3*B6/Financiacion!$C$4)-MAX(0,'Flujos de Caja'!F4-('Amortizacion Deuda'!C3*B6/Financiacion!$C$4))*Supuestos!$B$23 | I6: ='Flujos de Caja'!D5-('Amortizacion Deuda'!C4*B6/Financiacion!$C$4)-('Amortizacion Deuda'!D4*B6/Financiacion!$C$4)-MAX(0,'Flujos de Caja'!F5-('Amortizacion Deuda'!C4*B6/Financiacion!$C$4))*Supuestos!$B$23 | J6: ='Flujos de Caja'!D6-('Amortizacion Deuda'!C5*B6/Financiacion!$C$4)-('Amortizacion Deuda'!D5*B6/Financiacion!$C$4)-MAX(0,'Flujos de Caja'!F6-('Amortizacion Deuda'!C5*B6/Financiacion!$C$4))*Supuestos!$B$23 | K6: ='Flujos de Caja'!D7-('Amortizacion Deuda'!C6*B6/Financiacion!$C$4)-('Amortizacion Deuda'!D6*B6/Financiacion!$C$4)-MAX(0,'Flujos de Caja'!F7-('Amortizacion Deuda'!C6*B6/Financiacion!$C$4))*Supuestos!$B$23 | L6: ='Flujos de Caja'!D8-('Amortizacion Deuda'!C7*B6/Financiacion!$C$4)-('Amortizacion Deuda'!D7*B6/Financiacion!$C$4)-MAX(0,'Flujos de Caja'!F8-('Amortizacion Deuda'!C7*B6/Financiacion!$C$4))*Supuestos!$B$23 | M6: ='Flujos de Caja'!D9-('Amortizacion Deuda'!C8*B6/Financiacion!$C$4)-('Amortizacion Deuda'!D8*B6/Financiacion!$C$4)-MAX(0,'Flujos de Caja'!F9-('Amortizacion Deuda'!C8*B6/Financiacion!$C$4))*Supuestos!$B$23 | N6: ='Flujos de Caja'!D10-('Amortizacion Deuda'!C9*B6/Financiacion!$C$4)-('Amortizacion Deuda'!D9*B6/Financiacion!$C$4)-MAX(0,'Flujos de Caja'!F10-('Amortizacion Deuda'!C9*B6/Financiacion!$C$4))*Supuestos!$B$23 | O6: ='Flujos de Caja'!D11-('Amortizacion Deuda'!C10*B6/Financiacion!$C$4)-('Amortizacion Deuda'!D10*B6/Financiacion!$C$4)-MAX(0,'Flujos de Caja'!F11-('Amortizacion Deuda'!C10*B6/Financiacion!$C$4))*Supuestos!$B$23 | P6: ='Flujos de Caja'!D12-('Amortizacion Deuda'!C11*B6/Financiacion!$C$4)-('Amortizacion Deuda'!D11*B6/Financiacion!$C$4)-MAX(0,'Flujos de Caja'!F12-('Amortizacion Deuda'!C11*B6/Financiacion!$C$4))*Supuestos!$B$23 | Q6: ='Flujos de Caja'!D13-('Amortizacion Deuda'!C12*B6/Financiacion!$C$4)-('Amortizacion Deuda'!D12*B6/Financiacion!$C$4)-MAX(0,'Flujos de Caja'!F13-('Amortizacion Deuda'!C12*B6/Financiacion!$C$4))*Supuestos!$B$23 | R6: ='Flujos de Caja'!D14-('Amortizacion Deuda'!C13*B6/Financiacion!$C$4)-('Amortizacion Deuda'!D13*B6/Financiacion!$C$4)-MAX(0,'Flujos de Caja'!F14-('Amortizacion Deuda'!C13*B6/Financiacion!$C$4))*Supuestos!$B$23 | S6: ='Flujos de Caja'!D15-('Amortizacion Deuda'!C14*B6/Financiacion!$C$4)-('Amortizacion Deuda'!D14*B6/Financiacion!$C$4)-MAX(0,'Flujos de Caja'!F15-('Amortizacion Deuda'!C14*B6/Financiacion!$C$4))*Supuestos!$B$23 | T6: ='Flujos de Caja'!D16-('Amortizacion Deuda'!C15*B6/Financiacion!$C$4)-('Amortizacion Deuda'!D15*B6/Financiacion!$C$4)-MAX(0,'Flujos de Caja'!F16-('Amortizacion Deuda'!C15*B6/Financiacion!$C$4))*Supuestos!$B$23 | U6: ='Flujos de Caja'!D17-('Amortizacion Deuda'!C16*B6/Financiacion!$C$4)-('Amortizacion Deuda'!D16*B6/Financiacion!$C$4)-MAX(0,'Flujos de Caja'!F17-('Amortizacion Deuda'!C16*B6/Financiacion!$C$4))*Supuestos!$B$23 | V6: ='Flujos de Caja'!D18-('Amortizacion Deuda'!C17*B6/Financiacion!$C$4)-('Amortizacion Deuda'!D17*B6/Financiacion!$C$4)-MAX(0,'Flujos de Caja'!F18-('Amortizacion Deuda'!C17*B6/Financiacion!$C$4))*Supuestos!$B$23 | W6: ='Flujos de Caja'!D19-('Amortizacion Deuda'!C18*B6/Financiacion!$C$4)-('Amortizacion Deuda'!D18*B6/Financiacion!$C$4)-MAX(0,'Flujos de Caja'!F19-('Amortizacion Deuda'!C18*B6/Financiacion!$C$4))*Supuestos!$B$23 | X6: ='Flujos de Caja'!D20-('Amortizacion Deuda'!C19*B6/Financiacion!$C$4)-('Amortizacion Deuda'!D19*B6/Financiacion!$C$4)-MAX(0,'Flujos de Caja'!F20-('Amortizacion Deuda'!C19*B6/Financiacion!$C$4))*Supuestos!$B$23 | Y6: ='Flujos de Caja'!D21-('Amortizacion Deuda'!C20*B6/Financiacion!$C$4)-('Amortizacion Deuda'!D20*B6/Financiacion!$C$4)-MAX(0,'Flujos de Caja'!F21-('Amortizacion Deuda'!C20*B6/Financiacion!$C$4))*Supuestos!$B$23 | Z6: ='Flujos de Caja'!D22-('Amortizacion Deuda'!C21*B6/Financiacion!$C$4)-('Amortizacion Deuda'!D21*B6/Financiacion!$C$4)-MAX(0,'Flujos de Caja'!F22-('Amortizacion Deuda'!C21*B6/Financiacion!$C$4))*Supuestos!$B$23 | AA6: ='Flujos de Caja'!D23-('Amortizacion Deuda'!C22*B6/Financiacion!$C$4)-('Amortizacion Deuda'!D22*B6/Financiacion!$C$4)-MAX(0,'Flujos de Caja'!F23-('Amortizacion Deuda'!C22*B6/Financiacion!$C$4))*Supuestos!$B$23 | AB6: ='Flujos de Caja'!D24-('Amortizacion Deuda'!C23*B6/Financiacion!$C$4)-('Amortizacion Deuda'!D23*B6/Financiacion!$C$4)-MAX(0,'Flujos de Caja'!F24-('Amortizacion Deuda'!C23*B6/Financiacion!$C$4))*Supuestos!$B$23 | AC6: ='Flujos de Caja'!D25-('Amortizacion Deuda'!C24*B6/Financiacion!$C$4)-('Amortizacion Deuda'!D24*B6/Financiacion!$C$4)-MAX(0,'Flujos de Caja'!F25-('Amortizacion Deuda'!C24*B6/Financiacion!$C$4))*Supuestos!$B$23 | AD6: ='Flujos de Caja'!D26-('Amortizacion Deuda'!C25*B6/Financiacion!$C$4)-('Amortizacion Deuda'!D25*B6/Financiacion!$C$4)-MAX(0,'Flujos de Caja'!F26-('Amortizacion Deuda'!C25*B6/Financiacion!$C$4))*Supuestos!$B$23 | AE6: ='Flujos de Caja'!D27-('Amortizacion Deuda'!C26*B6/Financiacion!$C$4)-('Amortizacion Deuda'!D26*B6/Financiacion!$C$4)-MAX(0,'Flujos de Caja'!F27-('Amortizacion Deuda'!C26*B6/Financiacion!$C$4))*Supuestos!$B$23 | AF6: ='Flujos de Caja'!D28-('Amortizacion Deuda'!C27*B6/Financiacion!$C$4)-('Amortizacion Deuda'!D27*B6/Financiacion!$C$4)-MAX(0,'Flujos de Caja'!F28-('Amortizacion Deuda'!C27*B6/Financiacion!$C$4))*Supuestos!$B$23
A7: 0.8 | B7: =(1-A7)/2*Presupuesto!$B$9 | C7: =(1-A7)/2*Presupuesto!$B$9 | D7: =IRR(G7:AF7) | E7: =NPV(Supuestos!$B$22,H7:AF7)+G7 | F7: =IF(D7>=Supuestos!$B$22,"Viable","No viable") | G7: =-C7 | H7: ='Flujos de Caja'!D4-('Amortizacion Deuda'!C3*B7/Financiacion!$C$4)-('Amortizacion Deuda'!D3*B7/Financiacion!$C$4)-MAX(0,'Flujos de Caja'!F4-('Amortizacion Deuda'!C3*B7/Financiacion!$C$4))*Supuestos!$B$23 | I7: ='Flujos de Caja'!D5-('Amortizacion Deuda'!C4*B7/Financiacion!$C$4)-('Amortizacion Deuda'!D4*B7/Financiacion!$C$4)-MAX(0,'Flujos de Caja'!F5-('Amortizacion Deuda'!C4*B7/Financiacion!$C$4))*Supuestos!$B$23 | J7: ='Flujos de Caja'!D6-('Amortizacion Deuda'!C5*B7/Financiacion!$C$4)-('Amortizacion Deuda'!D5*B7/Financiacion!$C$4)-MAX(0,'Flujos de Caja'!F6-('Amortizacion Deuda'!C5*B7/Financiacion!$C$4))*Supuestos!$B$23 | K7: ='Flujos de Caja'!D7-('Amortizacion Deuda'!C6*B7/Financiacion!$C$4)-('Amortizacion Deuda'!D6*B7/Financiacion!$C$4)-MAX(0,'Flujos de Caja'!F7-('Amortizacion Deuda'!C6*B7/Financiacion!$C$4))*Supuestos!$B$23 | L7: ='Flujos de Caja'!D8-('Amortizacion Deuda'!C7*B7/Financiacion!$C$4)-('Amortizacion Deuda'!D7*B7/Financiacion!$C$4)-MAX(0,'Flujos de Caja'!F8-('Amortizacion Deuda'!C7*B7/Financiacion!$C$4))*Supuestos!$B$23 | M7: ='Flujos de Caja'!D9-('Amortizacion Deuda'!C8*B7/Financiacion!$C$4)-('Amortizacion Deuda'!D8*B7/Financiacion!$C$4)-MAX(0,'Flujos de Caja'!F9-('Amortizacion Deuda'!C8*B7/Financiacion!$C$4))*Supuestos!$B$23 | N7: ='Flujos de Caja'!D10-('Amortizacion Deuda'!C9*B7/Financiacion!$C$4)-('Amortizacion Deuda'!D9*B7/Financiacion!$C$4)-MAX(0,'Flujos de Caja'!F10-('Amortizacion Deuda'!C9*B7/Financiacion!$C$4))*Supuestos!$B$23 | O7: ='Flujos de Caja'!D11-('Amortizacion Deuda'!C10*B7/Financiacion!$C$4)-('Amortizacion Deuda'!D10*B7/Financiacion!$C$4)-MAX(0,'Flujos de Caja'!F11-('Amortizacion Deuda'!C10*B7/Financiacion!$C$4))*Supuestos!$B$23 | P7: ='Flujos de Caja'!D12-('Amortizacion Deuda'!C11*B7/Financiacion!$C$4)-('Amortizacion Deuda'!D11*B7/Financiacion!$C$4)-MAX(0,'Flujos de Caja'!F12-('Amortizacion Deuda'!C11*B7/Financiacion!$C$4))*Supuestos!$B$23 | Q7: ='Flujos de Caja'!D13-('Amortizacion Deuda'!C12*B7/Financiacion!$C$4)-('Amortizacion Deuda'!D12*B7/Financiacion!$C$4)-MAX(0,'Flujos de Caja'!F13-('Amortizacion Deuda'!C12*B7/Financiacion!$C$4))*Supuestos!$B$23 | R7: ='Flujos de Caja'!D14-('Amortizacion Deuda'!C13*B7/Financiacion!$C$4)-('Amortizacion Deuda'!D13*B7/Financiacion!$C$4)-MAX(0,'Flujos de Caja'!F14-('Amortizacion Deuda'!C13*B7/Financiacion!$C$4))*Supuestos!$B$23 | S7: ='Flujos de Caja'!D15-('Amortizacion Deuda'!C14*B7/Financiacion!$C$4)-('Amortizacion Deuda'!D14*B7/Financiacion!$C$4)-MAX(0,'Flujos de Caja'!F15-('Amortizacion Deuda'!C14*B7/Financiacion!$C$4))*Supuestos!$B$23 | T7: ='Flujos de Caja'!D16-('Amortizacion Deuda'!C15*B7/Financiacion!$C$4)-('Amortizacion Deuda'!D15*B7/Financiacion!$C$4)-MAX(0,'Flujos de Caja'!F16-('Amortizacion Deuda'!C15*B7/Financiacion!$C$4))*Supuestos!$B$23 | U7: ='Flujos de Caja'!D17-('Amortizacion Deuda'!C16*B7/Financiacion!$C$4)-('Amortizacion Deuda'!D16*B7/Financiacion!$C$4)-MAX(0,'Flujos de Caja'!F17-('Amortizacion Deuda'!C16*B7/Financiacion!$C$4))*Supuestos!$B$23 | V7: ='Flujos de Caja'!D18-('Amortizacion Deuda'!C17*B7/Financiacion!$C$4)-('Amortizacion Deuda'!D17*B7/Financiacion!$C$4)-MAX(0,'Flujos de Caja'!F18-('Amortizacion Deuda'!C17*B7/Financiacion!$C$4))*Supuestos!$B$23 | W7: ='Flujos de Caja'!D19-('Amortizacion Deuda'!C18*B7/Financiacion!$C$4)-('Amortizacion Deuda'!D18*B7/Financiacion!$C$4)-MAX(0,'Flujos de Caja'!F19-('Amortizacion Deuda'!C18*B7/Financiacion!$C$4))*Supuestos!$B$23 | X7: ='Flujos de Caja'!D20-('Amortizacion Deuda'!C19*B7/Financiacion!$C$4)-('Amortizacion Deuda'!D19*B7/Financiacion!$C$4)-MAX(0,'Flujos de Caja'!F20-('Amortizacion Deuda'!C19*B7/Financiacion!$C$4))*Supuestos!$B$23 | Y7: ='Flujos de Caja'!D21-('Amortizacion Deuda'!C20*B7/Financiacion!$C$4)-('Amortizacion Deuda'!D20*B7/Financiacion!$C$4)-MAX(0,'Flujos de Caja'!F21-('Amortizacion Deuda'!C20*B7/Financiacion!$C$4))*Supuestos!$B$23 | Z7: ='Flujos de Caja'!D22-('Amortizacion Deuda'!C21*B7/Financiacion!$C$4)-('Amortizacion Deuda'!D21*B7/Financiacion!$C$4)-MAX(0,'Flujos de Caja'!F22-('Amortizacion Deuda'!C21*B7/Financiacion!$C$4))*Supuestos!$B$23 | AA7: ='Flujos de Caja'!D23-('Amortizacion Deuda'!C22*B7/Financiacion!$C$4)-('Amortizacion Deuda'!D22*B7/Financiacion!$C$4)-MAX(0,'Flujos de Caja'!F23-('Amortizacion Deuda'!C22*B7/Financiacion!$C$4))*Supuestos!$B$23 | AB7: ='Flujos de Caja'!D24-('Amortizacion Deuda'!C23*B7/Financiacion!$C$4)-('Amortizacion Deuda'!D23*B7/Financiacion!$C$4)-MAX(0,'Flujos de Caja'!F24-('Amortizacion Deuda'!C23*B7/Financiacion!$C$4))*Supuestos!$B$23 | AC7: ='Flujos de Caja'!D25-('Amortizacion Deuda'!C24*B7/Financiacion!$C$4)-('Amortizacion Deuda'!D24*B7/Financiacion!$C$4)-MAX(0,'Flujos de Caja'!F25-('Amortizacion Deuda'!C24*B7/Financiacion!$C$4))*Supuestos!$B$23 | AD7: ='Flujos de Caja'!D26-('Amortizacion Deuda'!C25*B7/Financiacion!$C$4)-('Amortizacion Deuda'!D25*B7/Financiacion!$C$4)-MAX(0,'Flujos de Caja'!F26-('Amortizacion Deuda'!C25*B7/Financiacion!$C$4))*Supuestos!$B$23 | AE7: ='Flujos de Caja'!D27-('Amortizacion Deuda'!C26*B7/Financiacion!$C$4)-('Amortizacion Deuda'!D26*B7/Financiacion!$C$4)-MAX(0,'Flujos de Caja'!F27-('Amortizacion Deuda'!C26*B7/Financiacion!$C$4))*Supuestos!$B$23 | AF7: ='Flujos de Caja'!D28-('Amortizacion Deuda'!C27*B7/Financiacion!$C$4)-('Amortizacion Deuda'!D27*B7/Financiacion!$C$4)-MAX(0,'Flujos de Caja'!F28-('Amortizacion Deuda'!C27*B7/Financiacion!$C$4))*Supuestos!$B$23
A8: 0.9 | B8: =(1-A8)/2*Presupuesto!$B$9 | C8: =(1-A8)/2*Presupuesto!$B$9 | D8: =IRR(G8:AF8) | E8: =NPV(Supuestos!$B$22,H8:AF8)+G8 | F8: =IF(D8>=Supuestos!$B$22,"Viable","No viable") | G8: =-C8 | H8: ='Flujos de Caja'!D4-('Amortizacion Deuda'!C3*B8/Financiacion!$C$4)-('Amortizacion Deuda'!D3*B8/Financiacion!$C$4)-MAX(0,'Flujos de Caja'!F4-('Amortizacion Deuda'!C3*B8/Financiacion!$C$4))*Supuestos!$B$23 | I8: ='Flujos de Caja'!D5-('Amortizacion Deuda'!C4*B8/Financiacion!$C$4)-('Amortizacion Deuda'!D4*B8/Financiacion!$C$4)-MAX(0,'Flujos de Caja'!F5-('Amortizacion Deuda'!C4*B8/Financiacion!$C$4))*Supuestos!$B$23 | J8: ='Flujos de Caja'!D6-('Amortizacion Deuda'!C5*B8/Financiacion!$C$4)-('Amortizacion Deuda'!D5*B8/Financiacion!$C$4)-MAX(0,'Flujos de Caja'!F6-('Amortizacion Deuda'!C5*B8/Financiacion!$C$4))*Supuestos!$B$23 | K8: ='Flujos de Caja'!D7-('Amortizacion Deuda'!C6*B8/Financiacion!$C$4)-('Amortizacion Deuda'!D6*B8/Financiacion!$C$4)-MAX(0,'Flujos de Caja'!F7-('Amortizacion Deuda'!C6*B8/Financiacion!$C$4))*Supuestos!$B$23 | L8: ='Flujos de Caja'!D8-('Amortizacion Deuda'!C7*B8/Financiacion!$C$4)-('Amortizacion Deuda'!D7*B8/Financiacion!$C$4)-MAX(0,'Flujos de Caja'!F8-('Amortizacion Deuda'!C7*B8/Financiacion!$C$4))*Supuestos!$B$23 | M8: ='Flujos de Caja'!D9-('Amortizacion Deuda'!C8*B8/Financiacion!$C$4)-('Amortizacion Deuda'!D8*B8/Financiacion!$C$4)-MAX(0,'Flujos de Caja'!F9-('Amortizacion Deuda'!C8*B8/Financiacion!$C$4))*Supuestos!$B$23 | N8: ='Flujos de Caja'!D10-('Amortizacion Deuda'!C9*B8/Financiacion!$C$4)-('Amortizacion Deuda'!D9*B8/Financiacion!$C$4)-MAX(0,'Flujos de Caja'!F10-('Amortizacion Deuda'!C9*B8/Financiacion!$C$4))*Supuestos!$B$23 | O8: ='Flujos de Caja'!D11-('Amortizacion Deuda'!C10*B8/Financiacion!$C$4)-('Amortizacion Deuda'!D10*B8/Financiacion!$C$4)-MAX(0,'Flujos de Caja'!F11-('Amortizacion Deuda'!C10*B8/Financiacion!$C$4))*Supuestos!$B$23 | P8: ='Flujos de Caja'!D12-('Amortizacion Deuda'!C11*B8/Financiacion!$C$4)-('Amortizacion Deuda'!D11*B8/Financiacion!$C$4)-MAX(0,'Flujos de Caja'!F12-('Amortizacion Deuda'!C11*B8/Financiacion!$C$4))*Supuestos!$B$23 | Q8: ='Flujos de Caja'!D13-('Amortizacion Deuda'!C12*B8/Financiacion!$C$4)-('Amortizacion Deuda'!D12*B8/Financiacion!$C$4)-MAX(0,'Flujos de Caja'!F13-('Amortizacion Deuda'!C12*B8/Financiacion!$C$4))*Supuestos!$B$23 | R8: ='Flujos de Caja'!D14-('Amortizacion Deuda'!C13*B8/Financiacion!$C$4)-('Amortizacion Deuda'!D13*B8/Financiacion!$C$4)-MAX(0,'Flujos de Caja'!F14-('Amortizacion Deuda'!C13*B8/Financiacion!$C$4))*Supuestos!$B$23 | S8: ='Flujos de Caja'!D15-('Amortizacion Deuda'!C14*B8/Financiacion!$C$4)-('Amortizacion Deuda'!D14*B8/Financiacion!$C$4)-MAX(0,'Flujos de Caja'!F15-('Amortizacion Deuda'!C14*B8/Financiacion!$C$4))*Supuestos!$B$23 | T8: ='Flujos de Caja'!D16-('Amortizacion Deuda'!C15*B8/Financiacion!$C$4)-('Amortizacion Deuda'!D15*B8/Financiacion!$C$4)-MAX(0,'Flujos de Caja'!F16-('Amortizacion Deuda'!C15*B8/Financiacion!$C$4))*Supuestos!$B$23 | U8: ='Flujos de Caja'!D17-('Amortizacion Deuda'!C16*B8/Financiacion!$C$4)-('Amortizacion Deuda'!D16*B8/Financiacion!$C$4)-MAX(0,'Flujos de Caja'!F17-('Amortizacion Deuda'!C16*B8/Financiacion!$C$4))*Supuestos!$B$23 | V8: ='Flujos de Caja'!D18-('Amortizacion Deuda'!C17*B8/Financiacion!$C$4)-('Amortizacion Deuda'!D17*B8/Financiacion!$C$4)-MAX(0,'Flujos de Caja'!F18-('Amortizacion Deuda'!C17*B8/Financiacion!$C$4))*Supuestos!$B$23 | W8: ='Flujos de Caja'!D19-('Amortizacion Deuda'!C18*B8/Financiacion!$C$4)-('Amortizacion Deuda'!D18*B8/Financiacion!$C$4)-MAX(0,'Flujos de Caja'!F19-('Amortizacion Deuda'!C18*B8/Financiacion!$C$4))*Supuestos!$B$23 | X8: ='Flujos de Caja'!D20-('Amortizacion Deuda'!C19*B8/Financiacion!$C$4)-('Amortizacion Deuda'!D19*B8/Financiacion!$C$4)-MAX(0,'Flujos de Caja'!F20-('Amortizacion Deuda'!C19*B8/Financiacion!$C$4))*Supuestos!$B$23 | Y8: ='Flujos de Caja'!D21-('Amortizacion Deuda'!C20*B8/Financiacion!$C$4)-('Amortizacion Deuda'!D20*B8/Financiacion!$C$4)-MAX(0,'Flujos de Caja'!F21-('Amortizacion Deuda'!C20*B8/Financiacion!$C$4))*Supuestos!$B$23 | Z8: ='Flujos de Caja'!D22-('Amortizacion Deuda'!C21*B8/Financiacion!$C$4)-('Amortizacion Deuda'!D21*B8/Financiacion!$C$4)-MAX(0,'Flujos de Caja'!F22-('Amortizacion Deuda'!C21*B8/Financiacion!$C$4))*Supuestos!$B$23 | AA8: ='Flujos de Caja'!D23-('Amortizacion Deuda'!C22*B8/Financiacion!$C$4)-('Amortizacion Deuda'!D22*B8/Financiacion!$C$4)-MAX(0,'Flujos de Caja'!F23-('Amortizacion Deuda'!C22*B8/Financiacion!$C$4))*Supuestos!$B$23 | AB8: ='Flujos de Caja'!D24-('Amortizacion Deuda'!C23*B8/Financiacion!$C$4)-('Amortizacion Deuda'!D23*B8/Financiacion!$C$4)-MAX(0,'Flujos de Caja'!F24-('Amortizacion Deuda'!C23*B8/Financiacion!$C$4))*Supuestos!$B$23 | AC8: ='Flujos de Caja'!D25-('Amortizacion Deuda'!C24*B8/Financiacion!$C$4)-('Amortizacion Deuda'!D24*B8/Financiacion!$C$4)-MAX(0,'Flujos de Caja'!F25-('Amortizacion Deuda'!C24*B8/Financiacion!$C$4))*Supuestos!$B$23 | AD8: ='Flujos de Caja'!D26-('Amortizacion Deuda'!C25*B8/Financiacion!$C$4)-('Amortizacion Deuda'!D25*B8/Financiacion!$C$4)-MAX(0,'Flujos de Caja'!F26-('Amortizacion Deuda'!C25*B8/Financiacion!$C$4))*Supuestos!$B$23 | AE8: ='Flujos de Caja'!D27-('Amortizacion Deuda'!C26*B8/Financiacion!$C$4)-('Amortizacion Deuda'!D26*B8/Financiacion!$C$4)-MAX(0,'Flujos de Caja'!F27-('Amortizacion Deuda'!C26*B8/Financiacion!$C$4))*Supuestos!$B$23 | AF8: ='Flujos de Caja'!D28-('Amortizacion Deuda'!C27*B8/Financiacion!$C$4)-('Amortizacion Deuda'!D27*B8/Financiacion!$C$4)-MAX(0,'Flujos de Caja'!F28-('Amortizacion Deuda'!C27*B8/Financiacion!$C$4))*Supuestos!$B$23

Sheet Indicadores
A1: INDICADORES
A2: Indicador | B2: Valor | C2: Criterio | D2: Conclusión
A3: WACC | B3: =Financiacion!B8 | C3: Tasa proyecto | D3: Referencia
A4: VPN Proyecto | B4: =NPV(B3,'Flujos de Caja'!L4:L28)+'Flujos de Caja'!L3 | C4: >0 | D4: =IF(B4>0,"Viable","No viable")
A5: TIR Proyecto | B5: =IRR('Flujos de Caja'!L3:L28) | C5: >WACC | D5: =IF(B5>B3,"Viable","No viable")
A6: VPN Inversionista | B6: =NPV(Supuestos!B22,'Flujos de Caja'!M4:M28)+'Flujos de Caja'!M3 | C6: >0 | D6: =IF(B6>0,"Viable","No alcanza Ke")
A7: TIR Inversionista | B7: =IRR('Flujos de Caja'!M3:M28) | C7: >Ke | D7: =IF(B7>Supuestos!B22,"Viable","No alcanza Ke")
A8: VPN Social | B8: =NPV(Supuestos!B25,'Flujos de Caja'!P4:P28)+'Flujos de Caja'!P3 | C8: >0 | D8: =IF(B8>0,"Viable","No viable")
A9: B/C | B9: =NPV(Supuestos!B25,'Flujos de Caja'!O4:O28)/(Presupuesto!B9+NPV(Supuestos!B25,'Flujos de Caja'!C4:C28)) | C9: >1 | D9: =IF(B9>1,"Viable","No viable")
A10: TIR Banco | B10: =IRR('Flujos de Caja'!N3:N28) | C10: Kd = 11 % | D10: =IF(ABS(B10-Supuestos!B21)<0.000001,"Concilia","Revisar")

Sheet Riesgos
A1: MATRIZ 20 RIESGOS E INTERVENCIÓN 10 (5 AMBIENTALES)
A2: # | B2: Riesgo | C2: Tipo | D2: P | E2: I | F2: P×I | G2: Nivel | H2: Observación
A3: 1 | B3: Sobrecostos en la construcción | C3: Financiero | D3: 4 | E3: 4 | F3: =D3*E3 | G3: =IF(F3<=6,"Bajo",IF(F3<=12,"Medio","Alto")) | H3: Prioritario
A4: 2 | B4: Retrasos en el cronograma de obra | C4: Operativo | D4: 4 | E4: 3 | F4: =D4*E4 | G4: =IF(F4<=6,"Bajo",IF(F4<=12,"Medio","Alto"))
A5: 3 | B5: Demoras en gestión predial y servidumbres | C5: Legal | D5: 3 | E5: 4 | F5: =D5*E5 | G5: =IF(F5<=6,"Bajo",IF(F5<=12,"Medio","Alto"))
A6: 4 | B6: Insuficiencia/retraso del aporte público | C6: Financiero | D6: 3 | E6: 5 | F6: =D6*E6 | G6: =IF(F6<=6,"Bajo",IF(F6<=12,"Medio","Alto")) | H6: Prioritario
A7: 5 | B7: Incremento de tasas de interés | C7: Financiero | D7: 3 | E7: 4 | F7: =D7*E7 | G7: =IF(F7<=6,"Bajo",IF(F7<=12,"Medio","Alto"))
A8: 6 | B8: Recaudo tarifario inferior al proyectado | C8: Comercial | D8: 4 | E8: 4 | F8: =D8*E8 | G8: =IF(F8<=6,"Bajo",IF(F8<=12,"Medio","Alto")) | H8: Prioritario
A9: 7 | B9: Cambios regulatorios del marco tarifario | C9: Regulatorio | D9: 2 | E9: 4 | F9: =D9*E9 | G9: =IF(F9<=6,"Bajo",IF(F9<=12,"Medio","Alto"))
A10: 8 | B10: Alta turbiedad/mercurio del río San Juan | C10: Ambiental | D10: 4 | E10: 5 | F10: =D10*E10 | G10: =IF(F10<=6,"Bajo",IF(F10<=12,"Medio","Alto")) | H10: Prioritario
A11: 9 | B11: Inundaciones por lluvias extremas | C11: Ambiental | D11: 4 | E11: 4 | F11: =D11*E11 | G11: =IF(F11<=6,"Bajo",IF(F11<=12,"Medio","Alto")) | H11: Prioritario
A12: 10 | B12: Disposición inadecuada de lodos PTAP | C12: Ambiental | D12: 3 | E12: 4 | F12: =D12*E12 | G12: =IF(F12<=6,"Bajo",IF(F12<=12,"Medio","Alto"))
A13: 11 | B13: Aguas de lavado vertidas sin tratar | C13: Ambiental | D13: 3 | E13: 4 | F13: =D13*E13 | G13: =IF(F13<=6,"Bajo",IF(F13<=12,"Medio","Alto"))
A14: 12 | B14: Afectación de fauna y flora en obras | C14: Ambiental | D14: 2 | E14: 3 | F14: =D14*E14 | G14: =IF(F14<=6,"Bajo",IF(F14<=12,"Medio","Alto"))
A15: 13 | B15: Fallas de equipos de bombeo | C15: Operativo | D15: 3 | E15: 3 | F15: =D15*E15 | G15: =IF(F15<=6,"Bajo",IF(F15<=12,"Medio","Alto"))
A16: 14 | B16: Interrupción del suministro eléctrico | C16: Operativo | D16: 3 | E16: 4 | F16: =D16*E16 | G16: =IF(F16<=6,"Bajo",IF(F16<=12,"Medio","Alto"))
A17: 15 | B17: Accidentes laborales en obra | C17: SST | D17: 3 | E17: 4 | F17: =D17*E17 | G17: =IF(F17<=6,"Bajo",IF(F17<=12,"Medio","Alto"))
