Workbook

Sheet PORTADA
A1: UNIVERSIDAD NACIONAL DE COLOMBIA
A2: FACULTAD DE INGENIERIA - DEPTO. DE INGENIERIA CIVIL Y AGRICOLA
A3: FUNDAMENTOS EN CONSTRUCCION
A5: PRESUPUESTO GENERAL DE OBRA
A6: PROYECTO: MODULO 1 - CENTRO DE DESARROLLO INFANTIL (CDI) TESALIA (HUILA)
A7: ETAPA: OBRA GRIS
A9: CONTENIDO DEL LIBRO:
A10: 1. INSUMOS - lista de materiales, mano de obra y equipo con precios y fuentes
A11: 2. APU - analisis de precios unitarios de las 19 actividades
A12: 3. PRESUPUESTO - presupuesto jerarquico (capitulos e items) con AIU
A13: 4. AIU - justificacion del A.I.U. para proyecto publico
A14: 5. CANTIDADES - cuadro de cantidades con memoria/formula
... A20: Las cantidades provienen de los planos DWG; los precios son de referencia (Construdata 2025).

Sheet INSUMOS
A1: LISTA DE INSUMOS - CDI TESALIA (HUILA) - MODULO 1
A2: Precios de referencia COP - 2026. Fuente: cotizaciones de referencia (Argos, Homecenter, ferreterias y proveedores Huila), Construdata 2026 y SMLMV 2026 (Decreto 1469 de 2025). Reemplazar por cotizaciones formales si la entidad lo exige.
A3: CODIGO | B3: DESCRIPCION DEL INSUMO | C3: UNIDAD | D3: TIPO | E3: VALOR UNITARIO (COP) | F3: FUENTE
A4: M01 | B4: Cemento gris Portland Tipo I (saco 50 kg) | C4: saco | D4: MAT | E4: 34000 | F4: Cot. ref. Homecenter/Argos 2026
A5: M02 | B5: Arena de rio | C5: m3 | D5: MAT | E5: 82000 | F5: Cot. ref. proveedor agregados Neiva-Huila 2026
A6: M03 | B6: Arena lavada/pena | C6: m3 | D6: MAT | E6: 74000 | F6: Cot. ref. proveedor agregados Neiva-Huila 2026
A7: M04 | B7: Triturado / gravilla 3/4" | C7: m3 | D7: MAT | E7: 88000 | F7: Cot. ref. proveedor agregados Neiva-Huila 2026
A8: M05 | B8: Agua | C8: m3 | D8: MAT | E8: 8500 | F8: Tarifa acueducto / carrotanque 2026
A9: M06 | B9: Concreto premezclado 3000 psi (21 MPa) | C9: m3 | D9: MAT | E9: 590000 | F9: Cot. ref. Cementos Argos / Concretodo 2026
A10: M07 | B10: Concreto premezclado 1500 psi (solado) | C10: m3 | D10: MAT | E10: 430000 | F10: Cot. ref. Cementos Argos 2026
A11: M08 | B11: Acero de refuerzo fy=420 MPa (60000psi) figurado | C11: kg | D11: MAT | E11: 4800 | F11: Cot. ref. ferreteria/figurado (varilla 1/2") 2026
A12: M09 | B12: Alambre negro recocido No.18 | C12: kg | D12: MAT | E12: 7000 | F12: Cot. ref. ferreteria 2026
A13: M10 | B13: Malla electrosoldada 8mm (15x15) | C13: kg | D13: MAT | E13: 6500 | F13: Cot. ref. Acesco/ferreteria 2026
A14: M11 | B14: Bloque de concreto No.4 (hueco) | C14: und | D14: MAT | E14: 2700 | F14: Cot. ref. bloquera local Huila 2026
A15: M12 | B15: Bloque de concreto No.5 | C15: und | D15: MAT | E15: 3100 | F15: Cot. ref. bloquera local Huila 2026
... A32: EQ6 | B32: Cortadora y dobladora de hierro | C32: dia | D32: EQU | E32: 52000 | F32: Tarifa alquiler equipo 2026

Sheet APU
A1: ANALISIS DE PRECIOS UNITARIOS (APU) - CDI TESALIA - MODULO 1
A3: APU 2.1.1 | B3: Excavacion a maquina, conglomerado 0.0-2.0 m, incluye retiro y disposicion final (15 km) | C3: UND: M3
A4: CODIGO | B4: INSUMO / RECURSO | C4: UNIDAD | D4: CANT./REND. | E4: VR. UNITARIO | F4: VR. PARCIAL
A5: EQ1 | B5: Retroexcavadora sobre llantas [Retroexcavadora] | C5: hora | D5: 0.12 | E5: =INSUMOS!$E$27 | F5: =D5*E5
A6: EQ2 | B6: Volqueta - retiro y disposicion (hasta 15 km) [Retiro+disposicion (esponj. 1.25)] | C6: m3 | D6: 1.25 | E6: =INSUMOS!$E$28 | F6: =D6*E6
A7: MO2 | B7: Ayudante / obrero (jornal + prestaciones) [Ayudante] | C7: dia | D7: 0.01667 | E7: =INSUMOS!$E$26 | F7: =D7*E7
A8: HM | B8: Herramienta menor (5% de la mano de obra) | C8: % | D8: 0.05 | F8: =(F7)*0.05
B9: VALOR UNITARIO TOTAL - APU 2.1.1 | F9: =SUM(F5:F8)
A11: APU 2.1.2 | B11: Relleno compactado en material granular de subbase B-400 | C11: UND: M3
A12: CODIGO | B12: INSUMO / RECURSO | C12: UNIDAD | D12: CANT./REND. | E12: VR. UNITARIO | F12: VR. PARCIAL
A13: M15 | B13: Material granular subbase B-400 [Material granular B-400 (comp. 1.25)] | C13: m3 | D13: 1.25 | E13: =INSUMOS!$E$18 | F13: =D13*E13
A14: EQ5 | B14: Vibrocompactador tipo rana / canguro [Vibrocompactador] | C14: dia | D14: 0.025 | E14: =INSUMOS!$E$31 | F14: =D14*E14
A15: MO1 | B15: Oficial de construccion (jornal + prestaciones) [Oficial] | C15: dia | D15: 0.025 | E15: =INSUMOS!$E$25 | F15: =D15*E15
A16: MO2 | B16: Ayudante / obrero (jornal + prestaciones) [Ayudante x2] | C16: dia | D16: 0.05 | E16: =INSUMOS!$E$26 | F16: =D16*E16
A17: HM | B17: Herramienta menor (5% de la mano de obra) | C17: % | D17: 0.05 | F17: =(F15+F16)*0.05
B18: VALOR UNITARIO TOTAL - APU 2.1.2 | F18: =SUM(F13:F17)
A20: APU 2.1.3 | B20: Excavacion manual, material comun 0.0-2.0 m, incluye retiro (15 km) | C20: UND: M3
A21: CODIGO | B21: INSUMO / RECURSO | C21: UNIDAD | D21: CANT./REND. | E21: VR. UNITARIO | F21: VR. PARCIAL
A22: MO2 | B22: Ayudante / obrero (jornal + prestaciones) [Ayudante] | C22: dia | D22: 0.33333 | E22: =INSUMOS!$E$26 | F22: =D22*E22
A23: EQ2 | B23: Volqueta - retiro y disposicion (hasta 15 km) [Retiro+disposicion] | C23: m3 | D23: 1.25 | E23: =INSUMOS!$E$28 | F23: =D23*E23
A24: HM | B24: Herramienta menor (5% de la mano de obra) | C24: % | D24: 0.05 | F24: =(F22)*0.05
B25: VALOR UNITARIO TOTAL - APU 2.1.3 | F25: =SUM(F22:F24)
A27: APU 2.1.4 | B27: Relleno compactado con material comun (recebo) | C27: UND: M3
A28: CODIGO | B28: INSUMO / RECURSO | C28: UNIDAD | D28: CANT./REND. | E28: VR. UNITARIO | F28: VR. PARCIAL
A29: M16 | B29: Recebo comun compactable [Recebo comun (comp. 1.25)] | C29: m3 | D29: 1.25 | E29: =INSUMOS!$E$19 | F29: =D29*E29
A30: EQ5 | B30: Vibrocompactador tipo rana / canguro [Vibrocompactador] | C30: dia | D30: 0.025 | E30: =INSUMOS!$E$31 | F30: =D30*E30
A31: MO1 | B31: Oficial de construccion (jornal + prestaciones) [Oficial] | C31: dia | D31: 0.025 | E31: =INSUMOS!$E$25 | F31: =D31*E31
A32: MO2 | B32: Ayudante / obrero (jornal + prestaciones) [Ayudante x2] | C32: dia | D32: 0.05 | E32: =INSUMOS!$E$26 | F32: =D32*E32
A33: HM | B33: Herramienta menor (5% de la mano de obra) | C33: % | D33: 0.05 | F33: =(F31+F32)*0.05
B34: VALOR UNITARIO TOTAL - APU 2.1.4 | F34: =SUM(F29:F33)
A36: APU 2.1.6 | B36: Geotextil NT 1600, suministro e instalacion | C36: UND: M2
A37: CODIGO | B37: INSUMO / RECURSO | C37: UNIDAD | D37: CANT./REND. | E37: VR. UNITARIO | F37: VR. PARCIAL
A38: M14 | B38: Geotextil no tejido NT 1600 [Geotextil NT1600 (traslapo 1.10)] | C38: m2 | D38: 1.1 | E38: =INSUMOS!$E$17 | F38: =D38*E38
A39: MO2 | B39: Ayudante / obrero (jornal + prestaciones) [Ayudante] | C39: dia | D39: 0.00833 | E39: =INSUMOS!$E$26 | F39: =D39*E39
A40: HM | B40: Herramienta menor (5% de la mano de obra) | C40: % | D40: 0.05 | F40: =(F39)*0.05
B41: VALOR UNITARIO TOTAL - APU 2.1.6 | F41: =SUM(F38:F40)
A43: APU 2.2.1 | B43: Vigas de cimentacion en concreto 3000 psi (incluye formaleta, vibrado, curado, desmoldeante; no incluye acero) | C43: UND: M3
A44: CODIGO | B44: INSUMO / RECURSO | C44: UNIDAD | D44: CANT./REND. | E44: VR. UNITARIO | F44: VR. PARCIAL
A45: M06 | B45: Concreto premezclado 3000 psi (21 MPa) [Concreto 3000psi (1.03)] | C45: m3 | D45: 1.03 | E45: =INSUMOS!$E$9 | F45: =D45*E45
A46: M17 | B46: Formaleta (madera/metalica) - costo por uso [Formaleta] | C46: m2 | D46: 5 | E46: =INSUMOS!$E$20 | F46: =D46*E46
...

Sheet PRESUPUESTO
A1: PRESUPUESTO GENERAL DE OBRA - CDI TESALIA (HUILA) - MODULO 1 - ETAPA OBRA GRIS
A2: ITEM | B2: DESCRIPCION | C2: UND | D2: CANTIDAD | E2: VALOR UNITARIO | F2: VALOR TOTAL
A3: 2 | B3: CIMENTACION
A4: 2.1 | B4: EXCAVACIONES, RELLENOS Y REEMPLAZOS
A5: 2.1.1 | B5: Excavacion a maquina conglomerado 0-2m (incl. retiro 15km) | C5: M3 | D5: 118.91 | E5: =APU!$F$9 | F5: =D5*E5
A6: 2.1.2 | B6: Relleno compactado material granular subbase B-400 | C6: M3 | D6: 32.43 | E6: =APU!$F$18 | F6: =D6*E6
A7: 2.1.3 | B7: Excavacion manual material comun 0-2m (incl. retiro 15km) | C7: M3 | D7: 12.18 | E7: =APU!$F$25 | F7: =D7*E7
A8: 2.1.4 | B8: Relleno compactado material comun (recebo) | C8: M3 | D8: 43.24 | E8: =APU!$F$34 | F8: =D8*E8
A9: 2.1.6 | B9: Geotextil NT 1600 suministro e instalacion | C9: M2 | D9: 216.2 | E9: =APU!$F$41 | F9: =D9*E9
A10: 2.2 | B10: CONCRETOS DE CIMENTACION
A11: 2.2.1 | B11: Vigas de cimentacion concreto 3000psi (incl. formaleta) | C11: M3 | D11: 13.7 | E11: =APU!$F$53 | F11: =D11*E11
A12: 2.2.2 | B12: Concreto 1500psi para solados e=0.05m | C12: M2 | D12: 38.05 | E12: =APU!$F$61 | F12: =D12*E12
A13: 2.3 | B13: REFUERZOS DE CIMENTACION
A14: 2.3.1 | B14: Acero figurado 60000psi vigas de cimentacion | C14: KG | D14: 1302.6 | E14: =APU!$F$71 | F14: =D14*E14
A15: 4 | B15: ESTRUCTURA EN CONCRETO Y METALICAS
A16: 4.1 | B16: COLUMNAS EN CONCRETO
A17: 4.1.1 | B17: Columnas concreto 3000psi acabado a la vista | C17: M3 | D17: 7.84 | E17: =APU!$F$83 | F17: =D17*E17
A18: 4.2 | B18: VIGAS DE CUBIERTA EN CONCRETO
A19: 4.2.1 | B19: Concreto 3000psi para viga cinta / cubierta | C19: M3 | D19: 15.22 | E19: =APU!$F$94 | F19: =D19*E19
A20: 4.3 | B20: PLACA DE CONTRAPISO Y CUBIERTA
A21: 4.3.1 | B21: Concreto 3000psi losas de piso (contrapiso) e=0.10 | C21: M3 | D21: 21.62 | E21: =APU!$F$104 | F21: =D21*E21
A22: 4.3.3 | B22: Placa aligerada cubierta concreto 3000psi e=0.08 | C22: M2 | D22: 135.2 | E22: =APU!$F$115 | F22: =D22*E22
A23: 4.6 | B23: ACERO DE REFUERZO PLACA CONTRAPISO
A24: 4.6.1 | B24: Malla electrosoldada 8mm 15x15 contrapiso | C24: KG | D24: 1252.5 | E24: =APU!$F$123 | F24: =D24*E24
A25: 4.7 | B25: ACERO DE REFUERZO COLUMNAS
A26: 4.7.1 | B26: Acero figurado 60000psi columnas y otros | C26: KG | D26: 791.8 | E26: =APU!$F$133 | F26: =D26*E26
A27: 4.8 | B27: ACERO DE REFUERZO VIGAS DE CUBIERTA
A28: 4.8.1 | B28: Acero figurado 60000psi vigas de cubierta | C28: KG | D28: 1757.7 | E28: =APU!$F$143 | F28: =D28*E28
A29: 4.9 | B29: ACERO DE REFUERZO PLACAS CUBIERTA
A30: 4.9.1 | B30: Malla electrosoldada 8mm 15x15 placa cubierta | C30: KG | D30: 783.3 | E30: =APU!$F$151 | F30: =D30*E30
A31: 5 | B31: MAMPOSTERIA
A32: 5.1 | B32: MAMPOSTERIA Y PANETE
A33: 5.1.1 | B33: Muros bloque hueco No.4 (incl. mortero pega 1:3) | C33: M2 | D33: 402.75 | E33: =APU!$F$161 | F33: =D33*E33
A34: 5.1.2 | B34: Columneta de confinamiento bloque No.5 | C34: ML | D34: 168.2 | E34: =APU!$F$171 | F34: =D34*E34
A35: 5.1.4 | B35: Panete liso impermeabilizado mortero 1:4 muros | C35: M2 | D35: 261.79 | E35: =APU!$F$181 | F35: =D35*E35
A36: 5.2 | B36: ACERO DE REFUERZO MAMPOSTERIA CONFINADA
A37: 5.2.1 | B37: Acero figurado 60000psi mamposteria confinada | C37: KG | D37: 530.1 | E37: =APU!$F$191 | F37: =D37*E37
A38: 8 | B38: PISOS
A39: 8.1 | B39: PISOS ACABADOS
A40: 8.1.1 | B40: Adoquin en concreto 0.20x0.10x0.06m suministro e instalacion | C40: M2 | D40: 115.3 | E40: =APU!$F$202 | F40: =D40*E40
...

Sheet AIU
A1: JUSTIFICACION DEL A.I.U. - PROYECTO PUBLICO (CDI TESALIA)
A3: El A.I.U. corresponde a Administracion, Imprevistos y Utilidad. Por tratarse de un proyecto del
A4: sector publico (Centro de Desarrollo Infantil financiado con recursos publicos), se adopta un
A5: A.I.U. moderado y competitivo, acorde con licitaciones de infraestructura social en Colombia.
A7: COMPONENTE | B7: % | C7: SUSTENTACION
A8: Administracion (A) | B8: 8% | C8: Costos indirectos: direccion de obra, residente, almacenista, campamento, valla, polizas, servicios publicos provisionales, administracion central prorrateada.
A9: Imprevistos (I) | B9: 3% | C9: Cobertura de riesgos no previstos (clima, variacion menor de cantidades, reprocesos). Para obra publica suele estar entre 1% y 5%.
A10: Utilidad (U) | B10: 5% | C10: Ganancia razonable del contratista para proyecto publico (usual 5%).
A11: TOTAL A.I.U. | B11: 16%
A13: IVA | C13: En obra publica el IVA del 19% se liquida SOBRE LA UTILIDAD (Art. 462-1 E.T.), no sobre todo el contrato.
A15: Nota | C15: Si la entidad exige otro AIU (p.ej. 25% A+5% I+5% U), basta cambiar los porcentajes en la hoja PRESUPUESTO.

Sheet CANTIDADES
A1: CUADRO DE CANTIDADES DE OBRA - SOPORTE DE CALCULO
A2: ITEM | B2: DESCRIPCION | C2: UND | D2: CANTIDAD | E2: MEMORIA / FORMULA DE CALCULO
A3: 2.1.1 | B3: Excavacion a maquina conglomerado 0-2m (incl. retiro 15km) | C3: M3 | D3: 118.91 | E3: A_plataforma 216.20 m2 x prof. masiva 0.55 m
A4: 2.1.2 | B4: Relleno compactado material granular subbase B-400 | C4: M3 | D4: 32.43 | E4: A_placa 216.20 m2 x espesor capa 0.15 m
A5: 2.1.3 | B5: Excavacion manual material comun 0-2m (incl. retiro 15km) | C5: M3 | D5: 12.18 | E5: Afinado zanjas vigas: L 76.10 m x 0.40 x 0.40 m
A6: 2.1.4 | B6: Relleno compactado material comun (recebo) | C6: M3 | D6: 43.24 | E6: A_placa 216.20 m2 x espesor nivelacion 0.20 m
A7: 2.1.6 | B7: Geotextil NT 1600 suministro e instalacion | C7: M2 | D7: 216.2 | E7: Area placa contrapiso 216.20 m2
A8: 2.2.1 | B8: Vigas de cimentacion concreto 3000psi (incl. formaleta) | C8: M3 | D8: 13.7 | E8: L_vigas 76.10 m x 0.40 x 0.45 m
A9: 2.2.2 | B9: Concreto 1500psi para solados e=0.05m | C9: M2 | D9: 38.05 | E9: L_vigas 76.10 m x ancho solado 0.50 m
A10: 2.3.1 | B10: Acero figurado 60000psi vigas de cimentacion | C10: KG | D10: 1302.6 | E10: Ver cartilla de hierros (cimentacion)
A11: 4.1.1 | B11: Columnas concreto 3000psi acabado a la vista | C11: M3 | D11: 7.84 | E11: 10 col x 0.40 x 0.40 x 4.90 m
A12: 4.2.1 | B12: Concreto 3000psi para viga cinta / cubierta | C12: M3 | D12: 15.22 | E12: L_vigas cubierta 76.10 m x 0.40 x 0.50 m
A13: 4.3.1 | B13: Concreto 3000psi losas de piso (contrapiso) e=0.10 | C13: M3 | D13: 21.62 | E13: Area 216.20 m2 x espesor 0.10 m
A14: 4.3.3 | B14: Placa aligerada cubierta concreto 3000psi e=0.08 | C14: M2 | D14: 135.2 | E14: Area placa cubierta 7.30 x 18.52 = 135.20 m2
... A23: 8.1.1 | B23: Adoquin en concreto 0.20x0.10x0.06m suministro e instalacion | C23: M2 | D23: 115.3 | E23: Suma 9 areas adoquinadas = 115.30 m2

Sheet CARTILLA HIERROS
A1: CARTILLA DE HIERROS / DESPIECE DE ACERO - CDI TESALIA MODULO 1
A2: Pesos: #2=0.250 #3=0.560 #4=0.994 #5=1.552 #6=2.235 #7=3.042 kg/m. Incluye 10% por desperdicio y traslapos.
A3: ITEM 2.3.1 - ACERO VIGAS DE CIMENTACION (40x45)
B4: Long. 3#6+3#5 (kg) | C4: 864.6 | D4: kg
B5: Estribos #3 c/0.20 (kg) | C5: 319.6 | D5: kg
B6: Subtotal (kg) | C6: 1184.2 | D6: kg
B7: Con 10% desperd/traslapo (kg) | C7: 1302.6 | D7: kg
A9: ITEM 4.7.1 - ACERO COLUMNAS (2#6+2#7, estribo #2 c/0.20)
B10: Long. 10col x (2#6+2#7) L=5.95 (kg) | C10: 628 | D10: kg
B11: Estribos #2 c/0.20 (kg) | C11: 91.9 | D11: kg
B12: Subtotal (kg) | C12: 719.8 | D12: kg
B13: Con 10% (kg) | C13: 791.8 | D13: kg
A15: ITEM 4.8.1 - ACERO VIGAS DE CUBIERTA (40x50)
B16: Long. 2#6+2#7+2#6 (kg) | C16: 1143.3 | D16: kg
B17: Estribos #3 c/0.15 (kg) | C17: 454.6 | D17: kg
B18: Subtotal (kg) | C18: 1597.9 | D18: kg
B19: Con 10% (kg) | C19: 1757.7 | D19: kg
A21: ITEM 5.2.1 - ACERO MAMPOSTERIA CONFINADA (columnetas)
B22: Long. 4#3 (kg) | C22: 376.8 | D22: kg
B23: Estribos #2 c/0.20 (kg) | C23: 105.1 | D23: kg
B24: Subtotal (kg) | C24: 481.9 | D24: kg
B25: Con 10% (kg) | C25: 530.1 | D25: kg
A27: MALLAS ELECTROSOLDADAS 8mm @0.15 (densidad 5.27 kg/m2 + 10%)
B28: Item 4.6.1 - Malla contrapiso (216.20 m2) | C28: 1252.5 | D28: kg
B29: Item 4.9.1 - Malla placa cubierta (135.20 m2) | C29: 783.3 | D29: kg

Sheet PROGRAMACION
A1: PROGRAMACION DE OBRA (base para Microsoft Project) - CDI TESALIA MODULO 1
A2: No. | B2: ACTIVIDAD | C2: DURACION (dias) | D2: PREDECESORA | E2: RECURSOS PRINCIPALES (del APU)
A3: 1 | B3: Preliminares y localizacion | C3: 3 | D3: - | E3: Comision topografia, ayudantes
A4: 2 | B4: Excavacion a maquina (2.1.1) | C4: 4 | D4: 1 | E4: Retroexcavadora, volqueta, ayudante
A5: 3 | B5: Excavacion manual y afinado (2.1.3) | C5: 3 | D5: 2 | E5: Ayudantes
A6: 4 | B6: Solado 1500psi (2.2.2) | C6: 2 | D6: 3 | E6: Cuadrilla concreto
A7: 5 | B7: Figurado y armado acero cimentacion (2.3.1) | C7: 4 | D7: 3 | E7: Figurador, oficial, cortadora
A8: 6 | B8: Fundida vigas de cimentacion (2.2.1) | C8: 3 | D8: 4,5 | E8: Cuadrilla concreto, vibrador, formaleta
A9: 7 | B9: Subbase B-400 + geotextil (2.1.2/2.1.6) | C9: 3 | D9: 6 | E9: Material granular, rana, ayudantes
A10: 8 | B10: Relleno recebo (2.1.4) | C10: 2 | D10: 7 | E10: Recebo, rana
A11: 9 | B11: Armado y fundida columnas (4.1.1/4.7.1) | C11: 6 | D11: 6 | E11: Cuadrilla concreto, formaleta, figurado
A12: 10 | B12: Malla y fundida contrapiso (4.3.1/4.6.1) | C12: 4 | D12: 8 | E12: Cuadrilla concreto, malla
A13: 11 | B13: Armado y fundida vigas cubierta (4.2.1/4.8.1) | C13: 6 | D13: 9 | E13: Cuadrilla concreto, formaleta, figurado
A14: 12 | B14: Placa aligerada cubierta (4.3.3/4.9.1) | C14: 6 | D14: 11 | E14: Cuadrilla concreto, casetones, malla
... A18: 16 | B18: Adoquin exterior (8.1.1) | C18: 5 | D18: 15 | E18: Cuadrilla pisos, rana
B19: DURACION TOTAL ESTIMADA (con traslapos en MSP) | C19: ~ 60-70 dias
